Workbook

Sheet DATOS
B1: ÁREAS TRIBUTARIAS Y CARGAS PARA STAAD — HANGAR NOSE-DOCK H5-H6 — DATOS (R3.7)
B2: Largueros y vigas de techo y largueros de muro del modelo 001_NOSE_DOCK_H5_H6_R3.7.STD (en el modelo: cm y kg)
B4: 1. CARGAS MUERTAS (TABLA DE CM DEL PROYECTO)
B5: Concepto | C5: Valor | D5: Unidad | E5: Cómo se calcula / de dónde sale | F5: Referencia
B6: Panel sándwich GLAMET (Metecno) PUR/PIR 1.5" — techo | C6: 9.32 | D6: kg/m² | E6: CAPTURA. Renglón 1 de la tabla de CM, columna Techos. | F6: Tabla de CM del proyecto (foto) · renglón 1
B7: Instalaciones generales (iluminación, datos) — techo | C7: 10 | D7: kg/m² | E7: CAPTURA. Renglón 2 de la tabla de CM, columna Techos. | F7: Tabla de CM del proyecto (foto) · renglón 2
B8: CM de techo | C8: =C6+C7 | D8: kg/m² | E8: CALCULADA = panel + instalaciones. No incluye el acero: ése lo mete STAAD con SELFWEIGHT. | F8: Tabla de CM del proyecto · total Techos (19.32)
B9: Lámina SSR KR-18 acanalada cal. 24 — muros | C9: 5.85 | D9: kg/m² | E9: CAPTURA. Renglón 3 de la tabla de CM, columna Muros. | F9: Tabla de CM del proyecto (foto) · renglón 3
B10: CM de muros | C10: =C9 | D10: kg/m² | E10: CALCULADA. Se aplica como carga vertical en los largueros de muro. | F10: Tabla de CM del proyecto · total Muros (5.85)
B12: 2. CARGA VIVA DE TECHO — RESESCO 1996
B13: La tabla del Reglamento cambia con la pendiente: hasta 5% (inciso h) w_m = 100, w_i = 50; más de 5% (inciso i) w_m = 20, w_i = 0 kg/m².
B14: Concepto | C14: Valor | D14: Unidad | E14: Cómo se calcula / de dónde sale | F14: Referencia
B15: Y del techo en el eje 1 (Z = 0) | C15: 10.43 | D15: m | E15: CAPTURA del modelo: nodos 7 y 8, Y = 1043 cm. | F15: 001_NOSE_DOCK_H5_H6_R3.7.STD · JOINT COORDINATES
B16: Y del techo en el eje 3 (Z = 16 m) | C16: 9.60002 | D16: m | E16: CAPTURA del modelo: nodos 9 y 10, Y = 960.002 cm. | F16: 001_NOSE_DOCK_H5_H6_R3.7.STD · JOINT COORDINATES
B17: L — largo en el sentido de la pendiente (eje 1 a eje 3) | C17: =C33-C31 | D17: m | E17: CALCULADA con los ejes de la sección 3 (Z de 0 a 1600 cm). | F17: 001_NOSE_DOCK_H5_H6_R3.7.STD · JOINT COORDINATES
B18: Pendiente del modelo = (Y₁ − Y₃) / L | C18: =(C15-C16)/C17 | D18: % | E18: CALCULADA con la geometría de STAAD (0.83 m de caída en 16 m). | F18: Geometría del modelo
B19: θ — ángulo del techo | C19: =DEGREES(ATAN(C18)) | D19: ° | E19: CALCULADA = arctan(pendiente). | F19: —
B20: Pendiente que rige (arquitectónico) | C20: 0.054 | D20: % | E20: CAPTURA. La que indicaste (5.4%); el modelo R3.7 da 5.19%. Las dos pasan de 5%: w_m y w_i se ajustan solos si la cambias. | F20: Arquitectónico (dato del proyecto)
B21: Inciso de la tabla que aplica | C21: =IF(C20>0.05,"i) pendiente mayor de 5%","h) pendiente no mayor de 5%") | D21: — | E21: CALCULADA con la pendiente que rige. | F21: RESESCO 1996 · Tabla de Cargas Vivas Unitarias Mínimas, incisos h) e i), pág. 12
B22: w_m — carga viva máxima (caso 2 CV) | C22: =IF(C20>0.05,20,100) | D22: kg/m² | E22: CALCULADA. Para diseño por gravedad (combinación 1.4CM + 1.7CV). | F22: RESESCO · Art. 25 num. 1, pág. 9 · Tabla, pág. 12
B23: w_i — carga viva instantánea (caso 3 CVR y masa sísmica) | C23: =IF(C20>0.05,0,50) | D23: kg/m² | E23: CALCULADA. Para sismo y viento; con 0 el caso 3 queda vacío y no suma masa. | F23: RESESCO · Art. 25 num. 2, pág. 10 · Tabla, pág. 12
B24: w — carga viva media | C24: =IF(C20>0.05,5,15) | D24: kg/m² | E24: CALCULADA. Sólo para deflexiones diferidas. | F24: RESESCO · Art. 25 num. 3, pág. 10 · Tabla, pág. 12
B25: Carga concentrada en elementos de cubierta | C25: 100 | D25: kg | E25: Revisión aparte de largueros y vigas de techo: 100 kg en la posición más crítica (no es un caso general de STAAD). | F25: RESESCO · Observación 5 a la tabla, pág. 13
B27: 3. GEOMETRÍA DEL MODELO
B28: Concepto | C28: Valor | D28: Unidad | E28: Cómo se calcula / de dónde sale | F28: Referencia
B29: Claro de largueros de techo (eje A a eje B) | C29: 10.08 | D29: m | E29: CAPTURA del modelo: X de 0 a 1008 cm. | F29: .STD R3.7 · nodos 7 y 8
B30: Mitad del claro (lo que cada larguero entrega a cada viga de alero) | C30: =C29/2 | D30: m | E30: CALCULADA. Ancho en X del área de las vigas VA y VB y de los nodos de cabeza de columna. | F30: Criterio de área tributaria
B31: Z del eje 1 | C31: 0 | D31: m | E31: CAPTURA del modelo. | F31: .STD R3.7 · nodos 1 y 4
B32: Z del eje 2 | C32: 10 | D32: m | E32: CAPTURA del modelo. Desde la R2.7 los marcos intermedios pasaron de 6.75 y 13.50 m a uno solo en 10.00 m. | F32: .STD R3.7 · nodos 2 y 5
B33: Z del eje 3 | C33: 16 | D33: m | E33: CAPTURA del modelo. | F33: .STD R3.7 · nodos 3 y 6
B34: Y del techo en el eje 2 (Z = 10 m) | C34: 9.91126 | D34: m | E34: CAPTURA del modelo: nodos 75 y 76, Y = 991.126 cm. | F34: .STD R3.7 · JOINT COORDINATES
B35: Factor por pendiente 1 / cos θ | C35: =1/COS(RADIANS(C19)) | D35: — | E35: CALCULADA. Las áreas van en proyección horizontal: este factor se desprecia. | F35: —
B36: Nivel del último larguero de muro | C36: 9.6 | D36: m | E36: CAPTURA del modelo: largueros de muro a 1.20, 2.40 … 9.60 m. | F36: .STD R3.7
B37: Franja de la base (baja directo a la cimentación) | C37: 0.6 | D37: m | E37: CALCULADA a mano = mitad de 1.20 m (del piso al primer larguero). No carga largueros. | F37: Criterio de área tributaria
B39: 4. CRITERIOS
B40: 1. Los PIPX7 del techo no se consideran portantes: cada larguero MC12-14 trabaja de alero a alero (10.08 m) y entrega la mitad a cada viga de alero MCC12-12.
B41: 2. En los ejes 1, 2 y 3 no hay larguero en el modelo: la franja de ese eje la toma directo la viga MCC12-12 del marco (VM-1 a VM-3).
B42: 3. Techo: franja de cada línea = mitad de la separación a cada lado. Muros: igual en vertical; la franja de abajo (0.00–0.60 m) baja directo a la base y la de arriba va a la viga de alero (ejes A y B) o a la VM-1 (eje 1). Los vanos no llevan lámina: la cortina carga su peso al dintel (miembro 234) y su viento a las jambas; la puerta de 1.22 × 2.40 carga su viento a su dintel (hoja de viento).
B43: 4. El eje 3 (Z = 16 m) no tiene largueros de muro en el modelo: se tomó sin muro (frente abierto).
B44: 5. En STAAD (R3.7): CM y CV de techo como UNI GY en cada larguero y viga con su franja b (hoja TECHO); muros como UNI GY con una carga por larguero completo (hoja MUROS), con la franja de VA y VB en un valor por tramo (tabla D); masa sísmica: techo en las 6 cabezas de columna (hoja NODOS_TECHO, FX y FZ) y muros y cortina en sus miembros (UNI GX y GZ).
...

Sheet TECHO
B1: TECHO — ÁREAS TRIBUTARIAS DE LARGUEROS MC12-14 Y VIGAS DE MARCO MCE12-12 (R3.7)
B2: Planta en proyección horizontal. Las líneas en X (largueros LT y vigas de marco VM) reciben su franja; las vigas de alero VA y VB reciben la mitad del claro de cada larguero. Mismas áreas que el DXF R2.9. En STAAD la CM y la CV van en UNI GY en cada línea con su franja b (hoja STAAD); la masa del techo va a las cabezas de columna (hoja NODOS_TECHO).
B4: A. LÍNEAS EN X — LARGUEROS LT Y VIGAS DE MARCO VM
B5: ID | C5: Elemento | D5: Perfil | E5: Z (m) | F5: Franja desde (m) | G5: Franja hasta (m) | H5: b (m) | I5: Claro (m) | J5: A (m²) | K5: w CM (kg/m) | L5: w CV (kg/m) | M5: w CVi (kg/m) | N5: R extremo CM (kg) | O5: R extremo CV (kg) | P5: Miembros STAAD | Q5: Referencia
E6: del modelo | F6: (Z ant. + Z)/2 | G6: (Z + Z sig.)/2 | H6: hasta − desde | I6: DATOS C29 | J6: b × claro | K6: CM techo × b | L6: w_m × b | M6: w_i × b | N6: w CM × claro/2 | O6: w CV × claro/2 | P6: del .STD
B7: VM-1 | C7: Viga de marco eje 1 | D7: MCE12-12 | E7: 0 | F7: =E7 | G7: =(E7+E8)/2 | H7: =G7-F7 | I7: =DATOS!$C$29 | J7: =H7*I7 | K7: =DATOS!$C$8*H7 | L7: =DATOS!$C$22*H7 | M7: =DATOS!$C$23*H7 | N7: =K7*I7/2 | O7: =L7*I7/2 | P7: 11 48 TO 51 | Q7: .STD R3.7 · nodos 7 a 8 (Z = 0 cm)
B8: LT-1 | C8: Larguero de techo | D8: MC12-14 | E8: 1 | F8: =(E7+E8)/2 | G8: =(E8+E9)/2 | H8: =G8-F8 | I8: =DATOS!$C$29 | J8: =H8*I8 | K8: =DATOS!$C$8*H8 | L8: =DATOS!$C$22*H8 | M8: =DATOS!$C$23*H8 | N8: =K8*I8/2 | O8: =L8*I8/2 | P8: 327 372 TO 375 | Q8: .STD R3.7 · nodos 170 a 176 (Z = 100 cm)
B9: LT-2 | C9: Larguero de techo | D9: MC12-14 | E9: 2.5 | F9: =(E8+E9)/2 | G9: =(E9+E10)/2 | H9: =G9-F9 | I9: =DATOS!$C$29 | J9: =H9*I9 | K9: =DATOS!$C$8*H9 | L9: =DATOS!$C$22*H9 | M9: =DATOS!$C$23*H9 | N9: =K9*I9/2 | O9: =L9*I9/2 | P9: 326 368 TO 371 | Q9: .STD R3.7 · nodos 169 a 175 (Z = 250 cm)
B10: LT-3 | C10: Larguero de techo | D10: MC12-14 | E10: 4 | F10: =(E9+E10)/2 | G10: =(E10+E11)/2 | H10: =G10-F10 | I10: =DATOS!$C$29 | J10: =H10*I10 | K10: =DATOS!$C$8*H10 | L10: =DATOS!$C$22*H10 | M10: =DATOS!$C$23*H10 | N10: =K10*I10/2 | O10: =L10*I10/2 | P10: 325 364 TO 367 | Q10: .STD R3.7 · nodos 168 a 174 (Z = 400 cm)
B11: LT-4 | C11: Larguero de techo | D11: MC12-14 | E11: 5.5 | F11: =(E10+E11)/2 | G11: =(E11+E12)/2 | H11: =G11-F11 | I11: =DATOS!$C$29 | J11: =H11*I11 | K11: =DATOS!$C$8*H11 | L11: =DATOS!$C$22*H11 | M11: =DATOS!$C$23*H11 | N11: =K11*I11/2 | O11: =L11*I11/2 | P11: 324 360 TO 363 | Q11: .STD R3.7 · nodos 167 a 173 (Z = 550 cm)
B12: LT-5 | C12: Larguero de techo | D12: MC12-14 | E12: 7 | F12: =(E11+E12)/2 | G12: =(E12+E13)/2 | H12: =G12-F12 | I12: =DATOS!$C$29 | J12: =H12*I12 | K12: =DATOS!$C$8*H12 | L12: =DATOS!$C$22*H12 | M12: =DATOS!$C$23*H12 | N12: =K12*I12/2 | O12: =L12*I12/2 | P12: 323 356 TO 359 | Q12: .STD R3.7 · nodos 166 a 172 (Z = 700 cm)
B13: LT-6 | C13: Larguero de techo | D13: MC12-14 | E13: 8.5 | F13: =(E12+E13)/2 | G13: =(E13+E14)/2 | H13: =G13-F13 | I13: =DATOS!$C$29 | J13: =H13*I13 | K13: =DATOS!$C$8*H13 | L13: =DATOS!$C$22*H13 | M13: =DATOS!$C$23*H13 | N13: =K13*I13/2 | O13: =L13*I13/2 | P13: 322 352 TO 355 | Q13: .STD R3.7 · nodos 165 a 171 (Z = 850 cm)
B14: VM-2 | C14: Viga de marco eje 2 | D14: MCE12-12 | E14: 10 | F14: =(E13+E14)/2 | G14: =(E14+E15)/2 | H14: =G14-F14 | I14: =DATOS!$C$29 | J14: =H14*I14 | K14: =DATOS!$C$8*H14 | L14: =DATOS!$C$22*H14 | M14: =DATOS!$C$23*H14 | N14: =K14*I14/2 | O14: =L14*I14/2 | P14: 74 121 TO 124 | Q14: .STD R3.7 · nodos 75 a 76 (Z = 1000 cm)
B15: LT-7 | C15: Larguero de techo | D15: MC12-14 | E15: 11.5 | F15: =(E14+E15)/2 | G15: =(E15+E16)/2 | H15: =G15-F15 | I15: =DATOS!$C$29 | J15: =H15*I15 | K15: =DATOS!$C$8*H15 | L15: =DATOS!$C$22*H15 | M15: =DATOS!$C$23*H15 | N15: =K15*I15/2 | O15: =L15*I15/2 | P15: 287 318 TO 321 | Q15: .STD R3.7 · nodos 133 a 136 (Z = 1150 cm)
B16: LT-8 | C16: Larguero de techo | D16: MC12-14 | E16: 13 | F16: =(E15+E16)/2 | G16: =(E16+E17)/2 | H16: =G16-F16 | I16: =DATOS!$C$29 | J16: =H16*I16 | K16: =DATOS!$C$8*H16 | L16: =DATOS!$C$22*H16 | M16: =DATOS!$C$23*H16 | N16: =K16*I16/2 | O16: =L16*I16/2 | P16: 286 314 TO 317 | Q16: .STD R3.7 · nodos 134 a 137 (Z = 1300 cm)
B17: LT-9 | C17: Larguero de techo | D17: MC12-14 | E17: 14.5 | F17: =(E16+E17)/2 | G17: =(E17+E18)/2 | H17: =G17-F17 | I17: =DATOS!$C$29 | J17: =H17*I17 | K17: =DATOS!$C$8*H17 | L17: =DATOS!$C$22*H17 | M17: =DATOS!$C$23*H17 | N17: =K17*I17/2 | O17: =L17*I17/2 | P17: 285 310 TO 313 | Q17: .STD R3.7 · nodos 135 a 138 (Z = 1450 cm)
B18: VM-3 | C18: Viga de marco eje 3 | D18: MCE12-12 | E18: 16 | F18: =(E17+E18)/2 | G18: =E18 | H18: =G18-F18 | I18: =DATOS!$C$29 | J18: =H18*I18 | K18: =DATOS!$C$8*H18 | L18: =DATOS!$C$22*H18 | M18: =DATOS!$C$23*H18 | N18: =K18*I18/2 | O18: =L18*I18/2 | P18: 12 52 TO 55 | Q18: .STD R3.7 · nodos 9 a 10 (Z = 1600 cm)
B19: Total | C19: Suma de áreas de techo (debe dar claro × largo = 10.08 × 16.00) | J19: =SUM(J7:J18) | K19: =IF(ABS(J19-DATOS!$C$29*(DATOS!$C$33-DATOS!$C$31))<0.01,"CUADRA","NO CUADRA")
B21: B. VIGAS DE ALERO MCE12-12 (EJES A Y B) — RECIBEN LA MITAD DE CADA LARGUERO
B22: Área = franja en Z de los largueros que se le apoyan × mitad del claro de los largueros. Sirve para diseñar las vigas de alero.
B23: ID | C23: Eje y tramo | D23: Perfil | E23: Largueros que recibe | F23: Franja desde (m) | G23: Franja hasta (m) | H23: Ancho en Z (m) | I23: Ancho en X (m) | J23: A (m²) | K23: CM total (kg) | L23: CV total (kg) | M23: Nº de largueros | N23: R CM por larguero (kg) | O23: R CV por larguero (kg) | P23: Miembros STAAD | Q23: Referencia
F24: del 1er larguero | G24: del último larguero | H24: hasta − desde | I24: DATOS C30 | J24: Z × X | K24: CM techo × A | L24: w_m × A | N24: CM total ÷ Nº | O24: CV total ÷ Nº | P24: del .STD
B25: VA-1 | C25: Eje A, tramo 1-2 | D25: MCE12-12 | E25: LT-1 a LT-6 | F25: =F8 | G25: =G13 | H25: =G25-F25 | I25: =DATOS!$C$30 | J25: =H25*I25 | K25: =DATOS!$C$8*J25 | L25: =DATOS!$C$22*J25 | M25: 6 | N25: =K25/M25 | O25: =L25/M25 | P25: 241 269 TO 274 605 606 | Q25: .STD R3.7 · X = 0 cm, Z 0 a 1000 cm
B26: VA-2 | C26: Eje A, tramo 2-3 | D26: MCE12-12 | E26: LT-7 a LT-9 | F26: =F15 | G26: =G17 | H26: =G26-F26 | I26: =DATOS!$C$30 | J26: =H26*I26 | K26: =DATOS!$C$8*J26 | L26: =DATOS!$C$22*J26 | M26: 3 | N26: =K26/M26 | O26: =L26/M26 | P26: 243 245 TO 247 601 602 | Q26: .STD R3.7 · X = 0 cm, Z 1000 a 1600 cm
B27: VB-1 | C27: Eje B, tramo 1-2 | D27: MCE12-12 | E27: LT-1 a LT-6 | F27: =F8 | G27: =G13 | H27: =G27-F27 | I27: =DATOS!$C$30 | J27: =H27*I27 | K27: =DATOS!$C$8*J27 | L27: =DATOS!$C$22*J27 | M27: 6 | N27: =K27/M27 | O27: =L27/M27 | P27: 242 275 TO 280 607 608 | Q27: .STD R3.7 · X = 1008 cm, Z 0 a 1000 cm
B28: VB-2 | C28: Eje B, tramo 2-3 | D28: MCE12-12 | E28: LT-7 a LT-9 | F28: =F15 | G28: =G17 | H28: =G28-F28 | I28: =DATOS!$C$30 | J28: =H28*I28 | K28: =DATOS!$C$8*J28 | L28: =DATOS!$C$22*J28 | M28: 3 | N28: =K28/M28 | O28: =L28/M28 | P28: 244 248 TO 250 603 604 | Q28: .STD R3.7 · X = 1008 cm, Z 1000 a 1600 cm
B29: Total | C29: Vigas de alero + franjas directas de VM (debe dar el total del techo) | J29: =SUM(J25:J28)+J7+J14+J18 | K29: =IF(ABS(J29-J19)<0.01,"CUADRA","NO CUADRA")

Sheet MUROS
B1: MUROS — ÁREAS TRIBUTARIAS DE LARGUEROS DE MURO
B2: Elevaciones de los muros de los ejes A, B (laterales) y 1 (frontal). Franja de cada larguero = mitad de la distancia al miembro de abajo y al de arriba. Carga vertical de la lámina (CM de muros). El eje 3 (Z = 16 m) no tiene largueros en el modelo (frente abierto).
B4: A. MUROS LATERALES — EJE A (X = 0) Y EJE B (X = 10.08 m) — LARGUEROS MCC10-14
B5: ID | C5: Muro | D5: Nivel | E5: Y larguero (m) | F5: Tramo (ejes) | G5: L (m) | H5: Y abajo (m) | I5: Y arriba inicio (m) | J5: Y arriba fin (m) | K5: Franja desde (m) | L5: Franja hasta inicio (m) | M5: Franja hasta fin (m) | N5: h (m) | O5: A (m²) | P5: w CM (kg/m) | Q5: STAAD CM (kg/cm) | R5: Miembro STAAD | S5: Referencia
E6: del modelo | G6: del modelo | H6: miembro de abajo (0 = base) | I6: miembro de arriba | J6: miembro de arriba | K6: (Y ab. + Y)/2 | L6: (Y + Y arr.)/2 | M6: (Y + Y arr.)/2 | N6: promedio | O6: L × h | P6: CM muros × h | Q6: −w ÷ 100 | R6: del .STD
B7: LA-1.1 | C7: Eje A | D7: 1 | E7: 1.2 | F7: 1-2 | G7: =DATOS!$C$32-DATOS!$C$31 | H7: 0 | I7: 2.4 | J7: 2.4 | K7: =(H7+E7)/2 | L7: =(E7+I7)/2 | M7: =(E7+J7)/2 | N7: =(L7+M7)/2-K7 | O7: =G7*N7 | P7: =DATOS!$C$10*N7 | Q7: =-P7/100 | R7: 16 501 TO 503 | S7: .STD R3.7 · nodos 11–12
B8: LA-1.2 | C8: Eje A | D8: 1 | E8: 1.2 | F8: 2-3 | G8: =DATOS!$C$33-DATOS!$C$32 | H8: 0 | I8: 2.4 | J8: 2.4 | K8: =(H8+E8)/2 | L8: =(E8+I8)/2 | M8: =(E8+J8)/2 | N8: =(L8+M8)/2-K8 | O8: =G8*N8 | P8: =DATOS!$C$10*N8 | Q8: =-P8/100 | R8: 199 549 550 | S8: .STD R3.7 · nodos 12–13
B9: LA-2.1 | C9: Eje A | D9: 2 | E9: 2.4 | F9: 1-2 | G9: =DATOS!$C$32-DATOS!$C$31 | H9: 1.2 | I9: 3.6 | J9: 3.6 | K9: =(H9+E9)/2 | L9: =(E9+I9)/2 | M9: =(E9+J9)/2 | N9: =(L9+M9)/2-K9 | O9: =G9*N9 | P9: =DATOS!$C$10*N9 | Q9: =-P9/100 | R9: 20 507 TO 509 | S9: .STD R3.7 · nodos 17–18
B10: LA-2.2 | C10: Eje A | D10: 2 | E10: 2.4 | F10: 2-3 | G10: =DATOS!$C$33-DATOS!$C$32 | H10: 1.2 | I10: 3.6 | J10: 3.6 | K10: =(H10+E10)/2 | L10: =(E10+I10)/2 | M10: =(E10+J10)/2 | N10: =(L10+M10)/2-K10 | O10: =G10*N10 | P10: =DATOS!$C$10*N10 | Q10: =-P10/100 | R10: 201 553 554 | S10: .STD R3.7 · nodos 18–19
B11: LA-3.1 | C11: Eje A | D11: 3 | E11: 3.6 | F11: 1-2 | G11: =DATOS!$C$32-DATOS!$C$31 | H11: 2.4 | I11: 4.8 | J11: 4.8 | K11: =(H11+E11)/2 | L11: =(E11+I11)/2 | M11: =(E11+J11)/2 | N11: =(L11+M11)/2-K11 | O11: =G11*N11 | P11: =DATOS!$C$10*N11 | Q11: =-P11/100 | R11: 24 513 TO 515 | S11: .STD R3.7 · nodos 23–24
B12: LA-3.2 | C12: Eje A | D12: 3 | E12: 3.6 | F12: 2-3 | G12: =DATOS!$C$33-DATOS!$C$32 | H12: 2.4 | I12: 4.8 | J12: 4.8 | K12: =(H12+E12)/2 | L12: =(E12+I12)/2 | M12: =(E12+J12)/2 | N12: =(L12+M12)/2-K12 | O12: =G12*N12 | P12: =DATOS!$C$10*N12 | Q12: =-P12/100 | R12: 205 557 558 | S12: .STD R3.7 · nodos 24–25
B13: LA-4.1 | C13: Eje A | D13: 4 | E13: 4.8 | F13: 1-2 | G13: =DATOS!$C$32-DATOS!$C$31 | H13: 3.6 | I13: 6 | J13: 6 | K13: =(H13+E13)/2 | L13: =(E13+I13)/2 | M13: =(E13+J13)/2 | N13: =(L13+M13)/2-K13 | O13: =G13*N13 | P13: =DATOS!$C$10*N13 | Q13: =-P13/100 | R13: 28 519 TO 521 | S13: .STD R3.7 · nodos 29–30
B14: LA-4.2 | C14: Eje A | D14: 4 | E14: 4.8 | F14: 2-3 | G14: =DATOS!$C$33-DATOS!$C$32 | H14: 3.6 | I14: 6 | J14: 6 | K14: =(H14+E14)/2 | L14: =(E14+I14)/2 | M14: =(E14+J14)/2 | N14: =(L14+M14)/2-K14 | O14: =G14*N14 | P14: =DATOS!$C$10*N14 | Q14: =-P14/100 | R14: 207 561 562 | S14: .STD R3.7 · nodos 30–31
B15: LA-5.1 | C15: Eje A | D15: 5 | E15: 6 | F15: 1-2 | G15: =DATOS!$C$32-DATOS!$C$31 | H15: 4.8 | I15: 7.2 | J15: 7.2 | K15: =(H15+E15)/2 | L15: =(E15+I15)/2 | M15: =(E15+J15)/2 | N15: =(L15+M15)/2-K15 | O15: =G15*N15 | P15: =DATOS!$C$10*N15 | Q15: =-P15/100 | R15: 32 525 TO 527 | S15: .STD R3.7 · nodos 35–36
B16: LA-5.2 | C16: Eje A | D16: 5 | E16: 6 | F16: 2-3 | G16: =DATOS!$C$33-DATOS!$C$32 | H16: 4.8 | I16: 7.2 | J16: 7.2 | K16: =(H16+E16)/2 | L16: =(E16+I16)/2 | M16: =(E16+J16)/2 | N16: =(L16+M16)/2-K16 | O16: =G16*N16 | P16: =DATOS!$C$10*N16 | Q16: =-P16/100 | R16: 209 565 566 | S16: .STD R3.7 · nodos 36–37
B17: LA-6.1 | C17: Eje A | D17: 6 | E17: 7.2 | F17: 1-2 | G17: =DATOS!$C$32-DATOS!$C$31 | H17: 6 | I17: 8.4 | J17: 8.4 | K17: =(H17+E17)/2 | L17: =(E17+I17)/2 | M17: =(E17+J17)/2 | N17: =(L17+M17)/2-K17 | O17: =G17*N17 | P17: =DATOS!$C$10*N17 | Q17: =-P17/100 | R17: 36 531 TO 533 | S17: .STD R3.7 · nodos 41–42
B18: LA-6.2 | C18: Eje A | D18: 6 | E18: 7.2 | F18: 2-3 | G18: =DATOS!$C$33-DATOS!$C$32 | H18: 6 | I18: 8.4 | J18: 8.4 | K18: =(H18+E18)/2 | L18: =(E18+I18)/2 | M18: =(E18+J18)/2 | N18: =(L18+M18)/2-K18 | O18: =G18*N18 | P18: =DATOS!$C$10*N18 | Q18: =-P18/100 | R18: 211 569 570 | S18: .STD R3.7 · nodos 42–43
B19: LA-7.1 | C19: Eje A | D19: 7 | E19: 8.4 | F19: 1-2 | G19: =DATOS!$C$32-DATOS!$C$31 | H19: 7.2 | I19: 9.6 | J19: 9.6 | K19: =(H19+E19)/2 | L19: =(E19+I19)/2 | M19: =(E19+J19)/2 | N19: =(L19+M19)/2-K19 | O19: =G19*N19 | P19: =DATOS!$C$10*N19 | Q19: =-P19/100 | R19: 40 537 TO 539 | S19: .STD R3.7 · nodos 47–48
B20: LA-7.2 | C20: Eje A | D20: 7 | E20: 8.4 | F20: 2-3 | G20: =DATOS!$C$33-DATOS!$C$32 | H20: 7.2 | I20: 9.6 | J20: 9.6 | K20: =(H20+E20)/2 | L20: =(E20+I20)/2 | M20: =(E20+J20)/2 | N20: =(L20+M20)/2-K20 | O20: =G20*N20 | P20: =DATOS!$C$10*N20 | Q20: =-P20/100 | R20: 213 573 574 | S20: .STD R3.7 · nodos 48–49
B21: LA-8.1 | C21: Eje A | D21: 8 | E21: 9.6 | F21: 1-2 | G21: =DATOS!$C$32-DATOS!$C$31 | H21: 8.4 | I21: =DATOS!$C$15 | J21: =DATOS!$C$34 | K21: =(H21+E21)/2 | L21: =(E21+I21)/2 | M21: =(E21+J21)/2 | N21: =(L21+M21)/2-K21 | O21: =G21*N21 | P21: =DATOS!$C$10*N21 | Q21: =-P21/100 | R21: 44 543 TO 545 | S21: .STD R3.7 · nodos 53–131 · arriba: alero inclinado
B22: LA-8.2 | C22: Eje A | D22: 8 | E22: 9.6 | F22: 2-3 | G22: =DATOS!$C$33-DATOS!$C$32 | H22: 8.4 | I22: =DATOS!$C$34 | J22: =DATOS!$C$16 | K22: =(H22+E22)/2 | L22: =(E22+I22)/2 | M22: =(E22+J22)/2 | N22: =(L22+M22)/2-K22 | O22: =G22*N22 | P22: =DATOS!$C$10*N22 | Q22: =-P22/100 | R22: 215 577 578 | S22: .STD R3.7 · nodos 131–9 · arriba: alero inclinado
B23: LB-1.1 | C23: Eje B | D23: 1 | E23: 1.2 | F23: 1-2 | G23: =DATOS!$C$32-DATOS!$C$31 | H23: 0 | I23: 2.4 | J23: 2.4 | K23: =(H23+E23)/2 | L23: =(E23+I23)/2 | M23: =(E23+J23)/2 | N23: =(L23+M23)/2-K23 | O23: =G23*N23 | P23: =DATOS!$C$10*N23 | Q23: =-P23/100 | R23: 17 504 TO 506 | S23: .STD R3.7 · nodos 14–15
B24: LB-1.2 | C24: Eje B | D24: 1 | E24: 1.2 | F24: 2-3 | G24: =DATOS!$C$33-DATOS!$C$32 | H24: 0 | I24: 2.4 | J24: 2.4 | K24: =(H24+E24)/2 | L24: =(E24+I24)/2 | M24: =(E24+J24)/2 | N24: =(L24+M24)/2-K24 | O24: =G24*N24 | P24: =DATOS!$C$10*N24 | Q24: =-P24/100 | R24: 200 551 552 | S24: .STD R3.7 · nodos 15–16
B25: LB-2.1 | C25: Eje B | D25: 2 | E25: 2.4 | F25: 1-2 | G25: =DATOS!$C$32-DATOS!$C$31 | H25: 1.2 | I25: 3.6 | J25: 3.6 | K25: =(H25+E25)/2 | L25: =(E25+I25)/2 | M25: =(E25+J25)/2 | N25: =(L25+M25)/2-K25 | O25: =G25*N25 | P25: =DATOS!$C$10*N25 | Q25: =-P25/100 | R25: 21 510 TO 512 | S25: .STD R3.7 · nodos 20–21
B26: LB-2.2 | C26: Eje B | D26: 2 | E26: 2.4 | F26: 2-3 | G26: =DATOS!$C$33-DATOS!$C$32 | H26: 1.2 | I26: 3.6 | J26: 3.6 | K26: =(H26+E26)/2 | L26: =(E26+I26)/2 | M26: =(E26+J26)/2 | N26: =(L26+M26)/2-K26 | O26: =G26*N26 | P26: =DATOS!$C$10*N26 | Q26: =-P26/100 | R26: 202 555 556 | S26: .STD R3.7 · nodos 21–22
B27: LB-3.1 | C27: Eje B | D27: 3 | E27: 3.6 | F27: 1-2 | G27: =DATOS!$C$32-DATOS!$C$31 | H27: 2.4 | I27: 4.8 | J27: 4.8 | K27: =(H27+E27)/2 | L27: =(E27+I27)/2 | M27: =(E27+J27)/2 | N27: =(L27+M27)/2-K27 | O27: =G27*N27 | P27: =DATOS!$C$10*N27 | Q27: =-P27/100 | R27: 25 516 TO 518 | S27: .STD R3.7 · nodos 26–27
B28: LB-3.2 | C28: Eje B | D28: 3 | E28: 3.6 | F28: 2-3 | G28: =DATOS!$C$33-DATOS!$C$32 | H28: 2.4 | I28: 4.8 | J28: 4.8 | K28: =(H28+E28)/2 | L28: =(E28+I28)/2 | M28: =(E28+J28)/2 | N28: =(L28+M28)/2-K28 | O28: =G28*N28 | P28: =DATOS!$C$10*N28 | Q28: =-P28/100 | R28: 206 559 560 | S28: .STD R3.7 · nodos 27–28
B29: LB-4.1 | C29: Eje B | D29: 4 | E29: 4.8 | F29: 1-2 | G29: =DATOS!$C$32-DATOS!$C$31 | H29: 3.6 | I29: 6 | J29: 6 | K29: =(H29+E29)/2 | L29: =(E29+I29)/2 | M29: =(E29+J29)/2 | N29: =(L29+M29)/2-K29 | O29: =G29*N29 | P29: =DATOS!$C$10*N29 | Q29: =-P29/100 | R29: 29 522 TO 524 | S29: .STD R3.7 · nodos 32–33
B30: LB-4.2 | C30: Eje B | D30: 4 | E30: 4.8 | F30: 2-3 | G30: =DATOS!$C$33-DATOS!$C$32 | H30: 3.6 | I30: 6 | J30: 6 | K30: =(H30+E30)/2 | L30: =(E30+I30)/2 | M30: =(E30+J30)/2 | N30: =(L30+M30)/2-K30 | O30: =G30*N30 | P30: =DATOS!$C$10*N30 | Q30: =-P30/100 | R30: 208 563 564 | S30: .STD R3.7 · nodos 33–34
B31: LB-5.1 | C31: Eje B | D31: 5 | E31: 6 | F31: 1-2 | G31: =DATOS!$C$32-DATOS!$C$31 | H31: 4.8 | I31: 7.2 | J31: 7.2 | K31: =(H31+E31)/2 | L31: =(E31+I31)/2 | M31: =(E31+J31)/2 | N31: =(L31+M31)/2-K31 | O31: =G31*N31 | P31: =DATOS!$C$10*N31 | Q31: =-P31/100 | R31: 33 528 TO 530 | S31: .STD R3.7 · nodos 38–39
B32: LB-5.2 | C32: Eje B | D32: 5 | E32: 6 | F32: 2-3 | G32: =DATOS!$C$33-DATOS!$C$32 | H32: 4.8 | I32: 7.2 | J32: 7.2 | K32: =(H32+E32)/2 | L32: =(E32+I32)/2 | M32: =(E32+J32)/2 | N32: =(L32+M32)/2-K32 | O32: =G32*N32 | P32: =DATOS!$C$10*N32 | Q32: =-P32/100 | R32: 210 567 568 | S32: .STD R3.7 · nodos 39–40
B33: LB-6.1 | C33: Eje B | D33: 6 | E33: 7.2 | F33: 1-2 | G33: =DATOS!$C$32-DATOS!$C$31 | H33: 6 | I33: 8.4 | J33: 8.4 | K33: =(H33+E33)/2 | L33: =(E33+I33)/2 | M33: =(E33+J33)/2 | N33: =(L33+M33)/2-K33 | O33: =G33*N33 | P33: =DATOS!$C$10*N33 | Q33: =-P33/100 | R33: 37 534 TO 536 | S33: .STD R3.7 · nodos 44–45
B34: LB-6.2 | C34: Eje B | D34: 6 | E34: 7.2 | F34: 2-3 | G34: =DATOS!$C$33-DATOS!$C$32 | H34: 6 | I34: 8.4 | J34: 8.4 | K34: =(H34+E34)/2 | L34: =(E34+I34)/2 | M34: =(E34+J34)/2 | N34: =(L34+M34)/2-K34 | O34: =G34*N34 | P34: =DATOS!$C$10*N34 | Q34: =-P34/100 | R34: 212 571 572 | S34: .STD R3.7 · nodos 45–46
B35: LB-7.1 | C35: Eje B | D35: 7 | E35: 8.4 | F35: 1-2 | G35: =DATOS!$C$32-DATOS!$C$31 | H35: 7.2 | I35: 9.6 | J35: 9.6 | K35: =(H35+E35)/2 | L35: =(E35+I35)/2 | M35: =(E35+J35)/2 | N35: =(L35+M35)/2-K35 | O35: =G35*N35 | P35: =DATOS!$C$10*N35 | Q35: =-P35/100 | R35: 41 540 TO 542 | S35: .STD R3.7 · nodos 50–51
B36: LB-7.2 | C36: Eje B | D36: 7 | E36: 8.4 | F36: 2-3 | G36: =DATOS!$C$33-DATOS!$C$32 | H36: 7.2 | I36: 9.6 | J36: 9.6 | K36: =(H36+E36)/2 | L36: =(E36+I36)/2 | M36: =(E36+J36)/2 | N36: =(L36+M36)/2-K36 | O36: =G36*N36 | P36: =DATOS!$C$10*N36 | Q36: =-P36/100 | R36: 214 575 576 | S36: .STD R3.7 · nodos 51–52
B37: LB-8.1 | C37: Eje B | D37: 8 | E37: 9.6 | F37: 1-2 | G37: =DATOS!$C$32-DATOS!$C$31 | H37: 8.4 | I37: =DATOS!$C$15 | J37: =DATOS!$C$34 | K37: =(H37+E37)/2 | L37: =(E37+I37)/2 | M37: =(E37+J37)/2 | N37: =(L37+M37)/2-K37 | O37: =G37*N37 | P37: =DATOS!$C$10*N37 | Q37: =-P37/100 | R37: 45 546 TO 548 | S37: .STD R3.7 · nodos 55–132 · arriba: alero inclinado
B38: LB-8.2 | C38: Eje B | D38: 8 | E38: 9.6 | F38: 2-3 | G38: =DATOS!$C$33-DATOS!$C$32 | H38: 8.4 | I38: =DATOS!$C$34 | J38: =DATOS!$C$16 | K38: =(H38+E38)/2 | L38: =(E38+I38)/2 | M38: =(E38+J38)/2 | N38: =(L38+M38)/2-K38 | O38: =G38*N38 | P38: =DATOS!$C$10*N38 | Q38: =-P38/100 | R38: 216 579 580 | S38: .STD R3.7 · nodos 132–10 · arriba: alero inclinado
B39: Total | C39: Área de muros laterales en largueros (ejes A y B) | O39: =SUM(O7:O38)
B41: B. FRANJA SUPERIOR DE MUROS LATERALES → VIGAS DE ALERO VA Y VB (POR MIEMBRO)
B42: Arriba del último larguero (Y = 9.60 m) la mitad de la lámina cuelga de la viga de alero. Como el alero baja 5.2%, la franja cambia a lo largo: se toma el promedio de cada miembro.
...

Sheet NODOS_TECHO
B1: NODOS DE COLUMNA — TECHO: ÁREA TRIBUTARIA Y MASA SÍSMICA PUNTUAL (CASO 4)
B2: El techo se reparte a los 6 nodos de cabeza de columna: mitad del claro en X × mitad entre marcos en Z. Esta hoja da la masa sísmica del techo (JOINT LOAD FX y FZ); la CM y la CV van repartidas en largueros y vigas (hoja TECHO).
B4: A. TECHO → NODOS DE CABEZA DE COLUMNA
B5: ID | C5: Nodo STAAD | D5: Eje | E5: Lado | F5: X desde (m) | G5: X hasta (m) | H5: Z desde (m) | I5: Z hasta (m) | J5: A (m²) | K5: CM techo (kg) | L5: w_i techo (kg) | M5: Masa techo (kg) | N5: CV techo (kg) | O5: Línea STAAD caso 4 (masa) | P5: Nota | Q5: Referencia
C6: del .STD | F6: mitad del claro | G6: mitad / claro | H6: (Z ant. + Z)/2 | I6: (Z + Z sig.)/2 | J6: ΔX × ΔZ | K6: CM techo × A | L6: w_i × A | M6: K + L | N6: w_m × A | O6: nodo FX M FZ M
B7: T-1A | C7: 7 | D7: 1 | E7: A | F7: 0 | G7: =DATOS!$C$30 | H7: =DATOS!$C$31 | I7: =(DATOS!$C$31+DATOS!$C$32)/2 | J7: =(G7-F7)*(I7-H7) | K7: =DATOS!$C$8*J7 | L7: =DATOS!$C$23*J7 | M7: =K7+L7 | N7: =DATOS!$C$22*J7 | O7: =C7&" FX "&TEXT(M7,"0.00")&" FZ "&TEXT(M7,"0.00") | P7: La CM y la CV van en largueros (hoja TECHO) | Q7: Área tributaria (mitades) · masa sísmica del techo (caso 4)
B8: T-1B | C8: 8 | D8: 1 | E8: B | F8: =DATOS!$C$30 | G8: =DATOS!$C$29 | H8: =DATOS!$C$31 | I8: =(DATOS!$C$31+DATOS!$C$32)/2 | J8: =(G8-F8)*(I8-H8) | K8: =DATOS!$C$8*J8 | L8: =DATOS!$C$23*J8 | M8: =K8+L8 | N8: =DATOS!$C$22*J8 | O8: =C8&" FX "&TEXT(M8,"0.00")&" FZ "&TEXT(M8,"0.00") | P8: La CM y la CV van en largueros (hoja TECHO) | Q8: Área tributaria (mitades) · masa sísmica del techo (caso 4)
B9: T-2A | C9: 75 | D9: 2 | E9: A | F9: 0 | G9: =DATOS!$C$30 | H9: =(DATOS!$C$31+DATOS!$C$32)/2 | I9: =(DATOS!$C$32+DATOS!$C$33)/2 | J9: =(G9-F9)*(I9-H9) | K9: =DATOS!$C$8*J9 | L9: =DATOS!$C$23*J9 | M9: =K9+L9 | N9: =DATOS!$C$22*J9 | O9: =C9&" FX "&TEXT(M9,"0.00")&" FZ "&TEXT(M9,"0.00") | P9: La CM y la CV van en largueros (hoja TECHO) | Q9: Área tributaria (mitades) · masa sísmica del techo (caso 4)
B10: T-2B | C10: 76 | D10: 2 | E10: B | F10: =DATOS!$C$30 | G10: =DATOS!$C$29 | H10: =(DATOS!$C$31+DATOS!$C$32)/2 | I10: =(DATOS!$C$32+DATOS!$C$33)/2 | J10: =(G10-F10)*(I10-H10) | K10: =DATOS!$C$8*J10 | L10: =DATOS!$C$23*J10 | M10: =K10+L10 | N10: =DATOS!$C$22*J10 | O10: =C10&" FX "&TEXT(M10,"0.00")&" FZ "&TEXT(M10,"0.00") | P10: La CM y la CV van en largueros (hoja TECHO) | Q10: Área tributaria (mitades) · masa sísmica del techo (caso 4)
B11: T-3A | C11: 9 | D11: 3 | E11: A | F11: 0 | G11: =DATOS!$C$30 | H11: =(DATOS!$C$32+DATOS!$C$33)/2 | I11: =DATOS!$C$33 | J11: =(G11-F11)*(I11-H11) | K11: =DATOS!$C$8*J11 | L11: =DATOS!$C$23*J11 | M11: =K11+L11 | N11: =DATOS!$C$22*J11 | O11: =C11&" FX "&TEXT(M11,"0.00")&" FZ "&TEXT(M11,"0.00") | P11: La CM y la CV van en largueros (hoja TECHO) | Q11: Área tributaria (mitades) · masa sísmica del techo (caso 4)
B12: T-3B | C12: 10 | D12: 3 | E12: B | F12: =DATOS!$C$30 | G12: =DATOS!$C$29 | H12: =(DATOS!$C$32+DATOS!$C$33)/2 | I12: =DATOS!$C$33 | J12: =(G12-F12)*(I12-H12) | K12: =DATOS!$C$8*J12 | L12: =DATOS!$C$23*J12 | M12: =K12+L12 | N12: =DATOS!$C$22*J12 | O12: =C12&" FX "&TEXT(M12,"0.00")&" FZ "&TEXT(M12,"0.00") | P12: La CM y la CV van en largueros (hoja TECHO) | Q12: Área tributaria (mitades) · masa sísmica del techo (caso 4)
B13: Total | C13: Suma de áreas de techo (debe dar claro × largo = 10.08 × 16.00) | J13: =SUM(J7:J12) | K13: =SUM(K7:K12) | L13: =SUM(L7:L12) | M13: =SUM(M7:M12) | N13: =SUM(N7:N12) | Q13: =IF(AND(ABS(J13-TECHO!$J$19)<0.01,ABS(N13-RESUMEN!$C$16)<0.5),"CUADRA","NO CUADRA")

Sheet NODOS_MUROS
B1: NODOS DE COLUMNA — MUROS: ÁREA TRIBUTARIA DE LÁMINA POR NODO (REFERENCIA)
B2: Desde la R3.6 la masa de los muros SÍ va en los nodos de los extremos de cada larguero (columnas, jambas y postes), a la altura del larguero, junto con el acero del larguero y los contraflambeos de muro (hoja STAAD, caso 4). Esta tabla da sólo la parte de lámina por nodo de columna, como referencia.
B4: A. PANELES DE MURO → NODOS DE COLUMNA DE SUS EXTREMOS
B5: ID | C5: Muro | D5: Nivel | E5: Nodo A | F5: Nodo B | G5: L (m) | H5: h en A (m) | I5: h en B (m) | J5: A (m²) | K5: Masa (kg) | L5: Referencia
E6: del .STD | F6: del .STD | G6: del modelo | H6: franja en el nodo A | I6: franja en el nodo B | J6: L × (h A + h B) ÷ 2 | K6: CM muros × A
B7: LA-1.1 | C7: Eje A (X = 0) | D7: 1 | E7: 11 | F7: 12 | G7: 10 | H7: 1.2 | I7: 1.2 | J7: =G7*(H7+I7)/2 | K7: =DATOS!$C$10*J7 | L7: Franja de LA-1.1 (hoja MUROS) · .STD R3.7
B8: LA-1.2 | C8: Eje A (X = 0) | D8: 1 | E8: 12 | F8: 13 | G8: 6 | H8: 1.2 | I8: 1.2 | J8: =G8*(H8+I8)/2 | K8: =DATOS!$C$10*J8 | L8: Franja de LA-1.2 (hoja MUROS) · .STD R3.7
B9: LA-2.1 | C9: Eje A (X = 0) | D9: 2 | E9: 17 | F9: 18 | G9: 10 | H9: 1.2 | I9: 1.2 | J9: =G9*(H9+I9)/2 | K9: =DATOS!$C$10*J9 | L9: Franja de LA-2.1 (hoja MUROS) · .STD R3.7
B10: LA-2.2 | C10: Eje A (X = 0) | D10: 2 | E10: 18 | F10: 19 | G10: 6 | H10: 1.2 | I10: 1.2 | J10: =G10*(H10+I10)/2 | K10: =DATOS!$C$10*J10 | L10: Franja de LA-2.2 (hoja MUROS) · .STD R3.7
B11: LA-3.1 | C11: Eje A (X = 0) | D11: 3 | E11: 23 | F11: 24 | G11: 10 | H11: 1.2 | I11: 1.2 | J11: =G11*(H11+I11)/2 | K11: =DATOS!$C$10*J11 | L11: Franja de LA-3.1 (hoja MUROS) · .STD R3.7
B12: LA-3.2 | C12: Eje A (X = 0) | D12: 3 | E12: 24 | F12: 25 | G12: 6 | H12: 1.2 | I12: 1.2 | J12: =G12*(H12+I12)/2 | K12: =DATOS!$C$10*J12 | L12: Franja de LA-3.2 (hoja MUROS) · .STD R3.7
B13: LA-4.1 | C13: Eje A (X = 0) | D13: 4 | E13: 29 | F13: 30 | G13: 10 | H13: 1.2 | I13: 1.2 | J13: =G13*(H13+I13)/2 | K13: =DATOS!$C$10*J13 | L13: Franja de LA-4.1 (hoja MUROS) · .STD R3.7
B14: LA-4.2 | C14: Eje A (X = 0) | D14: 4 | E14: 30 | F14: 31 | G14: 6 | H14: 1.2 | I14: 1.2 | J14: =G14*(H14+I14)/2 | K14: =DATOS!$C$10*J14 | L14: Franja de LA-4.2 (hoja MUROS) · .STD R3.7
B15: LA-5.1 | C15: Eje A (X = 0) | D15: 5 | E15: 35 | F15: 36 | G15: 10 | H15: 1.2 | I15: 1.2 | J15: =G15*(H15+I15)/2 | K15: =DATOS!$C$10*J15 | L15: Franja de LA-5.1 (hoja MUROS) · .STD R3.7
B16: LA-5.2 | C16: Eje A (X = 0) | D16: 5 | E16: 36 | F16: 37 | G16: 6 | H16: 1.2 | I16: 1.2 | J16: =G16*(H16+I16)/2 | K16: =DATOS!$C$10*J16 | L16: Franja de LA-5.2 (hoja MUROS) · .STD R3.7
B17: LA-6.1 | C17: Eje A (X = 0) | D17: 6 | E17: 41 | F17: 42 | G17: 10 | H17: 1.2 | I17: 1.2 | J17: =G17*(H17+I17)/2 | K17: =DATOS!$C$10*J17 | L17: Franja de LA-6.1 (hoja MUROS) · .STD R3.7
B18: LA-6.2 | C18: Eje A (X = 0) | D18: 6 | E18: 42 | F18: 43 | G18: 6 | H18: 1.2 | I18: 1.2 | J18: =G18*(H18+I18)/2 | K18: =DATOS!$C$10*J18 | L18: Franja de LA-6.2 (hoja MUROS) · .STD R3.7
... B42: LB-T.2 | C42: Eje B (X = 10.08 m) | D42: 9 | E42: 76 | F42: 10 | G42: 6 | H42: 0.1556 | I42: 0 | J42: =G42*(H42+I42)/2 | K42: =DATOS!$C$10*J42 | L42: Franja superior (mitad entre último larguero y alero) → cabeza de columna · .STD R3.7
B43: Total | C43: Muros laterales (debe dar tabla A + tabla B de MUROS) | J43: =SUM(J7:J42) | K43: =SUM(K7:K42) | L43: =IF(ABS(J43-MUROS!$O$39-MUROS!$O$67)<0.01,"CUADRA","NO CUADRA")

Sheet STAAD
B1: LÍNEAS DE CARGA PARA STAAD (kg/cm y kg) — LAS QUE VAN EN EL .STD R3.7
B2: Armadas con fórmulas desde TECHO, MUROS, NODOS_TECHO y DATOS, con las áreas tributarias del DXF R3.7. Los grupos con el mismo valor van en un solo renglón, igual que en el .STD. El viento está en PresionesViento_Naves_ElSalvador_NTV_R3.7.xlsx, hoja STAAD.
B4: CASO 1 — CARGA MUERTA (debajo de SELFWEIGHT Y -1): TECHO EN LARGUEROS Y VIGAS + MUROS EN LARGUEROS + CORTINA
B5: ID | C5: Origen | D5: Línea para STAAD | E5: Nota | F5: Revisión
B6: — | C6: — | D6: MEMBER LOAD | E6: Encabezado | F6: =IF(LEN($D6)>79,"MÁS DE 79","")
B7: LT-2 a LT-6, VM-2, LT-7 a LT-9 | C7: TECHO | D7: ="74 121 TO 124 285 TO 287 310 TO 326 352 TO 371 UNI GY "&TEXT(-TECHO!K9/100,"0.0000") | E7: =IF(AND(TECHO!$H$9=TECHO!$H$10,TECHO!$H$9=TECHO!$H$11,TECHO!$H$9=TECHO!$H$12,TECHO!$H$9=TECHO!$H$13,TECHO!$H$9=TECHO!$H$14,TECHO!$H$9=TECHO!$H$15,TECHO!$H$9=TECHO!$H$16,TECHO!$H$9=TECHO!$H$17),"","OJO: las b de este grupo ya no son iguales: separa el renglón") | F7: =IF(LEN($D7)>79,"MÁS DE 79","")
B8: LT-1 | C8: TECHO | D8: ="327 372 TO 375 UNI GY "&TEXT(-TECHO!K8/100,"0.0000") | E8: ="CM de techo × b (TECHO K8) · b = "&TEXT(TECHO!H8,"0.00")&" m" | F8: =IF(LEN($D8)>79,"MÁS DE 79","")
B9: VM-1 | C9: TECHO | D9: ="11 48 TO 51 UNI GY "&TEXT(-TECHO!K7/100,"0.0000") | E9: ="CM de techo × b (TECHO K7) · b = "&TEXT(TECHO!H7,"0.00")&" m" | F9: =IF(LEN($D9)>79,"MÁS DE 79","")
B10: VM-3 | C10: TECHO | D10: ="12 52 TO 55 UNI GY "&TEXT(-TECHO!K18/100,"0.0000") | E10: ="CM de techo × b (TECHO K18) · b = "&TEXT(TECHO!H18,"0.00")&" m" | F10: =IF(LEN($D10)>79,"MÁS DE 79","")
B11: LA y LB, niveles 1 a 7 | C11: MUROS | D11: ="16 17 20 21 24 25 28 29 32 33 36 37 40 41 501 TO 542 UNI GY "&TEXT(MUROS!Q7,"0.0000")&CHAR(10)&"199 TO 202 205 TO 214 549 TO 576 UNI GY "&TEXT(MUROS!Q7,"0.0000") | E11: CM de muros × h (MUROS Q7) · Largueros típicos (h = 1.20 m) de los muros 3 y 4 | F11: =IF(MAX(LEN(LEFT($D11,FIND(CHAR(10),$D11)-1)),LEN(MID($D11,FIND(CHAR(10),$D11)+1,200)))>79,"MÁS DE 79","")
B12: L1 con h = 1.20 m | C12: MUROS | D12: ="23 27 31 43 46 149 153 155 159 161 203 585 TO 588 UNI GY "&TEXT(MUROS!P73,"0.0000") | E12: CM de muros × h (MUROS P73) · Largueros típicos (h = 1.20 m) del muro 1 | F12: =IF(LEN($D12)>79,"MÁS DE 79","")
B13: LA-8.1, LB-8.1 | C13: MUROS | D13: ="44 45 543 TO 548 UNI GY "&TEXT(MUROS!Q21,"0.0000") | E13: CM de muros × h (MUROS Q21) · Último larguero de los muros 3 y 4, claro 1-2 (LA-8.1, LB-8.1) | F13: =IF(LEN($D13)>79,"MÁS DE 79","")
B14: LA-8.2, LB-8.2 | C14: MUROS | D14: ="215 216 577 TO 580 UNI GY "&TEXT(MUROS!Q22,"0.0000") | E14: CM de muros × h (MUROS Q22) · Último larguero de los muros 3 y 4, claro 2-3 (LA-8.2, LB-8.2) | F14: =IF(LEN($D14)>79,"MÁS DE 79","")
B15: L1-2.2, L1-6.1, L1-6.3 | C15: MUROS | D15: ="68 204 233 UNI GY "&TEXT(MUROS!P77,"0.0000") | E15: CM de muros × h (MUROS P77) · Dintel de la puerta y largueros a 6.50 m junto a la cortina | F15: =IF(LEN($D15)>79,"MÁS DE 79","")
B16: L1-5.1, L1-5.2 | C16: MUROS | D16: ="35 157 UNI GY "&TEXT(MUROS!P84,"0.0000") | E16: CM de muros × h (MUROS P84) · Largueros a 6.00 m junto a la cortina (L1-5) | F16: =IF(LEN($D16)>79,"MÁS DE 79","")
B17: L1-6.2 (dintel) | C17: MUROS | D17: ="234 UNI GY "&TEXT(MUROS!P87,"0.0000") | E17: CM de muros × h (MUROS P87) · Dintel de la cortina (L1-6.2) | F17: =IF(LEN($D17)>79,"MÁS DE 79","")
B18: L1-7.1 | C18: MUROS | D18: ="39 581 TO 584 UNI GY "&TEXT(MUROS!P89,"0.0000") | E18: CM de muros × h (MUROS P89) · Larguero a 7.20 m del muro 1 (L1-7.1) | F18: =IF(LEN($D18)>79,"MÁS DE 79","")
B19: L1-9.1 | C19: MUROS | D19: ="47 589 TO 592 UNI GY "&TEXT(MUROS!P91,"0.0000") | E19: CM de muros × h (MUROS P91) · Último larguero del muro 1 (L1-9.1) | F19: =IF(LEN($D19)>79,"MÁS DE 79","")
B20: VM-1 (franja del muro eje 1) | C20: MUROS | D20: ="11 48 TO 51 UNI GY "&TEXT(MUROS!P92,"0.0000") | E20: CM de muros × h (MUROS P92) · Franja alta del muro 1 a la viga del eje 1 (VM-1) | F20: =IF(LEN($D20)>79,"MÁS DE 79","")
B21: VA-1 y VB-1 (franja) | C21: MUROS | D21: ="241 242 269 TO 280 605 TO 608 UNI GY "&TEXT(MUROS!Q99,"0.0000") | E21: CM de muros × h (MUROS Q99) · Vigas de alero del claro 1-2 (VA-1 y VB-1) | F21: =IF(LEN($D21)>79,"MÁS DE 79","")
B22: VA-2 y VB-2 (franja) | C22: MUROS | D22: ="243 TO 250 601 TO 604 UNI GY "&TEXT(MUROS!Q100,"0.0000") | E22: CM de muros × h (MUROS Q100) · Vigas de alero del claro 2-3 (VA-2 y VB-2) | F22: =IF(LEN($D22)>79,"MÁS DE 79","")
B23: — | C23: — | D23: JOINT LOAD | E23: Encabezado (cortina en las jambas) | F23: =IF(LEN($D23)>79,"MÁS DE 79","")
B24: Cortina | C24: DATOS | D24: =DATOS!$C$54&" FY "&TEXT(-DATOS!$C$53,"0.0") | E24: Mitad del peso de la cortina arriba de cada jamba (DATOS C53) | F24: =IF(LEN($D24)>79,"MÁS DE 79","")
B25: CASO 2 — CARGA VIVA (w_m de DATOS): TECHO EN LARGUEROS Y VIGAS
B26: ID | C26: Origen | D26: Línea para STAAD | E26: Nota | F26: Revisión
B27: — | C27: — | D27: MEMBER LOAD | E27: Encabezado | F27: =IF(LEN($D27)>79,"MÁS DE 79","")
B28: LT-2 a LT-6, VM-2, LT-7 a LT-9 | C28: TECHO | D28: ="74 121 TO 124 285 TO 287 310 TO 326 352 TO 371 UNI GY "&TEXT(-TECHO!L9/100,"0.0000") | E28: ="w_m × b (TECHO L9) · b = "&TEXT(TECHO!H9,"0.00")&" m" | F28: =IF(LEN($D28)>79,"MÁS DE 79","")
B29: LT-1 | C29: TECHO | D29: ="327 372 TO 375 UNI GY "&TEXT(-TECHO!L8/100,"0.0000") | E29: ="w_m × b (TECHO L8) · b = "&TEXT(TECHO!H8,"0.00")&" m" | F29: =IF(LEN($D29)>79,"MÁS DE 79","")
B30: VM-1 | C30: TECHO | D30: ="11 48 TO 51 UNI GY "&TEXT(-TECHO!L7/100,"0.0000") | E30: ="w_m × b (TECHO L7) · b = "&TEXT(TECHO!H7,"0.00")&" m" | F30: =IF(LEN($D30)>79,"MÁS DE 79","")
B31: VM-3 | C31: TECHO | D31: ="12 52 TO 55 UNI GY "&TEXT(-TECHO!L18/100,"0.0000") | E31: ="w_m × b (TECHO L18) · b = "&TEXT(TECHO!H18,"0.00")&" m" | F31: =IF(LEN($D31)>79,"MÁS DE 79","")
B33: CASO 3 — CARGA VIVA INSTANTÁNEA
B34: ID | C34: Origen | D34: Línea para STAAD | E34: Nota | F34: Revisión
B35: — | C35: DATOS | D35: =IF(DATOS!$C$23=0,"* w_i = 0: el caso queda sin carga","Aplicar w_i × b como en el caso 2 (w_i = "&DATOS!$C$23&" kg/m²)") | E35: w_i de DATOS C23 | F35: =IF(LEN($D35)>79,"MÁS DE 79","")
B37: CASO 4 — MASA SÍSMICA (ANTES DEL SPECTRUM). R3.6/R3.7: techo en las cabezas de columna; cortina arriba de las jambas; largueros, dinteles, lámina y contraflambeos de muro en los extremos de cada larguero; SELFWEIGHT X/Z sólo del resto del acero. Así no hay modos locales de largueros.
B38: ID | C38: Origen | D38: Línea para STAAD | E38: Nota | F38: Revisión
B39: — | C39: .STD R3.7 | D39: JOINT LOAD | F39: =IF(LEN($D39)>79,"MÁS DE 79","")
C40: .STD R3.7 | D40: * TECHO: 19.32 KG/M2 X AREA TRIBUTARIA DE CADA CABEZA (SOLO TECHO) | F40: =IF(LEN($D40)>79,"MÁS DE 79","")
B41: N7, N8 | C41: NODOS_TECHO | D41: =NODOS_TECHO!C7&" "&NODOS_TECHO!C8&" FX "&TEXT(NODOS_TECHO!M7,"0.00")&" FZ "&TEXT(NODOS_TECHO!M7,"0.00") | E41: (CM + w_i) de techo × A del nodo (NODOS_TECHO M7) | F41: =IF(LEN($D41)>79,"MÁS DE 79","")
B42: N75, N76 | C42: NODOS_TECHO | D42: =NODOS_TECHO!C9&" "&NODOS_TECHO!C10&" FX "&TEXT(NODOS_TECHO!M9,"0.00")&" FZ "&TEXT(NODOS_TECHO!M9,"0.00") | E42: (CM + w_i) de techo × A del nodo (NODOS_TECHO M9) | F42: =IF(LEN($D42)>79,"MÁS DE 79","")
B43: N9, N10 | C43: NODOS_TECHO | D43: =NODOS_TECHO!C11&" "&NODOS_TECHO!C12&" FX "&TEXT(NODOS_TECHO!M11,"0.00")&" FZ "&TEXT(NODOS_TECHO!M11,"0.00") | E43: (CM + w_i) de techo × A del nodo (NODOS_TECHO M11) | F43: =IF(LEN($D43)>79,"MÁS DE 79","")
...

Sheet RESUMEN
B1: RESUMEN — ÁREAS, CARGAS TOTALES Y PESO SÍSMICO W
B2: Totales para revisar contra STAAD (suma de cargas del caso 1) y el W que va a la hoja de espectros (DATOS C60 y C61).
B4: 1. ÁREAS TRIBUTARIAS
B5: Concepto | C5: Valor | D5: Unidad | E5: Cómo se calcula / de dónde sale | F5: Referencia
B6: Techo (largueros + vigas de marco) | C6: =TECHO!$J$19 | D6: m² | E6: Suma de la tabla A de TECHO = 10.08 × 16.00. | F6: Hoja TECHO
B7: Muros laterales en largueros (ejes A y B) | C7: =MUROS!$O$39 | D7: m² | E7: Suma de la tabla A de MUROS. | F7: Hoja MUROS
B8: Muros laterales, franja a vigas de alero | C8: =MUROS!$O$67 | D8: m² | E8: Suma de la tabla B de MUROS. | F8: Hoja MUROS
B9: Muro frontal (eje 1) en miembros | C9: =MUROS!$N$93 | D9: m² | E9: Suma de la tabla C de MUROS (sin vanos ni franja de base). | F9: Hoja MUROS
B10: Muros en total (van a largueros y vigas en STAAD) | C10: =C7+C8+C9 | D10: m² | E10: CALCULADA. | F10: —
B12: 2. CARGAS TOTALES APLICADAS EN STAAD
B13: Concepto | C13: Valor | D13: Unidad | E13: Cómo se calcula / de dónde sale | F13: Referencia
B14: CM de techo (caso 1) | C14: =DATOS!$C$8*C6 | D14: kg | E14: CM de techo × área de techo. En STAAD: UNI GY en cada larguero y viga con su franja b (hoja TECHO). | F14: DATOS C8 · tabla de CM
B15: CM de muros (caso 1) | C15: =DATOS!$C$10*C10 | D15: kg | E15: CM de muros × área de muros en miembros. En STAAD: UNI GY en largueros, franja alta de VA/VB/VM-1 y dinteles. | F15: DATOS C10 · tabla de CM
B16: CV máxima de techo (caso 2) | C16: =DATOS!$C$22*C6 | D16: kg | E16: w_m × área de techo. En STAAD: UNI GY en cada larguero y viga con su franja b (hoja TECHO). | F16: RESESCO · Tabla, pág. 12
B17: CV instantánea de techo (caso 3) | C17: =DATOS!$C$23*C6 | D17: kg | E17: w_i × área de techo. | F17: RESESCO · Tabla, pág. 12
B18: CM de cortina (casos 1 y 4) | C18: =DATOS!$C$52 | D18: kg | E18: Peso de la cortina de oruga: la mitad arriba de cada jamba (nodos 69 y 70). | F18: DATOS · ficha técnica Protec Ingeniería
B20: 3. PESO PROPIO DEL ACERO (LO QUE CALCULA SELFWEIGHT)
B21: Longitudes medidas en el modelo 001_NOSE_DOCK_H5_H6_R3.7.STD (todos los miembros). Densidad del .STD: 0.00783341 kg/cm³.
B22: Perfil | C22: L total (m) | D22: A (cm²) | E22: Peso (kg) = L × A × densidad | F22: Uso
B23: HSST10X10X0.313 | C23: 59.883 | D23: 69.6773 | E23: =C23*100*D23*0.00783341 | F23: Columnas
B24: MCE12-12 | C24: 62.283 | D24: 25.81 | E24: =C24*100*D24*0.00783341 | F24: Vigas de marco y de alero (UPTABLE 3)
B25: MCC12-12 | C25: 10.08 | D25: 25.81 | E25: =C25*100*D25*0.00783341 | F25: Dinteles de la cortina y la puerta (UPTABLE 4)
B26: MC12-14 | C26: 90.72 | D26: 9.2425 | E26: =C26*100*D26*0.00783341 | F26: Largueros de techo (UPTABLE 2)
B27: MC10-12 | C27: 160.16 | D27: 11.5552 | E27: =C27*100*D27*0.00783341 | F27: Largueros de 10 m (muros A, B y 1)
B28: MC10-14 | C28: 84 | D28: 8.2789 | E28: =C28*100*D28*0.00783341 | F28: Largueros de 6 m (muros A y B)
B29: MCC10-14 | C29: 42.08 | D29: 16.5577 | E29: =C29*100*D29*0.00783341 | F29: Largueros a 9.60 m en cajón (UPTABLE 4)
B30: MC6-14 | C30: 23.68 | D30: 5.3878 | E30: =C30*100*D30*0.00783341 | F30: Largueros cortos del muro 1
B31: HSST4X4X0.25 | C31: 92.677 | D31: 21.7419 | E31: =C31*100*D31*0.00783341 | F31: Contravientos de muros
B32: HSST5X5X0.25 | C32: 13 | D32: 27.7419 | E32: =C32*100*D32*0.00783341 | F32: Jambas de la cortina
B33: HSST5X5X0.125 | C33: 4.8 | D33: 14.3871 | E33: =C33*100*D33*0.00783341 | F33: Postes de la puerta
B34: PIPX7 | C34: 165.052 | D34: 2.7935 | E34: =C34*100*D34*0.00783341 | F34: Contraflambeos de techo y muros
B35: RED_1IN | C35: 51.886 | D35: 5.0671 | E35: =C35*100*D35*0.00783341 | F35: Cables de techo Ø1" (PRIS YD 2.54)
B36: Acero total | C36: =SUM(C23:C35) | E36: =SUM(E23:E35) | F36: STAAD (.anl R3.7): TOTAL UNFACTORED WEIGHT = 10,579.79 kg
B38: 4. PESO SÍSMICO W (NTDS: CM + w_i)
B39: Concepto | C39: Valor | D39: Unidad | E39: Cómo se calcula / de dónde sale | F39: Referencia
B40: Acero (peso propio) | C40: =E36/1000 | D40: t | E40: De la sección 3. | F40: —
B41: CM de techo | C41: =C14/1000 | D41: t | E41: De la sección 2 (masa en las 6 cabezas de columna, JOINT LOAD del caso 4). | F41: Hoja NODOS_TECHO
B42: CM de muros | C42: =C15/1000 | D42: t | E42: De la sección 2. En la masa (caso 4) va en los extremos de cada larguero (R3.6). | F42: Hoja MUROS
B43: CM de cortina | C43: =C18/1000 | D43: t | E43: De la sección 2: la mitad arriba de cada jamba (nodos 69 y 70). | F43: DATOS C52 y C53
B44: CV instantánea w_i | C44: =C17/1000 | D44: t | E44: Con pendiente mayor de 5% vale cero. | F44: RESESCO 1996 · Tabla, pág. 12
...
