Workbook

Sheet DATOS
B1: CIMENTACIONES SUPERFICIALES — ACI 318-19 · DATOS DE ENTRADA
B2: =$C$9&" · "&$C$10 -> Ejemplo — nave industrial · Columna tipo eje B-2 · muro eje 1
B3: HOJAS DEL LIBRO: DATOS → COMBINACIONES → AISLADA → AISLADA_CT → CORRIDA → LINDERO → CROQUIS → RESUMEN · de apoyo: TABLAS, REFERENCIAS, CROQUIS_DATOS
B4: CÓMO SE USA: sólo se tocan las celdas AMARILLAS con número AZUL (aquí y en las secciones 1 y 2 de AISLADA, AISLADA_CT, CORRIDA y LINDERO, y la 13 de AISLADA_CT y LINDERO). Todo lo demás son fórmulas. Los valores que trae son un EJEMPLO para que veas el formato: cámbialos por los de tu proyecto. El croquis se escoge en la hoja CROQUIS (celda amarilla de arriba).
B5: ALCANCE: ACI 318-19 cap. 13 y los capítulos a los que remite. Cuatro tipos: (1) zapata aislada, (2) zapata aislada ligada con contratrabes, (3) zapata corrida bajo muro, (4) zapata de lindero con o sin contratrabe de equilibrio. Revisa presiones de servicio contra qa, volteo, deslizamiento, penetración, cortante en una dirección, flexión, refuerzo mínimo y separaciones, desarrollo, aplastamiento dado-zapata y dovelas, y arroja el armado. NO incluye: zapatas de esquina, combinadas, losas de cimentación, pilotes, asentamientos, ni el diseño del dado como columna. El CROQUIS dibuja sólo los tipos 1 a 3.
B7: 1. PROYECTO
B8: Concepto | C8: Valor | D8: Unidad | E8: Cómo se calcula / de dónde sale | F8: Referencia
B9: Proyecto | C9: Ejemplo — nave industrial | D9: — | E9: CAPTURA. Sólo aparece en los encabezados. | F9: Datos del proyecto
B10: Elemento / eje | C10: Columna tipo eje B-2 · muro eje 1 | D10: — | E10: CAPTURA. Sólo aparece en los encabezados. | F10: Datos del proyecto
B11: Sistema de unidades | C11: t · m · cm · kg/cm² | D11: — | E11: Las ecuaciones del ACI 318-19 están en SI (MPa, mm). La hoja pasa f'c y fy a MPa, evalúa la ecuación tal como viene en el reglamento y regresa el resultado a kg/cm² o t. | F11: 1 MPa = 10.1972 kg/cm²
B13: 2. MATERIALES
B14: Concepto | C14: Valor | D14: Unidad | E14: Cómo se calcula / de dónde sale | F14: Referencia
B15: f'c — resistencia del concreto | C15: 250 | D15: kg/cm² | E15: CAPTURA. El ACI pide al menos 17 MPa (≈ 175 kg/cm²) en cimentaciones. | F15: ACI 318-19, Tabla 19.2.1.1 · 13.2.1.1, pág. 199
B16: f'c en MPa | C16: =$C$15/$C$89 -> 24.516534 | D16: MPa | E16: CALCULADA = f'c / 10.1972. | F16: Conversión de unidades
B17: √f'c usada en cortante y desarrollo | C17: =MIN(SQRT($C$16),8.3) -> 4.9514174 | D17: √MPa | E17: CALCULADA = √f'c con el tope de 8.3 MPa del reglamento. | F17: ACI 318-19, 22.5.3.1, 22.6.3.1 y 25.4.1.4
B18: fy — fluencia del refuerzo | C18: 4200 | D18: kg/cm² | E18: CAPTURA. Varilla corrugada grado 42. | F18: NMX-C-407-ONNCCE · ACI 318-19, 20.2.2.4
B19: fy en MPa | C19: =$C$18/$C$89 -> 411.87777 | D19: MPa | E19: CALCULADA = fy / 10.1972. | F19: Conversión de unidades
B20: Es — módulo del acero | C20: =200000*$C$89 -> 2039440 | D20: kg/cm² | E20: CALCULADA = 200,000 MPa pasado a kg/cm². | F20: ACI 318-19, 20.2.2.2
B21: εty — deformación de fluencia | C21: =$C$18/$C$20 -> 0.0020593889 | D21: — | E21: CALCULADA = fy / Es. | F21: ACI 318-19, 21.2.2.1
B22: β₁ — factor del bloque de compresión | C22: =IF($C$16<=28,0.85,IF($C$16>=55,0.65,0.85-0.05*($C$16-28)/7)) -> 0.85 | D22: — | E22: CALCULADA con f'c en MPa: 0.85 hasta 28 MPa, baja 0.05 por cada 7 MPa, mínimo 0.65. | F22: ACI 318-19, Tabla 22.2.2.4.3
B23: λ — factor de concreto ligero | C23: 1 | D23: — | E23: CAPTURA. 1.00 para concreto de peso normal. | F23: ACI 318-19, 19.2.4.2 (Tabla 19.2.4.2)
B24: γc — peso volumétrico del concreto reforzado | C24: 2.4 | D24: t/m³ | E24: CAPTURA. | F24: Práctica de ingeniería
B25: Tamaño máximo del agregado grueso | C25: 19 | D25: mm | E25: CAPTURA. 19 mm = 3/4". Sirve para la separación libre mínima entre varillas. | F25: ACI 318-19, 25.2.1
B26: ψg — factor por grado del refuerzo | C26: =IF($C$19<=420,1,IF($C$19<=550,1.15,1.3)) -> 1 | D26: — | E26: CALCULADA: 1.00 para grado 280 y 420; 1.15 para 550; 1.30 para 690. | F26: ACI 318-19, Tabla 25.4.2.5
B28: 3. SUELO — sin estudio de mecánica de suelos, estos son datos de entrada que tú propones
B29: Concepto | C29: Valor | D29: Unidad | E29: Cómo se calcula / de dónde sale | F29: Referencia
B30: qa — capacidad de carga admisible (bruta) al nivel de desplante | C30: 18 | D30: t/m² | E30: CAPTURA. Presión total admisible (incluye peso de zapata y relleno). SIN ESTUDIO: orienta el valor con la tabla presuntiva de TABLAS y confírmalo antes de construir. | F30: Estudio de mecánica de suelos · orientación: NAVFAC DM 7.02, Tabla 1, págs. 7.2-142 y 7.2-143 · ACI 318-19, 13.3.1.1, pág. 203
B31: Incremento de qa en combinaciones con acción accidental | C31: 1 | D31: — | E31: CAPTURA. Déjalo en 1.00 salvo que el estudio permita aumentar la capacidad para cargas de corta duración (típico 1.33). | F31: Estudio de mecánica de suelos · Bowles 5ª ed., §4.15, pág. 275
B32: γs — peso volumétrico del relleno sobre la zapata | C32: 1.6 | D32: t/m³ | E32: CAPTURA. Relleno compactado. | F32: Estudio de mecánica de suelos · práctica
B33: μ — factor de fricción suelo-concreto (tan δ) | C33: 0.45 | D33: — | E33: CAPTURA. Ver la tabla 4 de TABLAS. No se cuenta el empuje pasivo del relleno lateral (queda del lado seguro). | F33: NAVFAC DM 7.02, Cap. 3, Tabla 1, pág. 7.2-63
B34: FS exigido contra volteo | C34: 1.5 | D34: — | E34: CAPTURA. Se revisa con TODAS las combinaciones de servicio, incluida la de 0.6D (queda del lado seguro). | F34: ACI 318-19, 13.2.6.1, págs. 199–200 · Bowles 5ª ed., Tabla 4-9, pág. 276
B35: FS exigido contra deslizamiento | C35: 1.5 | D35: — | E35: CAPTURA. Igual criterio que el de volteo. | F35: ACI 318-19, 13.2.6.1, págs. 199–200 · Bowles 5ª ed., Tabla 4-9, pág. 276
B37: 4. ACCIÓN ACCIDENTAL Y COMBINACIONES
B38: Concepto | C38: Valor | D38: Unidad | E38: Cómo se calcula / de dónde sale | F38: Referencia
B39: Acción accidental A que se captura abajo | C39: SISMO | D39: — | E39: CAPTURA (lista). Cambia los factores de servicio: sismo 0.7E y 0.525E; viento 0.6W y 0.45W. Las de resistencia usan 1.0 en ambos casos. | F39: ASCE/SEI 7-16, §2.4.1 · ACI 318-19, Tabla 5.3.1
B40: Factor de la carga viva en las combinaciones de resistencia con A | C40: 1 | D40: — | E40: CAPTURA. 1.0, o 0.5 si L ≤ 4.8 kPa (≈ 490 kg/m²) y no es estacionamiento ni lugar de reunión. | F40: ACI 318-19, 5.3.3
B41: Tabla completa de combinaciones | C41: Hoja COMBINACIONES | D41: — | E41: La A entra con los dos signos: se toma la que suma a los momentos de D y L, y en P la que suma (S4, U4) y la que resta (S5, U5). | F41: ACI 318-19, 13.2.6.1 y 13.2.6.3, pág. 200
B43: 5. CARGAS DE SERVICIO EN LA BASE DE LA COLUMNA — para AISLADA, AISLADA_CT y LINDERO (por caso de carga, sin factorizar)
B44: Concepto | C44: Valor | D44: Unidad | E44: Cómo se calcula / de dónde sale | F44: Referencia
B45: EJES: X y Y en planta. Mx gira alrededor de X y produce excentricidad ey; My gira alrededor de Y y produce ex. En STAAD (Y vertical): FY → P, MX → Mx, MZ → My, FX → Vx, FZ → Vy. Los momentos y cortantes se usan en valor absoluto (la zapata es simétrica).
...

Sheet COMBINACIONES
B1: COMBINACIONES DE CARGA — ASCE/SEI 7-16 · ACI 318-19, 5.3
B2: De servicio (S) para presiones contra qa, volteo y deslizamiento (ACI R13.2.6.1, págs. 199–200); de resistencia (U) para cortante, flexión y aplastamiento (ACI 13.2.6.3, pág. 200). Aquí no se captura nada: los factores de A cambian solos con la lista de DATOS.
B4: 1. FACTORES DE CARGA
B5: Clave | C5: Combinación | D5: Uso | E5: γD | F5: γL | G5: γA | H5: signo de P_A | I5: — | J5: Referencia
B6: S1 | C6: ="D + L" -> D + L | D6: Servicio | E6: 1 | F6: 1 | G6: 0 | H6: 1 | I6: — | J6: ASCE 7-16 §2.4.1 comb. 2
B7: S2 | C7: ="D + "&TEXT(IF(DATOS!$C$39="SISMO",0.7,0.6),"0.0##")&IF(DATOS!$C$39="SISMO","E","W") -> D + 0.7E | D7: Servicio | E7: 1 | F7: 0 | G7: =IF(DATOS!$C$39="SISMO",0.7,0.6) -> 0.7 | H7: 1 | I7: — | J7: ASCE 7-16 §2.4.1 comb. 5
B8: S3 | C8: ="D + 0.75L + "&TEXT(IF(DATOS!$C$39="SISMO",0.525,0.45),"0.0##")&IF(DATOS!$C$39="SISMO","E","W") -> D + 0.75L + 0.525E | D8: Servicio | E8: 1 | F8: 0.75 | G8: =IF(DATOS!$C$39="SISMO",0.525,0.45) -> 0.525 | H8: 1 | I8: — | J8: ASCE 7-16 §2.4.1 comb. 6
B9: S4 | C9: ="0.6D + "&TEXT(IF(DATOS!$C$39="SISMO",0.7,0.6),"0.0##")&IF(DATOS!$C$39="SISMO","E","W")&" (P de A suma)" -> 0.6D + 0.7E (P de A suma) | D9: Servicio | E9: 0.6 | F9: 0 | G9: =IF(DATOS!$C$39="SISMO",0.7,0.6) -> 0.7 | H9: 1 | I9: — | J9: ASCE 7-16 §2.4.1 comb. 7 y 8
B10: S5 | C10: ="0.6D + "&TEXT(IF(DATOS!$C$39="SISMO",0.7,0.6),"0.0##")&IF(DATOS!$C$39="SISMO","E","W")&" (P de A resta)" -> 0.6D + 0.7E (P de A resta) | D10: Servicio (levantamiento) | E10: 0.6 | F10: 0 | G10: =IF(DATOS!$C$39="SISMO",0.7,0.6) -> 0.7 | H10: -1 | I10: — | J10: ASCE 7-16 §2.4.1 comb. 7 y 8
B11: U1 | C11: ="1.4D" -> 1.4D | D11: Resistencia | E11: 1.4 | F11: 0 | G11: 0 | H11: 1 | I11: — | J11: ACI 318-19 ec. 5.3.1a
B12: U2 | C12: ="1.2D + 1.6L" -> 1.2D + 1.6L | D12: Resistencia | E12: 1.2 | F12: 1.6 | G12: 0 | H12: 1 | I12: — | J12: ACI 318-19 ec. 5.3.1b
B13: U3 | C13: ="1.2D + "&TEXT(DATOS!$C$40,"0.0")&"L + 1.0"&IF(DATOS!$C$39="SISMO","E","W") -> 1.2D + 1.0L + 1.0E | D13: Resistencia | E13: 1.2 | F13: =DATOS!$C$40 -> 1 | G13: 1 | H13: 1 | I13: — | J13: ACI 318-19 ec. 5.3.1d / 5.3.1e
B14: U4 | C14: ="0.9D + 1.0"&IF(DATOS!$C$39="SISMO","E","W")&" (P de A suma)" -> 0.9D + 1.0E (P de A suma) | D14: Resistencia | E14: 0.9 | F14: 0 | G14: 1 | H14: 1 | I14: — | J14: ACI 318-19 ec. 5.3.1f / 5.3.1g
B15: U5 | C15: ="0.9D + 1.0"&IF(DATOS!$C$39="SISMO","E","W")&" (P de A resta)" -> 0.9D + 1.0E (P de A resta) | D15: Resistencia (levantamiento) | E15: 0.9 | F15: 0 | G15: 1 | H15: -1 | I15: — | J15: ACI 318-19 ec. 5.3.1f / 5.3.1g
B17: 2. CARGAS COMBINADAS EN LA BASE DE LA COLUMNA — para AISLADA y AISLADA_CT (t, t·m)
B18: Clave | C18: Combinación | D18: Uso | E18: P | F18: Mx | G18: My | H18: Vx | I18: Vy | J18: Cómo se calcula
B19: S1 | C19: =C6 -> D + L | D19: =D6 -> Servicio | E19: =E6*DATOS!$C$46+F6*DATOS!$C$47+H6*G6*ABS(DATOS!$C$48) -> 42 | F19: =ABS(E6*DATOS!$C$49+F6*DATOS!$C$50)+G6*ABS(DATOS!$C$51) -> 1.2 | G19: =ABS(E6*DATOS!$C$52+F6*DATOS!$C$53)+G6*ABS(DATOS!$C$54) -> 0.9 | H19: =ABS(E6*DATOS!$C$55+F6*DATOS!$C$56)+G6*ABS(DATOS!$C$57) -> 0.3 | I19: =ABS(E6*DATOS!$C$58+F6*DATOS!$C$59)+G6*ABS(DATOS!$C$60) -> 0.4 | J19: P = γD·PD + γL·PL ± γA·|PA| ; M, V = |γD·D + γL·L| + γA·|A|
B20: S2 | C20: =C7 -> D + 0.7E | D20: =D7 -> Servicio | E20: =E7*DATOS!$C$46+F7*DATOS!$C$47+H7*G7*ABS(DATOS!$C$48) -> 34.2 | F20: =ABS(E7*DATOS!$C$49+F7*DATOS!$C$50)+G7*ABS(DATOS!$C$51) -> 4.65 | G20: =ABS(E7*DATOS!$C$52+F7*DATOS!$C$53)+G7*ABS(DATOS!$C$54) -> 5.15 | H20: =ABS(E7*DATOS!$C$55+F7*DATOS!$C$56)+G7*ABS(DATOS!$C$57) -> 1.95 | I20: =ABS(E7*DATOS!$C$58+F7*DATOS!$C$59)+G7*ABS(DATOS!$C$60) -> 1.7 | J20: P = γD·PD + γL·PL ± γA·|PA| ; M, V = |γD·D + γL·L| + γA·|A|
B21: S3 | C21: =C8 -> D + 0.75L + 0.525E | D21: =D8 -> Servicio | E21: =E8*DATOS!$C$46+F8*DATOS!$C$47+H8*G8*ABS(DATOS!$C$48) -> 42.15 | F21: =ABS(E8*DATOS!$C$49+F8*DATOS!$C$50)+G8*ABS(DATOS!$C$51) -> 3.9875 | G21: =ABS(E8*DATOS!$C$52+F8*DATOS!$C$53)+G8*ABS(DATOS!$C$54) -> 4.2375 | H21: =ABS(E8*DATOS!$C$55+F8*DATOS!$C$56)+G8*ABS(DATOS!$C$57) -> 1.5875 | I21: =ABS(E8*DATOS!$C$58+F8*DATOS!$C$59)+G8*ABS(DATOS!$C$60) -> 1.425 | J21: P = γD·PD + γL·PL ± γA·|PA| ; M, V = |γD·D + γL·L| + γA·|A|
B22: S4 | C22: =C9 -> 0.6D + 0.7E (P de A suma) | D22: =D9 -> Servicio | E22: =E9*DATOS!$C$46+F9*DATOS!$C$47+H9*G9*ABS(DATOS!$C$48) -> 22.2 | F22: =ABS(E9*DATOS!$C$49+F9*DATOS!$C$50)+G9*ABS(DATOS!$C$51) -> 4.33 | G22: =ABS(E9*DATOS!$C$52+F9*DATOS!$C$53)+G9*ABS(DATOS!$C$54) -> 4.91 | H22: =ABS(E9*DATOS!$C$55+F9*DATOS!$C$56)+G9*ABS(DATOS!$C$57) -> 1.87 | I22: =ABS(E9*DATOS!$C$58+F9*DATOS!$C$59)+G9*ABS(DATOS!$C$60) -> 1.58 | J22: P = γD·PD + γL·PL ± γA·|PA| ; M, V = |γD·D + γL·L| + γA·|A|
B23: S5 | C23: =C10 -> 0.6D + 0.7E (P de A resta) | D23: =D10 -> Servicio (levantamiento) | E23: =E10*DATOS!$C$46+F10*DATOS!$C$47+H10*G10*ABS(DATOS!$C$48) -> 13.8 | F23: =ABS(E10*DATOS!$C$49+F10*DATOS!$C$50)+G10*ABS(DATOS!$C$51) -> 4.33 | G23: =ABS(E10*DATOS!$C$52+F10*DATOS!$C$53)+G10*ABS(DATOS!$C$54) -> 4.91 | H23: =ABS(E10*DATOS!$C$55+F10*DATOS!$C$56)+G10*ABS(DATOS!$C$57) -> 1.87 | I23: =ABS(E10*DATOS!$C$58+F10*DATOS!$C$59)+G10*ABS(DATOS!$C$60) -> 1.58 | J23: P = γD·PD + γL·PL ± γA·|PA| ; M, V = |γD·D + γL·L| + γA·|A|
B24: U1 | C24: =C11 -> 1.4D | D24: =D11 -> Resistencia | E24: =E11*DATOS!$C$46+F11*DATOS!$C$47+H11*G11*ABS(DATOS!$C$48) -> 42 | F24: =ABS(E11*DATOS!$C$49+F11*DATOS!$C$50)+G11*ABS(DATOS!$C$51) -> 1.12 | G24: =ABS(E11*DATOS!$C$52+F11*DATOS!$C$53)+G11*ABS(DATOS!$C$54) -> 0.84 | H24: =ABS(E11*DATOS!$C$55+F11*DATOS!$C$56)+G11*ABS(DATOS!$C$57) -> 0.28 | I24: =ABS(E11*DATOS!$C$58+F11*DATOS!$C$59)+G11*ABS(DATOS!$C$60) -> 0.42 | J24: P = γD·PD + γL·PL ± γA·|PA| ; M, V = |γD·D + γL·L| + γA·|A|
B25: U2 | C25: =C12 -> 1.2D + 1.6L | D25: =D12 -> Resistencia | E25: =E12*DATOS!$C$46+F12*DATOS!$C$47+H12*G12*ABS(DATOS!$C$48) -> 55.2 | F25: =ABS(E12*DATOS!$C$49+F12*DATOS!$C$50)+G12*ABS(DATOS!$C$51) -> 1.6 | G25: =ABS(E12*DATOS!$C$52+F12*DATOS!$C$53)+G12*ABS(DATOS!$C$54) -> 1.2 | H25: =ABS(E12*DATOS!$C$55+F12*DATOS!$C$56)+G12*ABS(DATOS!$C$57) -> 0.4 | I25: =ABS(E12*DATOS!$C$58+F12*DATOS!$C$59)+G12*ABS(DATOS!$C$60) -> 0.52 | J25: P = γD·PD + γL·PL ± γA·|PA| ; M, V = |γD·D + γL·L| + γA·|A|
B26: U3 | C26: =C13 -> 1.2D + 1.0L + 1.0E | D26: =D13 -> Resistencia | E26: =E13*DATOS!$C$46+F13*DATOS!$C$47+H13*G13*ABS(DATOS!$C$48) -> 54 | F26: =ABS(E13*DATOS!$C$49+F13*DATOS!$C$50)+G13*ABS(DATOS!$C$51) -> 6.86 | G26: =ABS(E13*DATOS!$C$52+F13*DATOS!$C$53)+G13*ABS(DATOS!$C$54) -> 7.52 | H26: =ABS(E13*DATOS!$C$55+F13*DATOS!$C$56)+G13*ABS(DATOS!$C$57) -> 2.84 | I26: =ABS(E13*DATOS!$C$58+F13*DATOS!$C$59)+G13*ABS(DATOS!$C$60) -> 2.46 | J26: P = γD·PD + γL·PL ± γA·|PA| ; M, V = |γD·D + γL·L| + γA·|A|
B27: U4 | C27: =C14 -> 0.9D + 1.0E (P de A suma) | D27: =D14 -> Resistencia | E27: =E14*DATOS!$C$46+F14*DATOS!$C$47+H14*G14*ABS(DATOS!$C$48) -> 33 | F27: =ABS(E14*DATOS!$C$49+F14*DATOS!$C$50)+G14*ABS(DATOS!$C$51) -> 6.22 | G27: =ABS(E14*DATOS!$C$52+F14*DATOS!$C$53)+G14*ABS(DATOS!$C$54) -> 7.04 | H27: =ABS(E14*DATOS!$C$55+F14*DATOS!$C$56)+G14*ABS(DATOS!$C$57) -> 2.68 | I27: =ABS(E14*DATOS!$C$58+F14*DATOS!$C$59)+G14*ABS(DATOS!$C$60) -> 2.27 | J27: P = γD·PD + γL·PL ± γA·|PA| ; M, V = |γD·D + γL·L| + γA·|A|
B28: U5 | C28: =C15 -> 0.9D + 1.0E (P de A resta) | D28: =D15 -> Resistencia (levantamiento) | E28: =E15*DATOS!$C$46+F15*DATOS!$C$47+H15*G15*ABS(DATOS!$C$48) -> 21 | F28: =ABS(E15*DATOS!$C$49+F15*DATOS!$C$50)+G15*ABS(DATOS!$C$51) -> 6.22 | G28: =ABS(E15*DATOS!$C$52+F15*DATOS!$C$53)+G15*ABS(DATOS!$C$54) -> 7.04 | H28: =ABS(E15*DATOS!$C$55+F15*DATOS!$C$56)+G15*ABS(DATOS!$C$57) -> 2.68 | I28: =ABS(E15*DATOS!$C$58+F15*DATOS!$C$59)+G15*ABS(DATOS!$C$60) -> 2.27 | J28: P = γD·PD + γL·PL ± γA·|PA| ; M, V = |γD·D + γL·L| + γA·|A|
B30: 3. CARGAS COMBINADAS DEL MURO, POR METRO — para CORRIDA (t/m, t·m/m)
B31: Clave | C31: Combinación | D31: Uso | E31: w | F31: Mw | G31: Vw | H31: — | I31: — | J31: Cómo se calcula
B32: S1 | C32: =C6 -> D + L | D32: =D6 -> Servicio | E32: =E6*DATOS!$C$74+F6*DATOS!$C$75+H6*G6*ABS(DATOS!$C$76) -> 6.5 | F32: =ABS(E6*DATOS!$C$77+F6*DATOS!$C$78)+G6*ABS(DATOS!$C$79) -> 0 | G32: =ABS(E6*DATOS!$C$80+F6*DATOS!$C$81)+G6*ABS(DATOS!$C$82) -> 0 | H32: — | I32: — | J32: w = γD·wD + γL·wL ± γA·|wA| ; M, V igual que arriba
B33: S2 | C33: =C7 -> D + 0.7E | D33: =D7 -> Servicio | E33: =E7*DATOS!$C$74+F7*DATOS!$C$75+H7*G7*ABS(DATOS!$C$76) -> 5.56 | F33: =ABS(E7*DATOS!$C$77+F7*DATOS!$C$78)+G7*ABS(DATOS!$C$79) -> 0.21 | G33: =ABS(E7*DATOS!$C$80+F7*DATOS!$C$81)+G7*ABS(DATOS!$C$82) -> 0.28 | H33: — | I33: — | J33: w = γD·wD + γL·wL ± γA·|wA| ; M, V igual que arriba
B34: S3 | C34: =C8 -> D + 0.75L + 0.525E | D34: =D8 -> Servicio | E34: =E8*DATOS!$C$74+F8*DATOS!$C$75+H8*G8*ABS(DATOS!$C$76) -> 6.545 | F34: =ABS(E8*DATOS!$C$77+F8*DATOS!$C$78)+G8*ABS(DATOS!$C$79) -> 0.1575 | G34: =ABS(E8*DATOS!$C$80+F8*DATOS!$C$81)+G8*ABS(DATOS!$C$82) -> 0.21 | H34: — | I34: — | J34: w = γD·wD + γL·wL ± γA·|wA| ; M, V igual que arriba
B35: S4 | C35: =C9 -> 0.6D + 0.7E (P de A suma) | D35: =D9 -> Servicio | E35: =E9*DATOS!$C$74+F9*DATOS!$C$75+H9*G9*ABS(DATOS!$C$76) -> 3.56 | F35: =ABS(E9*DATOS!$C$77+F9*DATOS!$C$78)+G9*ABS(DATOS!$C$79) -> 0.21 | G35: =ABS(E9*DATOS!$C$80+F9*DATOS!$C$81)+G9*ABS(DATOS!$C$82) -> 0.28 | H35: — | I35: — | J35: w = γD·wD + γL·wL ± γA·|wA| ; M, V igual que arriba
B36: S5 | C36: =C10 -> 0.6D + 0.7E (P de A resta) | D36: =D10 -> Servicio (levantamiento) | E36: =E10*DATOS!$C$74+F10*DATOS!$C$75+H10*G10*ABS(DATOS!$C$76) -> 2.44 | F36: =ABS(E10*DATOS!$C$77+F10*DATOS!$C$78)+G10*ABS(DATOS!$C$79) -> 0.21 | G36: =ABS(E10*DATOS!$C$80+F10*DATOS!$C$81)+G10*ABS(DATOS!$C$82) -> 0.28 | H36: — | I36: — | J36: w = γD·wD + γL·wL ± γA·|wA| ; M, V igual que arriba
B37: U1 | C37: =C11 -> 1.4D | D37: =D11 -> Resistencia | E37: =E11*DATOS!$C$74+F11*DATOS!$C$75+H11*G11*ABS(DATOS!$C$76) -> 7 | F37: =ABS(E11*DATOS!$C$77+F11*DATOS!$C$78)+G11*ABS(DATOS!$C$79) -> 0 | G37: =ABS(E11*DATOS!$C$80+F11*DATOS!$C$81)+G11*ABS(DATOS!$C$82) -> 0 | H37: — | I37: — | J37: w = γD·wD + γL·wL ± γA·|wA| ; M, V igual que arriba
B38: U2 | C38: =C12 -> 1.2D + 1.6L | D38: =D12 -> Resistencia | E38: =E12*DATOS!$C$74+F12*DATOS!$C$75+H12*G12*ABS(DATOS!$C$76) -> 8.4 | F38: =ABS(E12*DATOS!$C$77+F12*DATOS!$C$78)+G12*ABS(DATOS!$C$79) -> 0 | G38: =ABS(E12*DATOS!$C$80+F12*DATOS!$C$81)+G12*ABS(DATOS!$C$82) -> 0 | H38: — | I38: — | J38: w = γD·wD + γL·wL ± γA·|wA| ; M, V igual que arriba
B39: U3 | C39: =C13 -> 1.2D + 1.0L + 1.0E | D39: =D13 -> Resistencia | E39: =E13*DATOS!$C$74+F13*DATOS!$C$75+H13*G13*ABS(DATOS!$C$76) -> 8.3 | F39: =ABS(E13*DATOS!$C$77+F13*DATOS!$C$78)+G13*ABS(DATOS!$C$79) -> 0.3 | G39: =ABS(E13*DATOS!$C$80+F13*DATOS!$C$81)+G13*ABS(DATOS!$C$82) -> 0.4 | H39: — | I39: — | J39: w = γD·wD + γL·wL ± γA·|wA| ; M, V igual que arriba
B40: U4 | C40: =C14 -> 0.9D + 1.0E (P de A suma) | D40: =D14 -> Resistencia | E40: =E14*DATOS!$C$74+F14*DATOS!$C$75+H14*G14*ABS(DATOS!$C$76) -> 5.3 | F40: =ABS(E14*DATOS!$C$77+F14*DATOS!$C$78)+G14*ABS(DATOS!$C$79) -> 0.3 | G40: =ABS(E14*DATOS!$C$80+F14*DATOS!$C$81)+G14*ABS(DATOS!$C$82) -> 0.4 | H40: — | I40: — | J40: w = γD·wD + γL·wL ± γA·|wA| ; M, V igual que arriba
B41: U5 | C41: =C15 -> 0.9D + 1.0E (P de A resta) | D41: =D15 -> Resistencia (levantamiento) | E41: =E15*DATOS!$C$74+F15*DATOS!$C$75+H15*G15*ABS(DATOS!$C$76) -> 3.7 | F41: =ABS(E15*DATOS!$C$77+F15*DATOS!$C$78)+G15*ABS(DATOS!$C$79) -> 0.3 | G41: =ABS(E15*DATOS!$C$80+F15*DATOS!$C$81)+G15*ABS(DATOS!$C$82) -> 0.4 | H41: — | I41: — | J41: w = γD·wD + γL·wL ± γA·|wA| ; M, V igual que arriba

Sheet AISLADA
B1: ZAPATA AISLADA — ACI 318-19 | H1: TABLA POR COMBINACIÓN — la memoria (col. B–F) toma de aquí lo que rige
B2: =DATOS!$C$9&" · "&DATOS!$C$10 -> Ejemplo — nave industrial · Columna tipo eje B-2 · muro eje 1 | H2: Cada columna es una combinación de la hoja COMBINACIONES. Bloque S: presiones y estabilidad con la carga TOTAL (incluye zapata, relleno y dado, multiplicados por su γD). Bloque U: diseño estructural con presión NETA (se descuenta el peso de zapata y relleno), ACI 13.2.6.3 y R13.2.6.3.
B3: Se capturan sólo las celdas amarillas de las secciones 1 y 2; cargas, materiales y suelo vienen de DATOS. A la derecha (columnas H a N) está la tabla por combinación de donde salen los valores que rigen.
H4: BLOQUE S — SERVICIO
B5: 1. GEOMETRÍA DE LA ZAPATA | H5: Combinación | I5: =COMBINACIONES!$B$6 -> S1 | J5: =COMBINACIONES!$B$7 -> S2 | K5: =COMBINACIONES!$B$8 -> S3 | L5: =COMBINACIONES!$B$9 -> S4 | M5: =COMBINACIONES!$B$10 -> S5
B6: Concepto | C6: Valor | D6: Unidad | E6: Cómo se calcula / de dónde sale | F6: Referencia | H6: Descripción | I6: =COMBINACIONES!$C$6 -> D + L | J6: =COMBINACIONES!$C$7 -> D + 0.7E | K6: =COMBINACIONES!$C$8 -> D + 0.75L + 0.525E | L6: =COMBINACIONES!$C$9 -> 0.6D + 0.7E (P de A suma) | M6: =COMBINACIONES!$C$10 -> 0.6D + 0.7E (P de A resta)
B7: Lx — lado de la zapata en dirección X | C7: 2.6 | D7: m | E7: CAPTURA. Se ajusta hasta que la presión máxima de la sección 5 quede por debajo de qa. | F7: Propuesta — se verifica en la sección 5 | H7: γD | I7: =COMBINACIONES!$E$6 -> 1 | J7: =COMBINACIONES!$E$7 -> 1 | K7: =COMBINACIONES!$E$8 -> 1 | L7: =COMBINACIONES!$E$9 -> 0.6 | M7: =COMBINACIONES!$E$10 -> 0.6
B8: Ly — lado de la zapata en dirección Y | C8: 2.6 | D8: m | E8: CAPTURA. | F8: Propuesta — se verifica en la sección 5 | H8: γA | I8: =COMBINACIONES!$G$6 -> 0 | J8: =COMBINACIONES!$G$7 -> 0.7 | K8: =COMBINACIONES!$G$8 -> 0.525 | L8: =COMBINACIONES!$G$9 -> 0.7 | M8: =COMBINACIONES!$G$10 -> 0.7
B9: h — peralte total de la zapata | C9: 0.5 | D9: m | E9: CAPTURA. Los mínimos por penetración y por dovelas salen en las secciones 4 y 12. | F9: Propuesta — se verifica en las secciones 6, 9 y 12 | H9: P de la columna | I9: =COMBINACIONES!$E$19 -> 42 | J9: =COMBINACIONES!$E$20 -> 34.2 | K9: =COMBINACIONES!$E$21 -> 42.15 | L9: =COMBINACIONES!$E$22 -> 22.2 | M9: =COMBINACIONES!$E$23 -> 13.8 | N9: t
B10: Df — profundidad de desplante | C10: 1.5 | D10: m | E10: CAPTURA. Del nivel de terreno a la cara inferior de la zapata. | F10: Estudio de mecánica de suelos / proyecto | H10: Mx de la columna | I10: =COMBINACIONES!$F$19 -> 1.2 | J10: =COMBINACIONES!$F$20 -> 4.65 | K10: =COMBINACIONES!$F$21 -> 3.9875 | L10: =COMBINACIONES!$F$22 -> 4.33 | M10: =COMBINACIONES!$F$23 -> 4.33 | N10: t·m
B11: r — recubrimiento libre inferior | C11: 7.5 | D11: cm | E11: CAPTURA. Concreto colado contra el suelo: 75 mm. | F11: ACI 318-19, Tabla 20.5.1.3.1 (ver TABLAS) | H11: My de la columna | I11: =COMBINACIONES!$G$19 -> 0.9 | J11: =COMBINACIONES!$G$20 -> 5.15 | K11: =COMBINACIONES!$G$21 -> 4.2375 | L11: =COMBINACIONES!$G$22 -> 4.91 | M11: =COMBINACIONES!$G$23 -> 4.91 | N11: t·m
B12: r_lat — recubrimiento en las puntas de las varillas | C12: 7.5 | D12: cm | E12: CAPTURA. Caras laterales coladas contra el suelo. | F12: ACI 318-19, Tabla 20.5.1.3.1 | H12: Vx de la columna | I12: =COMBINACIONES!$H$19 -> 0.3 | J12: =COMBINACIONES!$H$20 -> 1.95 | K12: =COMBINACIONES!$H$21 -> 1.5875 | L12: =COMBINACIONES!$H$22 -> 1.87 | M12: =COMBINACIONES!$H$23 -> 1.87 | N12: t
B13: r_sup — recubrimiento superior | C13: 5 | D13: cm | E13: CAPTURA. Cara superior en contacto con el relleno: 50 mm (40 mm para #5 y menores). | F13: ACI 318-19, Tabla 20.5.1.3.1 | H13: Vy de la columna | I13: =COMBINACIONES!$I$19 -> 0.4 | J13: =COMBINACIONES!$I$20 -> 1.7 | K13: =COMBINACIONES!$I$21 -> 1.425 | L13: =COMBINACIONES!$I$22 -> 1.58 | M13: =COMBINACIONES!$I$23 -> 1.58 | N13: t
B14: α — fracción del momento que toma una contratrabe | C14: 0 | D14: — | E14: FIJO = 0. Zapata aislada sin contratrabe: la zapata toma todo el momento. | F14: Tipo de cimentación | H14: γD · ΣW (zapata + relleno + dado) | I14: =I7*$C$54 -> 19.218 | J14: =J7*$C$54 -> 19.218 | K14: =K7*$C$54 -> 19.218 | L14: =L7*$C$54 -> 11.5308 | M14: =M7*$C$54 -> 11.5308 | N14: t
B15: A — área de la zapata | C15: =$C$7*$C$8 -> 6.76 | D15: m² | E15: CALCULADA = Lx · Ly. | F15: Geometría | H15: P total sobre el terreno | I15: =I9+I14 -> 61.218 | J15: =J9+J14 -> 53.418 | K15: =K9+K14 -> 61.368 | L15: =L9+L14 -> 33.7308 | M15: =M9+M14 -> 25.3308 | N15: t
B16: h_rell — relleno sobre la zapata | C16: =$C$10-$C$9 -> 1 | D16: m | E16: CALCULADA = Df − h. | F16: Geometría | H16: Mx en el desplante = (1−α)(Mx + Vy·brazo) | I16: =(1-$C$14)*(I10+I13*$C$18) -> 1.86 | J16: =(1-$C$14)*(J10+J13*$C$18) -> 7.455 | K16: =(1-$C$14)*(K10+K13*$C$18) -> 6.33875 | L16: =(1-$C$14)*(L10+L13*$C$18) -> 6.937 | M16: =(1-$C$14)*(M10+M13*$C$18) -> 6.937 | N16: t·m
B17: H_dado — altura del dado sobre la zapata | C17: =$C$10-$C$9+DATOS!$C$66 -> 1.15 | D17: m | E17: CALCULADA = Df − h + altura del dado sobre el terreno (DATOS). | F17: Geometría | H17: My en el desplante = (1−α)(My + Vx·brazo) | I17: =(1-$C$14)*(I11+I12*$C$18) -> 1.395 | J17: =(1-$C$14)*(J11+J12*$C$18) -> 8.3675 | K17: =(1-$C$14)*(K11+K12*$C$18) -> 6.856875 | L17: =(1-$C$14)*(L11+L12*$C$18) -> 7.9955 | M17: =(1-$C$14)*(M11+M12*$C$18) -> 7.9955 | N17: t·m
B18: Brazo del cortante V hasta el desplante | C18: =IF(DATOS!$C$70="CARA SUPERIOR DEL DADO",$C$17+$C$9,$C$9) -> 1.65 | D18: m | E18: CALCULADA. Del punto donde el modelo entrega la reacción a la cara inferior de la zapata: M_desplante = M + V·brazo. | F18: Estática · DATOS, sección 6 | H18: ex = My / P | I18: =IF(I15>0,I17/I15,99) -> 0.022787415 | J18: =IF(J15>0,J17/J15,99) -> 0.15664196 | K18: =IF(K15>0,K17/K15,99) -> 0.11173372 | L18: =IF(L15>0,L17/L15,99) -> 0.23703855 | M18: =IF(M15>0,M17/M15,99) -> 0.31564341 | N18: m
B19: Brazo del cortante V hasta la cara superior de la zapata | C19: =IF(DATOS!$C$70="CARA SUPERIOR DEL DADO",$C$17,0) -> 1.15 | D19: m | E19: CALCULADA. Sirve para el momento que el dado le transmite a la zapata (penetración) y a la contratrabe. | F19: Estática | H19: ey = Mx / P | I19: =IF(I15>0,I16/I15,99) -> 0.030383221 | J19: =IF(J15>0,J16/J15,99) -> 0.1395597 | K19: =IF(K15>0,K16/K15,99) -> 0.1032908 | L19: =IF(L15>0,L16/L15,99) -> 0.20565774 | M19: =IF(M15>0,M16/M15,99) -> 0.27385633 | N19: m
B20: β — relación lado largo / lado corto | C20: =MAX($C$7,$C$8)/MIN($C$7,$C$8) -> 1 | D20: — | E20: CALCULADA. | F20: ACI 318-19, 13.3.3.3, pág. 204 | H20: Índice de núcleo 6ex/Lx + 6ey/Ly (≤ 1: contacto total) | I20: =6*I18/$C$7+6*I19/$C$8 -> 0.12270147 | J20: =6*J18/$C$7+6*J19/$C$8 -> 0.68354228 | K20: =6*K18/$C$7+6*K19/$C$8 -> 0.49621044 | L20: =6*L18/$C$7+6*L19/$C$8 -> 1.0216068 | M20: =6*M18/$C$7+6*M19/$C$8 -> 1.360384 | N20: —
B21: Ix — momento de inercia de la base (gira alrededor de X) | C21: =$C$7*$C$8^3/12 -> 3.8081333 | D21: m⁴ | E21: CALCULADA = Lx·Ly³/12. | F21: Mecánica de materiales | H21: Kx (factor uniaxial en X) | I21: =IF(I18<=$C$7/6,1+6*I18/$C$7,IF(I18<$C$7/2,4*$C$7/(3*($C$7-2*I18)),999)) -> 1.0525863 | J21: =IF(J18<=$C$7/6,1+6*J18/$C$7,IF(J18<$C$7/2,4*$C$7/(3*($C$7-2*J18)),999)) -> 1.3614814 | K21: =IF(K18<=$C$7/6,1+6*K18/$C$7,IF(K18<$C$7/2,4*$C$7/(3*($C$7-2*K18)),999)) -> 1.257847 | L21: =IF(L18<=$C$7/6,1+6*L18/$C$7,IF(L18<$C$7/2,4*$C$7/(3*($C$7-2*L18)),999)) -> 1.547012 | M21: =IF(M18<=$C$7/6,1+6*M18/$C$7,IF(M18<$C$7/2,4*$C$7/(3*($C$7-2*M18)),999)) -> 1.7284079 | N21: —
B22: Iy — momento de inercia de la base (gira alrededor de Y) | C22: =$C$8*$C$7^3/12 -> 3.8081333 | D22: m⁴ | E22: CALCULADA = Ly·Lx³/12. | F22: Mecánica de materiales | H22: Ky (factor uniaxial en Y) | I22: =IF(I19<=$C$8/6,1+6*I19/$C$8,IF(I19<$C$8/2,4*$C$8/(3*($C$8-2*I19)),999)) -> 1.0701151 | J22: =IF(J19<=$C$8/6,1+6*J19/$C$8,IF(J19<$C$8/2,4*$C$8/(3*($C$8-2*J19)),999)) -> 1.3220608 | K22: =IF(K19<=$C$8/6,1+6*K19/$C$8,IF(K19<$C$8/2,4*$C$8/(3*($C$8-2*K19)),999)) -> 1.2383634 | L22: =IF(L19<=$C$8/6,1+6*L19/$C$8,IF(L19<$C$8/2,4*$C$8/(3*($C$8-2*L19)),999)) -> 1.4745948 | M22: =IF(M19<=$C$8/6,1+6*M19/$C$8,IF(M19<$C$8/2,4*$C$8/(3*($C$8-2*M19)),999)) -> 1.6319762 | N22: —
B23: Sección crítica por flexión, distancia al centro en X | C23: =DATOS!$C$64/2 -> 0.25 | D23: m | E23: CALCULADA = cx/2: en la cara del dado. | F23: ACI 318-19, Tabla 13.2.7.1, págs. 201–202 | H23: q máx | I23: =IF(I15<=0,999,IF(I20<=1,I15/$C$15*(1+I20),MIN(999,I15/$C$15*I21*I22))) -> 10.167091 | J23: =IF(J15<=0,999,IF(J20<=1,J15/$C$15*(1+J20),MIN(999,J15/$C$15*J21*J22))) -> 13.303471 | K23: =IF(K15<=0,999,IF(K20<=1,K15/$C$15*(1+K20),MIN(999,K15/$C$15*K21*K22))) -> 13.582758 | L23: =IF(L15<=0,999,IF(L20<=1,L15/$C$15*(1+L20),MIN(999,L15/$C$15*L21*L22))) -> 11.382727 | M23: =IF(M15<=0,999,IF(M20<=1,M15/$C$15*(1+M20),MIN(999,M15/$C$15*M21*M22))) -> 10.56969 | N23: t/m²
B24: Sección crítica por flexión, distancia al centro en Y | C24: =DATOS!$C$65/2 -> 0.25 | D24: m | E24: CALCULADA = cy/2. | F24: ACI 318-19, Tabla 13.2.7.1, págs. 201–202 | H24: q mín (0 = despegue) | I24: =IF(I15<=0,0,IF(I20<=1,I15/$C$15*(1-I20),0)) -> 7.9447428 | J24: =IF(J15<=0,0,IF(J20<=1,J15/$C$15*(1-J20),0)) -> 2.5006714 | K24: =IF(K15<=0,0,IF(K20<=1,K15/$C$15*(1-K20),0)) -> 4.5734553 | L24: =IF(L15<=0,0,IF(L20<=1,L15/$C$15*(1-L20),0)) -> 0 | M24: =IF(M15<=0,0,IF(M20<=1,M15/$C$15*(1-M20),0)) -> 0 | N24: t/m²
B25: Volado en X desde la cara del dado | C25: =$C$7/2-$C$23 -> 1.05 | D25: m | E25: CALCULADA = (Lx − cx)/2. | F25: Geometría | H25: Contacto | I25: =IF(I20<=1,"TOTAL","PARCIAL") -> TOTAL | J25: =IF(J20<=1,"TOTAL","PARCIAL") -> TOTAL | K25: =IF(K20<=1,"TOTAL","PARCIAL") -> TOTAL | L25: =IF(L20<=1,"TOTAL","PARCIAL") -> PARCIAL | M25: =IF(M20<=1,"TOTAL","PARCIAL") -> PARCIAL
B26: Volado en Y desde la cara del dado | C26: =$C$8/2-$C$24 -> 1.05 | D26: m | E26: CALCULADA = (Ly − cy)/2. | F26: Geometría | H26: q adm (con incremento si hay A) | I26: =DATOS!$C$30*IF(I8>0,DATOS!$C$31,1) -> 18 | J26: =DATOS!$C$30*IF(J8>0,DATOS!$C$31,1) -> 18 | K26: =DATOS!$C$30*IF(K8>0,DATOS!$C$31,1) -> 18 | L26: =DATOS!$C$30*IF(L8>0,DATOS!$C$31,1) -> 18 | M26: =DATOS!$C$30*IF(M8>0,DATOS!$C$31,1) -> 18 | N26: t/m²
B27: ¿La geometría es coherente? | C27: =IF(AND($C$25>0,$C$26>0,$C$16>=0),"CUMPLE","NO CUMPLE — la zapata debe ser mayor que el dado y Df ≥ h") -> CUMPLE | D27: — | E27: Revisa que haya volado en las dos direcciones y que el desplante no quede arriba de la cara superior. | F27: Geometría | H27: q máx / q adm | I27: =I23/I26 -> 0.56483842 | J27: =J23/J26 -> 0.7390817 | K27: =K23/K26 -> 0.75459765 | L27: =L23/L26 -> 0.63237374 | M27: =M23/M26 -> 0.587205 | N27: —
H28: FS volteo X = Lx/(2ex) | I28: =IF(I18>0.0001,$C$7/(2*I18),99) -> 57.049032 | J28: =IF(J18>0.0001,$C$7/(2*J18),99) -> 8.2991814 | K28: =IF(K18>0.0001,$C$7/(2*K18),99) -> 11.634804 | L28: =IF(L18>0.0001,$C$7/(2*L18),99) -> 5.4843399 | M28: =IF(M18>0.0001,$C$7/(2*M18),99) -> 4.1185717 | N28: —
B29: 2. VARILLAS Y PERALTES EFECTIVOS | H29: FS volteo Y = Ly/(2ey) | I29: =IF(I19>0.0001,$C$8/(2*I19),99) -> 42.786774 | J29: =IF(J19>0.0001,$C$8/(2*J19),99) -> 9.3150101 | K29: =IF(K19>0.0001,$C$8/(2*K19),99) -> 12.585825 | L29: =IF(L19>0.0001,$C$8/(2*L19),99) -> 6.3211821 | M29: =IF(M19>0.0001,$C$8/(2*M19),99) -> 4.7470146 | N29: —
B30: Concepto | C30: Valor | D30: Unidad | E30: Cómo se calcula / de dónde sale | F30: Referencia | H30: V horizontal = (1−α)√(Vx²+Vy²) | I30: =(1-$C$14)*SQRT(I12^2+I13^2) -> 0.5 | J30: =(1-$C$14)*SQRT(J12^2+J13^2) -> 2.5869867 | K30: =(1-$C$14)*SQRT(K12^2+K13^2) -> 2.133256 | L30: =(1-$C$14)*SQRT(L12^2+L13^2) -> 2.4481217 | M30: =(1-$C$14)*SQRT(M12^2+M13^2) -> 2.4481217 | N30: t
B31: Varilla del lecho inferior ‖ X (se reparte sobre Ly) | C31: 5 | D31: # | E31: CAPTURA (lista). | F31: Propuesta | H31: FS deslizamiento = μ·P/V | I31: =IF(I30>0.0001,DATOS!$C$33*I15/I30,99) -> 55.0962 | J31: =IF(J30>0.0001,DATOS!$C$33*J15/J30,99) -> 9.2919304 | K31: =IF(K30>0.0001,DATOS!$C$33*K15/K30,99) -> 12.945282 | L31: =IF(L30>0.0001,DATOS!$C$33*L15/L30,99) -> 6.2002064 | M31: =IF(M30>0.0001,DATOS!$C$33*M15/M30,99) -> 4.6561655 | N31: —
B32: Varilla del lecho inferior ‖ Y (se reparte sobre Lx) | C32: 5 | D32: # | E32: CAPTURA (lista). | F32: Propuesta
B33: ¿Qué varillas van hasta abajo? | C33: ‖ X | D33: — | E33: CAPTURA (lista). Conviene abajo la dirección del volado más largo, que es la que tiene más momento. | F33: Práctica de armado | H33: BLOQUE U — RESISTENCIA (cargas factorizadas)
B34: Separación ‖ X que tú fijas (0 = la calcula la hoja) | C34: 0 | D34: cm | E34: CAPTURA. Déjala en 0 para que la hoja proponga la separación; si pones un valor, la hoja la revisa. | F34: Propuesta | H34: Combinación | I34: =COMBINACIONES!$B$11 -> U1 | J34: =COMBINACIONES!$B$12 -> U2 | K34: =COMBINACIONES!$B$13 -> U3 | L34: =COMBINACIONES!$B$14 -> U4 | M34: =COMBINACIONES!$B$15 -> U5
B35: Separación ‖ Y que tú fijas (0 = la calcula la hoja) | C35: 0 | D35: cm | E35: CAPTURA. Mismo criterio. | F35: Propuesta | H35: Descripción | I35: =COMBINACIONES!$C$11 -> 1.4D | J35: =COMBINACIONES!$C$12 -> 1.2D + 1.6L | K35: =COMBINACIONES!$C$13 -> 1.2D + 1.0L + 1.0E | L35: =COMBINACIONES!$C$14 -> 0.9D + 1.0E (P de A suma) | M35: =COMBINACIONES!$C$15 -> 0.9D + 1.0E (P de A resta)
B36: ¿Lleva parrilla superior? | C36: NO | D36: — | E36: CAPTURA (lista). El ACI no la exige en zapatas; se vuelve obligatoria si hay momento negativo por despegue (sección 10). | F36: Práctica · sección 10 de esta hoja | H36: γD | I36: =COMBINACIONES!$E$11 -> 1.4 | J36: =COMBINACIONES!$E$12 -> 1.2 | K36: =COMBINACIONES!$E$13 -> 1.2 | L36: =COMBINACIONES!$E$14 -> 0.9 | M36: =COMBINACIONES!$E$15 -> 0.9
B37: Varilla de la parrilla superior | C37: 4 | D37: # | E37: CAPTURA (lista). Sólo se usa si hay parrilla superior. | F37: Propuesta | H37: Pu de la columna | I37: =COMBINACIONES!$E$24 -> 42 | J37: =COMBINACIONES!$E$25 -> 55.2 | K37: =COMBINACIONES!$E$26 -> 54 | L37: =COMBINACIONES!$E$27 -> 33 | M37: =COMBINACIONES!$E$28 -> 21 | N37: t
B38: db ‖ X | C38: =INDEX(TABLAS!$C$6:$C$13,MATCH($C$31,TABLAS!$B$6:$B$13,0)) -> 1.59 | D38: cm | E38: CALCULADA con la tabla de varillas. | F38: TABLAS, tabla 1 | H38: Mux de la columna | I38: =COMBINACIONES!$F$24 -> 1.12 | J38: =COMBINACIONES!$F$25 -> 1.6 | K38: =COMBINACIONES!$F$26 -> 6.86 | L38: =COMBINACIONES!$F$27 -> 6.22 | M38: =COMBINACIONES!$F$28 -> 6.22 | N38: t·m
B39: Área de una varilla ‖ X | C39: =INDEX(TABLAS!$D$6:$D$13,MATCH($C$31,TABLAS!$B$6:$B$13,0)) -> 1.98 | D39: cm² | E39: CALCULADA con la tabla de varillas. | F39: TABLAS, tabla 1 | H39: Muy de la columna | I39: =COMBINACIONES!$G$24 -> 0.84 | J39: =COMBINACIONES!$G$25 -> 1.2 | K39: =COMBINACIONES!$G$26 -> 7.52 | L39: =COMBINACIONES!$G$27 -> 7.04 | M39: =COMBINACIONES!$G$28 -> 7.04 | N39: t·m
B40: db ‖ Y | C40: =INDEX(TABLAS!$C$6:$C$13,MATCH($C$32,TABLAS!$B$6:$B$13,0)) -> 1.59 | D40: cm | E40: CALCULADA. | F40: TABLAS, tabla 1 | H40: Vux de la columna | I40: =COMBINACIONES!$H$24 -> 0.28 | J40: =COMBINACIONES!$H$25 -> 0.4 | K40: =COMBINACIONES!$H$26 -> 2.84 | L40: =COMBINACIONES!$H$27 -> 2.68 | M40: =COMBINACIONES!$H$28 -> 2.68 | N40: t
...

Sheet AISLADA_CT
B1: ZAPATA AISLADA LIGADA CON CONTRATRABES — ACI 318-19 | H1: TABLA POR COMBINACIÓN — la memoria (col. B–F) toma de aquí lo que rige
B2: =DATOS!$C$9&" · "&DATOS!$C$10 -> Ejemplo — nave industrial · Columna tipo eje B-2 · muro eje 1 | H2: Cada columna es una combinación de la hoja COMBINACIONES. Bloque S: presiones y estabilidad con la carga TOTAL (incluye zapata, relleno y dado, multiplicados por su γD). Bloque U: diseño estructural con presión NETA (se descuenta el peso de zapata y relleno), ACI 13.2.6.3 y R13.2.6.3.
B3: Se capturan sólo las celdas amarillas de las secciones 1 y 2 y 13; cargas, materiales y suelo vienen de DATOS. A la derecha (columnas H a N) está la tabla por combinación de donde salen los valores que rigen.
B4: POR QUÉ LA CONTRATRABE: con la columna empotrada en la base, a la zapata le llega momento. La contratrabe liga las zapatas y se lleva la fracción α del momento y del cortante de la base; la zapata queda trabajando casi a carga axial y sale más chica. Con α = 1.00 (práctica usual) la zapata se diseña sólo por carga axial y la contratrabe por todo el momento. | H4: BLOQUE S — SERVICIO
H5: Combinación | I5: =COMBINACIONES!$B$6 -> S1 | J5: =COMBINACIONES!$B$7 -> S2 | K5: =COMBINACIONES!$B$8 -> S3 | L5: =COMBINACIONES!$B$9 -> S4 | M5: =COMBINACIONES!$B$10 -> S5
B6: 1. GEOMETRÍA DE LA ZAPATA | H6: Descripción | I6: =COMBINACIONES!$C$6 -> D + L | J6: =COMBINACIONES!$C$7 -> D + 0.7E | K6: =COMBINACIONES!$C$8 -> D + 0.75L + 0.525E | L6: =COMBINACIONES!$C$9 -> 0.6D + 0.7E (P de A suma) | M6: =COMBINACIONES!$C$10 -> 0.6D + 0.7E (P de A resta)
B7: Concepto | C7: Valor | D7: Unidad | E7: Cómo se calcula / de dónde sale | F7: Referencia | H7: γD | I7: =COMBINACIONES!$E$6 -> 1 | J7: =COMBINACIONES!$E$7 -> 1 | K7: =COMBINACIONES!$E$8 -> 1 | L7: =COMBINACIONES!$E$9 -> 0.6 | M7: =COMBINACIONES!$E$10 -> 0.6
B8: Lx — lado de la zapata en dirección X | C8: 2 | D8: m | E8: CAPTURA. Se ajusta hasta que la presión máxima de la sección 5 quede por debajo de qa. | F8: Propuesta — se verifica en la sección 5 | H8: γA | I8: =COMBINACIONES!$G$6 -> 0 | J8: =COMBINACIONES!$G$7 -> 0.7 | K8: =COMBINACIONES!$G$8 -> 0.525 | L8: =COMBINACIONES!$G$9 -> 0.7 | M8: =COMBINACIONES!$G$10 -> 0.7
B9: Ly — lado de la zapata en dirección Y | C9: 2 | D9: m | E9: CAPTURA. | F9: Propuesta — se verifica en la sección 5 | H9: P de la columna | I9: =COMBINACIONES!$E$19 -> 42 | J9: =COMBINACIONES!$E$20 -> 34.2 | K9: =COMBINACIONES!$E$21 -> 42.15 | L9: =COMBINACIONES!$E$22 -> 22.2 | M9: =COMBINACIONES!$E$23 -> 13.8 | N9: t
B10: h — peralte total de la zapata | C10: 0.5 | D10: m | E10: CAPTURA. Los mínimos por penetración y por dovelas salen en las secciones 4 y 12. | F10: Propuesta — se verifica en las secciones 6, 9 y 12 | H10: Mx de la columna | I10: =COMBINACIONES!$F$19 -> 1.2 | J10: =COMBINACIONES!$F$20 -> 4.65 | K10: =COMBINACIONES!$F$21 -> 3.9875 | L10: =COMBINACIONES!$F$22 -> 4.33 | M10: =COMBINACIONES!$F$23 -> 4.33 | N10: t·m
B11: Df — profundidad de desplante | C11: 1.5 | D11: m | E11: CAPTURA. Del nivel de terreno a la cara inferior de la zapata. | F11: Estudio de mecánica de suelos / proyecto | H11: My de la columna | I11: =COMBINACIONES!$G$19 -> 0.9 | J11: =COMBINACIONES!$G$20 -> 5.15 | K11: =COMBINACIONES!$G$21 -> 4.2375 | L11: =COMBINACIONES!$G$22 -> 4.91 | M11: =COMBINACIONES!$G$23 -> 4.91 | N11: t·m
B12: r — recubrimiento libre inferior | C12: 7.5 | D12: cm | E12: CAPTURA. Concreto colado contra el suelo: 75 mm. | F12: ACI 318-19, Tabla 20.5.1.3.1 (ver TABLAS) | H12: Vx de la columna | I12: =COMBINACIONES!$H$19 -> 0.3 | J12: =COMBINACIONES!$H$20 -> 1.95 | K12: =COMBINACIONES!$H$21 -> 1.5875 | L12: =COMBINACIONES!$H$22 -> 1.87 | M12: =COMBINACIONES!$H$23 -> 1.87 | N12: t
B13: r_lat — recubrimiento en las puntas de las varillas | C13: 7.5 | D13: cm | E13: CAPTURA. Caras laterales coladas contra el suelo. | F13: ACI 318-19, Tabla 20.5.1.3.1 | H13: Vy de la columna | I13: =COMBINACIONES!$I$19 -> 0.4 | J13: =COMBINACIONES!$I$20 -> 1.7 | K13: =COMBINACIONES!$I$21 -> 1.425 | L13: =COMBINACIONES!$I$22 -> 1.58 | M13: =COMBINACIONES!$I$23 -> 1.58 | N13: t
B14: r_sup — recubrimiento superior | C14: 5 | D14: cm | E14: CAPTURA. Cara superior en contacto con el relleno: 50 mm (40 mm para #5 y menores). | F14: ACI 318-19, Tabla 20.5.1.3.1 | H14: γD · ΣW (zapata + relleno + dado) | I14: =I7*$C$55 -> 11.49 | J14: =J7*$C$55 -> 11.49 | K14: =K7*$C$55 -> 11.49 | L14: =L7*$C$55 -> 6.894 | M14: =M7*$C$55 -> 6.894 | N14: t
B15: α — fracción del momento y del cortante de la base que toma la contratrabe | C15: 1 | D15: — | E15: CAPTURA. 1.00 = la contratrabe se lleva todo (práctica usual); con menos, la zapata toma (1 − α). | F15: Criterio de diseño — la contratrabe se revisa en la sección 13 | H15: P total sobre el terreno | I15: =I9+I14 -> 53.49 | J15: =J9+J14 -> 45.69 | K15: =K9+K14 -> 53.64 | L15: =L9+L14 -> 29.094 | M15: =M9+M14 -> 20.694 | N15: t
B16: A — área de la zapata | C16: =$C$8*$C$9 -> 4 | D16: m² | E16: CALCULADA = Lx · Ly. | F16: Geometría | H16: Mx en el desplante = (1−α)(Mx + Vy·brazo) | I16: =(1-$C$15)*(I10+I13*$C$19) -> 0 | J16: =(1-$C$15)*(J10+J13*$C$19) -> 0 | K16: =(1-$C$15)*(K10+K13*$C$19) -> 0 | L16: =(1-$C$15)*(L10+L13*$C$19) -> 0 | M16: =(1-$C$15)*(M10+M13*$C$19) -> 0 | N16: t·m
B17: h_rell — relleno sobre la zapata | C17: =$C$11-$C$10 -> 1 | D17: m | E17: CALCULADA = Df − h. | F17: Geometría | H17: My en el desplante = (1−α)(My + Vx·brazo) | I17: =(1-$C$15)*(I11+I12*$C$19) -> 0 | J17: =(1-$C$15)*(J11+J12*$C$19) -> 0 | K17: =(1-$C$15)*(K11+K12*$C$19) -> 0 | L17: =(1-$C$15)*(L11+L12*$C$19) -> 0 | M17: =(1-$C$15)*(M11+M12*$C$19) -> 0 | N17: t·m
B18: H_dado — altura del dado sobre la zapata | C18: =$C$11-$C$10+DATOS!$C$66 -> 1.15 | D18: m | E18: CALCULADA = Df − h + altura del dado sobre el terreno (DATOS). | F18: Geometría | H18: ex = My / P | I18: =IF(I15>0,I17/I15,99) -> 0 | J18: =IF(J15>0,J17/J15,99) -> 0 | K18: =IF(K15>0,K17/K15,99) -> 0 | L18: =IF(L15>0,L17/L15,99) -> 0 | M18: =IF(M15>0,M17/M15,99) -> 0 | N18: m
B19: Brazo del cortante V hasta el desplante | C19: =IF(DATOS!$C$70="CARA SUPERIOR DEL DADO",$C$18+$C$10,$C$10) -> 1.65 | D19: m | E19: CALCULADA. Del punto donde el modelo entrega la reacción a la cara inferior de la zapata: M_desplante = M + V·brazo. | F19: Estática · DATOS, sección 6 | H19: ey = Mx / P | I19: =IF(I15>0,I16/I15,99) -> 0 | J19: =IF(J15>0,J16/J15,99) -> 0 | K19: =IF(K15>0,K16/K15,99) -> 0 | L19: =IF(L15>0,L16/L15,99) -> 0 | M19: =IF(M15>0,M16/M15,99) -> 0 | N19: m
B20: Brazo del cortante V hasta la cara superior de la zapata | C20: =IF(DATOS!$C$70="CARA SUPERIOR DEL DADO",$C$18,0) -> 1.15 | D20: m | E20: CALCULADA. Sirve para el momento que el dado le transmite a la zapata (penetración) y a la contratrabe. | F20: Estática | H20: Índice de núcleo 6ex/Lx + 6ey/Ly (≤ 1: contacto total) | I20: =6*I18/$C$8+6*I19/$C$9 -> 0 | J20: =6*J18/$C$8+6*J19/$C$9 -> 0 | K20: =6*K18/$C$8+6*K19/$C$9 -> 0 | L20: =6*L18/$C$8+6*L19/$C$9 -> 0 | M20: =6*M18/$C$8+6*M19/$C$9 -> 0 | N20: —
B21: β — relación lado largo / lado corto | C21: =MAX($C$8,$C$9)/MIN($C$8,$C$9) -> 1 | D21: — | E21: CALCULADA. | F21: ACI 318-19, 13.3.3.3, pág. 204 | H21: Kx (factor uniaxial en X) | I21: =IF(I18<=$C$8/6,1+6*I18/$C$8,IF(I18<$C$8/2,4*$C$8/(3*($C$8-2*I18)),999)) -> 1 | J21: =IF(J18<=$C$8/6,1+6*J18/$C$8,IF(J18<$C$8/2,4*$C$8/(3*($C$8-2*J18)),999)) -> 1 | K21: =IF(K18<=$C$8/6,1+6*K18/$C$8,IF(K18<$C$8/2,4*$C$8/(3*($C$8-2*K18)),999)) -> 1 | L21: =IF(L18<=$C$8/6,1+6*L18/$C$8,IF(L18<$C$8/2,4*$C$8/(3*($C$8-2*L18)),999)) -> 1 | M21: =IF(M18<=$C$8/6,1+6*M18/$C$8,IF(M18<$C$8/2,4*$C$8/(3*($C$8-2*M18)),999)) -> 1 | N21: —
B22: Ix — momento de inercia de la base (gira alrededor de X) | C22: =$C$8*$C$9^3/12 -> 1.3333333 | D22: m⁴ | E22: CALCULADA = Lx·Ly³/12. | F22: Mecánica de materiales | H22: Ky (factor uniaxial en Y) | I22: =IF(I19<=$C$9/6,1+6*I19/$C$9,IF(I19<$C$9/2,4*$C$9/(3*($C$9-2*I19)),999)) -> 1 | J22: =IF(J19<=$C$9/6,1+6*J19/$C$9,IF(J19<$C$9/2,4*$C$9/(3*($C$9-2*J19)),999)) -> 1 | K22: =IF(K19<=$C$9/6,1+6*K19/$C$9,IF(K19<$C$9/2,4*$C$9/(3*($C$9-2*K19)),999)) -> 1 | L22: =IF(L19<=$C$9/6,1+6*L19/$C$9,IF(L19<$C$9/2,4*$C$9/(3*($C$9-2*L19)),999)) -> 1 | M22: =IF(M19<=$C$9/6,1+6*M19/$C$9,IF(M19<$C$9/2,4*$C$9/(3*($C$9-2*M19)),999)) -> 1 | N22: —
B23: Iy — momento de inercia de la base (gira alrededor de Y) | C23: =$C$9*$C$8^3/12 -> 1.3333333 | D23: m⁴ | E23: CALCULADA = Ly·Lx³/12. | F23: Mecánica de materiales | H23: q máx | I23: =IF(I15<=0,999,IF(I20<=1,I15/$C$16*(1+I20),MIN(999,I15/$C$16*I21*I22))) -> 13.3725 | J23: =IF(J15<=0,999,IF(J20<=1,J15/$C$16*(1+J20),MIN(999,J15/$C$16*J21*J22))) -> 11.4225 | K23: =IF(K15<=0,999,IF(K20<=1,K15/$C$16*(1+K20),MIN(999,K15/$C$16*K21*K22))) -> 13.41 | L23: =IF(L15<=0,999,IF(L20<=1,L15/$C$16*(1+L20),MIN(999,L15/$C$16*L21*L22))) -> 7.2735 | M23: =IF(M15<=0,999,IF(M20<=1,M15/$C$16*(1+M20),MIN(999,M15/$C$16*M21*M22))) -> 5.1735 | N23: t/m²
B24: Sección crítica por flexión, distancia al centro en X | C24: =DATOS!$C$64/2 -> 0.25 | D24: m | E24: CALCULADA = cx/2: en la cara del dado. | F24: ACI 318-19, Tabla 13.2.7.1, págs. 201–202 | H24: q mín (0 = despegue) | I24: =IF(I15<=0,0,IF(I20<=1,I15/$C$16*(1-I20),0)) -> 13.3725 | J24: =IF(J15<=0,0,IF(J20<=1,J15/$C$16*(1-J20),0)) -> 11.4225 | K24: =IF(K15<=0,0,IF(K20<=1,K15/$C$16*(1-K20),0)) -> 13.41 | L24: =IF(L15<=0,0,IF(L20<=1,L15/$C$16*(1-L20),0)) -> 7.2735 | M24: =IF(M15<=0,0,IF(M20<=1,M15/$C$16*(1-M20),0)) -> 5.1735 | N24: t/m²
B25: Sección crítica por flexión, distancia al centro en Y | C25: =DATOS!$C$65/2 -> 0.25 | D25: m | E25: CALCULADA = cy/2. | F25: ACI 318-19, Tabla 13.2.7.1, págs. 201–202 | H25: Contacto | I25: =IF(I20<=1,"TOTAL","PARCIAL") -> TOTAL | J25: =IF(J20<=1,"TOTAL","PARCIAL") -> TOTAL | K25: =IF(K20<=1,"TOTAL","PARCIAL") -> TOTAL | L25: =IF(L20<=1,"TOTAL","PARCIAL") -> TOTAL | M25: =IF(M20<=1,"TOTAL","PARCIAL") -> TOTAL
B26: Volado en X desde la cara del dado | C26: =$C$8/2-$C$24 -> 0.75 | D26: m | E26: CALCULADA = (Lx − cx)/2. | F26: Geometría | H26: q adm (con incremento si hay A) | I26: =DATOS!$C$30*IF(I8>0,DATOS!$C$31,1) -> 18 | J26: =DATOS!$C$30*IF(J8>0,DATOS!$C$31,1) -> 18 | K26: =DATOS!$C$30*IF(K8>0,DATOS!$C$31,1) -> 18 | L26: =DATOS!$C$30*IF(L8>0,DATOS!$C$31,1) -> 18 | M26: =DATOS!$C$30*IF(M8>0,DATOS!$C$31,1) -> 18 | N26: t/m²
B27: Volado en Y desde la cara del dado | C27: =$C$9/2-$C$25 -> 0.75 | D27: m | E27: CALCULADA = (Ly − cy)/2. | F27: Geometría | H27: q máx / q adm | I27: =I23/I26 -> 0.74291667 | J27: =J23/J26 -> 0.63458333 | K27: =K23/K26 -> 0.745 | L27: =L23/L26 -> 0.40408333 | M27: =M23/M26 -> 0.28741667 | N27: —
B28: ¿La geometría es coherente? | C28: =IF(AND($C$26>0,$C$27>0,$C$17>=0),"CUMPLE","NO CUMPLE — la zapata debe ser mayor que el dado y Df ≥ h") -> CUMPLE | D28: — | E28: Revisa que haya volado en las dos direcciones y que el desplante no quede arriba de la cara superior. | F28: Geometría | H28: FS volteo X = Lx/(2ex) | I28: =IF(I18>0.0001,$C$8/(2*I18),99) -> 99 | J28: =IF(J18>0.0001,$C$8/(2*J18),99) -> 99 | K28: =IF(K18>0.0001,$C$8/(2*K18),99) -> 99 | L28: =IF(L18>0.0001,$C$8/(2*L18),99) -> 99 | M28: =IF(M18>0.0001,$C$8/(2*M18),99) -> 99 | N28: —
H29: FS volteo Y = Ly/(2ey) | I29: =IF(I19>0.0001,$C$9/(2*I19),99) -> 99 | J29: =IF(J19>0.0001,$C$9/(2*J19),99) -> 99 | K29: =IF(K19>0.0001,$C$9/(2*K19),99) -> 99 | L29: =IF(L19>0.0001,$C$9/(2*L19),99) -> 99 | M29: =IF(M19>0.0001,$C$9/(2*M19),99) -> 99 | N29: —
B30: 2. VARILLAS Y PERALTES EFECTIVOS | H30: V horizontal = (1−α)√(Vx²+Vy²) | I30: =(1-$C$15)*SQRT(I12^2+I13^2) -> 0 | J30: =(1-$C$15)*SQRT(J12^2+J13^2) -> 0 | K30: =(1-$C$15)*SQRT(K12^2+K13^2) -> 0 | L30: =(1-$C$15)*SQRT(L12^2+L13^2) -> 0 | M30: =(1-$C$15)*SQRT(M12^2+M13^2) -> 0 | N30: t
B31: Concepto | C31: Valor | D31: Unidad | E31: Cómo se calcula / de dónde sale | F31: Referencia | H31: FS deslizamiento = μ·P/V | I31: =IF(I30>0.0001,DATOS!$C$33*I15/I30,99) -> 99 | J31: =IF(J30>0.0001,DATOS!$C$33*J15/J30,99) -> 99 | K31: =IF(K30>0.0001,DATOS!$C$33*K15/K30,99) -> 99 | L31: =IF(L30>0.0001,DATOS!$C$33*L15/L30,99) -> 99 | M31: =IF(M30>0.0001,DATOS!$C$33*M15/M30,99) -> 99 | N31: —
B32: Varilla del lecho inferior ‖ X (se reparte sobre Ly) | C32: 5 | D32: # | E32: CAPTURA (lista). | F32: Propuesta
B33: Varilla del lecho inferior ‖ Y (se reparte sobre Lx) | C33: 5 | D33: # | E33: CAPTURA (lista). | F33: Propuesta | H33: BLOQUE U — RESISTENCIA (cargas factorizadas)
B34: ¿Qué varillas van hasta abajo? | C34: ‖ X | D34: — | E34: CAPTURA (lista). Conviene abajo la dirección del volado más largo, que es la que tiene más momento. | F34: Práctica de armado | H34: Combinación | I34: =COMBINACIONES!$B$11 -> U1 | J34: =COMBINACIONES!$B$12 -> U2 | K34: =COMBINACIONES!$B$13 -> U3 | L34: =COMBINACIONES!$B$14 -> U4 | M34: =COMBINACIONES!$B$15 -> U5
B35: Separación ‖ X que tú fijas (0 = la calcula la hoja) | C35: 0 | D35: cm | E35: CAPTURA. Déjala en 0 para que la hoja proponga la separación; si pones un valor, la hoja la revisa. | F35: Propuesta | H35: Descripción | I35: =COMBINACIONES!$C$11 -> 1.4D | J35: =COMBINACIONES!$C$12 -> 1.2D + 1.6L | K35: =COMBINACIONES!$C$13 -> 1.2D + 1.0L + 1.0E | L35: =COMBINACIONES!$C$14 -> 0.9D + 1.0E (P de A suma) | M35: =COMBINACIONES!$C$15 -> 0.9D + 1.0E (P de A resta)
B36: Separación ‖ Y que tú fijas (0 = la calcula la hoja) | C36: 0 | D36: cm | E36: CAPTURA. Mismo criterio. | F36: Propuesta | H36: γD | I36: =COMBINACIONES!$E$11 -> 1.4 | J36: =COMBINACIONES!$E$12 -> 1.2 | K36: =COMBINACIONES!$E$13 -> 1.2 | L36: =COMBINACIONES!$E$14 -> 0.9 | M36: =COMBINACIONES!$E$15 -> 0.9
B37: ¿Lleva parrilla superior? | C37: NO | D37: — | E37: CAPTURA (lista). El ACI no la exige en zapatas; se vuelve obligatoria si hay momento negativo por despegue (sección 10). | F37: Práctica · sección 10 de esta hoja | H37: Pu de la columna | I37: =COMBINACIONES!$E$24 -> 42 | J37: =COMBINACIONES!$E$25 -> 55.2 | K37: =COMBINACIONES!$E$26 -> 54 | L37: =COMBINACIONES!$E$27 -> 33 | M37: =COMBINACIONES!$E$28 -> 21 | N37: t
B38: Varilla de la parrilla superior | C38: 4 | D38: # | E38: CAPTURA (lista). Sólo se usa si hay parrilla superior. | F38: Propuesta | H38: Mux de la columna | I38: =COMBINACIONES!$F$24 -> 1.12 | J38: =COMBINACIONES!$F$25 -> 1.6 | K38: =COMBINACIONES!$F$26 -> 6.86 | L38: =COMBINACIONES!$F$27 -> 6.22 | M38: =COMBINACIONES!$F$28 -> 6.22 | N38: t·m
B39: db ‖ X | C39: =INDEX(TABLAS!$C$6:$C$13,MATCH($C$32,TABLAS!$B$6:$B$13,0)) -> 1.59 | D39: cm | E39: CALCULADA con la tabla de varillas. | F39: TABLAS, tabla 1 | H39: Muy de la columna | I39: =COMBINACIONES!$G$24 -> 0.84 | J39: =COMBINACIONES!$G$25 -> 1.2 | K39: =COMBINACIONES!$G$26 -> 7.52 | L39: =COMBINACIONES!$G$27 -> 7.04 | M39: =COMBINACIONES!$G$28 -> 7.04 | N39: t·m
B40: Área de una varilla ‖ X | C40: =INDEX(TABLAS!$D$6:$D$13,MATCH($C$32,TABLAS!$B$6:$B$13,0)) -> 1.98 | D40: cm² | E40: CALCULADA con la tabla de varillas. | F40: TABLAS, tabla 1 | H40: Vux de la columna | I40: =COMBINACIONES!$H$24 -> 0.28 | J40: =COMBINACIONES!$H$25 -> 0.4 | K40: =COMBINACIONES!$H$26 -> 2.84 | L40: =COMBINACIONES!$H$27 -> 2.68 | M40: =COMBINACIONES!$H$28 -> 2.68 | N40: t
...

Sheet CORRIDA
B1: ZAPATA CORRIDA BAJO MURO — ACI 318-19 (por metro de longitud) | H1: TABLA POR COMBINACIÓN — por metro de muro
B2: =DATOS!$C$9&" · "&DATOS!$C$10 -> Ejemplo — nave industrial · Columna tipo eje B-2 · muro eje 1 | H2: Bloque S con carga total (incluye zapata, relleno y muro enterrado por su γD); bloque U con presión neta para el diseño estructural (ACI 13.2.6.3).
B3: Se capturan sólo las celdas amarillas de las secciones 1 y 2; las cargas por metro vienen de DATOS (sección 7). A la derecha (columnas H a N) está la tabla por combinación.
H4: BLOQUE S — SERVICIO
B5: 1. GEOMETRÍA (por metro de muro) | H5: Combinación | I5: =COMBINACIONES!$B$6 -> S1 | J5: =COMBINACIONES!$B$7 -> S2 | K5: =COMBINACIONES!$B$8 -> S3 | L5: =COMBINACIONES!$B$9 -> S4 | M5: =COMBINACIONES!$B$10 -> S5
B6: Concepto | C6: Valor | D6: Unidad | E6: Cómo se calcula / de dónde sale | F6: Referencia | H6: Descripción | I6: =COMBINACIONES!$C$6 -> D + L | J6: =COMBINACIONES!$C$7 -> D + 0.7E | K6: =COMBINACIONES!$C$8 -> D + 0.75L + 0.525E | L6: =COMBINACIONES!$C$9 -> 0.6D + 0.7E (P de A suma) | M6: =COMBINACIONES!$C$10 -> 0.6D + 0.7E (P de A resta)
B7: B — ancho de la zapata | C7: 0.9 | D7: m | E7: CAPTURA. Se ajusta hasta que la presión de la sección 5 quede abajo de qa. | F7: Propuesta — se verifica en la sección 5 | H7: γD | I7: =COMBINACIONES!$E$6 -> 1 | J7: =COMBINACIONES!$E$7 -> 1 | K7: =COMBINACIONES!$E$8 -> 1 | L7: =COMBINACIONES!$E$9 -> 0.6 | M7: =COMBINACIONES!$E$10 -> 0.6
B8: h — peralte total | C8: 0.25 | D8: m | E8: CAPTURA. | F8: Propuesta — se verifica en las secciones 6 y 7 | H8: γA | I8: =COMBINACIONES!$G$6 -> 0 | J8: =COMBINACIONES!$G$7 -> 0.7 | K8: =COMBINACIONES!$G$8 -> 0.525 | L8: =COMBINACIONES!$G$9 -> 0.7 | M8: =COMBINACIONES!$G$10 -> 0.7
B9: Df — profundidad de desplante | C9: 0.8 | D9: m | E9: CAPTURA. | F9: Estudio de mecánica de suelos / proyecto | H9: w del muro | I9: =COMBINACIONES!$E$32 -> 6.5 | J9: =COMBINACIONES!$E$33 -> 5.56 | K9: =COMBINACIONES!$E$34 -> 6.545 | L9: =COMBINACIONES!$E$35 -> 3.56 | M9: =COMBINACIONES!$E$36 -> 2.44 | N9: t/m
B10: t — ancho del muro (o del dado corrido) sobre la zapata | C10: 0.2 | D10: m | E10: CAPTURA. | F10: Proyecto | H10: M del muro | I10: =COMBINACIONES!$F$32 -> 0 | J10: =COMBINACIONES!$F$33 -> 0.21 | K10: =COMBINACIONES!$F$34 -> 0.1575 | L10: =COMBINACIONES!$F$35 -> 0.21 | M10: =COMBINACIONES!$F$36 -> 0.21 | N10: t·m/m
B11: Tipo de muro que se apoya | C11: MAMPOSTERÍA | D11: — | E11: CAPTURA (lista). Define la sección crítica: cara del muro si es de concreto; a la mitad entre el eje y la cara si es de mampostería. | F11: ACI 318-19, Tabla 13.2.7.1, págs. 201–202 | H11: V del muro | I11: =COMBINACIONES!$G$32 -> 0 | J11: =COMBINACIONES!$G$33 -> 0.28 | K11: =COMBINACIONES!$G$34 -> 0.21 | L11: =COMBINACIONES!$G$35 -> 0.28 | M11: =COMBINACIONES!$G$36 -> 0.28 | N11: t/m
B12: γ del muro o dado bajo el terreno | C12: 2 | D12: t/m³ | E12: CAPTURA. Del nivel de terreno a la cara de la zapata. | F12: Práctica | H12: γD · ΣW | I12: =I7*$C$40 -> 1.376 | J12: =J7*$C$40 -> 1.376 | K12: =K7*$C$40 -> 1.376 | L12: =L7*$C$40 -> 0.8256 | M12: =M7*$C$40 -> 0.8256 | N12: t/m
B13: r — recubrimiento libre inferior | C13: 7.5 | D13: cm | E13: CAPTURA. Colado contra el suelo: 75 mm. | F13: ACI 318-19, Tabla 20.5.1.3.1 | H13: w total | I13: =I9+I12 -> 7.876 | J13: =J9+J12 -> 6.936 | K13: =K9+K12 -> 7.921 | L13: =L9+L12 -> 4.3856 | M13: =M9+M12 -> 3.2656 | N13: t/m
B14: r_lat — recubrimiento en las puntas | C14: 7.5 | D14: cm | E14: CAPTURA. | F14: ACI 318-19, Tabla 20.5.1.3.1 | H14: M en el desplante = M + V·Df | I14: =I10+I11*$C$20 -> 0 | J14: =J10+J11*$C$20 -> 0.434 | K14: =K10+K11*$C$20 -> 0.3255 | L14: =L10+L11*$C$20 -> 0.434 | M14: =M10+M11*$C$20 -> 0.434 | N14: t·m/m
B15: Tramo de zapata que se dibuja en el croquis | C15: 2 | D15: m | E15: CAPTURA. Sólo para el dibujo. | F15: CROQUIS | H15: e = M / w | I15: =IF(I13>0,I14/I13,99) -> 0 | J15: =IF(J13>0,J14/J13,99) -> 0.062572088 | K15: =IF(K13>0,K14/K13,99) -> 0.041093296 | L15: =IF(L13>0,L14/L13,99) -> 0.098960233 | M15: =IF(M13>0,M14/M13,99) -> 0.13290054 | N15: m
B16: h_rell — relleno sobre la zapata | C16: =$C$9-$C$8 -> 0.55 | D16: m | E16: CALCULADA = Df − h. | F16: Geometría | H16: q máx | I16: =IF(I13<=0,999,IF(I15<=$C$7/6,I13/$C$7*(1+6*I15/$C$7),IF(I15<$C$7/2,2*I13/(3*($C$7/2-I15)),999))) -> 8.7511111 | J16: =IF(J13<=0,999,IF(J15<=$C$7/6,J13/$C$7*(1+6*J15/$C$7),IF(J15<$C$7/2,2*J13/(3*($C$7/2-J15)),999))) -> 10.921481 | K16: =IF(K13<=0,999,IF(K15<=$C$7/6,K13/$C$7*(1+6*K15/$C$7),IF(K15<$C$7/2,2*K13/(3*($C$7/2-K15)),999))) -> 11.212222 | L16: =IF(L13<=0,999,IF(L15<=$C$7/6,L13/$C$7*(1+6*L15/$C$7),IF(L15<$C$7/2,2*L13/(3*($C$7/2-L15)),999))) -> 8.0877037 | M16: =IF(M13<=0,999,IF(M15<=$C$7/6,M13/$C$7*(1+6*M15/$C$7),IF(M15<$C$7/2,2*M13/(3*($C$7/2-M15)),999))) -> 6.8432593 | N16: t/m²
B17: Sección crítica, distancia al eje del muro | C17: =IF($C$11="MAMPOSTERÍA",$C$10/4,$C$10/2) -> 0.05 | D17: m | E17: CALCULADA: t/2 (cara) para concreto; t/4 (mitad entre eje y cara) para mampostería. | F17: ACI 318-19, Tabla 13.2.7.1, págs. 201–202 | H17: q mín | I17: =IF(I13<=0,0,IF(I15<=$C$7/6,I13/$C$7*(1-6*I15/$C$7),0)) -> 8.7511111 | J17: =IF(J13<=0,0,IF(J15<=$C$7/6,J13/$C$7*(1-6*J15/$C$7),0)) -> 4.4918519 | K17: =IF(K13<=0,0,IF(K15<=$C$7/6,K13/$C$7*(1-6*K15/$C$7),0)) -> 6.39 | L17: =IF(L13<=0,0,IF(L15<=$C$7/6,L13/$C$7*(1-6*L15/$C$7),0)) -> 1.6580741 | M17: =IF(M13<=0,0,IF(M15<=$C$7/6,M13/$C$7*(1-6*M15/$C$7),0)) -> 0.41362963 | N17: t/m²
B18: Volado de cálculo desde la sección crítica | C18: =$C$7/2-$C$17 -> 0.4 | D18: m | E18: CALCULADA. | F18: Geometría | H18: Contacto | I18: =IF(I15<=$C$7/6,"TOTAL","PARCIAL") -> TOTAL | J18: =IF(J15<=$C$7/6,"TOTAL","PARCIAL") -> TOTAL | K18: =IF(K15<=$C$7/6,"TOTAL","PARCIAL") -> TOTAL | L18: =IF(L15<=$C$7/6,"TOTAL","PARCIAL") -> TOTAL | M18: =IF(M15<=$C$7/6,"TOTAL","PARCIAL") -> TOTAL
B19: I de la base por metro de muro | C19: =$C$7^3/12 -> 0.06075 | D19: m⁴/m | E19: CALCULADA = 1·B³/12. | F19: Mecánica de materiales | H19: q adm | I19: =DATOS!$C$30*IF(I8>0,DATOS!$C$31,1) -> 18 | J19: =DATOS!$C$30*IF(J8>0,DATOS!$C$31,1) -> 18 | K19: =DATOS!$C$30*IF(K8>0,DATOS!$C$31,1) -> 18 | L19: =DATOS!$C$30*IF(L8>0,DATOS!$C$31,1) -> 18 | M19: =DATOS!$C$30*IF(M8>0,DATOS!$C$31,1) -> 18 | N19: t/m²
B20: Brazo del cortante V hasta el desplante | C20: =$C$9 -> 0.8 | D20: m | E20: CALCULADA = Df (la carga llega al nivel de terreno). | F20: Estática | H20: q máx / q adm | I20: =I16/I19 -> 0.48617284 | J20: =J16/J19 -> 0.60674897 | K20: =K16/K19 -> 0.62290123 | L20: =L16/L19 -> 0.44931687 | M20: =M16/M19 -> 0.38018107 | N20: —
B21: ¿La geometría es coherente? | C21: =IF(AND($C$7>$C$10,$C$16>=0),"CUMPLE","NO CUMPLE — B debe ser mayor que t y Df ≥ h") -> CUMPLE | D21: — | E21: Revisión de datos. | F21: Geometría | H21: FS volteo = B/(2e) | I21: =IF(I15>0.0001,$C$7/(2*I15),99) -> 99 | J21: =IF(J15>0.0001,$C$7/(2*J15),99) -> 7.1917051 | K21: =IF(K15>0.0001,$C$7/(2*K15),99) -> 10.950691 | L21: =IF(L15>0.0001,$C$7/(2*L15),99) -> 4.5472811 | M21: =IF(M15>0.0001,$C$7/(2*M15),99) -> 3.3859908 | N21: —
H22: FS deslizamiento = μ w / V | I22: =IF(I11>0.0001,DATOS!$C$33*I13/I11,99) -> 99 | J22: =IF(J11>0.0001,DATOS!$C$33*J13/J11,99) -> 11.147143 | K22: =IF(K11>0.0001,DATOS!$C$33*K13/K11,99) -> 16.973571 | L22: =IF(L11>0.0001,DATOS!$C$33*L13/L11,99) -> 7.0482857 | M22: =IF(M11>0.0001,DATOS!$C$33*M13/M11,99) -> 5.2482857 | N22: —
B23: 2. VARILLAS Y PERALTE EFECTIVO
B24: Concepto | C24: Valor | D24: Unidad | E24: Cómo se calcula / de dónde sale | F24: Referencia | H24: BLOQUE U — RESISTENCIA
B25: Varilla transversal (principal, lecho inferior) | C25: 4 | D25: # | E25: CAPTURA (lista). | F25: Propuesta | H25: Combinación | I25: =COMBINACIONES!$B$11 -> U1 | J25: =COMBINACIONES!$B$12 -> U2 | K25: =COMBINACIONES!$B$13 -> U3 | L25: =COMBINACIONES!$B$14 -> U4 | M25: =COMBINACIONES!$B$15 -> U5
B26: Varilla longitudinal (por temperatura, encima de la transversal) | C26: 3 | D26: # | E26: CAPTURA (lista). | F26: Propuesta | H26: Descripción | I26: =COMBINACIONES!$C$11 -> 1.4D | J26: =COMBINACIONES!$C$12 -> 1.2D + 1.6L | K26: =COMBINACIONES!$C$13 -> 1.2D + 1.0L + 1.0E | L26: =COMBINACIONES!$C$14 -> 0.9D + 1.0E (P de A suma) | M26: =COMBINACIONES!$C$15 -> 0.9D + 1.0E (P de A resta)
B27: Separación transversal que tú fijas (0 = la calcula la hoja) | C27: 0 | D27: cm | E27: CAPTURA. | F27: Propuesta | H27: γD | I27: =COMBINACIONES!$E$11 -> 1.4 | J27: =COMBINACIONES!$E$12 -> 1.2 | K27: =COMBINACIONES!$E$13 -> 1.2 | L27: =COMBINACIONES!$E$14 -> 0.9 | M27: =COMBINACIONES!$E$15 -> 0.9
B28: db transversal | C28: =INDEX(TABLAS!$C$6:$C$13,MATCH($C$25,TABLAS!$B$6:$B$13,0)) -> 1.27 | D28: cm | E28: CALCULADA. | F28: TABLAS, tabla 1 | H28: wu del muro | I28: =COMBINACIONES!$E$37 -> 7 | J28: =COMBINACIONES!$E$38 -> 8.4 | K28: =COMBINACIONES!$E$39 -> 8.3 | L28: =COMBINACIONES!$E$40 -> 5.3 | M28: =COMBINACIONES!$E$41 -> 3.7 | N28: t/m
B29: Área de una varilla transversal | C29: =INDEX(TABLAS!$D$6:$D$13,MATCH($C$25,TABLAS!$B$6:$B$13,0)) -> 1.27 | D29: cm² | E29: CALCULADA. | F29: TABLAS, tabla 1 | H29: Mu del muro | I29: =COMBINACIONES!$F$37 -> 0 | J29: =COMBINACIONES!$F$38 -> 0 | K29: =COMBINACIONES!$F$39 -> 0.3 | L29: =COMBINACIONES!$F$40 -> 0.3 | M29: =COMBINACIONES!$F$41 -> 0.3 | N29: t·m/m
B30: db longitudinal | C30: =INDEX(TABLAS!$C$6:$C$13,MATCH($C$26,TABLAS!$B$6:$B$13,0)) -> 0.95 | D30: cm | E30: CALCULADA. | F30: TABLAS, tabla 1 | H30: Vu del muro | I30: =COMBINACIONES!$G$37 -> 0 | J30: =COMBINACIONES!$G$38 -> 0 | K30: =COMBINACIONES!$G$39 -> 0.4 | L30: =COMBINACIONES!$G$40 -> 0.4 | M30: =COMBINACIONES!$G$41 -> 0.4 | N30: t/m
B31: Área de una varilla longitudinal | C31: =INDEX(TABLAS!$D$6:$D$13,MATCH($C$26,TABLAS!$B$6:$B$13,0)) -> 0.71 | D31: cm² | E31: CALCULADA. | F31: TABLAS, tabla 1 | H31: wu sobre la zapata = wu + γD·W_muro | I31: =I28+I27*$C$39 -> 7.308 | J31: =J28+J27*$C$39 -> 8.664 | K31: =K28+K27*$C$39 -> 8.564 | L31: =L28+L27*$C$39 -> 5.498 | M31: =M28+M27*$C$39 -> 3.898 | N31: t/m
B32: d — peralte efectivo de la transversal | C32: =$C$8*100-$C$13-$C$28/2 -> 16.865 | D32: cm | E32: CALCULADA = h − r − db/2. | F32: Geometría | H32: γD · (W_zap + W_rell) | I32: =I27*($C$37+$C$38) -> 1.6184 | J32: =J27*($C$37+$C$38) -> 1.3872 | K32: =K27*($C$37+$C$38) -> 1.3872 | L32: =L27*($C$37+$C$38) -> 1.0404 | M32: =M27*($C$37+$C$38) -> 1.0404 | N32: t/m
B33: ¿El peralte efectivo es de al menos 15 cm? | C33: =IF($C$32>=15,"CUMPLE","NO CUMPLE — aumentar h") -> CUMPLE | D33: — | E33: Mínimo 150 mm. | F33: ACI 318-19, 13.3.1.2, pág. 203 | H33: w_u repartido | I33: =I32/$C$7 -> 1.7982222 | J33: =J32/$C$7 -> 1.5413333 | K33: =K32/$C$7 -> 1.5413333 | L33: =L32/$C$7 -> 1.156 | M33: =M32/$C$7 -> 1.156 | N33: t/m²
H34: w total factorizada | I34: =I31+I32 -> 8.9264 | J34: =J31+J32 -> 10.0512 | K34: =K31+K32 -> 9.9512 | L34: =L31+L32 -> 6.5384 | M34: =M31+M32 -> 4.9384 | N34: t/m
