Workbook

Sheet DATOS
B1: ESPECTROS Y CARGAS SÍSMICAS PARA NAVES — EL SALVADOR — DATOS DE ENTRADA
B2: Norma Técnica para Diseño por Sismo NTDS-1994 (MOP, rige en todo el país) y, dentro del AMSS, la Reforma OPAMSS de 2022 que manda usar ASCE/SEI 7-16 con su Anexo 37. Eliges el tipo de estructura de cada dirección de la nave y salen el coeficiente, el cortante basal y el espectro para STAAD.
B4: 1. PROYECTO Y NORMA QUE RIGE
B5: La norma nacional es la NTDS-1994 (parte de la RESESCO). Si el predio está en el Área Metropolitana de San Salvador además rige la Reforma OPAMSS publicada el 6 de enero de 2022, que mete ASCE/SEI 7-16 con su Anexo 37.
B6: Concepto | C6: Valor | D6: Unidad | E6: Cómo se calcula / de dónde sale | F6: Referencia
B7: Proyecto | C7: HANGAR NOSE-DOCK H5-H6 | E7: CAPTURA. Sólo para identificar la corrida. | F7: NTDS-1994 · §1.2.3, pág. 1 (datos que pide la memoria)
B8: Ubicación | C8: Departamento de LA PAZ, EL SALVADOR | E8: CAPTURA. Municipio y departamento. La zona sísmica se elige abajo con el mapa de la Fig. 1. | F8: NTDS-1994 · §1.2.3, pág. 1
B9: ¿El predio está dentro del AMSS? | C9: NO | D9: — | E9: SELECTOR SÍ / NO. El AMSS son 14: San Salvador, Mejicanos, Ayutuxtepeque, Cuscatancingo, Ciudad Delgado, Apopa, Nejapa, Tonacatepeque, Soyapango, Ilopango, San Martín, San Marcos, Santa Tecla y Antiguo Cuscatlán. Fuera de ahí sólo rige la NTDS. | F9: Reforma OPAMSS · Considerando II · DO Tomo 434, pág. 67
B10: ¿Lleva aisladores o disipadores de energía? | C10: NO | D10: — | E10: SELECTOR SÍ / NO. Con SÍ, en el AMSS la ASCE 7-16 es obligatoria y también el estudio de respuesta sísmica local. | F10: Art. VI.7-B lit. C y Anexo 37 punto 1.a · DO págs. 74 y 75
B11: Criterio para comparar ASCE contra la NTDS | C11: FACTORIZADA | D11: — | E11: SELECTOR. FACTORIZADA: la NTDS se lleva a nivel último antes de comparar, porque sus fuerzas son de esfuerzos permisibles y las de ASCE son de resistencia. DIRECTA: se comparan los coeficientes tal cual (menos exigente). Recomendado: FACTORIZADA. | F11: Art. VI.7-B lit. B, DO pág. 73 · Comentarios NTDS, pág. 7 · RESESCO Art. 21, págs. 7 y 8
B12: Factor que se le aplica a la NTDS al comparar | C12: =IF($C$11="FACTORIZADA",1.43,1) -> 1.43 | D12: — | E12: CALCULADA. 1.43 es el mayor factor que la RESESCO le pone al sismo: 0.75 × 1.87 = 1.40 en la ec. (2) y 1.43 en la ec. (3). ASCE lo combina con 1.0. | F12: RESESCO 1996 · Art. 21, ecs. (2) y (3), págs. 7 y 8
B13: Norma que rige el diseño sísmico | C13: =IF($C$9="NO","NTDS-1994",IF($C$10="SÍ","ASCE 7-16","NTDS o ASCE 7-16")) -> NTDS-1994 | D13: — | E13: CALCULADA. Fuera del AMSS: NTDS. En el AMSS con aisladores o disipadores: ASCE 7-16 obligatoria. En el AMSS sin ellos se puede escoger; si usas ASCE hay que demostrar que no queda abajo de la NTDS (hoja COEFICIENTE, sección C). | F13: Art. VI.7-B, lits. A, B y C · DO págs. 73 y 74
B14: ¿Se exige estudio de respuesta sísmica local? | C14: =IF($C$9="NO","NO SE EXIGE",IF(OR($C$10="SÍ",$C$34="SÍ"),"OBLIGATORIO","NO SE EXIGE")) -> NO SE EXIGE | D14: — | E14: CALCULADA. La guía lo pide con aisladores o disipadores (1.a), con inversión de Vs entre estratos (1.f) y en clase F. No es lo mismo que el estudio de amplificación sísmica local. | F14: Anexo 37 · puntos 1.a y 1.f y Tabla 2 · DO págs. 75 y 76
B16: 2. NTDS-1994 — ZONA, SUELO Y OCUPACIÓN
B17: Con A (zona), C_o y T_o (suelo) e I (ocupación) sale el espectro nacional; R lo pone el tipo de estructura de cada dirección (sección 4). Aplica en todo el país, dentro y fuera del AMSS.
B18: Concepto | C18: Valor | D18: Unidad | E18: Cómo se calcula / de dónde sale | F18: Referencia
B19: Zona sísmica | C19: 1 | D19: — | E19: SELECTOR 1 ó 2 con la Fig. 1. La línea divisoria va de San Antonio Pajonal (Santa Ana) a la frontera con Honduras sobre el río Goascorán. Zona 1 al sur: todo el AMSS, la franja costera y todas las islas. Zona 2 al norte. | F19: NTDS-1994 · Tabla 1 y Fig. 1, pág. 19
B20: A — factor de zonificación sísmica | C20: =INDEX(TABLAS!$D$7:$D$8,MATCH($C$19,TABLAS!$B$7:$B$8,0)) -> 0.4 | D20: g | E20: CALCULADA. Aceleración pico efectiva del terreno para el sismo de 10% de excedencia en 50 años. | F20: NTDS-1994 · Tabla 1, pág. 19 · Comentarios, pág. 8
B21: Perfil de suelo | C21: S3 | D21: — | E21: SELECTOR S1 a S4 con el estudio geotécnico. S1 roca o suelo muy denso de menos de 30 m; S2 denso de 30 m o más, o compacto de menos de 30 m; S3 de 4 a 12 m de suelo blando o suelto; S4 más de 12 m blando con Vs < 150 m/s. Sin datos suficientes, S3. | F21: NTDS-1994 · Tabla 2 y nota (1), pág. 20
B22: C_o — coeficiente de sitio | C22: =INDEX(TABLAS!$D$13:$D$16,MATCH($C$21,TABLAS!$B$13:$B$16,0)) -> 3 | D22: — | E22: CALCULADA. Cuántas veces A vale la meseta del espectro. | F22: NTDS-1994 · Tabla 2, pág. 20
B23: T_o — periodo del sitio | C23: =INDEX(TABLAS!$E$13:$E$16,MATCH($C$21,TABLAS!$B$13:$B$16,0)) -> 0.6 | D23: s | E23: CALCULADA. Donde termina la meseta. La meseta empieza en T_o/3. | F23: NTDS-1994 · Tabla 2, pág. 20
B24: Categoría de ocupación | C24: II | D24: — | E24: SELECTOR. I esenciales o peligrosos. II ocupación especial: incluye locales que alojan equipo especialmente costoso y almacenes de 500 m² o más, o de más de 10 m de alto. III ocupación normal, incluye edificaciones industriales. EJEMPLO: II porque el hangar aloja la aeronave; si se acepta como industrial normal, pon III. | F24: NTDS-1994 · Tabla 3, pág. 21
B25: I — factor de importancia | C25: =INDEX(TABLAS!$D$21:$D$23,MATCH($C$24,TABLAS!$B$21:$B$23,0)) -> 1.2 | D25: — | E25: CALCULADA: 1.5 / 1.2 / 1.0. Multiplica todo el espectro. | F25: NTDS-1994 · Tabla 4, pág. 21
B26: Meseta elástica = I·A·C_o (con R = 1) | C26: =$C$25*$C$20*$C$22 -> 1.44 | D26: g | E26: CALCULADA. La de diseño de cada dirección (÷ R) sale en COEFICIENTE y ESPECTROS. | F26: NTDS-1994 · §5.2, pág. 11
B28: 3. ASCE/SEI 7-16 CON EL ANEXO 37 DE OPAMSS (SÓLO AMSS)
B29: La guía fija un solo S_S y S_1 para todo el AMSS y trae su propia clasificación de sitio y sus propios F_a y F_v. Todo lo demás es ASCE 7-16 íntegro. Fuera del AMSS esta sección queda sólo de referencia (sus capturas se ponen grises).
B30: Concepto | C30: Valor | D30: Unidad | E30: Cómo se calcula / de dónde sale | F30: Referencia
B31: S_S — aceleración espectral MCE en 0.2 s | C31: =TABLAS!$D$101 -> 2.21 | D31: g | E31: FIJA. Sismo de 2% de excedencia en 50 años (≈ 2,500 años de retorno). No se busca en mapas: es la misma para todo el AMSS. | F31: Anexo 37 · punto 2 · DO pág. 76
B32: S_1 — aceleración espectral MCE en 1 s | C32: =TABLAS!$D$102 -> 0.62 | D32: g | E32: FIJA. Mismo nivel de peligro. Como S_1 ≥ 0.6 g, siempre aplica el mínimo de la ec. 12.8-6. | F32: Anexo 37 · punto 2 · DO pág. 76
B33: V_s30 — velocidad de onda de corte promedio en 30 m | C33: 250 | D33: m/s | E33: CAPTURA. Medida con métodos directos o indirectos en dos direcciones ortogonales, una medición por cada 2,000 m². No se permite sacarla de SPT o CPT salvo edificios de hasta 2 niveles, de 500 m² o menos y con menos de 100 personas. | F33: Anexo 37 · puntos 1.b y 1.d · DO pág. 75
B34: ¿Suelo especial o inversión de V_s? | C34: NO | D34: — | E34: SELECTOR. SÍ si hay suelos licuables, turbas, arcillas muy sensibles o muy plásticas, o si los datos geofísicos muestran inversión de V_s entre estratos. Con SÍ la clase es F. | F34: Anexo 37 · punto 1.f · DO pág. 76 · ASCE 7-16 §20.3.1
B35: Clase de sitio | C35: =IF($C$34="SÍ","F",IF($C$33>1500,"A",IF($C$33>=760,"B",IF($C$33>=360,"C",IF($C$33>=180,"D","E"))))) -> D | D35: — | E35: CALCULADA con V_s30: A > 1500; B 760–1500; C 360–760; D 180–360; E < 180 m/s. En los límites exactos se toma la clase más rígida. | F35: Anexo 37 · Tabla 1 · DO pág. 75
B36: F_a — coeficiente de sitio en periodo corto | C36: =INDEX(TABLAS!$D$91:$D$96,MATCH($C$35,TABLAS!$B$91:$B$96,0)) -> 1.16 | D36: — | E36: CALCULADA. Tabla propia del Anexo: no depende de S_S. En clase F usa el de E sólo como referencia. | F36: Anexo 37 · Tabla 2 · DO pág. 76 (sustituye la Tabla 11.4-1)
B37: F_v — coeficiente de sitio en 1 s | C37: =INDEX(TABLAS!$E$91:$E$96,MATCH($C$35,TABLAS!$B$91:$B$96,0)) -> 3.25 | D37: — | E37: CALCULADA. Tabla propia del Anexo: no depende de S_1. En clase F usa el de E sólo como referencia. | F37: Anexo 37 · Tabla 2 · DO pág. 76 (sustituye la Tabla 11.4-2)
B38: S_MS = F_a · S_S | C38: =$C$36*$C$31 -> 2.5636 | D38: g | E38: CALCULADA. MCE_R ajustado por sitio, periodo corto. | F38: ASCE 7-16 · ec. 11.4-1
B39: S_M1 = F_v · S_1 | C39: =$C$37*$C$32 -> 2.015 | D39: g | E39: CALCULADA. MCE_R ajustado por sitio, 1 s. | F39: ASCE 7-16 · ec. 11.4-2
B40: S_DS = ⅔ · S_MS | C40: =2/3*$C$38 -> 1.7090667 | D40: g | E40: CALCULADA. Meseta del espectro de diseño (elástico). | F40: ASCE 7-16 · ec. 11.4-3
B41: S_D1 = ⅔ · S_M1 | C41: =2/3*$C$39 -> 1.3433333 | D41: g | E41: CALCULADA. Ordenada de diseño en T = 1 s. | F41: ASCE 7-16 · ec. 11.4-4
B42: T_0 = 0.2 · S_D1 / S_DS | C42: =0.2*$C$41/$C$40 -> 0.15720081 | D42: s | E42: CALCULADA. Donde empieza la meseta. | F42: ASCE 7-16 · §11.4.6
B43: T_S = S_D1 / S_DS | C43: =$C$41/$C$40 -> 0.78600406 | D43: s | E43: CALCULADA. Donde termina la meseta. | F43: ASCE 7-16 · §11.4.6
...

Sheet COEFICIENTE
B1: COEFICIENTE SÍSMICO Y CORTANTE BASAL POR DIRECCIÓN — RESULTADO
B2: V = C_s·W en cada dirección de la nave: X (transversal) y Z (longitudinal). Aquí salen el cortante estático, el mínimo para escalar el modal y la revisión que pide OPAMSS: que la demanda de ASCE no quede abajo de la NTDS.
B3: =IF(LEFT(DATOS!$C$62,5)="FALTA","¡ATENCIÓN! Faltan datos en DATOS ("&DATOS!$C$62&").",IF(AND(DATOS!$C$9="SÍ",DATOS!$C$35="F"),"¡ATENCIÓN! Clase F: manda el estudio de respuesta sísmica local; el espectro ASCE usa F_a y F_v de la clase E sólo como referencia.",IF(DATOS!$C$14="OBLIGATORIO","¡ATENCIÓN! La guía de OPAMSS exige estudio de respuesta sísmica local para este caso.",IF(OR(LEFT($C$15,2)="NO",LEFT($D$15,2)="NO"),"¡ATENCIÓN! h_n pasa la altura límite de la Tabla 7 para el sistema elegido.",IF(OR(LEFT($C$26,2)="NO",LEFT($D$26,2)="NO"),"¡ATENCIÓN! El método estático no procede: usa el espectro (hoja STAAD).",IF(AND(DATOS!$C$9="SÍ",OR(LEFT($C$40,2)="NO",LEFT($D$40,2)="NO")),"¡ATENCIÓN! El sistema ASCE no está permitido en SDC D a esa altura.",IF(AND(DATOS!$C$9="SÍ",OR(LEFT($C$63,9)="NO CUMPLE",LEFT($D$63,9)="NO CUMPLE")),"¡ATENCIÓN! ASCE queda abajo de la NTDS: calibra con el factor de la sección C.","Sin alertas: datos completos y sistemas dentro de sus límites."))))))) -> Sin alertas: datos completos y sistemas dentro de sus límites.
B4: CÓMO SE LEE: columna C = dirección X, columna D = dirección Z. La sección A es la norma nacional, la B es ASCE con el Anexo 37 (fuera del AMSS sólo es referencia, en gris) y la C es la comprobación de OPAMSS. V sale en toneladas con los W de DATOS. Aquí no se captura nada.
B6: A. NTDS-1994 — MÉTODO ESTÁTICO (§4.2)
B7: V = C_s·W. Si capturaste el periodo del modelo se usa con el tope del 80%; si no, el del Método A. Fuerzas a nivel de esfuerzos permisibles.
B8: Concepto | C8: Dir. X (transversal) | D8: Dir. Z (longitudinal) | E8: Unidad | F8: Cómo se calcula / de dónde sale | G8: Referencia
B9: Tipo de estructura | C9: =DATOS!$C$53 -> MARCO RÍGIDO ORDINARIO | D9: =DATOS!$C$54 -> MARCO RÍGIDO ORDINARIO | E9: — | F9: De DATOS §4. | G9: DATOS §4
B10: Sistema de la Tabla 7 — código | C10: =INDEX(TABLAS!$D$50:$D$60,MATCH(DATOS!$C$53,TABLAS!$C$50:$C$60,0)) -> A3 | D10: =INDEX(TABLAS!$D$50:$D$60,MATCH(DATOS!$C$54,TABLAS!$C$50:$C$60,0)) -> A3 | E10: — | F10: Del catálogo de naves (TABLAS). | G10: NTDS-1994 · Tabla 7, pág. 23 · catálogo en TABLAS
B11: Sistema de la Tabla 7 — descripción | C11: =INDEX(TABLAS!$C$28:$C$45,MATCH($C$10,TABLAS!$B$28:$B$45,0)) -> Sistema A — marcos de acero con detallado ordinario | D11: =INDEX(TABLAS!$C$28:$C$45,MATCH($D$10,TABLAS!$B$28:$B$45,0)) -> Sistema A — marcos de acero con detallado ordinario | E11: — | F11: Sistemas A a E definidos en §3.6. | G11: NTDS-1994 · §3.6, págs. 4 y 5
B12: R — factor de modificación de respuesta | C12: =INDEX(TABLAS!$E$28:$E$45,MATCH($C$10,TABLAS!$B$28:$B$45,0)) -> 7 | D12: =INDEX(TABLAS!$E$28:$E$45,MATCH($D$10,TABLAS!$B$28:$B$45,0)) -> 7 | E12: — | F12: Divide el espectro. Está a nivel de esfuerzos permisibles. | G12: NTDS-1994 · Tabla 7, pág. 23
B13: C_d — amplificación de desplazamientos | C13: =INDEX(TABLAS!$D$28:$D$45,MATCH($C$10,TABLAS!$B$28:$B$45,0)) -> 6 | D13: =INDEX(TABLAS!$D$28:$D$45,MATCH($D$10,TABLAS!$B$28:$B$45,0)) -> 6 | E13: — | F13: Desplazamiento de diseño = C_d × el elástico del análisis; la deriva se compara con la Tabla 8 (TABLAS). | G13: NTDS-1994 · ec. 4.11, pág. 9 · Tabla 8, pág. 24
B14: H — altura límite del sistema | C14: =INDEX(TABLAS!$F$28:$F$45,MATCH($C$10,TABLAS!$B$28:$B$45,0)) -> 30 | D14: =INDEX(TABLAS!$F$28:$F$45,MATCH($D$10,TABLAS!$B$28:$B$45,0)) -> 30 | E14: m | F14: S.L. = sin límite. | G14: NTDS-1994 · Tabla 7, pág. 23
B15: ¿h_n dentro del límite? | C15: =IF(ISNUMBER($C$14),IF(DATOS!$C$55<=$C$14,"SÍ","NO — excede "&TEXT($C$14,"0")&" m"),"SÍ — sin límite") -> SÍ | D15: =IF(ISNUMBER($D$14),IF(DATOS!$C$55<=$D$14,"SÍ","NO — excede "&TEXT($D$14,"0")&" m"),"SÍ — sin límite") -> SÍ | E15: — | F15: Revisa la h_n de DATOS contra H. | G15: NTDS-1994 · Tabla 7, pág. 23
B16: Tipo para el periodo aproximado | C16: =INDEX(TABLAS!$F$50:$F$60,MATCH(DATOS!$C$53,TABLAS!$C$50:$C$60,0)) -> MARCOS ACERO | D16: =INDEX(TABLAS!$F$50:$F$60,MATCH(DATOS!$C$54,TABLAS!$C$50:$C$60,0)) -> MARCOS ACERO | E16: — | F16: Del catálogo. Define C_t. | G16: NTDS ec. 4.3, pág. 7 · ASCE Tabla 12.8-2
B17: C_t — NTDS | C17: =INDEX(TABLAS!$D$65:$D$69,MATCH($C$16,TABLAS!$B$65:$B$69,0)) -> 0.085 | D17: =INDEX(TABLAS!$D$65:$D$69,MATCH($D$16,TABLAS!$B$65:$B$69,0)) -> 0.085 | E17: — | F17: 0.085 marcos de acero, 0.073 marcos de concreto, 0.049 lo demás. | G17: NTDS-1994 · §4.2.2 (1), pág. 7
B18: T — Método A = C_t · h_n^(3/4) | C18: =$C$17*DATOS!$C$55^(3/4) -> 0.47852776 | D18: =$D$17*DATOS!$C$55^(3/4) -> 0.47852776 | E18: s | F18: Periodo empírico: límite inferior del real. | G18: NTDS-1994 · ec. 4.3, pág. 7
B19: T que se usa | C19: =IF(DATOS!$C$58>0,DATOS!$C$58,$C$18) -> 0.375 | D19: =IF(DATOS!$C$59>0,DATOS!$C$59,$D$18) -> 0.12 | E19: s | F19: CALCULADA. Periodo del modelo si lo capturaste; si no, el del Método A. | G19: NTDS-1994 · §4.2.2, pág. 7
B20: T para la ec. 4.2 (entre T_o y 6T_o) | C20: =MIN(MAX($C$19,DATOS!$C$23),6*DATOS!$C$23) -> 0.6 | D20: =MIN(MAX($D$19,DATOS!$C$23),6*DATOS!$C$23) -> 0.6 | E20: s | F20: CALCULADA. La norma no deja usar un T menor que T_o ni mayor que 6T_o en esta ecuación. | G20: NTDS-1994 · §4.2.1, pág. 7
B21: C_s con ese T = A·I·C_o / R · (T_o/T)^(2/3) | C21: =DATOS!$C$20*DATOS!$C$25*DATOS!$C$22/$C$12*(DATOS!$C$23/$C$20)^(2/3) -> 0.20571429 | D21: =DATOS!$C$20*DATOS!$C$25*DATOS!$C$22/$D$12*(DATOS!$C$23/$D$20)^(2/3) -> 0.20571429 | E21: — | F21: CALCULADA. | G21: NTDS-1994 · ec. 4.2, pág. 7
B22: C_s con el T del Método A | C22: =DATOS!$C$20*DATOS!$C$25*DATOS!$C$22/$C$12*(DATOS!$C$23/MIN(MAX($C$18,DATOS!$C$23),6*DATOS!$C$23))^(2/3) -> 0.20571429 | D22: =DATOS!$C$20*DATOS!$C$25*DATOS!$C$22/$D$12*(DATOS!$C$23/MIN(MAX($D$18,DATOS!$C$23),6*DATOS!$C$23))^(2/3) -> 0.20571429 | E22: — | F22: CALCULADA. Referencia para el tope del 80% y para escalar el dinámico. | G22: NTDS-1994 · §4.2.2 (2), págs. 7 y 8
B23: C_s de diseño | C23: =IF(DATOS!$C$58>0,MAX($C$21,0.8*$C$22),$C$22) -> 0.20571429 | D23: =IF(DATOS!$C$59>0,MAX($D$21,0.8*$D$22),$D$22) -> 0.20571429 | E23: — | F23: CALCULADA. Con periodo del modelo, nunca menos del 80% del de Método A. | G23: NTDS-1994 · §4.2.2 (2), pág. 8
B24: V = C_s · W | C24: =$C$23*DATOS!$C$60 -> 3.5335543 | D24: =$D$23*DATOS!$C$60 -> 3.5335543 | E24: t | F24: CALCULADA con el W de la NTDS. Es fuerza a nivel de esfuerzos permisibles. | G24: NTDS-1994 · ec. 4.1, pág. 7
B25: F_t / V — fuerza extra en el último nivel | C25: =IF($C$19<=0.7,0,MIN(0.07*$C$19,0.25)) -> 0 | D25: =IF($D$19<=0.7,0,MIN(0.07*$D$19,0.25)) -> 0 | E25: — | F25: CALCULADA. F_t = 0.07·T·V ≤ 0.25V y vale cero si T ≤ 0.7 s. El resto (V − F_t) se reparte proporcional a w_x·h_x. | G25: NTDS-1994 · ecs. 4.6 a 4.8, pág. 8
B26: ¿Procede el método estático? | C26: =IF(DATOS!$C$57="SÍ",IF(AND(DATOS!$C$55<70,NOT(AND(DATOS!$C$21="S4",$C$19>0.7))),"SÍ — regular < 70 m","NO — usar dinámico"),IF(AND(DATOS!$C$56<=5,DATOS!$C$55<=20),"SÍ — irregular chico","NO — usar dinámico")) -> SÍ — regular < 70 m | D26: =IF(DATOS!$C$57="SÍ",IF(AND(DATOS!$C$55<70,NOT(AND(DATOS!$C$21="S4",$D$19>0.7))),"SÍ — regular < 70 m","NO — usar dinámico"),IF(AND(DATOS!$C$56<=5,DATOS!$C$55<=20),"SÍ — irregular chico","NO — usar dinámico")) -> SÍ — regular < 70 m | E26: — | F26: Regular: sí hasta 70 m, salvo suelo S4 con T > 0.7 s. Irregular: sólo hasta 5 pisos y 20 m (y cumpliendo §3.8.1). Si no, análisis dinámico del Capítulo 5. | G26: NTDS-1994 · §3.9, pág. 6
B27: Cortante mínimo para escalar el dinámico (÷ W) | C27: =IF(DATOS!$C$57="SÍ",MAX(0.9*$C$23,0.8*$C$22),$C$23) -> 0.18514286 | D27: =IF(DATOS!$C$57="SÍ",MAX(0.9*$D$23,0.8*$D$22),$D$23) -> 0.18514286 | E27: — | F27: CALCULADA. Regular: el mayor de 90% del estático y 80% del de Método A. Irregular: 100% del estático. Nunca hace falta usar más que el estático. | G27: NTDS-1994 · §5.4.1 (3), pág. 12
B28: C_s llevado a nivel último (× factor de DATOS) | C28: =$C$23*DATOS!$C$12 -> 0.29417143 | D28: =$D$23*DATOS!$C$12 -> 0.29417143 | E28: — | F28: CALCULADA. Es el que se compara contra ASCE cuando el criterio es FACTORIZADA. | G28: RESESCO 1996 · Art. 21, págs. 7 y 8
B30: B. ASCE 7-16 CON EL ANEXO 37 — FUERZA LATERAL EQUIVALENTE (§12.8)
B31: V = C_s·W. El análisis modal espectral se escala al 100% de este V. Fuera del AMSS es sólo de referencia.
B32: Concepto | C32: Dir. X (transversal) | D32: Dir. Z (longitudinal) | E32: Unidad | F32: Cómo se calcula / de dónde sale | G32: Referencia
B33: Sistema de la Tabla 12.2-1 — código | C33: =INDEX(TABLAS!$E$50:$E$60,MATCH(DATOS!$C$53,TABLAS!$C$50:$C$60,0)) -> C4 | D33: =INDEX(TABLAS!$E$50:$E$60,MATCH(DATOS!$C$54,TABLAS!$C$50:$C$60,0)) -> C4 | E33: — | F33: Del catálogo de naves (TABLAS). | G33: ASCE 7-16 · Tabla 12.2-1 · catálogo en TABLAS
B34: Sistema de la Tabla 12.2-1 — descripción | C34: =INDEX(TABLAS!$C$124:$C$144,MATCH($C$33,TABLAS!$B$124:$B$144,0)) -> Marcos ordinarios de acero a momento (OMF) | D34: =INDEX(TABLAS!$C$124:$C$144,MATCH($D$33,TABLAS!$B$124:$B$144,0)) -> Marcos ordinarios de acero a momento (OMF) | E34: — | F34: Extracto en TABLAS. | G34: ASCE 7-16 · Tabla 12.2-1
B35: R — coeficiente de modificación de respuesta | C35: =INDEX(TABLAS!$D$124:$D$144,MATCH($C$33,TABLAS!$B$124:$B$144,0)) -> 3.5 | D35: =INDEX(TABLAS!$D$124:$D$144,MATCH($D$33,TABLAS!$B$124:$B$144,0)) -> 3.5 | E35: — | F35: Está a nivel de resistencia. | G35: ASCE 7-16 · Tabla 12.2-1
B36: Ω_0 — factor de sobrerresistencia | C36: =INDEX(TABLAS!$E$124:$E$144,MATCH($C$33,TABLAS!$B$124:$B$144,0)) -> 3 | D36: =INDEX(TABLAS!$E$124:$E$144,MATCH($D$33,TABLAS!$B$124:$B$144,0)) -> 3 | E36: — | F36: CALCULADA. Para los elementos y conexiones que se diseñan con el sismo amplificado. | G36: ASCE 7-16 · Tabla 12.2-1 · §12.4.3
B37: C_d — amplificación de desplazamientos | C37: =INDEX(TABLAS!$F$124:$F$144,MATCH($C$33,TABLAS!$B$124:$B$144,0)) -> 3 | D37: =INDEX(TABLAS!$F$124:$F$144,MATCH($D$33,TABLAS!$B$124:$B$144,0)) -> 3 | E37: — | F37: CALCULADA. Desplazamiento de diseño = C_d · δ_e / I_e. | G37: ASCE 7-16 · Tabla 12.2-1 · ec. 12.8-15
B38: Límite de altura del sistema en SDC D | C38: =INDEX(TABLAS!$G$124:$G$144,MATCH($C$33,TABLAS!$B$124:$B$144,0)) -> NP | D38: =INDEX(TABLAS!$G$124:$G$144,MATCH($D$33,TABLAS!$B$124:$B$144,0)) -> NP | E38: m | F38: NL = sin límite; NP = no permitido. | G38: ASCE 7-16 · Tabla 12.2-1, columna de SDC D
B39: Excepción de un nivel: h_n máxima | C39: =INDEX(TABLAS!$I$124:$I$144,MATCH($C$33,TABLAS!$B$124:$B$144,0)) -> 20 | D39: =INDEX(TABLAS!$I$124:$I$144,MATCH($D$33,TABLAS!$B$124:$B$144,0)) -> 20 | E39: m | F39: Marcos ordinarios o intermedios de acero y contraventeo concéntrico ordinario en naves de un nivel con muerta de techo ≤ 0.96 kPa. | G39: ASCE 7-16 · §12.2.5.6.1, §12.2.5.7.1 y nota j
B40: ¿Sistema permitido a esa altura (SDC D)? | C40: =IF($C$38="NL","SÍ — sin límite",IF(AND(ISNUMBER($C$38),DATOS!$C$55<=$C$38),"SÍ",IF(AND(ISNUMBER($C$39),DATOS!$C$56=1,DATOS!$C$55<=$C$39,DATOS!$C$48="SÍ"),"SÍ — excepción de un nivel",IF($C$38="NP","NO — NP en SDC D","NO — excede "&TEXT($C$38,"0.0")&" m")))) -> SÍ — excepción de un nivel | D40: =IF($D$38="NL","SÍ — sin límite",IF(AND(ISNUMBER($D$38),DATOS!$C$55<=$D$38),"SÍ",IF(AND(ISNUMBER($D$39),DATOS!$C$56=1,DATOS!$C$55<=$D$39,DATOS!$C$48="SÍ"),"SÍ — excepción de un nivel",IF($D$38="NP","NO — NP en SDC D","NO — excede "&TEXT($D$38,"0.0")&" m")))) -> SÍ — excepción de un nivel | E40: — | F40: Con la h_n, el número de niveles y la muerta de techo de DATOS. Con marcos ordinarios revisa además que los muros de más de 10.7 m de altura no pasen de 0.96 kPa. | G40: ASCE 7-16 · Tabla 12.2-1 y §12.2.5
B41: C_t — ASCE (valor métrico) | C41: =INDEX(TABLAS!$E$65:$E$69,MATCH($C$16,TABLAS!$B$65:$B$69,0)) -> 0.0724 | D41: =INDEX(TABLAS!$E$65:$E$69,MATCH($D$16,TABLAS!$B$65:$B$69,0)) -> 0.0724 | E41: — | F41: Tabla 12.8-2 con h_n en metros. | G41: ASCE 7-16 · Tabla 12.8-2
B42: x — exponente de ASCE | C42: =INDEX(TABLAS!$F$65:$F$69,MATCH($C$16,TABLAS!$B$65:$B$69,0)) -> 0.8 | D42: =INDEX(TABLAS!$F$65:$F$69,MATCH($D$16,TABLAS!$B$65:$B$69,0)) -> 0.8 | E42: — | F42: Tabla 12.8-2. | G42: ASCE 7-16 · Tabla 12.8-2
...

Sheet ESPECTROS
B1: ESPECTROS DE DISEÑO POR DIRECCIÓN — RESULTADO FINAL
B2: NTDS §5.2: C_sm = I·A/R·[1 + 3(C_o−1)T/T_o] si T < T_o/3; I·A·C_o/R hasta T_o; I·A·C_o/R·(T_o/T)^(2/3) hasta 4 s; 2.5·I·A·C_o·T_o^(2/3)/(R·T^(4/3)) después. ASCE §11.4.6: S_DS(0.4 + 0.6T/T_0); S_DS; S_D1/T; S_D1·T_L/T².
B3: =COEFICIENTE!$B$3 -> Sin alertas: datos completos y sistemas dentro de sus límites.
B4: CÓMO SE LEE: todas las ordenadas en g. NTDS: C_sm ya trae I y el R de cada dirección. ASCE: S_a es el de diseño elástico (⅔ del MCE_R) y el reducido es S_a·I_e/R de cada dirección. «NTDS a comparar» = C_sm × factor de DATOS. Si la relación sale menor que 1 dentro del AMSS, OPAMSS pide calibrar. La columna O es la que se pega en STAAD.
B5: ="EN CORTO · NTDS (ya ÷ R): meseta X "&TEXT(DATOS!$C$26/COEFICIENTE!$C$12,"0.0000")&" g y Z "&TEXT(DATOS!$C$26/COEFICIENTE!$D$12,"0.0000")&" g entre "&TEXT(DATOS!$C$23/3,"0.000")&" y "&TEXT(DATOS!$C$23,"0.00")&" s · ASCE reducido: X "&TEXT(DATOS!$C$40*DATOS!$C$46/COEFICIENTE!$C$35,"0.0000")&" g y Z "&TEXT(DATOS!$C$40*DATOS!$C$46/COEFICIENTE!$D$35,"0.0000")&" g · Relación mínima ASCE / NTDS: X "&TEXT(MIN($L$73:$L$179),"0.00")&" y Z "&TEXT(MIN($M$73:$M$179),"0.00")&IF(DATOS!$C$9="NO"," (fuera del AMSS sólo es referencia)","") -> EN CORTO · NTDS (ya ÷ R): meseta X 0.2057 g y Z 0.2057 g entre 0.200 y 0.60 s · ASCE reducido: X 0.4883 g y Z 0.4883 g · Relación mínima ASCE / NTDS: X 1.16 y Z 1.16 (fuera del AMSS sólo es referencia)
B7: A. GRÁFICAS (de 0 a 6 s; la tabla sigue hasta 10 s)
B8: 1) Reducidos X y Z: lo que entra al análisis modal. 2) Elásticos: el peligro de cada norma sin reducir. 3) Relación ASCE / NTDS por dirección: si baja de 1.0 esa zona no cumple la revisión de OPAMSS (sólo AMSS).
B70: B. TABLA DE ORDENADAS (todas en g)
B71: Los quiebres de cada espectro (T_o/3, T_o, T_0, T_S y T_L) se meten exactos en la malla de periodos: por eso algunos T no son redondos. Las columnas grises de la derecha son la malla base; no se tocan.
B72: T (s) | C72: NTDS elástico (R = 1) | D72: NTDS diseño X C_sm (÷ R_X) | E72: NTDS diseño Z C_sm (÷ R_Z) | F72: ASCE MCE_R 1.5·S_a | G72: ASCE diseño S_a elástico | H72: ASCE reducido X S_a·I_e/R_X | I72: ASCE reducido Z S_a·I_e/R_Z | J72: NTDS a comparar X | K72: NTDS a comparar Z | L72: Relación X ASCE / NTDS | M72: Relación Z ASCE / NTDS | N72: ¿Cumple OPAMSS? | O72: Para STAAD (elástico elegido) | Q72: auxiliar: malla (s) | R72: auxiliar: ½ paso (s) | T72: auxiliar: línea 1.0
B73: =$Q73 -> 0 | C73: =IF($B73<DATOS!$C$23/3,DATOS!$C$25*DATOS!$C$20*(1+3*(DATOS!$C$22-1)*$B73/DATOS!$C$23),IF($B73<=DATOS!$C$23,DATOS!$C$25*DATOS!$C$20*DATOS!$C$22,IF($B73<=4,DATOS!$C$25*DATOS!$C$20*DATOS!$C$22*(DATOS!$C$23/$B73)^(2/3),2.5*DATOS!$C$25*DATOS!$C$20*DATOS!$C$22*DATOS!$C$23^(2/3)/$B73^(4/3)))) -> 0.48 | D73: =$C73/COEFICIENTE!$C$12 -> 0.068571429 | E73: =$C73/COEFICIENTE!$D$12 -> 0.068571429 | F73: =1.5*$G73 -> 1.02544 | G73: =IF($B73<DATOS!$C$42,DATOS!$C$40*(0.4+0.6*$B73/DATOS!$C$42),IF($B73<=DATOS!$C$43,DATOS!$C$40,IF($B73<=DATOS!$C$44,DATOS!$C$41/$B73,DATOS!$C$41*DATOS!$C$44/$B73^2))) -> 0.68362667 | H73: =$G73*DATOS!$C$46/COEFICIENTE!$C$35 -> 0.1953219 | I73: =$G73*DATOS!$C$46/COEFICIENTE!$D$35 -> 0.1953219 | J73: =$D73*DATOS!$C$12 -> 0.098057143 | K73: =$E73*DATOS!$C$12 -> 0.098057143 | L73: =IF($J73>0,$H73/$J73,0) -> 1.9919192 | M73: =IF($K73>0,$I73/$K73,0) -> 1.9919192 | N73: =IF(DATOS!$C$9="NO","—",IF(AND($L73>=1,$M73>=1),"OK","CALIBRAR")) -> — | O73: =IF(STAAD!$C$17="ASCE 7-16",$G73,$C73) -> 0.48 | Q73: 0 | R73: 0 | T73: 0 | U73: 1
B74: =IF(ABS($Q74-DATOS!$C$23/3)<$R74,DATOS!$C$23/3,IF(ABS($Q74-DATOS!$C$23)<$R74,DATOS!$C$23,IF(ABS($Q74-DATOS!$C$42)<$R74,DATOS!$C$42,IF(ABS($Q74-DATOS!$C$43)<$R74,DATOS!$C$43,IF(ABS($Q74-DATOS!$C$44)<$R74,DATOS!$C$44,$Q74))))) -> 0.02 | C74: =IF($B74<DATOS!$C$23/3,DATOS!$C$25*DATOS!$C$20*(1+3*(DATOS!$C$22-1)*$B74/DATOS!$C$23),IF($B74<=DATOS!$C$23,DATOS!$C$25*DATOS!$C$20*DATOS!$C$22,IF($B74<=4,DATOS!$C$25*DATOS!$C$20*DATOS!$C$22*(DATOS!$C$23/$B74)^(2/3),2.5*DATOS!$C$25*DATOS!$C$20*DATOS!$C$22*DATOS!$C$23^(2/3)/$B74^(4/3)))) -> 0.576 | D74: =$C74/COEFICIENTE!$C$12 -> 0.082285714 | E74: =$C74/COEFICIENTE!$D$12 -> 0.082285714 | F74: =1.5*$G74 -> 1.2211336 | G74: =IF($B74<DATOS!$C$42,DATOS!$C$40*(0.4+0.6*$B74/DATOS!$C$42),IF($B74<=DATOS!$C$43,DATOS!$C$40,IF($B74<=DATOS!$C$44,DATOS!$C$41/$B74,DATOS!$C$41*DATOS!$C$44/$B74^2))) -> 0.8140891 | H74: =$G74*DATOS!$C$46/COEFICIENTE!$C$35 -> 0.23259689 | I74: =$G74*DATOS!$C$46/COEFICIENTE!$D$35 -> 0.23259689 | J74: =$D74*DATOS!$C$12 -> 0.11766857 | K74: =$E74*DATOS!$C$12 -> 0.11766857 | L74: =IF($J74>0,$H74/$J74,0) -> 1.9767121 | M74: =IF($K74>0,$I74/$K74,0) -> 1.9767121 | N74: =IF(DATOS!$C$9="NO","—",IF(AND($L74>=1,$M74>=1),"OK","CALIBRAR")) -> — | O74: =IF(STAAD!$C$17="ASCE 7-16",$G74,$C74) -> 0.576 | Q74: 0.02 | R74: 0.01 | T74: 6 | U74: 1
B75: =IF(ABS($Q75-DATOS!$C$23/3)<$R75,DATOS!$C$23/3,IF(ABS($Q75-DATOS!$C$23)<$R75,DATOS!$C$23,IF(ABS($Q75-DATOS!$C$42)<$R75,DATOS!$C$42,IF(ABS($Q75-DATOS!$C$43)<$R75,DATOS!$C$43,IF(ABS($Q75-DATOS!$C$44)<$R75,DATOS!$C$44,$Q75))))) -> 0.04 | C75: =IF($B75<DATOS!$C$23/3,DATOS!$C$25*DATOS!$C$20*(1+3*(DATOS!$C$22-1)*$B75/DATOS!$C$23),IF($B75<=DATOS!$C$23,DATOS!$C$25*DATOS!$C$20*DATOS!$C$22,IF($B75<=4,DATOS!$C$25*DATOS!$C$20*DATOS!$C$22*(DATOS!$C$23/$B75)^(2/3),2.5*DATOS!$C$25*DATOS!$C$20*DATOS!$C$22*DATOS!$C$23^(2/3)/$B75^(4/3)))) -> 0.672 | D75: =$C75/COEFICIENTE!$C$12 -> 0.096 | E75: =$C75/COEFICIENTE!$D$12 -> 0.096 | F75: =1.5*$G75 -> 1.4168273 | G75: =IF($B75<DATOS!$C$42,DATOS!$C$40*(0.4+0.6*$B75/DATOS!$C$42),IF($B75<=DATOS!$C$43,DATOS!$C$40,IF($B75<=DATOS!$C$44,DATOS!$C$41/$B75,DATOS!$C$41*DATOS!$C$44/$B75^2))) -> 0.94455153 | H75: =$G75*DATOS!$C$46/COEFICIENTE!$C$35 -> 0.26987187 | I75: =$G75*DATOS!$C$46/COEFICIENTE!$D$35 -> 0.26987187 | J75: =$D75*DATOS!$C$12 -> 0.13728 | K75: =$E75*DATOS!$C$12 -> 0.13728 | L75: =IF($J75>0,$H75/$J75,0) -> 1.9658498 | M75: =IF($K75>0,$I75/$K75,0) -> 1.9658498 | N75: =IF(DATOS!$C$9="NO","—",IF(AND($L75>=1,$M75>=1),"OK","CALIBRAR")) -> — | O75: =IF(STAAD!$C$17="ASCE 7-16",$G75,$C75) -> 0.672 | Q75: 0.04 | R75: 0.01
B76: =IF(ABS($Q76-DATOS!$C$23/3)<$R76,DATOS!$C$23/3,IF(ABS($Q76-DATOS!$C$23)<$R76,DATOS!$C$23,IF(ABS($Q76-DATOS!$C$42)<$R76,DATOS!$C$42,IF(ABS($Q76-DATOS!$C$43)<$R76,DATOS!$C$43,IF(ABS($Q76-DATOS!$C$44)<$R76,DATOS!$C$44,$Q76))))) -> 0.06 | C76: =IF($B76<DATOS!$C$23/3,DATOS!$C$25*DATOS!$C$20*(1+3*(DATOS!$C$22-1)*$B76/DATOS!$C$23),IF($B76<=DATOS!$C$23,DATOS!$C$25*DATOS!$C$20*DATOS!$C$22,IF($B76<=4,DATOS!$C$25*DATOS!$C$20*DATOS!$C$22*(DATOS!$C$23/$B76)^(2/3),2.5*DATOS!$C$25*DATOS!$C$20*DATOS!$C$22*DATOS!$C$23^(2/3)/$B76^(4/3)))) -> 0.768 | D76: =$C76/COEFICIENTE!$C$12 -> 0.10971429 | E76: =$C76/COEFICIENTE!$D$12 -> 0.10971429 | F76: =1.5*$G76 -> 1.6125209 | G76: =IF($B76<DATOS!$C$42,DATOS!$C$40*(0.4+0.6*$B76/DATOS!$C$42),IF($B76<=DATOS!$C$43,DATOS!$C$40,IF($B76<=DATOS!$C$44,DATOS!$C$41/$B76,DATOS!$C$41*DATOS!$C$44/$B76^2))) -> 1.075014 | H76: =$G76*DATOS!$C$46/COEFICIENTE!$C$35 -> 0.30714685 | I76: =$G76*DATOS!$C$46/COEFICIENTE!$D$35 -> 0.30714685 | J76: =$D76*DATOS!$C$12 -> 0.15689143 | K76: =$E76*DATOS!$C$12 -> 0.15689143 | L76: =IF($J76>0,$H76/$J76,0) -> 1.9577032 | M76: =IF($K76>0,$I76/$K76,0) -> 1.9577032 | N76: =IF(DATOS!$C$9="NO","—",IF(AND($L76>=1,$M76>=1),"OK","CALIBRAR")) -> — | O76: =IF(STAAD!$C$17="ASCE 7-16",$G76,$C76) -> 0.768 | Q76: 0.06 | R76: 0.01
B77: =IF(ABS($Q77-DATOS!$C$23/3)<$R77,DATOS!$C$23/3,IF(ABS($Q77-DATOS!$C$23)<$R77,DATOS!$C$23,IF(ABS($Q77-DATOS!$C$42)<$R77,DATOS!$C$42,IF(ABS($Q77-DATOS!$C$43)<$R77,DATOS!$C$43,IF(ABS($Q77-DATOS!$C$44)<$R77,DATOS!$C$44,$Q77))))) -> 0.08 | C77: =IF($B77<DATOS!$C$23/3,DATOS!$C$25*DATOS!$C$20*(1+3*(DATOS!$C$22-1)*$B77/DATOS!$C$23),IF($B77<=DATOS!$C$23,DATOS!$C$25*DATOS!$C$20*DATOS!$C$22,IF($B77<=4,DATOS!$C$25*DATOS!$C$20*DATOS!$C$22*(DATOS!$C$23/$B77)^(2/3),2.5*DATOS!$C$25*DATOS!$C$20*DATOS!$C$22*DATOS!$C$23^(2/3)/$B77^(4/3)))) -> 0.864 | D77: =$C77/COEFICIENTE!$C$12 -> 0.12342857 | E77: =$C77/COEFICIENTE!$D$12 -> 0.12342857 | F77: =1.5*$G77 -> 1.8082146 | G77: =IF($B77<DATOS!$C$42,DATOS!$C$40*(0.4+0.6*$B77/DATOS!$C$42),IF($B77<=DATOS!$C$43,DATOS!$C$40,IF($B77<=DATOS!$C$44,DATOS!$C$41/$B77,DATOS!$C$41*DATOS!$C$44/$B77^2))) -> 1.2054764 | H77: =$G77*DATOS!$C$46/COEFICIENTE!$C$35 -> 0.34442183 | I77: =$G77*DATOS!$C$46/COEFICIENTE!$D$35 -> 0.34442183 | J77: =$D77*DATOS!$C$12 -> 0.17650286 | K77: =$E77*DATOS!$C$12 -> 0.17650286 | L77: =IF($J77>0,$H77/$J77,0) -> 1.9513669 | M77: =IF($K77>0,$I77/$K77,0) -> 1.9513669 | N77: =IF(DATOS!$C$9="NO","—",IF(AND($L77>=1,$M77>=1),"OK","CALIBRAR")) -> — | O77: =IF(STAAD!$C$17="ASCE 7-16",$G77,$C77) -> 0.864 | Q77: 0.08 | R77: 0.01
B78: =IF(ABS($Q78-DATOS!$C$23/3)<$R78,DATOS!$C$23/3,IF(ABS($Q78-DATOS!$C$23)<$R78,DATOS!$C$23,IF(ABS($Q78-DATOS!$C$42)<$R78,DATOS!$C$42,IF(ABS($Q78-DATOS!$C$43)<$R78,DATOS!$C$43,IF(ABS($Q78-DATOS!$C$44)<$R78,DATOS!$C$44,$Q78))))) -> 0.1 | C78: =IF($B78<DATOS!$C$23/3,DATOS!$C$25*DATOS!$C$20*(1+3*(DATOS!$C$22-1)*$B78/DATOS!$C$23),IF($B78<=DATOS!$C$23,DATOS!$C$25*DATOS!$C$20*DATOS!$C$22,IF($B78<=4,DATOS!$C$25*DATOS!$C$20*DATOS!$C$22*(DATOS!$C$23/$B78)^(2/3),2.5*DATOS!$C$25*DATOS!$C$20*DATOS!$C$22*DATOS!$C$23^(2/3)/$B78^(4/3)))) -> 0.96 | D78: =$C78/COEFICIENTE!$C$12 -> 0.13714286 | E78: =$C78/COEFICIENTE!$D$12 -> 0.13714286 | F78: =1.5*$G78 -> 2.0039082 | G78: =IF($B78<DATOS!$C$42,DATOS!$C$40*(0.4+0.6*$B78/DATOS!$C$42),IF($B78<=DATOS!$C$43,DATOS!$C$40,IF($B78<=DATOS!$C$44,DATOS!$C$41/$B78,DATOS!$C$41*DATOS!$C$44/$B78^2))) -> 1.3359388 | H78: =$G78*DATOS!$C$46/COEFICIENTE!$C$35 -> 0.38169681 | I78: =$G78*DATOS!$C$46/COEFICIENTE!$D$35 -> 0.38169681 | J78: =$D78*DATOS!$C$12 -> 0.19611429 | K78: =$E78*DATOS!$C$12 -> 0.19611429 | L78: =IF($J78>0,$H78/$J78,0) -> 1.9462978 | M78: =IF($K78>0,$I78/$K78,0) -> 1.9462978 | N78: =IF(DATOS!$C$9="NO","—",IF(AND($L78>=1,$M78>=1),"OK","CALIBRAR")) -> — | O78: =IF(STAAD!$C$17="ASCE 7-16",$G78,$C78) -> 0.96 | Q78: 0.1 | R78: 0.01
B79: =IF(ABS($Q79-DATOS!$C$23/3)<$R79,DATOS!$C$23/3,IF(ABS($Q79-DATOS!$C$23)<$R79,DATOS!$C$23,IF(ABS($Q79-DATOS!$C$42)<$R79,DATOS!$C$42,IF(ABS($Q79-DATOS!$C$43)<$R79,DATOS!$C$43,IF(ABS($Q79-DATOS!$C$44)<$R79,DATOS!$C$44,$Q79))))) -> 0.12 | C79: =IF($B79<DATOS!$C$23/3,DATOS!$C$25*DATOS!$C$20*(1+3*(DATOS!$C$22-1)*$B79/DATOS!$C$23),IF($B79<=DATOS!$C$23,DATOS!$C$25*DATOS!$C$20*DATOS!$C$22,IF($B79<=4,DATOS!$C$25*DATOS!$C$20*DATOS!$C$22*(DATOS!$C$23/$B79)^(2/3),2.5*DATOS!$C$25*DATOS!$C$20*DATOS!$C$22*DATOS!$C$23^(2/3)/$B79^(4/3)))) -> 1.056 | D79: =$C79/COEFICIENTE!$C$12 -> 0.15085714 | E79: =$C79/COEFICIENTE!$D$12 -> 0.15085714 | F79: =1.5*$G79 -> 2.1996019 | G79: =IF($B79<DATOS!$C$42,DATOS!$C$40*(0.4+0.6*$B79/DATOS!$C$42),IF($B79<=DATOS!$C$43,DATOS!$C$40,IF($B79<=DATOS!$C$44,DATOS!$C$41/$B79,DATOS!$C$41*DATOS!$C$44/$B79^2))) -> 1.4664013 | H79: =$G79*DATOS!$C$46/COEFICIENTE!$C$35 -> 0.41897179 | I79: =$G79*DATOS!$C$46/COEFICIENTE!$D$35 -> 0.41897179 | J79: =$D79*DATOS!$C$12 -> 0.21572571 | K79: =$E79*DATOS!$C$12 -> 0.21572571 | L79: =IF($J79>0,$H79/$J79,0) -> 1.9421504 | M79: =IF($K79>0,$I79/$K79,0) -> 1.9421504 | N79: =IF(DATOS!$C$9="NO","—",IF(AND($L79>=1,$M79>=1),"OK","CALIBRAR")) -> — | O79: =IF(STAAD!$C$17="ASCE 7-16",$G79,$C79) -> 1.056 | Q79: 0.12 | R79: 0.01
B80: =IF(ABS($Q80-DATOS!$C$23/3)<$R80,DATOS!$C$23/3,IF(ABS($Q80-DATOS!$C$23)<$R80,DATOS!$C$23,IF(ABS($Q80-DATOS!$C$42)<$R80,DATOS!$C$42,IF(ABS($Q80-DATOS!$C$43)<$R80,DATOS!$C$43,IF(ABS($Q80-DATOS!$C$44)<$R80,DATOS!$C$44,$Q80))))) -> 0.14 | C80: =IF($B80<DATOS!$C$23/3,DATOS!$C$25*DATOS!$C$20*(1+3*(DATOS!$C$22-1)*$B80/DATOS!$C$23),IF($B80<=DATOS!$C$23,DATOS!$C$25*DATOS!$C$20*DATOS!$C$22,IF($B80<=4,DATOS!$C$25*DATOS!$C$20*DATOS!$C$22*(DATOS!$C$23/$B80)^(2/3),2.5*DATOS!$C$25*DATOS!$C$20*DATOS!$C$22*DATOS!$C$23^(2/3)/$B80^(4/3)))) -> 1.152 | D80: =$C80/COEFICIENTE!$C$12 -> 0.16457143 | E80: =$C80/COEFICIENTE!$D$12 -> 0.16457143 | F80: =1.5*$G80 -> 2.3952955 | G80: =IF($B80<DATOS!$C$42,DATOS!$C$40*(0.4+0.6*$B80/DATOS!$C$42),IF($B80<=DATOS!$C$43,DATOS!$C$40,IF($B80<=DATOS!$C$44,DATOS!$C$41/$B80,DATOS!$C$41*DATOS!$C$44/$B80^2))) -> 1.5968637 | H80: =$G80*DATOS!$C$46/COEFICIENTE!$C$35 -> 0.45624677 | I80: =$G80*DATOS!$C$46/COEFICIENTE!$D$35 -> 0.45624677 | J80: =$D80*DATOS!$C$12 -> 0.23533714 | K80: =$E80*DATOS!$C$12 -> 0.23533714 | L80: =IF($J80>0,$H80/$J80,0) -> 1.9386943 | M80: =IF($K80>0,$I80/$K80,0) -> 1.9386943 | N80: =IF(DATOS!$C$9="NO","—",IF(AND($L80>=1,$M80>=1),"OK","CALIBRAR")) -> — | O80: =IF(STAAD!$C$17="ASCE 7-16",$G80,$C80) -> 1.152 | Q80: 0.14 | R80: 0.01
B81: =IF(ABS($Q81-DATOS!$C$23/3)<$R81,DATOS!$C$23/3,IF(ABS($Q81-DATOS!$C$23)<$R81,DATOS!$C$23,IF(ABS($Q81-DATOS!$C$42)<$R81,DATOS!$C$42,IF(ABS($Q81-DATOS!$C$43)<$R81,DATOS!$C$43,IF(ABS($Q81-DATOS!$C$44)<$R81,DATOS!$C$44,$Q81))))) -> 0.15720081 | C81: =IF($B81<DATOS!$C$23/3,DATOS!$C$25*DATOS!$C$20*(1+3*(DATOS!$C$22-1)*$B81/DATOS!$C$23),IF($B81<=DATOS!$C$23,DATOS!$C$25*DATOS!$C$20*DATOS!$C$22,IF($B81<=4,DATOS!$C$25*DATOS!$C$20*DATOS!$C$22*(DATOS!$C$23/$B81)^(2/3),2.5*DATOS!$C$25*DATOS!$C$20*DATOS!$C$22*DATOS!$C$23^(2/3)/$B81^(4/3)))) -> 1.2345639 | D81: =$C81/COEFICIENTE!$C$12 -> 0.17636627 | E81: =$C81/COEFICIENTE!$D$12 -> 0.17636627 | F81: =1.5*$G81 -> 2.5636 | G81: =IF($B81<DATOS!$C$42,DATOS!$C$40*(0.4+0.6*$B81/DATOS!$C$42),IF($B81<=DATOS!$C$43,DATOS!$C$40,IF($B81<=DATOS!$C$44,DATOS!$C$41/$B81,DATOS!$C$41*DATOS!$C$44/$B81^2))) -> 1.7090667 | H81: =$G81*DATOS!$C$46/COEFICIENTE!$C$35 -> 0.48830476 | I81: =$G81*DATOS!$C$46/COEFICIENTE!$D$35 -> 0.48830476 | J81: =$D81*DATOS!$C$12 -> 0.25220377 | K81: =$E81*DATOS!$C$12 -> 0.25220377 | L81: =IF($J81>0,$H81/$J81,0) -> 1.9361517 | M81: =IF($K81>0,$I81/$K81,0) -> 1.9361517 | N81: =IF(DATOS!$C$9="NO","—",IF(AND($L81>=1,$M81>=1),"OK","CALIBRAR")) -> — | O81: =IF(STAAD!$C$17="ASCE 7-16",$G81,$C81) -> 1.2345639 | Q81: 0.16 | R81: 0.01
B82: =IF(ABS($Q82-DATOS!$C$23/3)<$R82,DATOS!$C$23/3,IF(ABS($Q82-DATOS!$C$23)<$R82,DATOS!$C$23,IF(ABS($Q82-DATOS!$C$42)<$R82,DATOS!$C$42,IF(ABS($Q82-DATOS!$C$43)<$R82,DATOS!$C$43,IF(ABS($Q82-DATOS!$C$44)<$R82,DATOS!$C$44,$Q82))))) -> 0.18 | C82: =IF($B82<DATOS!$C$23/3,DATOS!$C$25*DATOS!$C$20*(1+3*(DATOS!$C$22-1)*$B82/DATOS!$C$23),IF($B82<=DATOS!$C$23,DATOS!$C$25*DATOS!$C$20*DATOS!$C$22,IF($B82<=4,DATOS!$C$25*DATOS!$C$20*DATOS!$C$22*(DATOS!$C$23/$B82)^(2/3),2.5*DATOS!$C$25*DATOS!$C$20*DATOS!$C$22*DATOS!$C$23^(2/3)/$B82^(4/3)))) -> 1.344 | D82: =$C82/COEFICIENTE!$C$12 -> 0.192 | E82: =$C82/COEFICIENTE!$D$12 -> 0.192 | F82: =1.5*$G82 -> 2.5636 | G82: =IF($B82<DATOS!$C$42,DATOS!$C$40*(0.4+0.6*$B82/DATOS!$C$42),IF($B82<=DATOS!$C$43,DATOS!$C$40,IF($B82<=DATOS!$C$44,DATOS!$C$41/$B82,DATOS!$C$41*DATOS!$C$44/$B82^2))) -> 1.7090667 | H82: =$G82*DATOS!$C$46/COEFICIENTE!$C$35 -> 0.48830476 | I82: =$G82*DATOS!$C$46/COEFICIENTE!$D$35 -> 0.48830476 | J82: =$D82*DATOS!$C$12 -> 0.27456 | K82: =$E82*DATOS!$C$12 -> 0.27456 | L82: =IF($J82>0,$H82/$J82,0) -> 1.7784993 | M82: =IF($K82>0,$I82/$K82,0) -> 1.7784993 | N82: =IF(DATOS!$C$9="NO","—",IF(AND($L82>=1,$M82>=1),"OK","CALIBRAR")) -> — | O82: =IF(STAAD!$C$17="ASCE 7-16",$G82,$C82) -> 1.344 | Q82: 0.18 | R82: 0.01
B83: =IF(ABS($Q83-DATOS!$C$23/3)<$R83,DATOS!$C$23/3,IF(ABS($Q83-DATOS!$C$23)<$R83,DATOS!$C$23,IF(ABS($Q83-DATOS!$C$42)<$R83,DATOS!$C$42,IF(ABS($Q83-DATOS!$C$43)<$R83,DATOS!$C$43,IF(ABS($Q83-DATOS!$C$44)<$R83,DATOS!$C$44,$Q83))))) -> 0.2 | C83: =IF($B83<DATOS!$C$23/3,DATOS!$C$25*DATOS!$C$20*(1+3*(DATOS!$C$22-1)*$B83/DATOS!$C$23),IF($B83<=DATOS!$C$23,DATOS!$C$25*DATOS!$C$20*DATOS!$C$22,IF($B83<=4,DATOS!$C$25*DATOS!$C$20*DATOS!$C$22*(DATOS!$C$23/$B83)^(2/3),2.5*DATOS!$C$25*DATOS!$C$20*DATOS!$C$22*DATOS!$C$23^(2/3)/$B83^(4/3)))) -> 1.44 | D83: =$C83/COEFICIENTE!$C$12 -> 0.20571429 | E83: =$C83/COEFICIENTE!$D$12 -> 0.20571429 | F83: =1.5*$G83 -> 2.5636 | G83: =IF($B83<DATOS!$C$42,DATOS!$C$40*(0.4+0.6*$B83/DATOS!$C$42),IF($B83<=DATOS!$C$43,DATOS!$C$40,IF($B83<=DATOS!$C$44,DATOS!$C$41/$B83,DATOS!$C$41*DATOS!$C$44/$B83^2))) -> 1.7090667 | H83: =$G83*DATOS!$C$46/COEFICIENTE!$C$35 -> 0.48830476 | I83: =$G83*DATOS!$C$46/COEFICIENTE!$D$35 -> 0.48830476 | J83: =$D83*DATOS!$C$12 -> 0.29417143 | K83: =$E83*DATOS!$C$12 -> 0.29417143 | L83: =IF($J83>0,$H83/$J83,0) -> 1.6599327 | M83: =IF($K83>0,$I83/$K83,0) -> 1.6599327 | N83: =IF(DATOS!$C$9="NO","—",IF(AND($L83>=1,$M83>=1),"OK","CALIBRAR")) -> — | O83: =IF(STAAD!$C$17="ASCE 7-16",$G83,$C83) -> 1.44 | Q83: 0.2 | R83: 0.01
B84: =IF(ABS($Q84-DATOS!$C$23/3)<$R84,DATOS!$C$23/3,IF(ABS($Q84-DATOS!$C$23)<$R84,DATOS!$C$23,IF(ABS($Q84-DATOS!$C$42)<$R84,DATOS!$C$42,IF(ABS($Q84-DATOS!$C$43)<$R84,DATOS!$C$43,IF(ABS($Q84-DATOS!$C$44)<$R84,DATOS!$C$44,$Q84))))) -> 0.22 | C84: =IF($B84<DATOS!$C$23/3,DATOS!$C$25*DATOS!$C$20*(1+3*(DATOS!$C$22-1)*$B84/DATOS!$C$23),IF($B84<=DATOS!$C$23,DATOS!$C$25*DATOS!$C$20*DATOS!$C$22,IF($B84<=4,DATOS!$C$25*DATOS!$C$20*DATOS!$C$22*(DATOS!$C$23/$B84)^(2/3),2.5*DATOS!$C$25*DATOS!$C$20*DATOS!$C$22*DATOS!$C$23^(2/3)/$B84^(4/3)))) -> 1.44 | D84: =$C84/COEFICIENTE!$C$12 -> 0.20571429 | E84: =$C84/COEFICIENTE!$D$12 -> 0.20571429 | F84: =1.5*$G84 -> 2.5636 | G84: =IF($B84<DATOS!$C$42,DATOS!$C$40*(0.4+0.6*$B84/DATOS!$C$42),IF($B84<=DATOS!$C$43,DATOS!$C$40,IF($B84<=DATOS!$C$44,DATOS!$C$41/$B84,DATOS!$C$41*DATOS!$C$44/$B84^2))) -> 1.7090667 | H84: =$G84*DATOS!$C$46/COEFICIENTE!$C$35 -> 0.48830476 | I84: =$G84*DATOS!$C$46/COEFICIENTE!$D$35 -> 0.48830476 | J84: =$D84*DATOS!$C$12 -> 0.29417143 | K84: =$E84*DATOS!$C$12 -> 0.29417143 | L84: =IF($J84>0,$H84/$J84,0) -> 1.6599327 | M84: =IF($K84>0,$I84/$K84,0) -> 1.6599327 | N84: =IF(DATOS!$C$9="NO","—",IF(AND($L84>=1,$M84>=1),"OK","CALIBRAR")) -> — | O84: =IF(STAAD!$C$17="ASCE 7-16",$G84,$C84) -> 1.44 | Q84: 0.22 | R84: 0.01
B85: =IF(ABS($Q85-DATOS!$C$23/3)<$R85,DATOS!$C$23/3,IF(ABS($Q85-DATOS!$C$23)<$R85,DATOS!$C$23,IF(ABS($Q85-DATOS!$C$42)<$R85,DATOS!$C$42,IF(ABS($Q85-DATOS!$C$43)<$R85,DATOS!$C$43,IF(ABS($Q85-DATOS!$C$44)<$R85,DATOS!$C$44,$Q85))))) -> 0.24 | C85: =IF($B85<DATOS!$C$23/3,DATOS!$C$25*DATOS!$C$20*(1+3*(DATOS!$C$22-1)*$B85/DATOS!$C$23),IF($B85<=DATOS!$C$23,DATOS!$C$25*DATOS!$C$20*DATOS!$C$22,IF($B85<=4,DATOS!$C$25*DATOS!$C$20*DATOS!$C$22*(DATOS!$C$23/$B85)^(2/3),2.5*DATOS!$C$25*DATOS!$C$20*DATOS!$C$22*DATOS!$C$23^(2/3)/$B85^(4/3)))) -> 1.44 | D85: =$C85/COEFICIENTE!$C$12 -> 0.20571429 | E85: =$C85/COEFICIENTE!$D$12 -> 0.20571429 | F85: =1.5*$G85 -> 2.5636 | G85: =IF($B85<DATOS!$C$42,DATOS!$C$40*(0.4+0.6*$B85/DATOS!$C$42),IF($B85<=DATOS!$C$43,DATOS!$C$40,IF($B85<=DATOS!$C$44,DATOS!$C$41/$B85,DATOS!$C$41*DATOS!$C$44/$B85^2))) -> 1.7090667 | H85: =$G85*DATOS!$C$46/COEFICIENTE!$C$35 -> 0.48830476 | I85: =$G85*DATOS!$C$46/COEFICIENTE!$D$35 -> 0.48830476 | J85: =$D85*DATOS!$C$12 -> 0.29417143 | K85: =$E85*DATOS!$C$12 -> 0.29417143 | L85: =IF($J85>0,$H85/$J85,0) -> 1.6599327 | M85: =IF($K85>0,$I85/$K85,0) -> 1.6599327 | N85: =IF(DATOS!$C$9="NO","—",IF(AND($L85>=1,$M85>=1),"OK","CALIBRAR")) -> — | O85: =IF(STAAD!$C$17="ASCE 7-16",$G85,$C85) -> 1.44 | Q85: 0.24 | R85: 0.01
B86: =IF(ABS($Q86-DATOS!$C$23/3)<$R86,DATOS!$C$23/3,IF(ABS($Q86-DATOS!$C$23)<$R86,DATOS!$C$23,IF(ABS($Q86-DATOS!$C$42)<$R86,DATOS!$C$42,IF(ABS($Q86-DATOS!$C$43)<$R86,DATOS!$C$43,IF(ABS($Q86-DATOS!$C$44)<$R86,DATOS!$C$44,$Q86))))) -> 0.26 | C86: =IF($B86<DATOS!$C$23/3,DATOS!$C$25*DATOS!$C$20*(1+3*(DATOS!$C$22-1)*$B86/DATOS!$C$23),IF($B86<=DATOS!$C$23,DATOS!$C$25*DATOS!$C$20*DATOS!$C$22,IF($B86<=4,DATOS!$C$25*DATOS!$C$20*DATOS!$C$22*(DATOS!$C$23/$B86)^(2/3),2.5*DATOS!$C$25*DATOS!$C$20*DATOS!$C$22*DATOS!$C$23^(2/3)/$B86^(4/3)))) -> 1.44 | D86: =$C86/COEFICIENTE!$C$12 -> 0.20571429 | E86: =$C86/COEFICIENTE!$D$12 -> 0.20571429 | F86: =1.5*$G86 -> 2.5636 | G86: =IF($B86<DATOS!$C$42,DATOS!$C$40*(0.4+0.6*$B86/DATOS!$C$42),IF($B86<=DATOS!$C$43,DATOS!$C$40,IF($B86<=DATOS!$C$44,DATOS!$C$41/$B86,DATOS!$C$41*DATOS!$C$44/$B86^2))) -> 1.7090667 | H86: =$G86*DATOS!$C$46/COEFICIENTE!$C$35 -> 0.48830476 | I86: =$G86*DATOS!$C$46/COEFICIENTE!$D$35 -> 0.48830476 | J86: =$D86*DATOS!$C$12 -> 0.29417143 | K86: =$E86*DATOS!$C$12 -> 0.29417143 | L86: =IF($J86>0,$H86/$J86,0) -> 1.6599327 | M86: =IF($K86>0,$I86/$K86,0) -> 1.6599327 | N86: =IF(DATOS!$C$9="NO","—",IF(AND($L86>=1,$M86>=1),"OK","CALIBRAR")) -> — | O86: =IF(STAAD!$C$17="ASCE 7-16",$G86,$C86) -> 1.44 | Q86: 0.26 | R86: 0.01
... B179: =IF(ABS($Q179-DATOS!$C$23/3)<$R179,DATOS!$C$23/3,IF(ABS($Q179-DATOS!$C$23)<$R179,DATOS!$C$23,IF(ABS($Q179-DATOS!$C$42)<$R179,DATOS!$C$42,IF(ABS($Q179-DATOS!$C$43)<$R179,DATOS!$C$43,IF(ABS($Q179-DATOS!$C$44)<$R179,DATOS!$C$44,$Q179))))) -> 10 | C179: =IF($B179<DATOS!$C$23/3,DATOS!$C$25*DATOS!$C$20*(1+3*(DATOS!$C$22-1)*$B179/DATOS!$C$23),IF($B179<=DATOS!$C$23,DATOS!$C$25*DATOS!$C$20*DATOS!$C$22,IF($B179<=4,DATOS!$C$25*DATOS!$C$20*DATOS!$C$22*(DATOS!$C$23/$B179)^(2/3),2.5*DATOS!$C$25*DATOS!$C$20*DATOS!$C$22*DATOS!$C$23^(2/3)/$B179^(4/3)))) -> 0.11886938 | D179: =$C179/COEFICIENTE!$C$12 -> 0.01698134 | E179: =$C179/COEFICIENTE!$D$12 -> 0.01698134 | F179: =1.5*$G179 -> 0.1612 | G179: =IF($B179<DATOS!$C$42,DATOS!$C$40*(0.4+0.6*$B179/DATOS!$C$42),IF($B179<=DATOS!$C$43,DATOS!$C$40,IF($B179<=DATOS!$C$44,DATOS!$C$41/$B179,DATOS!$C$41*DATOS!$C$44/$B179^2))) -> 0.10746667 | H179: =$G179*DATOS!$C$46/COEFICIENTE!$C$35 -> 0.030704762 | I179: =$G179*DATOS!$C$46/COEFICIENTE!$D$35 -> 0.030704762 | J179: =$D179*DATOS!$C$12 -> 0.024283316 | K179: =$E179*DATOS!$C$12 -> 0.024283316 | L179: =IF($J179>0,$H179/$J179,0) -> 1.2644386 | M179: =IF($K179>0,$I179/$K179,0) -> 1.2644386 | N179: =IF(DATOS!$C$9="NO","—",IF(AND($L179>=1,$M179>=1),"OK","CALIBRAR")) -> — | O179: =IF(STAAD!$C$17="ASCE 7-16",$G179,$C179) -> 0.11886938 | Q179: 10 | R179: 0.25

Sheet STAAD
B1: ESPECTROS Y CORTANTES PARA STAAD PRO V8i — COPIAR Y PEGAR
B2: En STAAD el espectro se pega elástico (con I) y el R de cada dirección va en el SCALE: un mismo juego de pares sirve para X y para Z. El caso de sismo necesita antes sus masas (SELFWEIGHT X 1 / Y 1 / Z 1 y JOINT LOAD con los pesos en FX, FY y FZ).
B3: =COEFICIENTE!$B$3 -> Sin alertas: datos completos y sistemas dentro de sus límites.
B4: CÓMO SE USA: copia la columna B de cada bloque al caso de sismo del .STD. Las ordenadas van en g y el SCALE convierte a cm/s² con el R de cada dirección (factor de dirección 1). La masa del caso sale de la hoja CM_CV_MASA.
B6: A. RESUMEN POR DIRECCIÓN
B7: NTDS rige en todo el país; ASCE sólo en el AMSS (DATOS §1). Las fuerzas de la NTDS son de servicio: en las combinaciones de la RESESCO el sismo entra × 1.4025 (ec. 2) y × 1.43 (ec. 3), con 100% + 30% (NTDS §6.1.4).
B8: Concepto | C8: Dir. X | D8: Dir. Z | E8: Unidad | F8: Cómo se calcula | H8: Referencia
B9: V estático NTDS | C9: =COEFICIENTE!$C$24 -> 3.5335543 | D9: =COEFICIENTE!$D$24 -> 3.5335543 | E9: t | F9: De COEFICIENTE §A. | H9: NTDS-1994 · ec. 4.1, pág. 7
B10: V estático NTDS | C10: =COEFICIENTE!$C$24*9.80665 -> 34.65233 | D10: =COEFICIENTE!$D$24*9.80665 -> 34.65233 | E10: kN | F10: El mismo × 9.80665. | H10: —
B11: F_t en el último nivel (NTDS) | C11: =COEFICIENTE!$C$25*COEFICIENTE!$C$24 -> 0 | D11: =COEFICIENTE!$D$25*COEFICIENTE!$D$24 -> 0 | E11: t | F11: Va al nivel de cubierta; el resto de V se reparte con w·h. | H11: NTDS-1994 · ecs. 4.6 a 4.8, pág. 8
B12: Cortante mínimo del espectro NTDS | C12: =COEFICIENTE!$C$27*DATOS!$C$60 -> 3.1801989 | D12: =COEFICIENTE!$D$27*DATOS!$C$60 -> 3.1801989 | E12: t | F12: Regular: 90% del estático sin bajar de 80% del de Método A; irregular: 100%. | H12: NTDS-1994 · §5.4.1 (3), pág. 12
B13: Factor para desplazamientos NTDS (C_d) | C13: =COEFICIENTE!$C$13 -> 6 | D13: =COEFICIENTE!$D$13 -> 6 | E13: × | F13: Desplazamiento de STAAD × C_d; la deriva contra la Tabla 8 (TABLAS). | H13: NTDS-1994 · ec. 4.11, pág. 9 · Tabla 8, pág. 24
B14: V estático ASCE (sólo AMSS) | C14: =COEFICIENTE!$C$51 -> 8.3876109 | D14: =COEFICIENTE!$D$51 -> 8.3876109 | E14: t | F14: De COEFICIENTE §B, a nivel de resistencia. | H14: ASCE 7-16 · ec. 12.8-1
B15: Cortante mínimo del espectro ASCE | C15: =COEFICIENTE!$C$54*DATOS!$C$61*IF(DATOS!$C$9="SÍ",COEFICIENTE!$C$64,1) -> 8.3876109 | D15: =COEFICIENTE!$D$54*DATOS!$C$61*IF(DATOS!$C$9="SÍ",COEFICIENTE!$D$64,1) -> 8.3876109 | E15: t | F15: 100% del V estático de ASCE (calibrado dentro del AMSS). | H15: ASCE 7-16 · §12.9.1.4.1
B16: Factor para desplazamientos ASCE (C_d / I_e) | C16: =COEFICIENTE!$C$55 -> 3 | D16: =COEFICIENTE!$D$55 -> 3 | E16: × | F16: Deriva contra la Tabla 12.12-1 (TABLAS). | H16: ASCE 7-16 · ec. 12.8-15
B17: Norma del espectro que se pega abajo | C17: NTDS-1994 | D17: — | E17: SELECTOR. Fuera del AMSS siempre NTDS-1994. | H17: DATOS §1
B18: SCALE para STAAD (si usa el bloque elástico de abajo) | C18: =IF($C$17="NTDS-1994",9.80665/COEFICIENTE!$C$12,9.80665*DATOS!$C$46/COEFICIENTE!$C$35)*100 -> 140.095 | D18: =IF($C$17="NTDS-1994",9.80665/COEFICIENTE!$D$12,9.80665*DATOS!$C$46/COEFICIENTE!$D$35)*100 -> 140.095 | E18: cm/s² | F18: En kgf–cm: el modelo usa cm, por lo que g=980.665 cm/s². Este SCALE es g/R (o g·Iₑ/R para ASCE) expresado en cm/s². | H18: NTDS §5.2, pág. 11 · ASCE §12.9.1
B20: B. BLOQUE PARA EL CASO DE SISMO EN X — COPIA SÓLO LA COLUMNA B
B21: * SISMO X - ELÁSTICO - unidades kgf-cm - SCALE en cm/s2 - SRSS 5% LIN
B22: ="SPECTRUM SRSS X 1 ACC SCALE "&TEXT(C18,"0.000")&" DAMP 0.05 LIN" -> SPECTRUM SRSS X 1 ACC SCALE 140.095 DAMP 0.05 LIN
B23: =TEXT(ESPECTROS!$B$73,"0.000")&" "&TEXT(ESPECTROS!$O$73,"0.0000")&"; "&TEXT(ESPECTROS!$B$74,"0.000")&" "&TEXT(ESPECTROS!$O$74,"0.0000")&"; "&TEXT(ESPECTROS!$B$75,"0.000")&" "&TEXT(ESPECTROS!$O$75,"0.0000")&"; "&TEXT(ESPECTROS!$B$76,"0.000")&" "&TEXT(ESPECTROS!$O$76,"0.0000")&"; "&TEXT(ESPECTROS!$B$77,"0.000")&" "&TEXT(ESPECTROS!$O$77,"0.0000")&";" -> 0.000 0.4800; 0.020 0.5760; 0.040 0.6720; 0.060 0.7680; 0.080 0.8640;
B24: =TEXT(ESPECTROS!$B$78,"0.000")&" "&TEXT(ESPECTROS!$O$78,"0.0000")&"; "&TEXT(ESPECTROS!$B$79,"0.000")&" "&TEXT(ESPECTROS!$O$79,"0.0000")&"; "&TEXT(ESPECTROS!$B$80,"0.000")&" "&TEXT(ESPECTROS!$O$80,"0.0000")&"; "&TEXT(ESPECTROS!$B$81,"0.000")&" "&TEXT(ESPECTROS!$O$81,"0.0000")&"; "&TEXT(ESPECTROS!$B$82,"0.000")&" "&TEXT(ESPECTROS!$O$82,"0.0000")&";" -> 0.100 0.9600; 0.120 1.0560; 0.140 1.1520; 0.157 1.2346; 0.180 1.3440;
B25: =TEXT(ESPECTROS!$B$83,"0.000")&" "&TEXT(ESPECTROS!$O$83,"0.0000")&"; "&TEXT(ESPECTROS!$B$84,"0.000")&" "&TEXT(ESPECTROS!$O$84,"0.0000")&"; "&TEXT(ESPECTROS!$B$85,"0.000")&" "&TEXT(ESPECTROS!$O$85,"0.0000")&"; "&TEXT(ESPECTROS!$B$86,"0.000")&" "&TEXT(ESPECTROS!$O$86,"0.0000")&"; "&TEXT(ESPECTROS!$B$87,"0.000")&" "&TEXT(ESPECTROS!$O$87,"0.0000")&";" -> 0.200 1.4400; 0.220 1.4400; 0.240 1.4400; 0.260 1.4400; 0.280 1.4400;
B26: =TEXT(ESPECTROS!$B$88,"0.000")&" "&TEXT(ESPECTROS!$O$88,"0.0000")&"; "&TEXT(ESPECTROS!$B$89,"0.000")&" "&TEXT(ESPECTROS!$O$89,"0.0000")&"; "&TEXT(ESPECTROS!$B$90,"0.000")&" "&TEXT(ESPECTROS!$O$90,"0.0000")&"; "&TEXT(ESPECTROS!$B$91,"0.000")&" "&TEXT(ESPECTROS!$O$91,"0.0000")&"; "&TEXT(ESPECTROS!$B$92,"0.000")&" "&TEXT(ESPECTROS!$O$92,"0.0000")&";" -> 0.300 1.4400; 0.320 1.4400; 0.340 1.4400; 0.360 1.4400; 0.380 1.4400;
B27: =TEXT(ESPECTROS!$B$93,"0.000")&" "&TEXT(ESPECTROS!$O$93,"0.0000")&"; "&TEXT(ESPECTROS!$B$94,"0.000")&" "&TEXT(ESPECTROS!$O$94,"0.0000")&"; "&TEXT(ESPECTROS!$B$95,"0.000")&" "&TEXT(ESPECTROS!$O$95,"0.0000")&"; "&TEXT(ESPECTROS!$B$96,"0.000")&" "&TEXT(ESPECTROS!$O$96,"0.0000")&"; "&TEXT(ESPECTROS!$B$97,"0.000")&" "&TEXT(ESPECTROS!$O$97,"0.0000")&";" -> 0.400 1.4400; 0.420 1.4400; 0.440 1.4400; 0.460 1.4400; 0.480 1.4400;
B28: =TEXT(ESPECTROS!$B$98,"0.000")&" "&TEXT(ESPECTROS!$O$98,"0.0000")&"; "&TEXT(ESPECTROS!$B$99,"0.000")&" "&TEXT(ESPECTROS!$O$99,"0.0000")&"; "&TEXT(ESPECTROS!$B$100,"0.000")&" "&TEXT(ESPECTROS!$O$100,"0.0000")&"; "&TEXT(ESPECTROS!$B$101,"0.000")&" "&TEXT(ESPECTROS!$O$101,"0.0000")&"; "&TEXT(ESPECTROS!$B$102,"0.000")&" "&TEXT(ESPECTROS!$O$102,"0.0000")&";" -> 0.500 1.4400; 0.520 1.4400; 0.540 1.4400; 0.560 1.4400; 0.580 1.4400;
B29: =TEXT(ESPECTROS!$B$103,"0.000")&" "&TEXT(ESPECTROS!$O$103,"0.0000")&"; "&TEXT(ESPECTROS!$B$104,"0.000")&" "&TEXT(ESPECTROS!$O$104,"0.0000")&"; "&TEXT(ESPECTROS!$B$105,"0.000")&" "&TEXT(ESPECTROS!$O$105,"0.0000")&"; "&TEXT(ESPECTROS!$B$106,"0.000")&" "&TEXT(ESPECTROS!$O$106,"0.0000")&"; "&TEXT(ESPECTROS!$B$107,"0.000")&" "&TEXT(ESPECTROS!$O$107,"0.0000")&";" -> 0.600 1.4400; 0.620 1.4089; 0.640 1.3794; 0.660 1.3513; 0.680 1.3247;
B30: =TEXT(ESPECTROS!$B$108,"0.000")&" "&TEXT(ESPECTROS!$O$108,"0.0000")&"; "&TEXT(ESPECTROS!$B$109,"0.000")&" "&TEXT(ESPECTROS!$O$109,"0.0000")&"; "&TEXT(ESPECTROS!$B$110,"0.000")&" "&TEXT(ESPECTROS!$O$110,"0.0000")&"; "&TEXT(ESPECTROS!$B$111,"0.000")&" "&TEXT(ESPECTROS!$O$111,"0.0000")&"; "&TEXT(ESPECTROS!$B$112,"0.000")&" "&TEXT(ESPECTROS!$O$112,"0.0000")&";" -> 0.700 1.2994; 0.720 1.2752; 0.740 1.2521; 0.760 1.2300; 0.786 1.2028;
B31: =TEXT(ESPECTROS!$B$113,"0.000")&" "&TEXT(ESPECTROS!$O$113,"0.0000")&"; "&TEXT(ESPECTROS!$B$114,"0.000")&" "&TEXT(ESPECTROS!$O$114,"0.0000")&"; "&TEXT(ESPECTROS!$B$115,"0.000")&" "&TEXT(ESPECTROS!$O$115,"0.0000")&"; "&TEXT(ESPECTROS!$B$116,"0.000")&" "&TEXT(ESPECTROS!$O$116,"0.0000")&"; "&TEXT(ESPECTROS!$B$117,"0.000")&" "&TEXT(ESPECTROS!$O$117,"0.0000")&";" -> 0.800 1.1887; 0.820 1.1693; 0.840 1.1507; 0.860 1.1327; 0.880 1.1155;
B32: =TEXT(ESPECTROS!$B$118,"0.000")&" "&TEXT(ESPECTROS!$O$118,"0.0000")&"; "&TEXT(ESPECTROS!$B$119,"0.000")&" "&TEXT(ESPECTROS!$O$119,"0.0000")&"; "&TEXT(ESPECTROS!$B$120,"0.000")&" "&TEXT(ESPECTROS!$O$120,"0.0000")&"; "&TEXT(ESPECTROS!$B$121,"0.000")&" "&TEXT(ESPECTROS!$O$121,"0.0000")&"; "&TEXT(ESPECTROS!$B$122,"0.000")&" "&TEXT(ESPECTROS!$O$122,"0.0000")&";" -> 0.900 1.0989; 0.920 1.0829; 0.940 1.0675; 0.960 1.0526; 0.980 1.0383;
B33: =TEXT(ESPECTROS!$B$123,"0.000")&" "&TEXT(ESPECTROS!$O$123,"0.0000")&"; "&TEXT(ESPECTROS!$B$124,"0.000")&" "&TEXT(ESPECTROS!$O$124,"0.0000")&"; "&TEXT(ESPECTROS!$B$125,"0.000")&" "&TEXT(ESPECTROS!$O$125,"0.0000")&"; "&TEXT(ESPECTROS!$B$126,"0.000")&" "&TEXT(ESPECTROS!$O$126,"0.0000")&"; "&TEXT(ESPECTROS!$B$127,"0.000")&" "&TEXT(ESPECTROS!$O$127,"0.0000")&";" -> 1.000 1.0244; 1.050 0.9916; 1.100 0.9613; 1.150 0.9333; 1.200 0.9071;
B34: =TEXT(ESPECTROS!$B$128,"0.000")&" "&TEXT(ESPECTROS!$O$128,"0.0000")&"; "&TEXT(ESPECTROS!$B$129,"0.000")&" "&TEXT(ESPECTROS!$O$129,"0.0000")&"; "&TEXT(ESPECTROS!$B$130,"0.000")&" "&TEXT(ESPECTROS!$O$130,"0.0000")&"; "&TEXT(ESPECTROS!$B$131,"0.000")&" "&TEXT(ESPECTROS!$O$131,"0.0000")&"; "&TEXT(ESPECTROS!$B$132,"0.000")&" "&TEXT(ESPECTROS!$O$132,"0.0000")&";" -> 1.250 0.8828; 1.300 0.8600; 1.350 0.8386; 1.400 0.8185; 1.450 0.7996;
B35: =TEXT(ESPECTROS!$B$133,"0.000")&" "&TEXT(ESPECTROS!$O$133,"0.0000")&"; "&TEXT(ESPECTROS!$B$134,"0.000")&" "&TEXT(ESPECTROS!$O$134,"0.0000")&"; "&TEXT(ESPECTROS!$B$135,"0.000")&" "&TEXT(ESPECTROS!$O$135,"0.0000")&"; "&TEXT(ESPECTROS!$B$136,"0.000")&" "&TEXT(ESPECTROS!$O$136,"0.0000")&"; "&TEXT(ESPECTROS!$B$137,"0.000")&" "&TEXT(ESPECTROS!$O$137,"0.0000")&";" -> 1.500 0.7818; 1.550 0.7648; 1.600 0.7488; 1.650 0.7336; 1.700 0.7192;
B36: =TEXT(ESPECTROS!$B$138,"0.000")&" "&TEXT(ESPECTROS!$O$138,"0.0000")&"; "&TEXT(ESPECTROS!$B$139,"0.000")&" "&TEXT(ESPECTROS!$O$139,"0.0000")&"; "&TEXT(ESPECTROS!$B$140,"0.000")&" "&TEXT(ESPECTROS!$O$140,"0.0000")&"; "&TEXT(ESPECTROS!$B$141,"0.000")&" "&TEXT(ESPECTROS!$O$141,"0.0000")&"; "&TEXT(ESPECTROS!$B$142,"0.000")&" "&TEXT(ESPECTROS!$O$142,"0.0000")&";" -> 1.750 0.7054; 1.800 0.6923; 1.850 0.6797; 1.900 0.6678; 1.950 0.6563;
B37: =TEXT(ESPECTROS!$B$143,"0.000")&" "&TEXT(ESPECTROS!$O$143,"0.0000")&"; "&TEXT(ESPECTROS!$B$144,"0.000")&" "&TEXT(ESPECTROS!$O$144,"0.0000")&"; "&TEXT(ESPECTROS!$B$145,"0.000")&" "&TEXT(ESPECTROS!$O$145,"0.0000")&"; "&TEXT(ESPECTROS!$B$146,"0.000")&" "&TEXT(ESPECTROS!$O$146,"0.0000")&"; "&TEXT(ESPECTROS!$B$147,"0.000")&" "&TEXT(ESPECTROS!$O$147,"0.0000")&";" -> 2.000 0.6453; 2.100 0.6247; 2.200 0.6056; 2.300 0.5879; 2.400 0.5715;
B38: =TEXT(ESPECTROS!$B$148,"0.000")&" "&TEXT(ESPECTROS!$O$148,"0.0000")&"; "&TEXT(ESPECTROS!$B$149,"0.000")&" "&TEXT(ESPECTROS!$O$149,"0.0000")&"; "&TEXT(ESPECTROS!$B$150,"0.000")&" "&TEXT(ESPECTROS!$O$150,"0.0000")&"; "&TEXT(ESPECTROS!$B$151,"0.000")&" "&TEXT(ESPECTROS!$O$151,"0.0000")&"; "&TEXT(ESPECTROS!$B$152,"0.000")&" "&TEXT(ESPECTROS!$O$152,"0.0000")&";" -> 2.500 0.5561; 2.600 0.5418; 2.700 0.5283; 2.800 0.5157; 2.900 0.5037;
B39: =TEXT(ESPECTROS!$B$153,"0.000")&" "&TEXT(ESPECTROS!$O$153,"0.0000")&"; "&TEXT(ESPECTROS!$B$154,"0.000")&" "&TEXT(ESPECTROS!$O$154,"0.0000")&"; "&TEXT(ESPECTROS!$B$155,"0.000")&" "&TEXT(ESPECTROS!$O$155,"0.0000")&"; "&TEXT(ESPECTROS!$B$156,"0.000")&" "&TEXT(ESPECTROS!$O$156,"0.0000")&"; "&TEXT(ESPECTROS!$B$157,"0.000")&" "&TEXT(ESPECTROS!$O$157,"0.0000")&";" -> 3.000 0.4925; 3.100 0.4818; 3.200 0.4717; 3.300 0.4622; 3.400 0.4530;
B40: =TEXT(ESPECTROS!$B$158,"0.000")&" "&TEXT(ESPECTROS!$O$158,"0.0000")&"; "&TEXT(ESPECTROS!$B$159,"0.000")&" "&TEXT(ESPECTROS!$O$159,"0.0000")&"; "&TEXT(ESPECTROS!$B$160,"0.000")&" "&TEXT(ESPECTROS!$O$160,"0.0000")&"; "&TEXT(ESPECTROS!$B$161,"0.000")&" "&TEXT(ESPECTROS!$O$161,"0.0000")&"; "&TEXT(ESPECTROS!$B$162,"0.000")&" "&TEXT(ESPECTROS!$O$162,"0.0000")&";" -> 3.500 0.4444; 3.600 0.4361; 3.700 0.4282; 3.800 0.4207; 3.900 0.4134;
B41: =TEXT(ESPECTROS!$B$163,"0.000")&" "&TEXT(ESPECTROS!$O$163,"0.0000")&"; "&TEXT(ESPECTROS!$B$164,"0.000")&" "&TEXT(ESPECTROS!$O$164,"0.0000")&"; "&TEXT(ESPECTROS!$B$165,"0.000")&" "&TEXT(ESPECTROS!$O$165,"0.0000")&"; "&TEXT(ESPECTROS!$B$166,"0.000")&" "&TEXT(ESPECTROS!$O$166,"0.0000")&"; "&TEXT(ESPECTROS!$B$167,"0.000")&" "&TEXT(ESPECTROS!$O$167,"0.0000")&";" -> 4.000 0.4065; 4.250 0.3720; 4.500 0.3447; 4.750 0.3207; 5.000 0.2995;
B42: =TEXT(ESPECTROS!$B$168,"0.000")&" "&TEXT(ESPECTROS!$O$168,"0.0000")&"; "&TEXT(ESPECTROS!$B$169,"0.000")&" "&TEXT(ESPECTROS!$O$169,"0.0000")&"; "&TEXT(ESPECTROS!$B$170,"0.000")&" "&TEXT(ESPECTROS!$O$170,"0.0000")&"; "&TEXT(ESPECTROS!$B$171,"0.000")&" "&TEXT(ESPECTROS!$O$171,"0.0000")&"; "&TEXT(ESPECTROS!$B$172,"0.000")&" "&TEXT(ESPECTROS!$O$172,"0.0000")&";" -> 5.250 0.2807; 5.500 0.2638; 5.750 0.2486; 6.000 0.2349; 6.500 0.2111;
...

Sheet CM_CV_MASA
B1: CM, CV Y MASA DEL SISMO PARA STAAD — COPIAR Y PEGAR
B2: De aquí salen las cargas de los casos 1 (CM), 2 (CV) y 4 (masa del sismo) del .STD R2.9. Techo en UNI por larguero y viga con su ancho tributario; en el sismo la cubierta va a los nodos de arriba de las columnas; muros con una carga uniforme por larguero completo.
B4: A. DATOS
B5: Concepto | C5: Valor | D5: Unidad | E5: De dónde sale
B6: CM de techo | C6: 19.32 | D6: kg/m² | E6: Panel Glamet 9.32 + instalaciones 10.00 (AreasTributarias R2.9, DATOS C8)
B7: CV máxima de techo w_m | C7: 20 | D7: kg/m² | E7: RESESCO, tabla de cargas vivas, inciso i (pendiente mayor de 5%), pág. 12
B8: CV instantánea de techo w_i | C8: 0 | D8: kg/m² | E8: RESESCO, inciso i, pág. 12: con 0 no suma masa
B9: CM de muro | C9: 5.85 | D9: kg/m² | E9: Lámina KR-18 cal. 24
B10: B — claro de los marcos (X) | C10: 10.08 | D10: m | E10: Modelo STAAD R2.9: X de 0 a 1008 cm
B11: L — largo de la nave (Z) | C11: 16 | D11: m | E11: Modelo STAAD R2.9: Z de 0 a 1600 cm
B12: Altura del techo en el eje 1 (Z = 0) | C12: 10.43 | D12: m | E12: Modelo STAAD R2.9: nodos 7 y 8
B13: Altura del techo en el eje 2 (Z = 10 m) | C13: 9.91126 | D13: m | E13: Modelo STAAD R2.9: nodos 75 y 76
B14: Altura del techo en el eje 3 (Z = L) | C14: 9.60002 | D14: m | E14: Modelo STAAD R2.9: nodos 9 y 10
B15: Z del eje 2 | C15: 10 | D15: m | E15: Modelo STAAD R2.9: nodos 2 y 5
B16: Separación de largueros de muro | C16: 1.2 | D16: m | E16: Modelo STAAD R2.9: largueros a 1.20, 2.40 … 9.60 m
B17: Nivel del último larguero de muro | C17: 9.6 | D17: m | E17: Modelo STAAD R2.9
... B25: Factor kg/m² → unidades del .STD | C25: 0.0001 | D25: — | E25: UNIT CM KG: presión en kg/cm²
B27: B. TECHO EN LARGUEROS Y VIGAS (CASOS 1 Y 2)
B28: Cada línea de largueros o viga de marco toma la mitad de la separación con sus vecinas (b, hoja TECHO de AreasTributarias R2.9). Las que tienen el mismo b van en un renglón.
B29: Líneas | C29: Miembros de STAAD | D29: b (m) | E29: w CM (kg/m) | F29: w CV (kg/m) | G29: w CM (unid. .STD)
B30: LT-2 a LT-6, VM-2, LT-7 a LT-9 | C30: 74 121 TO 124 285 TO 287 310 TO 326 352 TO 371 | D30: 1.5 | E30: =$C$6*D30 -> 28.98 | F30: =$C$7*D30 -> 30 | G30: =E30*$C$24 -> 0.2898
B31: LT-1 | C31: 327 372 TO 375 | D31: 1.25 | E31: =$C$6*D31 -> 24.15 | F31: =$C$7*D31 -> 25 | G31: =E31*$C$24 -> 0.2415
B32: VM-1 | C32: 11 48 TO 51 | D32: 0.5 | E32: =$C$6*D32 -> 9.66 | F32: =$C$7*D32 -> 10 | G32: =E32*$C$24 -> 0.0966
B33: VM-3 | C33: 12 52 TO 55 | D33: 0.75 | E33: =$C$6*D33 -> 14.49 | F33: =$C$7*D33 -> 15 | G33: =E33*$C$24 -> 0.1449
B34: Revisión | C34: =IF(ABS(D30*9+D31+D32+D33-$C$11)<0.001,"OK: suma de b = L (9 líneas con b = 1.50 m)","REVISA LOS ANCHOS") -> OK: suma de b = L (9 líneas con b = 1.50 m)
B36: C. CUBIERTA EN LOS NODOS DE ARRIBA DE LAS COLUMNAS (MASA DEL SISMO, CASO 4)
B37: Cada nodo toma la mitad del claro B y la mitad de la separación con los marcos vecinos. Peso = (CM + w_i) × área tributaria; en el caso 4 va en FX y en FZ.
B38: Marco | C38: Nodos de arriba (X = 0 y X = B) | D38: Z (m) | E38: Ancho tributario en Z (m) | F38: Área por nodo (m²) | G38: Peso por nodo (kg)
B39: Eje 1 | C39: 7 8 | D39: 0 | E39: =(D40-D39)/2 -> 5 | F39: =$C$10/2*E39 -> 25.2 | G39: =($C$6+$C$8)*F39 -> 486.864
B40: Eje 2 | C40: 75 76 | D40: =$C$15 -> 10 | E40: =(D41-D39)/2 -> 8 | F40: =$C$10/2*E40 -> 40.32 | G40: =($C$6+$C$8)*F40 -> 778.9824
B41: Eje 3 | C41: 9 10 | D41: =$C$11 -> 16 | E41: =(D41-D40)/2 -> 3 | F41: =$C$10/2*E41 -> 15.12 | G41: =($C$6+$C$8)*F41 -> 292.1184
B42: Total (los dos nodos de cada marco) | E42: =SUM(E39:E41) -> 16 | F42: =2*SUM(F39:F41) -> 161.28 | G42: =2*SUM(G39:G41) -> 3115.9296
B43: Revisión | C43: =IF(ABS($G$42-($C$6+$C$8)*$C$10*$C$11)<0.01,"OK: suma = (CM + w_i)·B·L","REVISA LOS MARCOS") -> OK: suma = (CM + w_i)·B·L
B45: D. MUROS: UNA CARGA UNIFORME POR LARGUERO COMPLETO (CASOS 1 Y 4)
B46: Altura tributaria = la mitad hacia el larguero de abajo más la mitad hacia el de arriba. En las orillas inclinadas se usa la altura media del techo a lo largo del larguero: la carga queda uniforme en todo el larguero y la fuerza total no cambia.
B47: Elemento | C47: Miembros de STAAD | D47: Altura trib. (m) | E47: Cómo sale la altura | F47: w (kg/m) | G47: w (unid. .STD)
B48: Largueros típicos (h = 1.20 m) de los muros 3 y 4 | C48: 16 17 20 21 24 25 28 29 32 33 36 37 40 41 199 TO 202 205 TO 214 | D48: =$C$16 -> 1.2 | E48: Separación de largueros | F48: =$C$9*D48 -> 7.02 | G48: =F48*$C$24 -> 0.0702
