Workbook

Sheet DATOS
B1: PRESIONES DE VIENTO EN NAVES — EL SALVADOR (NORMA TÉCNICA PARA DISEÑO POR VIENTO 1997) — DATOS | AA1: auxiliar del croquis (no se toca)
B2: P = C_p·C_z·K·P_o (ec. 4.1). Nave rectangular de una crujía con techo a dos aguas, a un agua (hacia el muro que elijas), plano o curvo. La hoja resuelve de una vez los cuatro vientos (±X, ±Z) con puertas cerradas y con puertas abiertas (PA) y arma las cargas para STAAD. | AA2: s_k | AB2: h_k | AC2: eje dibujo | AE2: M1 u | AF2: M1 v | AG2: M1 x' | AH2: M1 y' | AI2: M2 u | AJ2: M2 v | AK2: M2 x' | AL2: M2 y' | AM2: M3 u | AN2: M3 v | AO2: M3 x' | AP2: M3 y' | AQ2: M4 u | AR2: M4 v | AS2: M4 x' | AT2: M4 y' | AU2: techo x' | AV2: techo y' | AY2: parámetro | AZ2: valor | BA2: flecha M1 x' | BB2: flecha M1 y' | BC2: flecha M2 x' | BD2: flecha M2 y' | BE2: flecha M3 x' | BF2: flecha M3 y' | BG2: flecha M4 x' | BH2: flecha M4 y' | BI2: eje X x' | BJ2: eje X y' | BK2: eje Y x' | BL2: eje Y y' | BM2: eje Z x' | BN2: eje Z y' | BO2: A1 fija x' | BP2: A1 fija y' | BQ2: A1 oper x' | BR2: A1 oper y' | BS2: A2 fija x' | BT2: A2 fija y' | BU2: A2 oper x' | BV2: A2 oper y' | BW2: A3 fija x' | BX2: A3 fija y' | BY2: A3 oper x' | BZ2: A3 oper y' | CA2: A4 fija x' | CB2: A4 fija y' | CC2: A4 oper x' | CD2: A4 oper y' | CE2: A5 fija x' | CF2: A5 fija y' | CG2: A5 oper x' | CH2: A5 oper y' | CI2: A6 fija x' | CJ2: A6 fija y' | CK2: A6 oper x' | CL2: A6 oper y' | CM2: A7 fija x' | CN2: A7 fija y' | CO2: A7 oper x' | CP2: A7 oper y' | CQ2: A8 fija x' | CR2: A8 fija y' | CS2: A8 oper x' | CT2: A8 oper y' | CU2: A9 fija x' | CV2: A9 fija y' | CW2: A9 oper x' | CX2: A9 oper y' | CY2: A10 fija x' | CZ2: A10 fija y' | DA2: A10 oper x' | DB2: A10 oper y' | DC2: A11 fija x' | DD2: A11 fija y' | DE2: A11 oper x' | DF2: A11 oper y' | DG2: A12 fija x' | DH2: A12 fija y' | DI2: A12 oper x' | DJ2: A12 oper y' | DK2: A13 fija x' | DL2: A13 fija y' | DM2: A13 oper x' | DN2: A13 oper y' | DO2: A14 fija x' | DP2: A14 fija y' | DQ2: A14 oper x' | DR2: A14 oper y' | DS2: A15 fija x' | DT2: A15 fija y' | DU2: A15 oper x' | DV2: A15 oper y' | DW2: A16 fija x' | DX2: A16 fija y' | DY2: A16 oper x' | DZ2: A16 oper y' | EA2: A17 fija x' | EB2: A17 fija y' | EC2: A17 oper x' | ED2: A17 oper y' | EE2: A18 fija x' | EF2: A18 fija y' | EG2: A18 oper x' | EH2: A18 oper y' | EI2: A19 fija x' | EJ2: A19 fija y' | EK2: A19 oper x' | EL2: A19 oper y' | EM2: A20 fija x' | EN2: A20 fija y' | EO2: A20 oper x' | EP2: A20 oper y'
B3: CÓMO SE LLENA: sólo celdas amarillas con letra azul (aquí, en ABERTURAS y en LINEAS). Muro 1 = atrás (Z = 0: puerta y cortina), Muro 2 = frente (Z = L: abierto, sin muro en STAAD), Muro 3 = izquierdo (X = 0), Muro 4 = derecho (X = B), como se ven en el croquis. Los marcos quedan en el plano X-Y. Lo marcado EJEMPLO es del NOSE DOCK H5-H6 (modelo R3): cámbialo para otra nave. | AA3: =$C$23*0/8 -> 0 | AB3: =IF($C$14="PLANO",$C$17,IF($C$14="DOS AGUAS",$C$17+($C$18-$C$17)*(1-ABS(2*($AA$3)/$C$23-1)),IF($C$14="UN AGUA",IF(N($C$25)=0,$C$18-($C$18-$C$17)*($AA$3)/$C$23,$C$17+($C$18-$C$17)*($AA$3)/$C$23),$C$17+4*($C$18-$C$17)*($AA$3)/$C$23*(1-($AA$3)/$C$23)))) -> 10.62 | AC3: =IF($C$22="Z","Z","X") -> Z | AE3: =0 -> 0 | AF3: =0 -> 0 | AG3: =((($AZ$5+$AE3*($C$12-2*$AZ$5)/$C$12)-$AZ$3*$C$13)+$AZ$39)/$AZ$38 -> 0.56267062 | AH3: =((IF($AF3>0,$AF3-$AZ$5,0)+$AZ$4*$C$13)+$AZ$40)/$AZ$38 -> 0.35505194 | AI3: =0 -> 0 | AJ3: =0 -> 0 | AK3: =((($AZ$5+$AI3*($C$12-2*$AZ$5)/$C$12))+$AZ$39)/$AZ$38 -> 0.87995107 | AL3: =((IF($AJ3>0,$AJ3-$AZ$5,0))+$AZ$40)/$AZ$38 -> 0.15864023 | AM3: =0 -> 0 | AN3: =0 -> 0 | AO3: =((-$AZ$3*($C$13-($AZ$5+$AM3*($C$13-2*$AZ$5)/$C$13)))+$AZ$39)/$AZ$38 -> 0.55390763 | AP3: =((IF($AN3>0,$AN3-$AZ$5,0)+$AZ$4*($C$13-($AZ$5+$AM3*($C$13-2*$AZ$5)/$C$13)))+$AZ$40)/$AZ$38 -> 0.3511237 | AQ3: =0 -> 0 | AR3: =0 -> 0 | AS3: =(($C$12-$AZ$3*($C$13-($AZ$5+$AQ3*($C$13-2*$AZ$5)/$C$13)))+$AZ$39)/$AZ$38 -> 1.0298283 | AT3: =((IF($AR3>0,$AR3-$AZ$5,0)+$AZ$4*($C$13-($AZ$5+$AQ3*($C$13-2*$AZ$5)/$C$13)))+$AZ$40)/$AZ$38 -> 0.3511237 | AU3: =((IF($AC$3="Z",0,$AA$3)-$AZ$3*($C$13-IF($AC$3="Z",$AA$3,0)))+$AZ$39)/$AZ$38 -> 0.54756202 | AV3: =(($AB$3+$AZ$4*($C$13-IF($AC$3="Z",$AA$3,0)))+$AZ$40)/$AZ$38 -> 0.85646837 | AY3: kx | AZ3: =0.42 -> 0.42 | BA3: =(($AZ$17)+$AZ$39)/$AZ$38 -> 0.78552236 | BB3: =(($AZ$18)+$AZ$40)/$AZ$38 -> 0.93654391 | BC3: =(($AZ$21)+$AZ$39)/$AZ$38 -> 1.1028028 | BD3: =(($AZ$22)+$AZ$40)/$AZ$38 -> 0.063456091 | BE3: =(($AZ$25)+$AZ$39)/$AZ$38 -> 0.6388969 | BF3: =(($AZ$26)+$AZ$40)/$AZ$38 -> 0.18954073 | BG3: =(($AZ$29)+$AZ$39)/$AZ$38 -> 1.2494283 | BH3: =(($AZ$30)+$AZ$40)/$AZ$38 -> 0.79157353 | BI3: =(($AZ$31)+$AZ$39)/$AZ$38 -> 1.4994034 | BJ3: =(($AZ$32)+$AZ$40)/$AZ$38 -> 0.23796034 | BK3: =(($AZ$31)+$AZ$39)/$AZ$38 -> 1.4994034 | BL3: =(($AZ$32)+$AZ$40)/$AZ$38 -> 0.23796034 | BM3: =(($AZ$31)+$AZ$39)/$AZ$38 -> 1.4994034 | BN3: =(($AZ$32)+$AZ$40)/$AZ$38 -> 0.23796034 | BO3: =((IF(AND(ABERTURAS!$K$7="OK",ABERTURAS!$E$7="FIJA"),CHOOSE(ABERTURAS!$N$7,ABERTURAS!$O$7-$AZ$3*$C$13,ABERTURAS!$O$7,-$AZ$3*($C$13-ABERTURAS!$O$7),$C$12-$AZ$3*($C$13-ABERTURAS!$O$7)),0))+$AZ$39)/$AZ$38 -> 0.86484248 | BP3: =((IF(AND(ABERTURAS!$K$7="OK",ABERTURAS!$E$7="FIJA"),ABERTURAS!$Q$7+CHOOSE(ABERTURAS!$N$7,$AZ$4*$C$13,0,$AZ$4*($C$13-ABERTURAS!$O$7),$AZ$4*($C$13-ABERTURAS!$O$7)),0))+$AZ$40)/$AZ$38 -> 0.15864023 | BQ3: =((IF(AND(ABERTURAS!$K$7="OK",ABERTURAS!$E$7="OPERABLE"),CHOOSE(ABERTURAS!$N$7,ABERTURAS!$O$7-$AZ$3*$C$13,ABERTURAS!$O$7,-$AZ$3*($C$13-ABERTURAS!$O$7),$C$12-$AZ$3*($C$13-ABERTURAS!$O$7)),0))+$AZ$39)/$AZ$38 -> 0.57789724 | BR3: =((IF(AND(ABERTURAS!$K$7="OK",ABERTURAS!$E$7="OPERABLE"),ABERTURAS!$Q$7+CHOOSE(ABERTURAS!$N$7,$AZ$4*$C$13,0,$AZ$4*($C$13-ABERTURAS!$O$7),$AZ$4*($C$13-ABERTURAS!$O$7)),0))+$AZ$40)/$AZ$38 -> 0.35505194 | BS3: =((IF(AND(ABERTURAS!$K$8="OK",ABERTURAS!$E$8="FIJA"),CHOOSE(ABERTURAS!$N$8,ABERTURAS!$O$8-$AZ$3*$C$13,ABERTURAS!$O$8,-$AZ$3*($C$13-ABERTURAS!$O$8),$C$12-$AZ$3*($C$13-ABERTURAS!$O$8)),0))+$AZ$39)/$AZ$38 -> 0.86484248 | BT3: =((IF(AND(ABERTURAS!$K$8="OK",ABERTURAS!$E$8="FIJA"),ABERTURAS!$Q$8+CHOOSE(ABERTURAS!$N$8,$AZ$4*$C$13,0,$AZ$4*($C$13-ABERTURAS!$O$8),$AZ$4*($C$13-ABERTURAS!$O$8)),0))+$AZ$40)/$AZ$38 -> 0.15864023 | BU3: =((IF(AND(ABERTURAS!$K$8="OK",ABERTURAS!$E$8="OPERABLE"),CHOOSE(ABERTURAS!$N$8,ABERTURAS!$O$8-$AZ$3*$C$13,ABERTURAS!$O$8,-$AZ$3*($C$13-ABERTURAS!$O$8),$C$12-$AZ$3*($C$13-ABERTURAS!$O$8)),0))+$AZ$39)/$AZ$38 -> 0.6649794 | BV3: =((IF(AND(ABERTURAS!$K$8="OK",ABERTURAS!$E$8="OPERABLE"),ABERTURAS!$Q$8+CHOOSE(ABERTURAS!$N$8,$AZ$4*$C$13,0,$AZ$4*($C$13-ABERTURAS!$O$8),$AZ$4*($C$13-ABERTURAS!$O$8)),0))+$AZ$40)/$AZ$38 -> 0.35505194 | BW3: =((IF(AND(ABERTURAS!$K$9="OK",ABERTURAS!$E$9="FIJA"),CHOOSE(ABERTURAS!$N$9,ABERTURAS!$O$9-$AZ$3*$C$13,ABERTURAS!$O$9,-$AZ$3*($C$13-ABERTURAS!$O$9),$C$12-$AZ$3*($C$13-ABERTURAS!$O$9)),0))+$AZ$39)/$AZ$38 -> 0.86484248 | BX3: =((IF(AND(ABERTURAS!$K$9="OK",ABERTURAS!$E$9="FIJA"),ABERTURAS!$Q$9+CHOOSE(ABERTURAS!$N$9,$AZ$4*$C$13,0,$AZ$4*($C$13-ABERTURAS!$O$9),$AZ$4*($C$13-ABERTURAS!$O$9)),0))+$AZ$40)/$AZ$38 -> 0.15864023 | BY3: =((IF(AND(ABERTURAS!$K$9="OK",ABERTURAS!$E$9="OPERABLE"),CHOOSE(ABERTURAS!$N$9,ABERTURAS!$O$9-$AZ$3*$C$13,ABERTURAS!$O$9,-$AZ$3*($C$13-ABERTURAS!$O$9),$C$12-$AZ$3*($C$13-ABERTURAS!$O$9)),0))+$AZ$39)/$AZ$38 -> 0.86484248 | BZ3: =((IF(AND(ABERTURAS!$K$9="OK",ABERTURAS!$E$9="OPERABLE"),ABERTURAS!$Q$9+CHOOSE(ABERTURAS!$N$9,$AZ$4*$C$13,0,$AZ$4*($C$13-ABERTURAS!$O$9),$AZ$4*($C$13-ABERTURAS!$O$9)),0))+$AZ$40)/$AZ$38 -> 0.15864023 | CA3: =((IF(AND(ABERTURAS!$K$10="OK",ABERTURAS!$E$10="FIJA"),CHOOSE(ABERTURAS!$N$10,ABERTURAS!$O$10-$AZ$3*$C$13,ABERTURAS!$O$10,-$AZ$3*($C$13-ABERTURAS!$O$10),$C$12-$AZ$3*($C$13-ABERTURAS!$O$10)),0))+$AZ$39)/$AZ$38 -> 0.86484248 | CB3: =((IF(AND(ABERTURAS!$K$10="OK",ABERTURAS!$E$10="FIJA"),ABERTURAS!$Q$10+CHOOSE(ABERTURAS!$N$10,$AZ$4*$C$13,0,$AZ$4*($C$13-ABERTURAS!$O$10),$AZ$4*($C$13-ABERTURAS!$O$10)),0))+$AZ$40)/$AZ$38 -> 0.15864023 | CC3: =((IF(AND(ABERTURAS!$K$10="OK",ABERTURAS!$E$10="OPERABLE"),CHOOSE(ABERTURAS!$N$10,ABERTURAS!$O$10-$AZ$3*$C$13,ABERTURAS!$O$10,-$AZ$3*($C$13-ABERTURAS!$O$10),$C$12-$AZ$3*($C$13-ABERTURAS!$O$10)),0))+$AZ$39)/$AZ$38 -> 0.86484248 | CD3: =((IF(AND(ABERTURAS!$K$10="OK",ABERTURAS!$E$10="OPERABLE"),ABERTURAS!$Q$10+CHOOSE(ABERTURAS!$N$10,$AZ$4*$C$13,0,$AZ$4*($C$13-ABERTURAS!$O$10),$AZ$4*($C$13-ABERTURAS!$O$10)),0))+$AZ$40)/$AZ$38 -> 0.15864023 | CE3: =((IF(AND(ABERTURAS!$K$11="OK",ABERTURAS!$E$11="FIJA"),CHOOSE(ABERTURAS!$N$11,ABERTURAS!$O$11-$AZ$3*$C$13,ABERTURAS!$O$11,-$AZ$3*($C$13-ABERTURAS!$O$11),$C$12-$AZ$3*($C$13-ABERTURAS!$O$11)),0))+$AZ$39)/$AZ$38 -> 0.86484248 | CF3: =((IF(AND(ABERTURAS!$K$11="OK",ABERTURAS!$E$11="FIJA"),ABERTURAS!$Q$11+CHOOSE(ABERTURAS!$N$11,$AZ$4*$C$13,0,$AZ$4*($C$13-ABERTURAS!$O$11),$AZ$4*($C$13-ABERTURAS!$O$11)),0))+$AZ$40)/$AZ$38 -> 0.15864023 | CG3: =((IF(AND(ABERTURAS!$K$11="OK",ABERTURAS!$E$11="OPERABLE"),CHOOSE(ABERTURAS!$N$11,ABERTURAS!$O$11-$AZ$3*$C$13,ABERTURAS!$O$11,-$AZ$3*($C$13-ABERTURAS!$O$11),$C$12-$AZ$3*($C$13-ABERTURAS!$O$11)),0))+$AZ$39)/$AZ$38 -> 0.86484248 | CH3: =((IF(AND(ABERTURAS!$K$11="OK",ABERTURAS!$E$11="OPERABLE"),ABERTURAS!$Q$11+CHOOSE(ABERTURAS!$N$11,$AZ$4*$C$13,0,$AZ$4*($C$13-ABERTURAS!$O$11),$AZ$4*($C$13-ABERTURAS!$O$11)),0))+$AZ$40)/$AZ$38 -> 0.15864023 | CI3: =((IF(AND(ABERTURAS!$K$12="OK",ABERTURAS!$E$12="FIJA"),CHOOSE(ABERTURAS!$N$12,ABERTURAS!$O$12-$AZ$3*$C$13,ABERTURAS!$O$12,-$AZ$3*($C$13-ABERTURAS!$O$12),$C$12-$AZ$3*($C$13-ABERTURAS!$O$12)),0))+$AZ$39)/$AZ$38 -> 0.86484248 | CJ3: =((IF(AND(ABERTURAS!$K$12="OK",ABERTURAS!$E$12="FIJA"),ABERTURAS!$Q$12+CHOOSE(ABERTURAS!$N$12,$AZ$4*$C$13,0,$AZ$4*($C$13-ABERTURAS!$O$12),$AZ$4*($C$13-ABERTURAS!$O$12)),0))+$AZ$40)/$AZ$38 -> 0.15864023 | CK3: =((IF(AND(ABERTURAS!$K$12="OK",ABERTURAS!$E$12="OPERABLE"),CHOOSE(ABERTURAS!$N$12,ABERTURAS!$O$12-$AZ$3*$C$13,ABERTURAS!$O$12,-$AZ$3*($C$13-ABERTURAS!$O$12),$C$12-$AZ$3*($C$13-ABERTURAS!$O$12)),0))+$AZ$39)/$AZ$38 -> 0.86484248 | CL3: =((IF(AND(ABERTURAS!$K$12="OK",ABERTURAS!$E$12="OPERABLE"),ABERTURAS!$Q$12+CHOOSE(ABERTURAS!$N$12,$AZ$4*$C$13,0,$AZ$4*($C$13-ABERTURAS!$O$12),$AZ$4*($C$13-ABERTURAS!$O$12)),0))+$AZ$40)/$AZ$38 -> 0.15864023 | CM3: =((IF(AND(ABERTURAS!$K$13="OK",ABERTURAS!$E$13="FIJA"),CHOOSE(ABERTURAS!$N$13,ABERTURAS!$O$13-$AZ$3*$C$13,ABERTURAS!$O$13,-$AZ$3*($C$13-ABERTURAS!$O$13),$C$12-$AZ$3*($C$13-ABERTURAS!$O$13)),0))+$AZ$39)/$AZ$38 -> 0.86484248 | CN3: =((IF(AND(ABERTURAS!$K$13="OK",ABERTURAS!$E$13="FIJA"),ABERTURAS!$Q$13+CHOOSE(ABERTURAS!$N$13,$AZ$4*$C$13,0,$AZ$4*($C$13-ABERTURAS!$O$13),$AZ$4*($C$13-ABERTURAS!$O$13)),0))+$AZ$40)/$AZ$38 -> 0.15864023 | CO3: =((IF(AND(ABERTURAS!$K$13="OK",ABERTURAS!$E$13="OPERABLE"),CHOOSE(ABERTURAS!$N$13,ABERTURAS!$O$13-$AZ$3*$C$13,ABERTURAS!$O$13,-$AZ$3*($C$13-ABERTURAS!$O$13),$C$12-$AZ$3*($C$13-ABERTURAS!$O$13)),0))+$AZ$39)/$AZ$38 -> 0.86484248 | CP3: =((IF(AND(ABERTURAS!$K$13="OK",ABERTURAS!$E$13="OPERABLE"),ABERTURAS!$Q$13+CHOOSE(ABERTURAS!$N$13,$AZ$4*$C$13,0,$AZ$4*($C$13-ABERTURAS!$O$13),$AZ$4*($C$13-ABERTURAS!$O$13)),0))+$AZ$40)/$AZ$38 -> 0.15864023 | CQ3: =((IF(AND(ABERTURAS!$K$14="OK",ABERTURAS!$E$14="FIJA"),CHOOSE(ABERTURAS!$N$14,ABERTURAS!$O$14-$AZ$3*$C$13,ABERTURAS!$O$14,-$AZ$3*($C$13-ABERTURAS!$O$14),$C$12-$AZ$3*($C$13-ABERTURAS!$O$14)),0))+$AZ$39)/$AZ$38 -> 0.86484248 | CR3: =((IF(AND(ABERTURAS!$K$14="OK",ABERTURAS!$E$14="FIJA"),ABERTURAS!$Q$14+CHOOSE(ABERTURAS!$N$14,$AZ$4*$C$13,0,$AZ$4*($C$13-ABERTURAS!$O$14),$AZ$4*($C$13-ABERTURAS!$O$14)),0))+$AZ$40)/$AZ$38 -> 0.15864023 | CS3: =((IF(AND(ABERTURAS!$K$14="OK",ABERTURAS!$E$14="OPERABLE"),CHOOSE(ABERTURAS!$N$14,ABERTURAS!$O$14-$AZ$3*$C$13,ABERTURAS!$O$14,-$AZ$3*($C$13-ABERTURAS!$O$14),$C$12-$AZ$3*($C$13-ABERTURAS!$O$14)),0))+$AZ$39)/$AZ$38 -> 0.86484248 | CT3: =((IF(AND(ABERTURAS!$K$14="OK",ABERTURAS!$E$14="OPERABLE"),ABERTURAS!$Q$14+CHOOSE(ABERTURAS!$N$14,$AZ$4*$C$13,0,$AZ$4*($C$13-ABERTURAS!$O$14),$AZ$4*($C$13-ABERTURAS!$O$14)),0))+$AZ$40)/$AZ$38 -> 0.15864023 | CU3: =((IF(AND(ABERTURAS!$K$15="OK",ABERTURAS!$E$15="FIJA"),CHOOSE(ABERTURAS!$N$15,ABERTURAS!$O$15-$AZ$3*$C$13,ABERTURAS!$O$15,-$AZ$3*($C$13-ABERTURAS!$O$15),$C$12-$AZ$3*($C$13-ABERTURAS!$O$15)),0))+$AZ$39)/$AZ$38 -> 0.86484248 | CV3: =((IF(AND(ABERTURAS!$K$15="OK",ABERTURAS!$E$15="FIJA"),ABERTURAS!$Q$15+CHOOSE(ABERTURAS!$N$15,$AZ$4*$C$13,0,$AZ$4*($C$13-ABERTURAS!$O$15),$AZ$4*($C$13-ABERTURAS!$O$15)),0))+$AZ$40)/$AZ$38 -> 0.15864023 | CW3: =((IF(AND(ABERTURAS!$K$15="OK",ABERTURAS!$E$15="OPERABLE"),CHOOSE(ABERTURAS!$N$15,ABERTURAS!$O$15-$AZ$3*$C$13,ABERTURAS!$O$15,-$AZ$3*($C$13-ABERTURAS!$O$15),$C$12-$AZ$3*($C$13-ABERTURAS!$O$15)),0))+$AZ$39)/$AZ$38 -> 0.86484248 | CX3: =((IF(AND(ABERTURAS!$K$15="OK",ABERTURAS!$E$15="OPERABLE"),ABERTURAS!$Q$15+CHOOSE(ABERTURAS!$N$15,$AZ$4*$C$13,0,$AZ$4*($C$13-ABERTURAS!$O$15),$AZ$4*($C$13-ABERTURAS!$O$15)),0))+$AZ$40)/$AZ$38 -> 0.15864023 | CY3: =((IF(AND(ABERTURAS!$K$16="OK",ABERTURAS!$E$16="FIJA"),CHOOSE(ABERTURAS!$N$16,ABERTURAS!$O$16-$AZ$3*$C$13,ABERTURAS!$O$16,-$AZ$3*($C$13-ABERTURAS!$O$16),$C$12-$AZ$3*($C$13-ABERTURAS!$O$16)),0))+$AZ$39)/$AZ$38 -> 0.86484248 | CZ3: =((IF(AND(ABERTURAS!$K$16="OK",ABERTURAS!$E$16="FIJA"),ABERTURAS!$Q$16+CHOOSE(ABERTURAS!$N$16,$AZ$4*$C$13,0,$AZ$4*($C$13-ABERTURAS!$O$16),$AZ$4*($C$13-ABERTURAS!$O$16)),0))+$AZ$40)/$AZ$38 -> 0.15864023 | DA3: =((IF(AND(ABERTURAS!$K$16="OK",ABERTURAS!$E$16="OPERABLE"),CHOOSE(ABERTURAS!$N$16,ABERTURAS!$O$16-$AZ$3*$C$13,ABERTURAS!$O$16,-$AZ$3*($C$13-ABERTURAS!$O$16),$C$12-$AZ$3*($C$13-ABERTURAS!$O$16)),0))+$AZ$39)/$AZ$38 -> 0.86484248 | DB3: =((IF(AND(ABERTURAS!$K$16="OK",ABERTURAS!$E$16="OPERABLE"),ABERTURAS!$Q$16+CHOOSE(ABERTURAS!$N$16,$AZ$4*$C$13,0,$AZ$4*($C$13-ABERTURAS!$O$16),$AZ$4*($C$13-ABERTURAS!$O$16)),0))+$AZ$40)/$AZ$38 -> 0.15864023 | DC3: =((IF(AND(ABERTURAS!$K$17="OK",ABERTURAS!$E$17="FIJA"),CHOOSE(ABERTURAS!$N$17,ABERTURAS!$O$17-$AZ$3*$C$13,ABERTURAS!$O$17,-$AZ$3*($C$13-ABERTURAS!$O$17),$C$12-$AZ$3*($C$13-ABERTURAS!$O$17)),0))+$AZ$39)/$AZ$38 -> 0.86484248 | DD3: =((IF(AND(ABERTURAS!$K$17="OK",ABERTURAS!$E$17="FIJA"),ABERTURAS!$Q$17+CHOOSE(ABERTURAS!$N$17,$AZ$4*$C$13,0,$AZ$4*($C$13-ABERTURAS!$O$17),$AZ$4*($C$13-ABERTURAS!$O$17)),0))+$AZ$40)/$AZ$38 -> 0.15864023 | DE3: =((IF(AND(ABERTURAS!$K$17="OK",ABERTURAS!$E$17="OPERABLE"),CHOOSE(ABERTURAS!$N$17,ABERTURAS!$O$17-$AZ$3*$C$13,ABERTURAS!$O$17,-$AZ$3*($C$13-ABERTURAS!$O$17),$C$12-$AZ$3*($C$13-ABERTURAS!$O$17)),0))+$AZ$39)/$AZ$38 -> 0.86484248 | DF3: =((IF(AND(ABERTURAS!$K$17="OK",ABERTURAS!$E$17="OPERABLE"),ABERTURAS!$Q$17+CHOOSE(ABERTURAS!$N$17,$AZ$4*$C$13,0,$AZ$4*($C$13-ABERTURAS!$O$17),$AZ$4*($C$13-ABERTURAS!$O$17)),0))+$AZ$40)/$AZ$38 -> 0.15864023 | DG3: =((IF(AND(ABERTURAS!$K$18="OK",ABERTURAS!$E$18="FIJA"),CHOOSE(ABERTURAS!$N$18,ABERTURAS!$O$18-$AZ$3*$C$13,ABERTURAS!$O$18,-$AZ$3*($C$13-ABERTURAS!$O$18),$C$12-$AZ$3*($C$13-ABERTURAS!$O$18)),0))+$AZ$39)/$AZ$38 -> 0.86484248 | DH3: =((IF(AND(ABERTURAS!$K$18="OK",ABERTURAS!$E$18="FIJA"),ABERTURAS!$Q$18+CHOOSE(ABERTURAS!$N$18,$AZ$4*$C$13,0,$AZ$4*($C$13-ABERTURAS!$O$18),$AZ$4*($C$13-ABERTURAS!$O$18)),0))+$AZ$40)/$AZ$38 -> 0.15864023 | DI3: =((IF(AND(ABERTURAS!$K$18="OK",ABERTURAS!$E$18="OPERABLE"),CHOOSE(ABERTURAS!$N$18,ABERTURAS!$O$18-$AZ$3*$C$13,ABERTURAS!$O$18,-$AZ$3*($C$13-ABERTURAS!$O$18),$C$12-$AZ$3*($C$13-ABERTURAS!$O$18)),0))+$AZ$39)/$AZ$38 -> 0.86484248 | DJ3: =((IF(AND(ABERTURAS!$K$18="OK",ABERTURAS!$E$18="OPERABLE"),ABERTURAS!$Q$18+CHOOSE(ABERTURAS!$N$18,$AZ$4*$C$13,0,$AZ$4*($C$13-ABERTURAS!$O$18),$AZ$4*($C$13-ABERTURAS!$O$18)),0))+$AZ$40)/$AZ$38 -> 0.15864023 | DK3: =((IF(AND(ABERTURAS!$K$19="OK",ABERTURAS!$E$19="FIJA"),CHOOSE(ABERTURAS!$N$19,ABERTURAS!$O$19-$AZ$3*$C$13,ABERTURAS!$O$19,-$AZ$3*($C$13-ABERTURAS!$O$19),$C$12-$AZ$3*($C$13-ABERTURAS!$O$19)),0))+$AZ$39)/$AZ$38 -> 0.86484248 | DL3: =((IF(AND(ABERTURAS!$K$19="OK",ABERTURAS!$E$19="FIJA"),ABERTURAS!$Q$19+CHOOSE(ABERTURAS!$N$19,$AZ$4*$C$13,0,$AZ$4*($C$13-ABERTURAS!$O$19),$AZ$4*($C$13-ABERTURAS!$O$19)),0))+$AZ$40)/$AZ$38 -> 0.15864023 | DM3: =((IF(AND(ABERTURAS!$K$19="OK",ABERTURAS!$E$19="OPERABLE"),CHOOSE(ABERTURAS!$N$19,ABERTURAS!$O$19-$AZ$3*$C$13,ABERTURAS!$O$19,-$AZ$3*($C$13-ABERTURAS!$O$19),$C$12-$AZ$3*($C$13-ABERTURAS!$O$19)),0))+$AZ$39)/$AZ$38 -> 0.86484248 | DN3: =((IF(AND(ABERTURAS!$K$19="OK",ABERTURAS!$E$19="OPERABLE"),ABERTURAS!$Q$19+CHOOSE(ABERTURAS!$N$19,$AZ$4*$C$13,0,$AZ$4*($C$13-ABERTURAS!$O$19),$AZ$4*($C$13-ABERTURAS!$O$19)),0))+$AZ$40)/$AZ$38 -> 0.15864023 | DO3: =((IF(AND(ABERTURAS!$K$20="OK",ABERTURAS!$E$20="FIJA"),CHOOSE(ABERTURAS!$N$20,ABERTURAS!$O$20-$AZ$3*$C$13,ABERTURAS!$O$20,-$AZ$3*($C$13-ABERTURAS!$O$20),$C$12-$AZ$3*($C$13-ABERTURAS!$O$20)),0))+$AZ$39)/$AZ$38 -> 0.86484248 | DP3: =((IF(AND(ABERTURAS!$K$20="OK",ABERTURAS!$E$20="FIJA"),ABERTURAS!$Q$20+CHOOSE(ABERTURAS!$N$20,$AZ$4*$C$13,0,$AZ$4*($C$13-ABERTURAS!$O$20),$AZ$4*($C$13-ABERTURAS!$O$20)),0))+$AZ$40)/$AZ$38 -> 0.15864023 | DQ3: =((IF(AND(ABERTURAS!$K$20="OK",ABERTURAS!$E$20="OPERABLE"),CHOOSE(ABERTURAS!$N$20,ABERTURAS!$O$20-$AZ$3*$C$13,ABERTURAS!$O$20,-$AZ$3*($C$13-ABERTURAS!$O$20),$C$12-$AZ$3*($C$13-ABERTURAS!$O$20)),0))+$AZ$39)/$AZ$38 -> 0.86484248 | DR3: =((IF(AND(ABERTURAS!$K$20="OK",ABERTURAS!$E$20="OPERABLE"),ABERTURAS!$Q$20+CHOOSE(ABERTURAS!$N$20,$AZ$4*$C$13,0,$AZ$4*($C$13-ABERTURAS!$O$20),$AZ$4*($C$13-ABERTURAS!$O$20)),0))+$AZ$40)/$AZ$38 -> 0.15864023 | DS3: =((IF(AND(ABERTURAS!$K$21="OK",ABERTURAS!$E$21="FIJA"),CHOOSE(ABERTURAS!$N$21,ABERTURAS!$O$21-$AZ$3*$C$13,ABERTURAS!$O$21,-$AZ$3*($C$13-ABERTURAS!$O$21),$C$12-$AZ$3*($C$13-ABERTURAS!$O$21)),0))+$AZ$39)/$AZ$38 -> 0.86484248 | DT3: =((IF(AND(ABERTURAS!$K$21="OK",ABERTURAS!$E$21="FIJA"),ABERTURAS!$Q$21+CHOOSE(ABERTURAS!$N$21,$AZ$4*$C$13,0,$AZ$4*($C$13-ABERTURAS!$O$21),$AZ$4*($C$13-ABERTURAS!$O$21)),0))+$AZ$40)/$AZ$38 -> 0.15864023 | DU3: =((IF(AND(ABERTURAS!$K$21="OK",ABERTURAS!$E$21="OPERABLE"),CHOOSE(ABERTURAS!$N$21,ABERTURAS!$O$21-$AZ$3*$C$13,ABERTURAS!$O$21,-$AZ$3*($C$13-ABERTURAS!$O$21),$C$12-$AZ$3*($C$13-ABERTURAS!$O$21)),0))+$AZ$39)/$AZ$38 -> 0.86484248 | DV3: =((IF(AND(ABERTURAS!$K$21="OK",ABERTURAS!$E$21="OPERABLE"),ABERTURAS!$Q$21+CHOOSE(ABERTURAS!$N$21,$AZ$4*$C$13,0,$AZ$4*($C$13-ABERTURAS!$O$21),$AZ$4*($C$13-ABERTURAS!$O$21)),0))+$AZ$40)/$AZ$38 -> 0.15864023 | DW3: =((IF(AND(ABERTURAS!$K$22="OK",ABERTURAS!$E$22="FIJA"),CHOOSE(ABERTURAS!$N$22,ABERTURAS!$O$22-$AZ$3*$C$13,ABERTURAS!$O$22,-$AZ$3*($C$13-ABERTURAS!$O$22),$C$12-$AZ$3*($C$13-ABERTURAS!$O$22)),0))+$AZ$39)/$AZ$38 -> 0.86484248 | DX3: =((IF(AND(ABERTURAS!$K$22="OK",ABERTURAS!$E$22="FIJA"),ABERTURAS!$Q$22+CHOOSE(ABERTURAS!$N$22,$AZ$4*$C$13,0,$AZ$4*($C$13-ABERTURAS!$O$22),$AZ$4*($C$13-ABERTURAS!$O$22)),0))+$AZ$40)/$AZ$38 -> 0.15864023 | DY3: =((IF(AND(ABERTURAS!$K$22="OK",ABERTURAS!$E$22="OPERABLE"),CHOOSE(ABERTURAS!$N$22,ABERTURAS!$O$22-$AZ$3*$C$13,ABERTURAS!$O$22,-$AZ$3*($C$13-ABERTURAS!$O$22),$C$12-$AZ$3*($C$13-ABERTURAS!$O$22)),0))+$AZ$39)/$AZ$38 -> 0.86484248 | DZ3: =((IF(AND(ABERTURAS!$K$22="OK",ABERTURAS!$E$22="OPERABLE"),ABERTURAS!$Q$22+CHOOSE(ABERTURAS!$N$22,$AZ$4*$C$13,0,$AZ$4*($C$13-ABERTURAS!$O$22),$AZ$4*($C$13-ABERTURAS!$O$22)),0))+$AZ$40)/$AZ$38 -> 0.15864023 | EA3: =((IF(AND(ABERTURAS!$K$23="OK",ABERTURAS!$E$23="FIJA"),CHOOSE(ABERTURAS!$N$23,ABERTURAS!$O$23-$AZ$3*$C$13,ABERTURAS!$O$23,-$AZ$3*($C$13-ABERTURAS!$O$23),$C$12-$AZ$3*($C$13-ABERTURAS!$O$23)),0))+$AZ$39)/$AZ$38 -> 0.86484248 | EB3: =((IF(AND(ABERTURAS!$K$23="OK",ABERTURAS!$E$23="FIJA"),ABERTURAS!$Q$23+CHOOSE(ABERTURAS!$N$23,$AZ$4*$C$13,0,$AZ$4*($C$13-ABERTURAS!$O$23),$AZ$4*($C$13-ABERTURAS!$O$23)),0))+$AZ$40)/$AZ$38 -> 0.15864023 | EC3: =((IF(AND(ABERTURAS!$K$23="OK",ABERTURAS!$E$23="OPERABLE"),CHOOSE(ABERTURAS!$N$23,ABERTURAS!$O$23-$AZ$3*$C$13,ABERTURAS!$O$23,-$AZ$3*($C$13-ABERTURAS!$O$23),$C$12-$AZ$3*($C$13-ABERTURAS!$O$23)),0))+$AZ$39)/$AZ$38 -> 0.86484248 | ED3: =((IF(AND(ABERTURAS!$K$23="OK",ABERTURAS!$E$23="OPERABLE"),ABERTURAS!$Q$23+CHOOSE(ABERTURAS!$N$23,$AZ$4*$C$13,0,$AZ$4*($C$13-ABERTURAS!$O$23),$AZ$4*($C$13-ABERTURAS!$O$23)),0))+$AZ$40)/$AZ$38 -> 0.15864023 | EE3: =((IF(AND(ABERTURAS!$K$24="OK",ABERTURAS!$E$24="FIJA"),CHOOSE(ABERTURAS!$N$24,ABERTURAS!$O$24-$AZ$3*$C$13,ABERTURAS!$O$24,-$AZ$3*($C$13-ABERTURAS!$O$24),$C$12-$AZ$3*($C$13-ABERTURAS!$O$24)),0))+$AZ$39)/$AZ$38 -> 0.86484248 | EF3: =((IF(AND(ABERTURAS!$K$24="OK",ABERTURAS!$E$24="FIJA"),ABERTURAS!$Q$24+CHOOSE(ABERTURAS!$N$24,$AZ$4*$C$13,0,$AZ$4*($C$13-ABERTURAS!$O$24),$AZ$4*($C$13-ABERTURAS!$O$24)),0))+$AZ$40)/$AZ$38 -> 0.15864023 | EG3: =((IF(AND(ABERTURAS!$K$24="OK",ABERTURAS!$E$24="OPERABLE"),CHOOSE(ABERTURAS!$N$24,ABERTURAS!$O$24-$AZ$3*$C$13,ABERTURAS!$O$24,-$AZ$3*($C$13-ABERTURAS!$O$24),$C$12-$AZ$3*($C$13-ABERTURAS!$O$24)),0))+$AZ$39)/$AZ$38 -> 0.86484248 | EH3: =((IF(AND(ABERTURAS!$K$24="OK",ABERTURAS!$E$24="OPERABLE"),ABERTURAS!$Q$24+CHOOSE(ABERTURAS!$N$24,$AZ$4*$C$13,0,$AZ$4*($C$13-ABERTURAS!$O$24),$AZ$4*($C$13-ABERTURAS!$O$24)),0))+$AZ$40)/$AZ$38 -> 0.15864023 | EI3: =((IF(AND(ABERTURAS!$K$25="OK",ABERTURAS!$E$25="FIJA"),CHOOSE(ABERTURAS!$N$25,ABERTURAS!$O$25-$AZ$3*$C$13,ABERTURAS!$O$25,-$AZ$3*($C$13-ABERTURAS!$O$25),$C$12-$AZ$3*($C$13-ABERTURAS!$O$25)),0))+$AZ$39)/$AZ$38 -> 0.86484248 | EJ3: =((IF(AND(ABERTURAS!$K$25="OK",ABERTURAS!$E$25="FIJA"),ABERTURAS!$Q$25+CHOOSE(ABERTURAS!$N$25,$AZ$4*$C$13,0,$AZ$4*($C$13-ABERTURAS!$O$25),$AZ$4*($C$13-ABERTURAS!$O$25)),0))+$AZ$40)/$AZ$38 -> 0.15864023 | EK3: =((IF(AND(ABERTURAS!$K$25="OK",ABERTURAS!$E$25="OPERABLE"),CHOOSE(ABERTURAS!$N$25,ABERTURAS!$O$25-$AZ$3*$C$13,ABERTURAS!$O$25,-$AZ$3*($C$13-ABERTURAS!$O$25),$C$12-$AZ$3*($C$13-ABERTURAS!$O$25)),0))+$AZ$39)/$AZ$38 -> 0.86484248 | EL3: =((IF(AND(ABERTURAS!$K$25="OK",ABERTURAS!$E$25="OPERABLE"),ABERTURAS!$Q$25+CHOOSE(ABERTURAS!$N$25,$AZ$4*$C$13,0,$AZ$4*($C$13-ABERTURAS!$O$25),$AZ$4*($C$13-ABERTURAS!$O$25)),0))+$AZ$40)/$AZ$38 -> 0.15864023 | EM3: =((IF(AND(ABERTURAS!$K$26="OK",ABERTURAS!$E$26="FIJA"),CHOOSE(ABERTURAS!$N$26,ABERTURAS!$O$26-$AZ$3*$C$13,ABERTURAS!$O$26,-$AZ$3*($C$13-ABERTURAS!$O$26),$C$12-$AZ$3*($C$13-ABERTURAS!$O$26)),0))+$AZ$39)/$AZ$38 -> 0.86484248 | EN3: =((IF(AND(ABERTURAS!$K$26="OK",ABERTURAS!$E$26="FIJA"),ABERTURAS!$Q$26+CHOOSE(ABERTURAS!$N$26,$AZ$4*$C$13,0,$AZ$4*($C$13-ABERTURAS!$O$26),$AZ$4*($C$13-ABERTURAS!$O$26)),0))+$AZ$40)/$AZ$38 -> 0.15864023 | EO3: =((IF(AND(ABERTURAS!$K$26="OK",ABERTURAS!$E$26="OPERABLE"),CHOOSE(ABERTURAS!$N$26,ABERTURAS!$O$26-$AZ$3*$C$13,ABERTURAS!$O$26,-$AZ$3*($C$13-ABERTURAS!$O$26),$C$12-$AZ$3*($C$13-ABERTURAS!$O$26)),0))+$AZ$39)/$AZ$38 -> 0.86484248 | EP3: =((IF(AND(ABERTURAS!$K$26="OK",ABERTURAS!$E$26="OPERABLE"),ABERTURAS!$Q$26+CHOOSE(ABERTURAS!$N$26,$AZ$4*$C$13,0,$AZ$4*($C$13-ABERTURAS!$O$26),$AZ$4*($C$13-ABERTURAS!$O$26)),0))+$AZ$40)/$AZ$38 -> 0.15864023
AA4: =$C$23*1/8 -> 2 | AB4: =IF($C$14="PLANO",$C$17,IF($C$14="DOS AGUAS",$C$17+($C$18-$C$17)*(1-ABS(2*($AA$4)/$C$23-1)),IF($C$14="UN AGUA",IF(N($C$25)=0,$C$18-($C$18-$C$17)*($AA$4)/$C$23,$C$17+($C$18-$C$17)*($AA$4)/$C$23),$C$17+4*($C$18-$C$17)*($AA$4)/$C$23*(1-($AA$4)/$C$23)))) -> 10.52 | AE4: =ABERTURAS!$D$51 -> 10.08 | AF4: =0 -> 0 | AG4: =((($AZ$5+$AE4*($C$12-2*$AZ$5)/$C$12)-$AZ$3*$C$13)+$AZ$39)/$AZ$38 -> 1.0083741 | AH4: =((IF($AF4>0,$AF4-$AZ$5,0)+$AZ$4*$C$13)+$AZ$40)/$AZ$38 -> 0.35505194 | AI4: =ABERTURAS!$D$52 -> 10.08 | AJ4: =0 -> 0 | AK4: =((($AZ$5+$AI4*($C$12-2*$AZ$5)/$C$12))+$AZ$39)/$AZ$38 -> 1.3256546 | AL4: =((IF($AJ4>0,$AJ4-$AZ$5,0))+$AZ$40)/$AZ$38 -> 0.15864023 | AM4: =ABERTURAS!$D$53 -> 16 | AN4: =0 -> 0 | AO4: =((-$AZ$3*($C$13-($AZ$5+$AM4*($C$13-2*$AZ$5)/$C$13)))+$AZ$39)/$AZ$38 -> 0.85849687 | AP4: =((IF($AN4>0,$AN4-$AZ$5,0)+$AZ$4*($C$13-($AZ$5+$AM4*($C$13-2*$AZ$5)/$C$13)))+$AZ$40)/$AZ$38 -> 0.16256846 | AQ4: =ABERTURAS!$D$54 -> 16 | AR4: =0 -> 0 | AS4: =(($C$12-$AZ$3*($C$13-($AZ$5+$AQ4*($C$13-2*$AZ$5)/$C$13)))+$AZ$39)/$AZ$38 -> 1.3344175 | AT4: =((IF($AR4>0,$AR4-$AZ$5,0)+$AZ$4*($C$13-($AZ$5+$AQ4*($C$13-2*$AZ$5)/$C$13)))+$AZ$40)/$AZ$38 -> 0.16256846 | AU4: =((IF($AC$3="Z",0,$AA$4)-$AZ$3*($C$13-IF($AC$3="Z",$AA$4,0)))+$AZ$39)/$AZ$38 -> 0.58722208 | AV4: =(($AB$4+$AZ$4*($C$13-IF($AC$3="Z",$AA$4,0)))+$AZ$40)/$AZ$38 -> 0.82719547 | AY4: ky | AZ4: =0.26 -> 0.26 | BA4: =(($AZ$15)+$AZ$39)/$AZ$38 -> 0.78552236 | BB4: =(($AZ$16)+$AZ$40)/$AZ$38 -> 0.84135977 | BC4: =(($AZ$19)+$AZ$39)/$AZ$38 -> 1.1028028 | BD4: =(($AZ$20)+$AZ$40)/$AZ$38 -> 0.15864023 | BE4: =(($AZ$23)+$AZ$39)/$AZ$38 -> 0.70620225 | BF4: =(($AZ$24)+$AZ$40)/$AZ$38 -> 0.25684608 | BG4: =(($AZ$27)+$AZ$39)/$AZ$38 -> 1.1821229 | BH4: =(($AZ$28)+$AZ$40)/$AZ$38 -> 0.72426818 | BI4: =(($AZ$31+$AZ$12)+$AZ$39)/$AZ$38 -> 1.5707915 | BJ4: =(($AZ$32)+$AZ$40)/$AZ$38 -> 0.23796034 | BK4: =(($AZ$31)+$AZ$39)/$AZ$38 -> 1.4994034 | BL4: =(($AZ$32+$AZ$12)+$AZ$40)/$AZ$38 -> 0.30934844 | BM4: =(($AZ$31+$AZ$12*$AZ$3/SQRT($AZ$3^2+$AZ$4^2))+$AZ$39)/$AZ$38 -> 1.5601022 | BN4: =(($AZ$32-$AZ$12*$AZ$4/SQRT($AZ$3^2+$AZ$4^2))+$AZ$40)/$AZ$38 -> 0.20038488 | BO4: =((IF(AND(ABERTURAS!$K$7="OK",ABERTURAS!$E$7="FIJA"),CHOOSE(ABERTURAS!$N$7,ABERTURAS!$P$7-$AZ$3*$C$13,ABERTURAS!$P$7,-$AZ$3*($C$13-ABERTURAS!$P$7),$C$12-$AZ$3*($C$13-ABERTURAS!$P$7)),0))+$AZ$39)/$AZ$38 -> 0.86484248 | BP4: =((IF(AND(ABERTURAS!$K$7="OK",ABERTURAS!$E$7="FIJA"),ABERTURAS!$Q$7+CHOOSE(ABERTURAS!$N$7,$AZ$4*$C$13,0,$AZ$4*($C$13-ABERTURAS!$P$7),$AZ$4*($C$13-ABERTURAS!$P$7)),0))+$AZ$40)/$AZ$38 -> 0.15864023 | BQ4: =((IF(AND(ABERTURAS!$K$7="OK",ABERTURAS!$E$7="OPERABLE"),CHOOSE(ABERTURAS!$N$7,ABERTURAS!$P$7-$AZ$3*$C$13,ABERTURAS!$P$7,-$AZ$3*($C$13-ABERTURAS!$P$7),$C$12-$AZ$3*($C$13-ABERTURAS!$P$7)),0))+$AZ$39)/$AZ$38 -> 0.639342 | BR4: =((IF(AND(ABERTURAS!$K$7="OK",ABERTURAS!$E$7="OPERABLE"),ABERTURAS!$Q$7+CHOOSE(ABERTURAS!$N$7,$AZ$4*$C$13,0,$AZ$4*($C$13-ABERTURAS!$P$7),$AZ$4*($C$13-ABERTURAS!$P$7)),0))+$AZ$40)/$AZ$38 -> 0.35505194 | BS4: =((IF(AND(ABERTURAS!$K$8="OK",ABERTURAS!$E$8="FIJA"),CHOOSE(ABERTURAS!$N$8,ABERTURAS!$P$8-$AZ$3*$C$13,ABERTURAS!$P$8,-$AZ$3*($C$13-ABERTURAS!$P$8),$C$12-$AZ$3*($C$13-ABERTURAS!$P$8)),0))+$AZ$39)/$AZ$38 -> 0.86484248 | BT4: =((IF(AND(ABERTURAS!$K$8="OK",ABERTURAS!$E$8="FIJA"),ABERTURAS!$Q$8+CHOOSE(ABERTURAS!$N$8,$AZ$4*$C$13,0,$AZ$4*($C$13-ABERTURAS!$P$8),$AZ$4*($C$13-ABERTURAS!$P$8)),0))+$AZ$40)/$AZ$38 -> 0.15864023 | BU4: =((IF(AND(ABERTURAS!$K$8="OK",ABERTURAS!$E$8="OPERABLE"),CHOOSE(ABERTURAS!$N$8,ABERTURAS!$P$8-$AZ$3*$C$13,ABERTURAS!$P$8,-$AZ$3*($C$13-ABERTURAS!$P$8),$C$12-$AZ$3*($C$13-ABERTURAS!$P$8)),0))+$AZ$39)/$AZ$38 -> 0.90584814 | BV4: =((IF(AND(ABERTURAS!$K$8="OK",ABERTURAS!$E$8="OPERABLE"),ABERTURAS!$Q$8+CHOOSE(ABERTURAS!$N$8,$AZ$4*$C$13,0,$AZ$4*($C$13-ABERTURAS!$P$8),$AZ$4*($C$13-ABERTURAS!$P$8)),0))+$AZ$40)/$AZ$38 -> 0.35505194 | BW4: =((IF(AND(ABERTURAS!$K$9="OK",ABERTURAS!$E$9="FIJA"),CHOOSE(ABERTURAS!$N$9,ABERTURAS!$P$9-$AZ$3*$C$13,ABERTURAS!$P$9,-$AZ$3*($C$13-ABERTURAS!$P$9),$C$12-$AZ$3*($C$13-ABERTURAS!$P$9)),0))+$AZ$39)/$AZ$38 -> 1.3407632 | BX4: =((IF(AND(ABERTURAS!$K$9="OK",ABERTURAS!$E$9="FIJA"),ABERTURAS!$Q$9+CHOOSE(ABERTURAS!$N$9,$AZ$4*$C$13,0,$AZ$4*($C$13-ABERTURAS!$P$9),$AZ$4*($C$13-ABERTURAS!$P$9)),0))+$AZ$40)/$AZ$38 -> 0.15864023 | BY4: =((IF(AND(ABERTURAS!$K$9="OK",ABERTURAS!$E$9="OPERABLE"),CHOOSE(ABERTURAS!$N$9,ABERTURAS!$P$9-$AZ$3*$C$13,ABERTURAS!$P$9,-$AZ$3*($C$13-ABERTURAS!$P$9),$C$12-$AZ$3*($C$13-ABERTURAS!$P$9)),0))+$AZ$39)/$AZ$38 -> 0.86484248 | BZ4: =((IF(AND(ABERTURAS!$K$9="OK",ABERTURAS!$E$9="OPERABLE"),ABERTURAS!$Q$9+CHOOSE(ABERTURAS!$N$9,$AZ$4*$C$13,0,$AZ$4*($C$13-ABERTURAS!$P$9),$AZ$4*($C$13-ABERTURAS!$P$9)),0))+$AZ$40)/$AZ$38 -> 0.15864023 | CA4: =((IF(AND(ABERTURAS!$K$10="OK",ABERTURAS!$E$10="FIJA"),CHOOSE(ABERTURAS!$N$10,ABERTURAS!$P$10-$AZ$3*$C$13,ABERTURAS!$P$10,-$AZ$3*($C$13-ABERTURAS!$P$10),$C$12-$AZ$3*($C$13-ABERTURAS!$P$10)),0))+$AZ$39)/$AZ$38 -> 0.86484248 | CB4: =((IF(AND(ABERTURAS!$K$10="OK",ABERTURAS!$E$10="FIJA"),ABERTURAS!$Q$10+CHOOSE(ABERTURAS!$N$10,$AZ$4*$C$13,0,$AZ$4*($C$13-ABERTURAS!$P$10),$AZ$4*($C$13-ABERTURAS!$P$10)),0))+$AZ$40)/$AZ$38 -> 0.15864023 | CC4: =((IF(AND(ABERTURAS!$K$10="OK",ABERTURAS!$E$10="OPERABLE"),CHOOSE(ABERTURAS!$N$10,ABERTURAS!$P$10-$AZ$3*$C$13,ABERTURAS!$P$10,-$AZ$3*($C$13-ABERTURAS!$P$10),$C$12-$AZ$3*($C$13-ABERTURAS!$P$10)),0))+$AZ$39)/$AZ$38 -> 0.86484248 | CD4: =((IF(AND(ABERTURAS!$K$10="OK",ABERTURAS!$E$10="OPERABLE"),ABERTURAS!$Q$10+CHOOSE(ABERTURAS!$N$10,$AZ$4*$C$13,0,$AZ$4*($C$13-ABERTURAS!$P$10),$AZ$4*($C$13-ABERTURAS!$P$10)),0))+$AZ$40)/$AZ$38 -> 0.15864023 | CE4: =((IF(AND(ABERTURAS!$K$11="OK",ABERTURAS!$E$11="FIJA"),CHOOSE(ABERTURAS!$N$11,ABERTURAS!$P$11-$AZ$3*$C$13,ABERTURAS!$P$11,-$AZ$3*($C$13-ABERTURAS!$P$11),$C$12-$AZ$3*($C$13-ABERTURAS!$P$11)),0))+$AZ$39)/$AZ$38 -> 0.86484248 | CF4: =((IF(AND(ABERTURAS!$K$11="OK",ABERTURAS!$E$11="FIJA"),ABERTURAS!$Q$11+CHOOSE(ABERTURAS!$N$11,$AZ$4*$C$13,0,$AZ$4*($C$13-ABERTURAS!$P$11),$AZ$4*($C$13-ABERTURAS!$P$11)),0))+$AZ$40)/$AZ$38 -> 0.15864023 | CG4: =((IF(AND(ABERTURAS!$K$11="OK",ABERTURAS!$E$11="OPERABLE"),CHOOSE(ABERTURAS!$N$11,ABERTURAS!$P$11-$AZ$3*$C$13,ABERTURAS!$P$11,-$AZ$3*($C$13-ABERTURAS!$P$11),$C$12-$AZ$3*($C$13-ABERTURAS!$P$11)),0))+$AZ$39)/$AZ$38 -> 0.86484248 | CH4: =((IF(AND(ABERTURAS!$K$11="OK",ABERTURAS!$E$11="OPERABLE"),ABERTURAS!$Q$11+CHOOSE(ABERTURAS!$N$11,$AZ$4*$C$13,0,$AZ$4*($C$13-ABERTURAS!$P$11),$AZ$4*($C$13-ABERTURAS!$P$11)),0))+$AZ$40)/$AZ$38 -> 0.15864023 | CI4: =((IF(AND(ABERTURAS!$K$12="OK",ABERTURAS!$E$12="FIJA"),CHOOSE(ABERTURAS!$N$12,ABERTURAS!$P$12-$AZ$3*$C$13,ABERTURAS!$P$12,-$AZ$3*($C$13-ABERTURAS!$P$12),$C$12-$AZ$3*($C$13-ABERTURAS!$P$12)),0))+$AZ$39)/$AZ$38 -> 0.86484248 | CJ4: =((IF(AND(ABERTURAS!$K$12="OK",ABERTURAS!$E$12="FIJA"),ABERTURAS!$Q$12+CHOOSE(ABERTURAS!$N$12,$AZ$4*$C$13,0,$AZ$4*($C$13-ABERTURAS!$P$12),$AZ$4*($C$13-ABERTURAS!$P$12)),0))+$AZ$40)/$AZ$38 -> 0.15864023 | CK4: =((IF(AND(ABERTURAS!$K$12="OK",ABERTURAS!$E$12="OPERABLE"),CHOOSE(ABERTURAS!$N$12,ABERTURAS!$P$12-$AZ$3*$C$13,ABERTURAS!$P$12,-$AZ$3*($C$13-ABERTURAS!$P$12),$C$12-$AZ$3*($C$13-ABERTURAS!$P$12)),0))+$AZ$39)/$AZ$38 -> 0.86484248 | CL4: =((IF(AND(ABERTURAS!$K$12="OK",ABERTURAS!$E$12="OPERABLE"),ABERTURAS!$Q$12+CHOOSE(ABERTURAS!$N$12,$AZ$4*$C$13,0,$AZ$4*($C$13-ABERTURAS!$P$12),$AZ$4*($C$13-ABERTURAS!$P$12)),0))+$AZ$40)/$AZ$38 -> 0.15864023 | CM4: =((IF(AND(ABERTURAS!$K$13="OK",ABERTURAS!$E$13="FIJA"),CHOOSE(ABERTURAS!$N$13,ABERTURAS!$P$13-$AZ$3*$C$13,ABERTURAS!$P$13,-$AZ$3*($C$13-ABERTURAS!$P$13),$C$12-$AZ$3*($C$13-ABERTURAS!$P$13)),0))+$AZ$39)/$AZ$38 -> 0.86484248 | CN4: =((IF(AND(ABERTURAS!$K$13="OK",ABERTURAS!$E$13="FIJA"),ABERTURAS!$Q$13+CHOOSE(ABERTURAS!$N$13,$AZ$4*$C$13,0,$AZ$4*($C$13-ABERTURAS!$P$13),$AZ$4*($C$13-ABERTURAS!$P$13)),0))+$AZ$40)/$AZ$38 -> 0.15864023 | CO4: =((IF(AND(ABERTURAS!$K$13="OK",ABERTURAS!$E$13="OPERABLE"),CHOOSE(ABERTURAS!$N$13,ABERTURAS!$P$13-$AZ$3*$C$13,ABERTURAS!$P$13,-$AZ$3*($C$13-ABERTURAS!$P$13),$C$12-$AZ$3*($C$13-ABERTURAS!$P$13)),0))+$AZ$39)/$AZ$38 -> 0.86484248 | CP4: =((IF(AND(ABERTURAS!$K$13="OK",ABERTURAS!$E$13="OPERABLE"),ABERTURAS!$Q$13+CHOOSE(ABERTURAS!$N$13,$AZ$4*$C$13,0,$AZ$4*($C$13-ABERTURAS!$P$13),$AZ$4*($C$13-ABERTURAS!$P$13)),0))+$AZ$40)/$AZ$38 -> 0.15864023 | CQ4: =((IF(AND(ABERTURAS!$K$14="OK",ABERTURAS!$E$14="FIJA"),CHOOSE(ABERTURAS!$N$14,ABERTURAS!$P$14-$AZ$3*$C$13,ABERTURAS!$P$14,-$AZ$3*($C$13-ABERTURAS!$P$14),$C$12-$AZ$3*($C$13-ABERTURAS!$P$14)),0))+$AZ$39)/$AZ$38 -> 0.86484248 | CR4: =((IF(AND(ABERTURAS!$K$14="OK",ABERTURAS!$E$14="FIJA"),ABERTURAS!$Q$14+CHOOSE(ABERTURAS!$N$14,$AZ$4*$C$13,0,$AZ$4*($C$13-ABERTURAS!$P$14),$AZ$4*($C$13-ABERTURAS!$P$14)),0))+$AZ$40)/$AZ$38 -> 0.15864023 | CS4: =((IF(AND(ABERTURAS!$K$14="OK",ABERTURAS!$E$14="OPERABLE"),CHOOSE(ABERTURAS!$N$14,ABERTURAS!$P$14-$AZ$3*$C$13,ABERTURAS!$P$14,-$AZ$3*($C$13-ABERTURAS!$P$14),$C$12-$AZ$3*($C$13-ABERTURAS!$P$14)),0))+$AZ$39)/$AZ$38 -> 0.86484248 | CT4: =((IF(AND(ABERTURAS!$K$14="OK",ABERTURAS!$E$14="OPERABLE"),ABERTURAS!$Q$14+CHOOSE(ABERTURAS!$N$14,$AZ$4*$C$13,0,$AZ$4*($C$13-ABERTURAS!$P$14),$AZ$4*($C$13-ABERTURAS!$P$14)),0))+$AZ$40)/$AZ$38 -> 0.15864023 | CU4: =((IF(AND(ABERTURAS!$K$15="OK",ABERTURAS!$E$15="FIJA"),CHOOSE(ABERTURAS!$N$15,ABERTURAS!$P$15-$AZ$3*$C$13,ABERTURAS!$P$15,-$AZ$3*($C$13-ABERTURAS!$P$15),$C$12-$AZ$3*($C$13-ABERTURAS!$P$15)),0))+$AZ$39)/$AZ$38 -> 0.86484248 | CV4: =((IF(AND(ABERTURAS!$K$15="OK",ABERTURAS!$E$15="FIJA"),ABERTURAS!$Q$15+CHOOSE(ABERTURAS!$N$15,$AZ$4*$C$13,0,$AZ$4*($C$13-ABERTURAS!$P$15),$AZ$4*($C$13-ABERTURAS!$P$15)),0))+$AZ$40)/$AZ$38 -> 0.15864023 | CW4: =((IF(AND(ABERTURAS!$K$15="OK",ABERTURAS!$E$15="OPERABLE"),CHOOSE(ABERTURAS!$N$15,ABERTURAS!$P$15-$AZ$3*$C$13,ABERTURAS!$P$15,-$AZ$3*($C$13-ABERTURAS!$P$15),$C$12-$AZ$3*($C$13-ABERTURAS!$P$15)),0))+$AZ$39)/$AZ$38 -> 0.86484248 | CX4: =((IF(AND(ABERTURAS!$K$15="OK",ABERTURAS!$E$15="OPERABLE"),ABERTURAS!$Q$15+CHOOSE(ABERTURAS!$N$15,$AZ$4*$C$13,0,$AZ$4*($C$13-ABERTURAS!$P$15),$AZ$4*($C$13-ABERTURAS!$P$15)),0))+$AZ$40)/$AZ$38 -> 0.15864023 | CY4: =((IF(AND(ABERTURAS!$K$16="OK",ABERTURAS!$E$16="FIJA"),CHOOSE(ABERTURAS!$N$16,ABERTURAS!$P$16-$AZ$3*$C$13,ABERTURAS!$P$16,-$AZ$3*($C$13-ABERTURAS!$P$16),$C$12-$AZ$3*($C$13-ABERTURAS!$P$16)),0))+$AZ$39)/$AZ$38 -> 0.86484248 | CZ4: =((IF(AND(ABERTURAS!$K$16="OK",ABERTURAS!$E$16="FIJA"),ABERTURAS!$Q$16+CHOOSE(ABERTURAS!$N$16,$AZ$4*$C$13,0,$AZ$4*($C$13-ABERTURAS!$P$16),$AZ$4*($C$13-ABERTURAS!$P$16)),0))+$AZ$40)/$AZ$38 -> 0.15864023 | DA4: =((IF(AND(ABERTURAS!$K$16="OK",ABERTURAS!$E$16="OPERABLE"),CHOOSE(ABERTURAS!$N$16,ABERTURAS!$P$16-$AZ$3*$C$13,ABERTURAS!$P$16,-$AZ$3*($C$13-ABERTURAS!$P$16),$C$12-$AZ$3*($C$13-ABERTURAS!$P$16)),0))+$AZ$39)/$AZ$38 -> 0.86484248 | DB4: =((IF(AND(ABERTURAS!$K$16="OK",ABERTURAS!$E$16="OPERABLE"),ABERTURAS!$Q$16+CHOOSE(ABERTURAS!$N$16,$AZ$4*$C$13,0,$AZ$4*($C$13-ABERTURAS!$P$16),$AZ$4*($C$13-ABERTURAS!$P$16)),0))+$AZ$40)/$AZ$38 -> 0.15864023 | DC4: =((IF(AND(ABERTURAS!$K$17="OK",ABERTURAS!$E$17="FIJA"),CHOOSE(ABERTURAS!$N$17,ABERTURAS!$P$17-$AZ$3*$C$13,ABERTURAS!$P$17,-$AZ$3*($C$13-ABERTURAS!$P$17),$C$12-$AZ$3*($C$13-ABERTURAS!$P$17)),0))+$AZ$39)/$AZ$38 -> 0.86484248 | DD4: =((IF(AND(ABERTURAS!$K$17="OK",ABERTURAS!$E$17="FIJA"),ABERTURAS!$Q$17+CHOOSE(ABERTURAS!$N$17,$AZ$4*$C$13,0,$AZ$4*($C$13-ABERTURAS!$P$17),$AZ$4*($C$13-ABERTURAS!$P$17)),0))+$AZ$40)/$AZ$38 -> 0.15864023 | DE4: =((IF(AND(ABERTURAS!$K$17="OK",ABERTURAS!$E$17="OPERABLE"),CHOOSE(ABERTURAS!$N$17,ABERTURAS!$P$17-$AZ$3*$C$13,ABERTURAS!$P$17,-$AZ$3*($C$13-ABERTURAS!$P$17),$C$12-$AZ$3*($C$13-ABERTURAS!$P$17)),0))+$AZ$39)/$AZ$38 -> 0.86484248 | DF4: =((IF(AND(ABERTURAS!$K$17="OK",ABERTURAS!$E$17="OPERABLE"),ABERTURAS!$Q$17+CHOOSE(ABERTURAS!$N$17,$AZ$4*$C$13,0,$AZ$4*($C$13-ABERTURAS!$P$17),$AZ$4*($C$13-ABERTURAS!$P$17)),0))+$AZ$40)/$AZ$38 -> 0.15864023 | DG4: =((IF(AND(ABERTURAS!$K$18="OK",ABERTURAS!$E$18="FIJA"),CHOOSE(ABERTURAS!$N$18,ABERTURAS!$P$18-$AZ$3*$C$13,ABERTURAS!$P$18,-$AZ$3*($C$13-ABERTURAS!$P$18),$C$12-$AZ$3*($C$13-ABERTURAS!$P$18)),0))+$AZ$39)/$AZ$38 -> 0.86484248 | DH4: =((IF(AND(ABERTURAS!$K$18="OK",ABERTURAS!$E$18="FIJA"),ABERTURAS!$Q$18+CHOOSE(ABERTURAS!$N$18,$AZ$4*$C$13,0,$AZ$4*($C$13-ABERTURAS!$P$18),$AZ$4*($C$13-ABERTURAS!$P$18)),0))+$AZ$40)/$AZ$38 -> 0.15864023 | DI4: =((IF(AND(ABERTURAS!$K$18="OK",ABERTURAS!$E$18="OPERABLE"),CHOOSE(ABERTURAS!$N$18,ABERTURAS!$P$18-$AZ$3*$C$13,ABERTURAS!$P$18,-$AZ$3*($C$13-ABERTURAS!$P$18),$C$12-$AZ$3*($C$13-ABERTURAS!$P$18)),0))+$AZ$39)/$AZ$38 -> 0.86484248 | DJ4: =((IF(AND(ABERTURAS!$K$18="OK",ABERTURAS!$E$18="OPERABLE"),ABERTURAS!$Q$18+CHOOSE(ABERTURAS!$N$18,$AZ$4*$C$13,0,$AZ$4*($C$13-ABERTURAS!$P$18),$AZ$4*($C$13-ABERTURAS!$P$18)),0))+$AZ$40)/$AZ$38 -> 0.15864023 | DK4: =((IF(AND(ABERTURAS!$K$19="OK",ABERTURAS!$E$19="FIJA"),CHOOSE(ABERTURAS!$N$19,ABERTURAS!$P$19-$AZ$3*$C$13,ABERTURAS!$P$19,-$AZ$3*($C$13-ABERTURAS!$P$19),$C$12-$AZ$3*($C$13-ABERTURAS!$P$19)),0))+$AZ$39)/$AZ$38 -> 0.86484248 | DL4: =((IF(AND(ABERTURAS!$K$19="OK",ABERTURAS!$E$19="FIJA"),ABERTURAS!$Q$19+CHOOSE(ABERTURAS!$N$19,$AZ$4*$C$13,0,$AZ$4*($C$13-ABERTURAS!$P$19),$AZ$4*($C$13-ABERTURAS!$P$19)),0))+$AZ$40)/$AZ$38 -> 0.15864023 | DM4: =((IF(AND(ABERTURAS!$K$19="OK",ABERTURAS!$E$19="OPERABLE"),CHOOSE(ABERTURAS!$N$19,ABERTURAS!$P$19-$AZ$3*$C$13,ABERTURAS!$P$19,-$AZ$3*($C$13-ABERTURAS!$P$19),$C$12-$AZ$3*($C$13-ABERTURAS!$P$19)),0))+$AZ$39)/$AZ$38 -> 0.86484248 | DN4: =((IF(AND(ABERTURAS!$K$19="OK",ABERTURAS!$E$19="OPERABLE"),ABERTURAS!$Q$19+CHOOSE(ABERTURAS!$N$19,$AZ$4*$C$13,0,$AZ$4*($C$13-ABERTURAS!$P$19),$AZ$4*($C$13-ABERTURAS!$P$19)),0))+$AZ$40)/$AZ$38 -> 0.15864023 | DO4: =((IF(AND(ABERTURAS!$K$20="OK",ABERTURAS!$E$20="FIJA"),CHOOSE(ABERTURAS!$N$20,ABERTURAS!$P$20-$AZ$3*$C$13,ABERTURAS!$P$20,-$AZ$3*($C$13-ABERTURAS!$P$20),$C$12-$AZ$3*($C$13-ABERTURAS!$P$20)),0))+$AZ$39)/$AZ$38 -> 0.86484248 | DP4: =((IF(AND(ABERTURAS!$K$20="OK",ABERTURAS!$E$20="FIJA"),ABERTURAS!$Q$20+CHOOSE(ABERTURAS!$N$20,$AZ$4*$C$13,0,$AZ$4*($C$13-ABERTURAS!$P$20),$AZ$4*($C$13-ABERTURAS!$P$20)),0))+$AZ$40)/$AZ$38 -> 0.15864023 | DQ4: =((IF(AND(ABERTURAS!$K$20="OK",ABERTURAS!$E$20="OPERABLE"),CHOOSE(ABERTURAS!$N$20,ABERTURAS!$P$20-$AZ$3*$C$13,ABERTURAS!$P$20,-$AZ$3*($C$13-ABERTURAS!$P$20),$C$12-$AZ$3*($C$13-ABERTURAS!$P$20)),0))+$AZ$39)/$AZ$38 -> 0.86484248 | DR4: =((IF(AND(ABERTURAS!$K$20="OK",ABERTURAS!$E$20="OPERABLE"),ABERTURAS!$Q$20+CHOOSE(ABERTURAS!$N$20,$AZ$4*$C$13,0,$AZ$4*($C$13-ABERTURAS!$P$20),$AZ$4*($C$13-ABERTURAS!$P$20)),0))+$AZ$40)/$AZ$38 -> 0.15864023 | DS4: =((IF(AND(ABERTURAS!$K$21="OK",ABERTURAS!$E$21="FIJA"),CHOOSE(ABERTURAS!$N$21,ABERTURAS!$P$21-$AZ$3*$C$13,ABERTURAS!$P$21,-$AZ$3*($C$13-ABERTURAS!$P$21),$C$12-$AZ$3*($C$13-ABERTURAS!$P$21)),0))+$AZ$39)/$AZ$38 -> 0.86484248 | DT4: =((IF(AND(ABERTURAS!$K$21="OK",ABERTURAS!$E$21="FIJA"),ABERTURAS!$Q$21+CHOOSE(ABERTURAS!$N$21,$AZ$4*$C$13,0,$AZ$4*($C$13-ABERTURAS!$P$21),$AZ$4*($C$13-ABERTURAS!$P$21)),0))+$AZ$40)/$AZ$38 -> 0.15864023 | DU4: =((IF(AND(ABERTURAS!$K$21="OK",ABERTURAS!$E$21="OPERABLE"),CHOOSE(ABERTURAS!$N$21,ABERTURAS!$P$21-$AZ$3*$C$13,ABERTURAS!$P$21,-$AZ$3*($C$13-ABERTURAS!$P$21),$C$12-$AZ$3*($C$13-ABERTURAS!$P$21)),0))+$AZ$39)/$AZ$38 -> 0.86484248 | DV4: =((IF(AND(ABERTURAS!$K$21="OK",ABERTURAS!$E$21="OPERABLE"),ABERTURAS!$Q$21+CHOOSE(ABERTURAS!$N$21,$AZ$4*$C$13,0,$AZ$4*($C$13-ABERTURAS!$P$21),$AZ$4*($C$13-ABERTURAS!$P$21)),0))+$AZ$40)/$AZ$38 -> 0.15864023 | DW4: =((IF(AND(ABERTURAS!$K$22="OK",ABERTURAS!$E$22="FIJA"),CHOOSE(ABERTURAS!$N$22,ABERTURAS!$P$22-$AZ$3*$C$13,ABERTURAS!$P$22,-$AZ$3*($C$13-ABERTURAS!$P$22),$C$12-$AZ$3*($C$13-ABERTURAS!$P$22)),0))+$AZ$39)/$AZ$38 -> 0.86484248 | DX4: =((IF(AND(ABERTURAS!$K$22="OK",ABERTURAS!$E$22="FIJA"),ABERTURAS!$Q$22+CHOOSE(ABERTURAS!$N$22,$AZ$4*$C$13,0,$AZ$4*($C$13-ABERTURAS!$P$22),$AZ$4*($C$13-ABERTURAS!$P$22)),0))+$AZ$40)/$AZ$38 -> 0.15864023 | DY4: =((IF(AND(ABERTURAS!$K$22="OK",ABERTURAS!$E$22="OPERABLE"),CHOOSE(ABERTURAS!$N$22,ABERTURAS!$P$22-$AZ$3*$C$13,ABERTURAS!$P$22,-$AZ$3*($C$13-ABERTURAS!$P$22),$C$12-$AZ$3*($C$13-ABERTURAS!$P$22)),0))+$AZ$39)/$AZ$38 -> 0.86484248 | DZ4: =((IF(AND(ABERTURAS!$K$22="OK",ABERTURAS!$E$22="OPERABLE"),ABERTURAS!$Q$22+CHOOSE(ABERTURAS!$N$22,$AZ$4*$C$13,0,$AZ$4*($C$13-ABERTURAS!$P$22),$AZ$4*($C$13-ABERTURAS!$P$22)),0))+$AZ$40)/$AZ$38 -> 0.15864023 | EA4: =((IF(AND(ABERTURAS!$K$23="OK",ABERTURAS!$E$23="FIJA"),CHOOSE(ABERTURAS!$N$23,ABERTURAS!$P$23-$AZ$3*$C$13,ABERTURAS!$P$23,-$AZ$3*($C$13-ABERTURAS!$P$23),$C$12-$AZ$3*($C$13-ABERTURAS!$P$23)),0))+$AZ$39)/$AZ$38 -> 0.86484248 | EB4: =((IF(AND(ABERTURAS!$K$23="OK",ABERTURAS!$E$23="FIJA"),ABERTURAS!$Q$23+CHOOSE(ABERTURAS!$N$23,$AZ$4*$C$13,0,$AZ$4*($C$13-ABERTURAS!$P$23),$AZ$4*($C$13-ABERTURAS!$P$23)),0))+$AZ$40)/$AZ$38 -> 0.15864023 | EC4: =((IF(AND(ABERTURAS!$K$23="OK",ABERTURAS!$E$23="OPERABLE"),CHOOSE(ABERTURAS!$N$23,ABERTURAS!$P$23-$AZ$3*$C$13,ABERTURAS!$P$23,-$AZ$3*($C$13-ABERTURAS!$P$23),$C$12-$AZ$3*($C$13-ABERTURAS!$P$23)),0))+$AZ$39)/$AZ$38 -> 0.86484248 | ED4: =((IF(AND(ABERTURAS!$K$23="OK",ABERTURAS!$E$23="OPERABLE"),ABERTURAS!$Q$23+CHOOSE(ABERTURAS!$N$23,$AZ$4*$C$13,0,$AZ$4*($C$13-ABERTURAS!$P$23),$AZ$4*($C$13-ABERTURAS!$P$23)),0))+$AZ$40)/$AZ$38 -> 0.15864023 | EE4: =((IF(AND(ABERTURAS!$K$24="OK",ABERTURAS!$E$24="FIJA"),CHOOSE(ABERTURAS!$N$24,ABERTURAS!$P$24-$AZ$3*$C$13,ABERTURAS!$P$24,-$AZ$3*($C$13-ABERTURAS!$P$24),$C$12-$AZ$3*($C$13-ABERTURAS!$P$24)),0))+$AZ$39)/$AZ$38 -> 0.86484248 | EF4: =((IF(AND(ABERTURAS!$K$24="OK",ABERTURAS!$E$24="FIJA"),ABERTURAS!$Q$24+CHOOSE(ABERTURAS!$N$24,$AZ$4*$C$13,0,$AZ$4*($C$13-ABERTURAS!$P$24),$AZ$4*($C$13-ABERTURAS!$P$24)),0))+$AZ$40)/$AZ$38 -> 0.15864023 | EG4: =((IF(AND(ABERTURAS!$K$24="OK",ABERTURAS!$E$24="OPERABLE"),CHOOSE(ABERTURAS!$N$24,ABERTURAS!$P$24-$AZ$3*$C$13,ABERTURAS!$P$24,-$AZ$3*($C$13-ABERTURAS!$P$24),$C$12-$AZ$3*($C$13-ABERTURAS!$P$24)),0))+$AZ$39)/$AZ$38 -> 0.86484248 | EH4: =((IF(AND(ABERTURAS!$K$24="OK",ABERTURAS!$E$24="OPERABLE"),ABERTURAS!$Q$24+CHOOSE(ABERTURAS!$N$24,$AZ$4*$C$13,0,$AZ$4*($C$13-ABERTURAS!$P$24),$AZ$4*($C$13-ABERTURAS!$P$24)),0))+$AZ$40)/$AZ$38 -> 0.15864023 | EI4: =((IF(AND(ABERTURAS!$K$25="OK",ABERTURAS!$E$25="FIJA"),CHOOSE(ABERTURAS!$N$25,ABERTURAS!$P$25-$AZ$3*$C$13,ABERTURAS!$P$25,-$AZ$3*($C$13-ABERTURAS!$P$25),$C$12-$AZ$3*($C$13-ABERTURAS!$P$25)),0))+$AZ$39)/$AZ$38 -> 0.86484248 | EJ4: =((IF(AND(ABERTURAS!$K$25="OK",ABERTURAS!$E$25="FIJA"),ABERTURAS!$Q$25+CHOOSE(ABERTURAS!$N$25,$AZ$4*$C$13,0,$AZ$4*($C$13-ABERTURAS!$P$25),$AZ$4*($C$13-ABERTURAS!$P$25)),0))+$AZ$40)/$AZ$38 -> 0.15864023 | EK4: =((IF(AND(ABERTURAS!$K$25="OK",ABERTURAS!$E$25="OPERABLE"),CHOOSE(ABERTURAS!$N$25,ABERTURAS!$P$25-$AZ$3*$C$13,ABERTURAS!$P$25,-$AZ$3*($C$13-ABERTURAS!$P$25),$C$12-$AZ$3*($C$13-ABERTURAS!$P$25)),0))+$AZ$39)/$AZ$38 -> 0.86484248 | EL4: =((IF(AND(ABERTURAS!$K$25="OK",ABERTURAS!$E$25="OPERABLE"),ABERTURAS!$Q$25+CHOOSE(ABERTURAS!$N$25,$AZ$4*$C$13,0,$AZ$4*($C$13-ABERTURAS!$P$25),$AZ$4*($C$13-ABERTURAS!$P$25)),0))+$AZ$40)/$AZ$38 -> 0.15864023 | EM4: =((IF(AND(ABERTURAS!$K$26="OK",ABERTURAS!$E$26="FIJA"),CHOOSE(ABERTURAS!$N$26,ABERTURAS!$P$26-$AZ$3*$C$13,ABERTURAS!$P$26,-$AZ$3*($C$13-ABERTURAS!$P$26),$C$12-$AZ$3*($C$13-ABERTURAS!$P$26)),0))+$AZ$39)/$AZ$38 -> 0.86484248 | EN4: =((IF(AND(ABERTURAS!$K$26="OK",ABERTURAS!$E$26="FIJA"),ABERTURAS!$Q$26+CHOOSE(ABERTURAS!$N$26,$AZ$4*$C$13,0,$AZ$4*($C$13-ABERTURAS!$P$26),$AZ$4*($C$13-ABERTURAS!$P$26)),0))+$AZ$40)/$AZ$38 -> 0.15864023 | EO4: =((IF(AND(ABERTURAS!$K$26="OK",ABERTURAS!$E$26="OPERABLE"),CHOOSE(ABERTURAS!$N$26,ABERTURAS!$P$26-$AZ$3*$C$13,ABERTURAS!$P$26,-$AZ$3*($C$13-ABERTURAS!$P$26),$C$12-$AZ$3*($C$13-ABERTURAS!$P$26)),0))+$AZ$39)/$AZ$38 -> 0.86484248 | EP4: =((IF(AND(ABERTURAS!$K$26="OK",ABERTURAS!$E$26="OPERABLE"),ABERTURAS!$Q$26+CHOOSE(ABERTURAS!$N$26,$AZ$4*$C$13,0,$AZ$4*($C$13-ABERTURAS!$P$26),$AZ$4*($C$13-ABERTURAS!$P$26)),0))+$AZ$40)/$AZ$38 -> 0.15864023
