Workbook

Sheet DATOS
B1: ÁREAS TRIBUTARIAS Y CARGAS PARA STAAD — HANGAR NOSE-DOCK H5-H6 — DATOS
B2: Largueros y vigas de techo y largueros de muro del modelo 002_NOSE_DOCK_H5_H6_R1.3_3.STD (en el modelo: cm y kg)
B4: 1. CARGAS MUERTAS (TABLA DE CM DEL PROYECTO)
B5: Concepto | C5: Valor | D5: Unidad | E5: Cómo se calcula / de dónde sale | F5: Referencia
B6: Panel sándwich GLAMET (Metecno) PUR/PIR 1.5" — techo | C6: 9.32 | D6: kg/m² | E6: CAPTURA. Renglón 1 de la tabla de CM, columna Techos. | F6: Tabla de CM del proyecto (foto) · renglón 1
B7: Instalaciones generales (iluminación, datos) — techo | C7: 10 | D7: kg/m² | E7: CAPTURA. Renglón 2 de la tabla de CM, columna Techos. | F7: Tabla de CM del proyecto (foto) · renglón 2
B8: CM de techo | C8: =C6+C7 -> 19.32 | D8: kg/m² | E8: CALCULADA = panel + instalaciones. No incluye el acero: ése lo mete STAAD con SELFWEIGHT. | F8: Tabla de CM del proyecto · total Techos (19.32)
B9: Lámina SSR KR-18 acanalada cal. 24 — muros | C9: 5.85 | D9: kg/m² | E9: CAPTURA. Renglón 3 de la tabla de CM, columna Muros. | F9: Tabla de CM del proyecto (foto) · renglón 3
B10: CM de muros | C10: =C9 -> 5.85 | D10: kg/m² | E10: CALCULADA. Se aplica como carga vertical en los largueros de muro. | F10: Tabla de CM del proyecto · total Muros (5.85)
B12: 2. CARGA VIVA DE TECHO — RESESCO 1996
B13: La tabla del Reglamento cambia con la pendiente: hasta 5% (inciso h) w_m = 100, w_i = 50; más de 5% (inciso i) w_m = 20, w_i = 0 kg/m².
B14: Concepto | C14: Valor | D14: Unidad | E14: Cómo se calcula / de dónde sale | F14: Referencia
B15: Y del techo en el eje 1 (Z = 0) | C15: 10.43 | D15: m | E15: CAPTURA del modelo: nodos 7 y 8, Y = 1043 cm. | F15: 002_NOSE_DOCK_H5_H6_R1.3_3.STD · JOINT COORDINATES
B16: Y del techo en el eje 3 (Z = 16 m) | C16: 9.60002 | D16: m | E16: CAPTURA del modelo: nodos 9 y 10, Y = 960.002 cm. | F16: 002_NOSE_DOCK_H5_H6_R1.3_3.STD · JOINT COORDINATES
B17: L — largo en el sentido de la pendiente (eje 1 a eje 3) | C17: =C33-C31 -> 16 | D17: m | E17: CALCULADA con los ejes de la sección 3 (Z de 0 a 1600 cm). | F17: 002_NOSE_DOCK_H5_H6_R1.3_3.STD · JOINT COORDINATES
B18: Pendiente del modelo = (Y₁ − Y₃) / L | C18: =(C15-C16)/C17 -> 0.05187375 | D18: % | E18: CALCULADA con la geometría de STAAD (0.83 m de caída en 16 m). | F18: Geometría del modelo
B19: θ — ángulo del techo | C19: =DEGREES(ATAN(C18)) -> 2.9694853 | D19: ° | E19: CALCULADA = arctan(pendiente). | F19: —
B20: Pendiente que rige (arquitectónico) | C20: 0.054 | D20: % | E20: CAPTURA. La que indicaste (5.4%); el modelo da 5.19%. Las dos pasan de 5%: w_m y w_i se ajustan solos si la cambias. | F20: Arquitectónico (dato del proyecto)
B21: Inciso de la tabla que aplica | C21: =IF(C20>0.05,"i) pendiente mayor de 5%","h) pendiente no mayor de 5%") -> i) pendiente mayor de 5% | D21: — | E21: CALCULADA con la pendiente que rige. | F21: RESESCO 1996 · Tabla de Cargas Vivas Unitarias Mínimas, incisos h) e i), pág. 12
B22: w_m — carga viva máxima (caso 2 CV) | C22: =IF(C20>0.05,20,100) -> 20 | D22: kg/m² | E22: CALCULADA. Para diseño por gravedad (combinación 1.4CM + 1.7CV). | F22: RESESCO · Art. 25 num. 1, pág. 9 · Tabla, pág. 12
B23: w_i — carga viva instantánea (caso 3 CVR y masa sísmica) | C23: =IF(C20>0.05,0,50) -> 0 | D23: kg/m² | E23: CALCULADA. Para sismo y viento; con 0 el caso 3 queda vacío y no suma masa. | F23: RESESCO · Art. 25 num. 2, pág. 10 · Tabla, pág. 12
B24: w — carga viva media | C24: =IF(C20>0.05,5,15) -> 5 | D24: kg/m² | E24: CALCULADA. Sólo para deflexiones diferidas. | F24: RESESCO · Art. 25 num. 3, pág. 10 · Tabla, pág. 12
B25: Carga concentrada en elementos de cubierta | C25: 100 | D25: kg | E25: Revisión aparte de largueros y vigas de techo: 100 kg en la posición más crítica (no es un caso general de STAAD). | F25: RESESCO · Observación 5 a la tabla, pág. 13
B27: 3. GEOMETRÍA DEL MODELO
B28: Concepto | C28: Valor | D28: Unidad | E28: Cómo se calcula / de dónde sale | F28: Referencia
B29: Claro de largueros de techo (eje A a eje B) | C29: 10.08 | D29: m | E29: CAPTURA del modelo: X de 0 a 1008 cm. | F29: .STD R1.3_3 · nodos 7 y 8
B30: Mitad del claro (lo que cada larguero entrega a cada viga de alero) | C30: =C29/2 -> 5.04 | D30: m | E30: CALCULADA. Ancho en X del área de las vigas VA y VB y de los nodos de cabeza de columna. | F30: Criterio de área tributaria
B31: Z del eje 1 | C31: 0 | D31: m | E31: CAPTURA del modelo. | F31: .STD R1.3_3 · nodos 1 y 4
B32: Z del eje 2 | C32: 10 | D32: m | E32: CAPTURA del modelo. Desde la R2.7 los marcos intermedios pasaron de 6.75 y 13.50 m a uno solo en 10.00 m. | F32: .STD R1.3_3 · nodos 2 y 5
B33: Z del eje 3 | C33: 16 | D33: m | E33: CAPTURA del modelo. | F33: .STD R1.3_3 · nodos 3 y 6
B34: Y del techo en el eje 2 (Z = 10 m) | C34: 9.91126 | D34: m | E34: CAPTURA del modelo: nodos 75 y 76, Y = 991.126 cm. | F34: .STD R1.3_3 · JOINT COORDINATES
B35: Factor por pendiente 1 / cos θ | C35: =1/COS(RADIANS(C19)) -> 1.0013445 | D35: — | E35: CALCULADA. Las áreas van en proyección horizontal: este factor se desprecia. | F35: —
B36: Nivel del último larguero de muro | C36: 9.45 | D36: m | E36: CAPTURA del modelo R1.3_3: largueros de muro a 0.60 m del desplante y después @1.20 m hasta 9.00 m; arriba de ése, uno a 9.45 m en el claro 1-2 de los muros A y B y en el muro 1. El claro 2-3 termina en 9.00 m. | F36: .STD R1.3_3
B37: Franja de la base (baja directo a la cimentación) | C37: 0.3 | D37: m | E37: CALCULADA a mano = mitad de 0.60 m (del desplante al primer larguero). No carga largueros. | F37: Criterio de área tributaria
B39: 4. CRITERIOS
B40: 1. Los contraflambeos PIPS7 del techo no se consideran portantes (articulados en sus extremos): cada larguero MC12-14 trabaja de alero a alero (10.08 m) y entrega la mitad a cada viga de alero MCE12-14.
B41: 2. En los ejes 1, 2 y 3 no hay larguero en el modelo: la franja de ese eje la toma directo la viga del marco (VM-1 MCE4-14, VM-2 MCE10-14, VM-3 MCE6-14).
B42: 3. Techo: franja de cada línea = mitad de la separación a cada lado. Muros: igual en vertical; la franja de abajo (0.00–0.30 m) baja directo a la base y la de arriba va a la viga de alero (ejes A y B) o a la VM-1 (eje 1). Los vanos no llevan lámina: la cortina carga su peso arriba de las jambas (nodos 69 y 70) y su viento a las jambas; la puerta de 1.22 × 2.40 carga su viento a su dintel (hoja de viento).
B43: 4. El eje 3 (Z = 16 m) no tiene largueros de muro en el modelo: se tomó sin muro (frente abierto).
B44: 5. En STAAD: CM y CV de techo como UNI GY en cada larguero y viga con su franja b; muros como UNI GY en sus largueros; masa sísmica (caso 4): cubierta y muros concentrados en las 6 cabezas de columna (JOINT LOAD).
...

Sheet TECHO
B1: TECHO — ÁREAS TRIBUTARIAS DE LARGUEROS MC12-14 Y VIGAS DE MARCO MCE4-14, MCE10-14 Y MCE6-14 (R1.3_3)
B2: Planta en proyección horizontal. Las líneas en X (largueros LT y vigas de marco VM) reciben su franja; las vigas de alero VA y VB reciben la mitad del claro de cada larguero. Mismas áreas que el DXF R1.3_3. En STAAD la CM y la CV van en UNI GY en cada línea con su franja b (hoja STAAD); la masa del techo va a las cabezas de columna (hoja NODOS_TECHO).
B4: A. LÍNEAS EN X — LARGUEROS LT Y VIGAS DE MARCO VM
B5: ID | C5: Elemento | D5: Perfil | E5: Z (m) | F5: Franja desde (m) | G5: Franja hasta (m) | H5: b (m) | I5: Claro (m) | J5: A (m²) | K5: w CM (kg/m) | L5: w CV (kg/m) | M5: w CVi (kg/m) | N5: R extremo CM (kg) | O5: R extremo CV (kg) | P5: Miembros STAAD | Q5: Referencia
E6: del modelo | F6: (Z ant. + Z)/2 | G6: (Z + Z sig.)/2 | H6: hasta − desde | I6: DATOS C29 | J6: b × claro | K6: CM techo × b | L6: w_m × b | M6: w_i × b | N6: w CM × claro/2 | O6: w CV × claro/2 | P6: del .STD
B7: VM-1 | C7: Viga de marco eje 1 | D7: MCE4-14 | E7: 0 | F7: =E7 -> 0 | G7: =(E7+E8)/2 -> 0.5 | H7: =G7-F7 -> 0.5 | I7: =DATOS!$C$29 -> 10.08 | J7: =H7*I7 -> 5.04 | K7: =DATOS!$C$8*H7 -> 9.66 | L7: =DATOS!$C$22*H7 -> 10 | M7: =DATOS!$C$23*H7 -> 0 | N7: =K7*I7/2 -> 48.6864 | O7: =L7*I7/2 -> 50.4 | P7: 11 48 TO 51 | Q7: .STD R1.3_3 · nodos 7 a 8 (Z = 0 cm)
B8: LT-1 | C8: Larguero de techo | D8: MC12-14 | E8: 1 | F8: =(E7+E8)/2 -> 0.5 | G8: =(E8+E9)/2 -> 1.75 | H8: =G8-F8 -> 1.25 | I8: =DATOS!$C$29 -> 10.08 | J8: =H8*I8 -> 12.6 | K8: =DATOS!$C$8*H8 -> 24.15 | L8: =DATOS!$C$22*H8 -> 25 | M8: =DATOS!$C$23*H8 -> 0 | N8: =K8*I8/2 -> 121.716 | O8: =L8*I8/2 -> 126 | P8: 327 372 TO 375 | Q8: .STD R1.3_3 · nodos 170 a 176 (Z = 100 cm)
B9: LT-2 | C9: Larguero de techo | D9: MC12-14 | E9: 2.5 | F9: =(E8+E9)/2 -> 1.75 | G9: =(E9+E10)/2 -> 3.25 | H9: =G9-F9 -> 1.5 | I9: =DATOS!$C$29 -> 10.08 | J9: =H9*I9 -> 15.12 | K9: =DATOS!$C$8*H9 -> 28.98 | L9: =DATOS!$C$22*H9 -> 30 | M9: =DATOS!$C$23*H9 -> 0 | N9: =K9*I9/2 -> 146.0592 | O9: =L9*I9/2 -> 151.2 | P9: 326 368 TO 371 | Q9: .STD R1.3_3 · nodos 169 a 175 (Z = 250 cm)
B10: LT-3 | C10: Larguero de techo | D10: MC12-14 | E10: 4 | F10: =(E9+E10)/2 -> 3.25 | G10: =(E10+E11)/2 -> 4.75 | H10: =G10-F10 -> 1.5 | I10: =DATOS!$C$29 -> 10.08 | J10: =H10*I10 -> 15.12 | K10: =DATOS!$C$8*H10 -> 28.98 | L10: =DATOS!$C$22*H10 -> 30 | M10: =DATOS!$C$23*H10 -> 0 | N10: =K10*I10/2 -> 146.0592 | O10: =L10*I10/2 -> 151.2 | P10: 325 364 TO 367 | Q10: .STD R1.3_3 · nodos 168 a 174 (Z = 400 cm)
B11: LT-4 | C11: Larguero de techo | D11: MC12-14 | E11: 5.5 | F11: =(E10+E11)/2 -> 4.75 | G11: =(E11+E12)/2 -> 6.25 | H11: =G11-F11 -> 1.5 | I11: =DATOS!$C$29 -> 10.08 | J11: =H11*I11 -> 15.12 | K11: =DATOS!$C$8*H11 -> 28.98 | L11: =DATOS!$C$22*H11 -> 30 | M11: =DATOS!$C$23*H11 -> 0 | N11: =K11*I11/2 -> 146.0592 | O11: =L11*I11/2 -> 151.2 | P11: 324 360 TO 363 | Q11: .STD R1.3_3 · nodos 167 a 173 (Z = 550 cm)
B12: LT-5 | C12: Larguero de techo | D12: MC12-14 | E12: 7 | F12: =(E11+E12)/2 -> 6.25 | G12: =(E12+E13)/2 -> 7.75 | H12: =G12-F12 -> 1.5 | I12: =DATOS!$C$29 -> 10.08 | J12: =H12*I12 -> 15.12 | K12: =DATOS!$C$8*H12 -> 28.98 | L12: =DATOS!$C$22*H12 -> 30 | M12: =DATOS!$C$23*H12 -> 0 | N12: =K12*I12/2 -> 146.0592 | O12: =L12*I12/2 -> 151.2 | P12: 323 356 TO 359 | Q12: .STD R1.3_3 · nodos 166 a 172 (Z = 700 cm)
B13: LT-6 | C13: Larguero de techo | D13: MC12-14 | E13: 8.5 | F13: =(E12+E13)/2 -> 7.75 | G13: =(E13+E14)/2 -> 9.25 | H13: =G13-F13 -> 1.5 | I13: =DATOS!$C$29 -> 10.08 | J13: =H13*I13 -> 15.12 | K13: =DATOS!$C$8*H13 -> 28.98 | L13: =DATOS!$C$22*H13 -> 30 | M13: =DATOS!$C$23*H13 -> 0 | N13: =K13*I13/2 -> 146.0592 | O13: =L13*I13/2 -> 151.2 | P13: 322 352 TO 355 | Q13: .STD R1.3_3 · nodos 165 a 171 (Z = 850 cm)
B14: VM-2 | C14: Viga de marco eje 2 | D14: MCE10-14 | E14: 10 | F14: =(E13+E14)/2 -> 9.25 | G14: =(E14+E15)/2 -> 10.75 | H14: =G14-F14 -> 1.5 | I14: =DATOS!$C$29 -> 10.08 | J14: =H14*I14 -> 15.12 | K14: =DATOS!$C$8*H14 -> 28.98 | L14: =DATOS!$C$22*H14 -> 30 | M14: =DATOS!$C$23*H14 -> 0 | N14: =K14*I14/2 -> 146.0592 | O14: =L14*I14/2 -> 151.2 | P14: 74 121 TO 124 | Q14: .STD R1.3_3 · nodos 75 a 76 (Z = 1000 cm)
B15: LT-7 | C15: Larguero de techo | D15: MC12-14 | E15: 11.5 | F15: =(E14+E15)/2 -> 10.75 | G15: =(E15+E16)/2 -> 12.25 | H15: =G15-F15 -> 1.5 | I15: =DATOS!$C$29 -> 10.08 | J15: =H15*I15 -> 15.12 | K15: =DATOS!$C$8*H15 -> 28.98 | L15: =DATOS!$C$22*H15 -> 30 | M15: =DATOS!$C$23*H15 -> 0 | N15: =K15*I15/2 -> 146.0592 | O15: =L15*I15/2 -> 151.2 | P15: 287 318 TO 321 | Q15: .STD R1.3_3 · nodos 133 a 136 (Z = 1150 cm)
B16: LT-8 | C16: Larguero de techo | D16: MC12-14 | E16: 13 | F16: =(E15+E16)/2 -> 12.25 | G16: =(E16+E17)/2 -> 13.75 | H16: =G16-F16 -> 1.5 | I16: =DATOS!$C$29 -> 10.08 | J16: =H16*I16 -> 15.12 | K16: =DATOS!$C$8*H16 -> 28.98 | L16: =DATOS!$C$22*H16 -> 30 | M16: =DATOS!$C$23*H16 -> 0 | N16: =K16*I16/2 -> 146.0592 | O16: =L16*I16/2 -> 151.2 | P16: 286 314 TO 317 | Q16: .STD R1.3_3 · nodos 134 a 137 (Z = 1300 cm)
B17: LT-9 | C17: Larguero de techo | D17: MC12-14 | E17: 14.5 | F17: =(E16+E17)/2 -> 13.75 | G17: =(E17+E18)/2 -> 15.25 | H17: =G17-F17 -> 1.5 | I17: =DATOS!$C$29 -> 10.08 | J17: =H17*I17 -> 15.12 | K17: =DATOS!$C$8*H17 -> 28.98 | L17: =DATOS!$C$22*H17 -> 30 | M17: =DATOS!$C$23*H17 -> 0 | N17: =K17*I17/2 -> 146.0592 | O17: =L17*I17/2 -> 151.2 | P17: 285 310 TO 313 | Q17: .STD R1.3_3 · nodos 135 a 138 (Z = 1450 cm)
B18: VM-3 | C18: Viga de marco eje 3 | D18: MCE6-14 | E18: 16 | F18: =(E17+E18)/2 -> 15.25 | G18: =E18 -> 16 | H18: =G18-F18 -> 0.75 | I18: =DATOS!$C$29 -> 10.08 | J18: =H18*I18 -> 7.56 | K18: =DATOS!$C$8*H18 -> 14.49 | L18: =DATOS!$C$22*H18 -> 15 | M18: =DATOS!$C$23*H18 -> 0 | N18: =K18*I18/2 -> 73.0296 | O18: =L18*I18/2 -> 75.6 | P18: 12 52 TO 55 | Q18: .STD R1.3_3 · nodos 9 a 10 (Z = 1600 cm)
B19: Total | C19: Suma de áreas de techo (debe dar claro × largo = 10.08 × 16.00) | J19: =SUM(J7:J18) -> 161.28 | K19: =IF(ABS(J19-DATOS!$C$29*(DATOS!$C$33-DATOS!$C$31))<0.01,"CUADRA","NO CUADRA") -> CUADRA
B21: B. VIGAS DE ALERO MCE12-14 (EJES A Y B) — RECIBEN LA MITAD DE CADA LARGUERO
B22: Área = franja en Z de los largueros que se le apoyan × mitad del claro de los largueros. Sirve para diseñar las vigas de alero.
B23: ID | C23: Eje y tramo | D23: Perfil | E23: Largueros que recibe | F23: Franja desde (m) | G23: Franja hasta (m) | H23: Ancho en Z (m) | I23: Ancho en X (m) | J23: A (m²) | K23: CM total (kg) | L23: CV total (kg) | M23: Nº de largueros | N23: R CM por larguero (kg) | O23: R CV por larguero (kg) | P23: Miembros STAAD | Q23: Referencia
F24: del 1er larguero | G24: del último larguero | H24: hasta − desde | I24: DATOS C30 | J24: Z × X | K24: CM techo × A | L24: w_m × A | N24: CM total ÷ Nº | O24: CV total ÷ Nº | P24: del .STD
B25: VA-1 | C25: Eje A, tramo 1-2 | D25: MCE12-14 | E25: LT-1 a LT-6 | F25: =F8 -> 0.5 | G25: =G13 -> 9.25 | H25: =G25-F25 -> 8.75 | I25: =DATOS!$C$30 -> 5.04 | J25: =H25*I25 -> 44.1 | K25: =DATOS!$C$8*J25 -> 852.012 | L25: =DATOS!$C$22*J25 -> 882 | M25: 6 | N25: =K25/M25 -> 142.002 | O25: =L25/M25 -> 147 | P25: 241 269 TO 274 | Q25: .STD R1.3_3 · X = 0 cm, Z 0 a 1000 cm
B26: VA-2 | C26: Eje A, tramo 2-3 | D26: MCE12-14 | E26: LT-7 a LT-9 | F26: =F15 -> 10.75 | G26: =G17 -> 15.25 | H26: =G26-F26 -> 4.5 | I26: =DATOS!$C$30 -> 5.04 | J26: =H26*I26 -> 22.68 | K26: =DATOS!$C$8*J26 -> 438.1776 | L26: =DATOS!$C$22*J26 -> 453.6 | M26: 3 | N26: =K26/M26 -> 146.0592 | O26: =L26/M26 -> 151.2 | P26: 243 245 TO 247 | Q26: .STD R1.3_3 · X = 0 cm, Z 1000 a 1600 cm
B27: VB-1 | C27: Eje B, tramo 1-2 | D27: MCE12-14 | E27: LT-1 a LT-6 | F27: =F8 -> 0.5 | G27: =G13 -> 9.25 | H27: =G27-F27 -> 8.75 | I27: =DATOS!$C$30 -> 5.04 | J27: =H27*I27 -> 44.1 | K27: =DATOS!$C$8*J27 -> 852.012 | L27: =DATOS!$C$22*J27 -> 882 | M27: 6 | N27: =K27/M27 -> 142.002 | O27: =L27/M27 -> 147 | P27: 242 275 TO 280 | Q27: .STD R1.3_3 · X = 1008 cm, Z 0 a 1000 cm
B28: VB-2 | C28: Eje B, tramo 2-3 | D28: MCE12-14 | E28: LT-7 a LT-9 | F28: =F15 -> 10.75 | G28: =G17 -> 15.25 | H28: =G28-F28 -> 4.5 | I28: =DATOS!$C$30 -> 5.04 | J28: =H28*I28 -> 22.68 | K28: =DATOS!$C$8*J28 -> 438.1776 | L28: =DATOS!$C$22*J28 -> 453.6 | M28: 3 | N28: =K28/M28 -> 146.0592 | O28: =L28/M28 -> 151.2 | P28: 244 248 TO 250 | Q28: .STD R1.3_3 · X = 1008 cm, Z 1000 a 1600 cm
B29: Total | C29: Vigas de alero + franjas directas de VM (debe dar el total del techo) | J29: =SUM(J25:J28)+J7+J14+J18 -> 161.28 | K29: =IF(ABS(J29-J19)<0.01,"CUADRA","NO CUADRA") -> CUADRA

Sheet MUROS
B1: MUROS — ÁREAS TRIBUTARIAS DE LARGUEROS DE MURO
B2: Elevaciones de los muros de los ejes A, B (laterales) y 1 (frontal). Franja de cada larguero = mitad de la distancia al miembro de abajo y al de arriba. Carga vertical de la lámina (CM de muros). El eje 3 (Z = 16 m) no tiene largueros en el modelo (frente abierto).
B4: A. MUROS LATERALES — EJE A (X = 0) Y EJE B (X = 10.08 m) — LARGUEROS MC10-12 (CLARO 1-2, 10 m), MC10-14 (CLARO 2-3, 6 m, Y A 9.00 m EN EL CLARO 1-2) Y MCC10-14 (A 9.45 m EN EL CLARO 1-2 Y A 9.00 m EN EL CLARO 2-3)
B5: ID | C5: Muro | D5: Nivel | E5: Y larguero (m) | F5: Tramo (ejes) | G5: L (m) | H5: Y abajo (m) | I5: Y arriba inicio (m) | J5: Y arriba fin (m) | K5: Franja desde (m) | L5: Franja hasta inicio (m) | M5: Franja hasta fin (m) | N5: h (m) | O5: A (m²) | P5: w CM (kg/m) | Q5: STAAD CM (kg/cm) | R5: Miembro STAAD | S5: Referencia
E6: del modelo | G6: del modelo | H6: miembro de abajo (0 = base) | I6: miembro de arriba | J6: miembro de arriba | K6: (Y ab. + Y)/2 | L6: (Y + Y arr.)/2 | M6: (Y + Y arr.)/2 | N6: promedio | O6: L × h | P6: CM muros × h | Q6: −w ÷ 100 | R6: del .STD
B7: LA-1.1 | C7: Eje A | D7: 1 | E7: 0.6 | F7: 1-2 | G7: =DATOS!$C$32-DATOS!$C$31 -> 10 | H7: 0 | I7: 1.8 | J7: 1.8 | K7: =(H7+E7)/2 -> 0.3 | L7: =(E7+I7)/2 -> 1.2 | M7: =(E7+J7)/2 -> 1.2 | N7: =(L7+M7)/2-K7 -> 0.9 | O7: =G7*N7 -> 9 | P7: =DATOS!$C$10*N7 -> 5.265 | Q7: =-P7/100 -> -0.05265 | R7: 16 501 TO 503 | S7: .STD R1.3_3 · nodos 11–12
B8: LA-1.2 | C8: Eje A | D8: 1 | E8: 0.6 | F8: 2-3 | G8: =DATOS!$C$33-DATOS!$C$32 -> 6 | H8: 0 | I8: 1.8 | J8: 1.8 | K8: =(H8+E8)/2 -> 0.3 | L8: =(E8+I8)/2 -> 1.2 | M8: =(E8+J8)/2 -> 1.2 | N8: =(L8+M8)/2-K8 -> 0.9 | O8: =G8*N8 -> 5.4 | P8: =DATOS!$C$10*N8 -> 5.265 | Q8: =-P8/100 -> -0.05265 | R8: 199 549 550 | S8: .STD R1.3_3 · nodos 12–13
B9: LA-2.1 | C9: Eje A | D9: 2 | E9: 1.8 | F9: 1-2 | G9: =DATOS!$C$32-DATOS!$C$31 -> 10 | H9: 0.6 | I9: 3 | J9: 3 | K9: =(H9+E9)/2 -> 1.2 | L9: =(E9+I9)/2 -> 2.4 | M9: =(E9+J9)/2 -> 2.4 | N9: =(L9+M9)/2-K9 -> 1.2 | O9: =G9*N9 -> 12 | P9: =DATOS!$C$10*N9 -> 7.02 | Q9: =-P9/100 -> -0.0702 | R9: 20 507 TO 509 | S9: .STD R1.3_3 · nodos 17–18
B10: LA-2.2 | C10: Eje A | D10: 2 | E10: 1.8 | F10: 2-3 | G10: =DATOS!$C$33-DATOS!$C$32 -> 6 | H10: 0.6 | I10: 3 | J10: 3 | K10: =(H10+E10)/2 -> 1.2 | L10: =(E10+I10)/2 -> 2.4 | M10: =(E10+J10)/2 -> 2.4 | N10: =(L10+M10)/2-K10 -> 1.2 | O10: =G10*N10 -> 7.2 | P10: =DATOS!$C$10*N10 -> 7.02 | Q10: =-P10/100 -> -0.0702 | R10: 201 553 554 | S10: .STD R1.3_3 · nodos 18–19
B11: LA-3.1 | C11: Eje A | D11: 3 | E11: 3 | F11: 1-2 | G11: =DATOS!$C$32-DATOS!$C$31 -> 10 | H11: 1.8 | I11: 4.2 | J11: 4.2 | K11: =(H11+E11)/2 -> 2.4 | L11: =(E11+I11)/2 -> 3.6 | M11: =(E11+J11)/2 -> 3.6 | N11: =(L11+M11)/2-K11 -> 1.2 | O11: =G11*N11 -> 12 | P11: =DATOS!$C$10*N11 -> 7.02 | Q11: =-P11/100 -> -0.0702 | R11: 24 513 TO 515 | S11: .STD R1.3_3 · nodos 23–24
B12: LA-3.2 | C12: Eje A | D12: 3 | E12: 3 | F12: 2-3 | G12: =DATOS!$C$33-DATOS!$C$32 -> 6 | H12: 1.8 | I12: 4.2 | J12: 4.2 | K12: =(H12+E12)/2 -> 2.4 | L12: =(E12+I12)/2 -> 3.6 | M12: =(E12+J12)/2 -> 3.6 | N12: =(L12+M12)/2-K12 -> 1.2 | O12: =G12*N12 -> 7.2 | P12: =DATOS!$C$10*N12 -> 7.02 | Q12: =-P12/100 -> -0.0702 | R12: 205 557 558 | S12: .STD R1.3_3 · nodos 24–25
B13: LA-4.1 | C13: Eje A | D13: 4 | E13: 4.2 | F13: 1-2 | G13: =DATOS!$C$32-DATOS!$C$31 -> 10 | H13: 3 | I13: 5.4 | J13: 5.4 | K13: =(H13+E13)/2 -> 3.6 | L13: =(E13+I13)/2 -> 4.8 | M13: =(E13+J13)/2 -> 4.8 | N13: =(L13+M13)/2-K13 -> 1.2 | O13: =G13*N13 -> 12 | P13: =DATOS!$C$10*N13 -> 7.02 | Q13: =-P13/100 -> -0.0702 | R13: 28 519 TO 521 | S13: .STD R1.3_3 · nodos 29–30
B14: LA-4.2 | C14: Eje A | D14: 4 | E14: 4.2 | F14: 2-3 | G14: =DATOS!$C$33-DATOS!$C$32 -> 6 | H14: 3 | I14: 5.4 | J14: 5.4 | K14: =(H14+E14)/2 -> 3.6 | L14: =(E14+I14)/2 -> 4.8 | M14: =(E14+J14)/2 -> 4.8 | N14: =(L14+M14)/2-K14 -> 1.2 | O14: =G14*N14 -> 7.2 | P14: =DATOS!$C$10*N14 -> 7.02 | Q14: =-P14/100 -> -0.0702 | R14: 207 561 562 | S14: .STD R1.3_3 · nodos 30–31
B15: LA-5.1 | C15: Eje A | D15: 5 | E15: 5.4 | F15: 1-2 | G15: =DATOS!$C$32-DATOS!$C$31 -> 10 | H15: 4.2 | I15: 6.6 | J15: 6.6 | K15: =(H15+E15)/2 -> 4.8 | L15: =(E15+I15)/2 -> 6 | M15: =(E15+J15)/2 -> 6 | N15: =(L15+M15)/2-K15 -> 1.2 | O15: =G15*N15 -> 12 | P15: =DATOS!$C$10*N15 -> 7.02 | Q15: =-P15/100 -> -0.0702 | R15: 32 525 TO 527 | S15: .STD R1.3_3 · nodos 35–36
B16: LA-5.2 | C16: Eje A | D16: 5 | E16: 5.4 | F16: 2-3 | G16: =DATOS!$C$33-DATOS!$C$32 -> 6 | H16: 4.2 | I16: 6.6 | J16: 6.6 | K16: =(H16+E16)/2 -> 4.8 | L16: =(E16+I16)/2 -> 6 | M16: =(E16+J16)/2 -> 6 | N16: =(L16+M16)/2-K16 -> 1.2 | O16: =G16*N16 -> 7.2 | P16: =DATOS!$C$10*N16 -> 7.02 | Q16: =-P16/100 -> -0.0702 | R16: 209 565 566 | S16: .STD R1.3_3 · nodos 36–37
B17: LA-6.1 | C17: Eje A | D17: 6 | E17: 6.6 | F17: 1-2 | G17: =DATOS!$C$32-DATOS!$C$31 -> 10 | H17: 5.4 | I17: 7.8 | J17: 7.8 | K17: =(H17+E17)/2 -> 6 | L17: =(E17+I17)/2 -> 7.2 | M17: =(E17+J17)/2 -> 7.2 | N17: =(L17+M17)/2-K17 -> 1.2 | O17: =G17*N17 -> 12 | P17: =DATOS!$C$10*N17 -> 7.02 | Q17: =-P17/100 -> -0.0702 | R17: 36 531 TO 533 | S17: .STD R1.3_3 · nodos 41–42
B18: LA-6.2 | C18: Eje A | D18: 6 | E18: 6.6 | F18: 2-3 | G18: =DATOS!$C$33-DATOS!$C$32 -> 6 | H18: 5.4 | I18: 7.8 | J18: 7.8 | K18: =(H18+E18)/2 -> 6 | L18: =(E18+I18)/2 -> 7.2 | M18: =(E18+J18)/2 -> 7.2 | N18: =(L18+M18)/2-K18 -> 1.2 | O18: =G18*N18 -> 7.2 | P18: =DATOS!$C$10*N18 -> 7.02 | Q18: =-P18/100 -> -0.0702 | R18: 211 569 570 | S18: .STD R1.3_3 · nodos 42–43
B19: LA-7.1 | C19: Eje A | D19: 7 | E19: 7.8 | F19: 1-2 | G19: =DATOS!$C$32-DATOS!$C$31 -> 10 | H19: 6.6 | I19: 9 | J19: 9 | K19: =(H19+E19)/2 -> 7.2 | L19: =(E19+I19)/2 -> 8.4 | M19: =(E19+J19)/2 -> 8.4 | N19: =(L19+M19)/2-K19 -> 1.2 | O19: =G19*N19 -> 12 | P19: =DATOS!$C$10*N19 -> 7.02 | Q19: =-P19/100 -> -0.0702 | R19: 40 537 TO 539 | S19: .STD R1.3_3 · nodos 47–48
B20: LA-7.2 | C20: Eje A | D20: 7 | E20: 7.8 | F20: 2-3 | G20: =DATOS!$C$33-DATOS!$C$32 -> 6 | H20: 6.6 | I20: 9 | J20: 9 | K20: =(H20+E20)/2 -> 7.2 | L20: =(E20+I20)/2 -> 8.4 | M20: =(E20+J20)/2 -> 8.4 | N20: =(L20+M20)/2-K20 -> 1.2 | O20: =G20*N20 -> 7.2 | P20: =DATOS!$C$10*N20 -> 7.02 | Q20: =-P20/100 -> -0.0702 | R20: 213 573 574 | S20: .STD R1.3_3 · nodos 48–49
B21: LA-8.1 | C21: Eje A | D21: 8 | E21: 9 | F21: 1-2 | G21: =DATOS!$C$32-DATOS!$C$31 -> 10 | H21: 7.8 | I21: 9.45 | J21: 9.45 | K21: =(H21+E21)/2 -> 8.4 | L21: =(E21+I21)/2 -> 9.225 | M21: =(E21+J21)/2 -> 9.225 | N21: =(L21+M21)/2-K21 -> 0.825 | O21: =G21*N21 -> 8.25 | P21: =DATOS!$C$10*N21 -> 4.82625 | Q21: =-P21/100 -> -0.0482625 | R21: 44 543 TO 545 | S21: .STD R1.3_3 · nodos 53–131 · arriba: larguero de 9.45 m
B22: LA-8.2 | C22: Eje A | D22: 8 | E22: 9 | F22: 2-3 | G22: =DATOS!$C$33-DATOS!$C$32 -> 6 | H22: 7.8 | I22: =DATOS!$C$34 -> 9.91126 | J22: =DATOS!$C$16 -> 9.60002 | K22: =(H22+E22)/2 -> 8.4 | L22: =(E22+I22)/2 -> 9.45563 | M22: =(E22+J22)/2 -> 9.30001 | N22: =(L22+M22)/2-K22 -> 0.97782 | O22: =G22*N22 -> 5.86692 | P22: =DATOS!$C$10*N22 -> 5.720247 | Q22: =-P22/100 -> -0.05720247 | R22: 215 577 578 | S22: .STD R1.3_3 · nodos 131–54 · arriba: alero inclinado
B23: LA-9.1 | C23: Eje A | D23: 9 | E23: 9.45 | F23: 1-2 | G23: =DATOS!$C$32-DATOS!$C$31 -> 10 | H23: 9 | I23: =DATOS!$C$15 -> 10.43 | J23: =DATOS!$C$34 -> 9.91126 | K23: =(H23+E23)/2 -> 9.225 | L23: =(E23+I23)/2 -> 9.94 | M23: =(E23+J23)/2 -> 9.68063 | N23: =(L23+M23)/2-K23 -> 0.585315 | O23: =G23*N23 -> 5.85315 | P23: =DATOS!$C$10*N23 -> 3.4240927 | Q23: =-P23/100 -> -0.034240927 | R23: 844 870 TO 872 | S23: .STD R1.3_3 · nodos 435–437 · arriba: alero inclinado
B24: LB-1.1 | C24: Eje B | D24: 1 | E24: 0.6 | F24: 1-2 | G24: =DATOS!$C$32-DATOS!$C$31 -> 10 | H24: 0 | I24: 1.8 | J24: 1.8 | K24: =(H24+E24)/2 -> 0.3 | L24: =(E24+I24)/2 -> 1.2 | M24: =(E24+J24)/2 -> 1.2 | N24: =(L24+M24)/2-K24 -> 0.9 | O24: =G24*N24 -> 9 | P24: =DATOS!$C$10*N24 -> 5.265 | Q24: =-P24/100 -> -0.05265 | R24: 17 504 TO 506 | S24: .STD R1.3_3 · nodos 14–15
B25: LB-1.2 | C25: Eje B | D25: 1 | E25: 0.6 | F25: 2-3 | G25: =DATOS!$C$33-DATOS!$C$32 -> 6 | H25: 0 | I25: 1.8 | J25: 1.8 | K25: =(H25+E25)/2 -> 0.3 | L25: =(E25+I25)/2 -> 1.2 | M25: =(E25+J25)/2 -> 1.2 | N25: =(L25+M25)/2-K25 -> 0.9 | O25: =G25*N25 -> 5.4 | P25: =DATOS!$C$10*N25 -> 5.265 | Q25: =-P25/100 -> -0.05265 | R25: 200 551 552 | S25: .STD R1.3_3 · nodos 15–16
B26: LB-2.1 | C26: Eje B | D26: 2 | E26: 1.8 | F26: 1-2 | G26: =DATOS!$C$32-DATOS!$C$31 -> 10 | H26: 0.6 | I26: 3 | J26: 3 | K26: =(H26+E26)/2 -> 1.2 | L26: =(E26+I26)/2 -> 2.4 | M26: =(E26+J26)/2 -> 2.4 | N26: =(L26+M26)/2-K26 -> 1.2 | O26: =G26*N26 -> 12 | P26: =DATOS!$C$10*N26 -> 7.02 | Q26: =-P26/100 -> -0.0702 | R26: 21 510 TO 512 | S26: .STD R1.3_3 · nodos 20–21
B27: LB-2.2 | C27: Eje B | D27: 2 | E27: 1.8 | F27: 2-3 | G27: =DATOS!$C$33-DATOS!$C$32 -> 6 | H27: 0.6 | I27: 3 | J27: 3 | K27: =(H27+E27)/2 -> 1.2 | L27: =(E27+I27)/2 -> 2.4 | M27: =(E27+J27)/2 -> 2.4 | N27: =(L27+M27)/2-K27 -> 1.2 | O27: =G27*N27 -> 7.2 | P27: =DATOS!$C$10*N27 -> 7.02 | Q27: =-P27/100 -> -0.0702 | R27: 202 555 556 | S27: .STD R1.3_3 · nodos 21–22
B28: LB-3.1 | C28: Eje B | D28: 3 | E28: 3 | F28: 1-2 | G28: =DATOS!$C$32-DATOS!$C$31 -> 10 | H28: 1.8 | I28: 4.2 | J28: 4.2 | K28: =(H28+E28)/2 -> 2.4 | L28: =(E28+I28)/2 -> 3.6 | M28: =(E28+J28)/2 -> 3.6 | N28: =(L28+M28)/2-K28 -> 1.2 | O28: =G28*N28 -> 12 | P28: =DATOS!$C$10*N28 -> 7.02 | Q28: =-P28/100 -> -0.0702 | R28: 25 516 TO 518 | S28: .STD R1.3_3 · nodos 26–27
B29: LB-3.2 | C29: Eje B | D29: 3 | E29: 3 | F29: 2-3 | G29: =DATOS!$C$33-DATOS!$C$32 -> 6 | H29: 1.8 | I29: 4.2 | J29: 4.2 | K29: =(H29+E29)/2 -> 2.4 | L29: =(E29+I29)/2 -> 3.6 | M29: =(E29+J29)/2 -> 3.6 | N29: =(L29+M29)/2-K29 -> 1.2 | O29: =G29*N29 -> 7.2 | P29: =DATOS!$C$10*N29 -> 7.02 | Q29: =-P29/100 -> -0.0702 | R29: 206 559 560 | S29: .STD R1.3_3 · nodos 27–28
B30: LB-4.1 | C30: Eje B | D30: 4 | E30: 4.2 | F30: 1-2 | G30: =DATOS!$C$32-DATOS!$C$31 -> 10 | H30: 3 | I30: 5.4 | J30: 5.4 | K30: =(H30+E30)/2 -> 3.6 | L30: =(E30+I30)/2 -> 4.8 | M30: =(E30+J30)/2 -> 4.8 | N30: =(L30+M30)/2-K30 -> 1.2 | O30: =G30*N30 -> 12 | P30: =DATOS!$C$10*N30 -> 7.02 | Q30: =-P30/100 -> -0.0702 | R30: 29 522 TO 524 | S30: .STD R1.3_3 · nodos 32–33
B31: LB-4.2 | C31: Eje B | D31: 4 | E31: 4.2 | F31: 2-3 | G31: =DATOS!$C$33-DATOS!$C$32 -> 6 | H31: 3 | I31: 5.4 | J31: 5.4 | K31: =(H31+E31)/2 -> 3.6 | L31: =(E31+I31)/2 -> 4.8 | M31: =(E31+J31)/2 -> 4.8 | N31: =(L31+M31)/2-K31 -> 1.2 | O31: =G31*N31 -> 7.2 | P31: =DATOS!$C$10*N31 -> 7.02 | Q31: =-P31/100 -> -0.0702 | R31: 208 563 564 | S31: .STD R1.3_3 · nodos 33–34
B32: LB-5.1 | C32: Eje B | D32: 5 | E32: 5.4 | F32: 1-2 | G32: =DATOS!$C$32-DATOS!$C$31 -> 10 | H32: 4.2 | I32: 6.6 | J32: 6.6 | K32: =(H32+E32)/2 -> 4.8 | L32: =(E32+I32)/2 -> 6 | M32: =(E32+J32)/2 -> 6 | N32: =(L32+M32)/2-K32 -> 1.2 | O32: =G32*N32 -> 12 | P32: =DATOS!$C$10*N32 -> 7.02 | Q32: =-P32/100 -> -0.0702 | R32: 33 528 TO 530 | S32: .STD R1.3_3 · nodos 38–39
B33: LB-5.2 | C33: Eje B | D33: 5 | E33: 5.4 | F33: 2-3 | G33: =DATOS!$C$33-DATOS!$C$32 -> 6 | H33: 4.2 | I33: 6.6 | J33: 6.6 | K33: =(H33+E33)/2 -> 4.8 | L33: =(E33+I33)/2 -> 6 | M33: =(E33+J33)/2 -> 6 | N33: =(L33+M33)/2-K33 -> 1.2 | O33: =G33*N33 -> 7.2 | P33: =DATOS!$C$10*N33 -> 7.02 | Q33: =-P33/100 -> -0.0702 | R33: 210 567 568 | S33: .STD R1.3_3 · nodos 39–40
B34: LB-6.1 | C34: Eje B | D34: 6 | E34: 6.6 | F34: 1-2 | G34: =DATOS!$C$32-DATOS!$C$31 -> 10 | H34: 5.4 | I34: 7.8 | J34: 7.8 | K34: =(H34+E34)/2 -> 6 | L34: =(E34+I34)/2 -> 7.2 | M34: =(E34+J34)/2 -> 7.2 | N34: =(L34+M34)/2-K34 -> 1.2 | O34: =G34*N34 -> 12 | P34: =DATOS!$C$10*N34 -> 7.02 | Q34: =-P34/100 -> -0.0702 | R34: 37 534 TO 536 | S34: .STD R1.3_3 · nodos 44–45
B35: LB-6.2 | C35: Eje B | D35: 6 | E35: 6.6 | F35: 2-3 | G35: =DATOS!$C$33-DATOS!$C$32 -> 6 | H35: 5.4 | I35: 7.8 | J35: 7.8 | K35: =(H35+E35)/2 -> 6 | L35: =(E35+I35)/2 -> 7.2 | M35: =(E35+J35)/2 -> 7.2 | N35: =(L35+M35)/2-K35 -> 1.2 | O35: =G35*N35 -> 7.2 | P35: =DATOS!$C$10*N35 -> 7.02 | Q35: =-P35/100 -> -0.0702 | R35: 212 571 572 | S35: .STD R1.3_3 · nodos 45–46
B36: LB-7.1 | C36: Eje B | D36: 7 | E36: 7.8 | F36: 1-2 | G36: =DATOS!$C$32-DATOS!$C$31 -> 10 | H36: 6.6 | I36: 9 | J36: 9 | K36: =(H36+E36)/2 -> 7.2 | L36: =(E36+I36)/2 -> 8.4 | M36: =(E36+J36)/2 -> 8.4 | N36: =(L36+M36)/2-K36 -> 1.2 | O36: =G36*N36 -> 12 | P36: =DATOS!$C$10*N36 -> 7.02 | Q36: =-P36/100 -> -0.0702 | R36: 41 540 TO 542 | S36: .STD R1.3_3 · nodos 50–51
B37: LB-7.2 | C37: Eje B | D37: 7 | E37: 7.8 | F37: 2-3 | G37: =DATOS!$C$33-DATOS!$C$32 -> 6 | H37: 6.6 | I37: 9 | J37: 9 | K37: =(H37+E37)/2 -> 7.2 | L37: =(E37+I37)/2 -> 8.4 | M37: =(E37+J37)/2 -> 8.4 | N37: =(L37+M37)/2-K37 -> 1.2 | O37: =G37*N37 -> 7.2 | P37: =DATOS!$C$10*N37 -> 7.02 | Q37: =-P37/100 -> -0.0702 | R37: 214 575 576 | S37: .STD R1.3_3 · nodos 51–52
B38: LB-8.1 | C38: Eje B | D38: 8 | E38: 9 | F38: 1-2 | G38: =DATOS!$C$32-DATOS!$C$31 -> 10 | H38: 7.8 | I38: 9.45 | J38: 9.45 | K38: =(H38+E38)/2 -> 8.4 | L38: =(E38+I38)/2 -> 9.225 | M38: =(E38+J38)/2 -> 9.225 | N38: =(L38+M38)/2-K38 -> 0.825 | O38: =G38*N38 -> 8.25 | P38: =DATOS!$C$10*N38 -> 4.82625 | Q38: =-P38/100 -> -0.0482625 | R38: 45 546 TO 548 | S38: .STD R1.3_3 · nodos 55–132 · arriba: larguero de 9.45 m
B39: LB-8.2 | C39: Eje B | D39: 8 | E39: 9 | F39: 2-3 | G39: =DATOS!$C$33-DATOS!$C$32 -> 6 | H39: 7.8 | I39: =DATOS!$C$34 -> 9.91126 | J39: =DATOS!$C$16 -> 9.60002 | K39: =(H39+E39)/2 -> 8.4 | L39: =(E39+I39)/2 -> 9.45563 | M39: =(E39+J39)/2 -> 9.30001 | N39: =(L39+M39)/2-K39 -> 0.97782 | O39: =G39*N39 -> 5.86692 | P39: =DATOS!$C$10*N39 -> 5.720247 | Q39: =-P39/100 -> -0.05720247 | R39: 216 579 580 | S39: .STD R1.3_3 · nodos 132–56 · arriba: alero inclinado
B40: LB-9.1 | C40: Eje B | D40: 9 | E40: 9.45 | F40: 1-2 | G40: =DATOS!$C$32-DATOS!$C$31 -> 10 | H40: 9 | I40: =DATOS!$C$15 -> 10.43 | J40: =DATOS!$C$34 -> 9.91126 | K40: =(H40+E40)/2 -> 9.225 | L40: =(E40+I40)/2 -> 9.94 | M40: =(E40+J40)/2 -> 9.68063 | N40: =(L40+M40)/2-K40 -> 0.585315 | O40: =G40*N40 -> 5.85315 | P40: =DATOS!$C$10*N40 -> 3.4240927 | Q40: =-P40/100 -> -0.034240927 | R40: 843 867 TO 869 | S40: .STD R1.3_3 · nodos 436–438 · arriba: alero inclinado
B41: Total | C41: Área de muros laterales en largueros (ejes A y B) | O41: =SUM(O7:O40) -> 299.14014
...

Sheet NODOS_TECHO
B1: NODOS DE COLUMNA — TECHO: ÁREA TRIBUTARIA Y MASA SÍSMICA PUNTUAL (CASO 4)
B2: El techo se reparte a los 6 nodos de cabeza de columna: mitad del claro en X × mitad entre marcos en Z. Esta hoja da la masa sísmica del techo (JOINT LOAD FX y FZ); la CM y la CV van repartidas en largueros y vigas (hoja TECHO).
B4: A. TECHO → NODOS DE CABEZA DE COLUMNA
B5: ID | C5: Nodo STAAD | D5: Eje | E5: Lado | F5: X desde (m) | G5: X hasta (m) | H5: Z desde (m) | I5: Z hasta (m) | J5: A (m²) | K5: CM techo (kg) | L5: w_i techo (kg) | M5: Masa techo (kg) | N5: CV techo (kg) | O5: Línea STAAD caso 4 (masa) | P5: Nota | Q5: Referencia
C6: del .STD | F6: mitad del claro | G6: mitad / claro | H6: (Z ant. + Z)/2 | I6: (Z + Z sig.)/2 | J6: ΔX × ΔZ | K6: CM techo × A | L6: w_i × A | M6: K + L | N6: w_m × A | O6: nodo FX M FZ M
B7: T-1A | C7: 7 | D7: 1 | E7: A | F7: 0 | G7: =DATOS!$C$30 -> 5.04 | H7: =DATOS!$C$31 -> 0 | I7: =(DATOS!$C$31+DATOS!$C$32)/2 -> 5 | J7: =(G7-F7)*(I7-H7) -> 25.2 | K7: =DATOS!$C$8*J7 -> 486.864 | L7: =DATOS!$C$23*J7 -> 0 | M7: =K7+L7 -> 486.864 | N7: =DATOS!$C$22*J7 -> 504 | O7: =C7&" FX "&TEXT(M7,"0.00")&" FZ "&TEXT(M7,"0.00") -> 7 FX 486.86 FZ 486.86 | P7: La CM y la CV van en largueros (hoja TECHO) | Q7: Área tributaria (mitades) · masa sísmica del techo (caso 4)
B8: T-1B | C8: 8 | D8: 1 | E8: B | F8: =DATOS!$C$30 -> 5.04 | G8: =DATOS!$C$29 -> 10.08 | H8: =DATOS!$C$31 -> 0 | I8: =(DATOS!$C$31+DATOS!$C$32)/2 -> 5 | J8: =(G8-F8)*(I8-H8) -> 25.2 | K8: =DATOS!$C$8*J8 -> 486.864 | L8: =DATOS!$C$23*J8 -> 0 | M8: =K8+L8 -> 486.864 | N8: =DATOS!$C$22*J8 -> 504 | O8: =C8&" FX "&TEXT(M8,"0.00")&" FZ "&TEXT(M8,"0.00") -> 8 FX 486.86 FZ 486.86 | P8: La CM y la CV van en largueros (hoja TECHO) | Q8: Área tributaria (mitades) · masa sísmica del techo (caso 4)
B9: T-2A | C9: 75 | D9: 2 | E9: A | F9: 0 | G9: =DATOS!$C$30 -> 5.04 | H9: =(DATOS!$C$31+DATOS!$C$32)/2 -> 5 | I9: =(DATOS!$C$32+DATOS!$C$33)/2 -> 13 | J9: =(G9-F9)*(I9-H9) -> 40.32 | K9: =DATOS!$C$8*J9 -> 778.9824 | L9: =DATOS!$C$23*J9 -> 0 | M9: =K9+L9 -> 778.9824 | N9: =DATOS!$C$22*J9 -> 806.4 | O9: =C9&" FX "&TEXT(M9,"0.00")&" FZ "&TEXT(M9,"0.00") -> 75 FX 778.98 FZ 778.98 | P9: La CM y la CV van en largueros (hoja TECHO) | Q9: Área tributaria (mitades) · masa sísmica del techo (caso 4)
B10: T-2B | C10: 76 | D10: 2 | E10: B | F10: =DATOS!$C$30 -> 5.04 | G10: =DATOS!$C$29 -> 10.08 | H10: =(DATOS!$C$31+DATOS!$C$32)/2 -> 5 | I10: =(DATOS!$C$32+DATOS!$C$33)/2 -> 13 | J10: =(G10-F10)*(I10-H10) -> 40.32 | K10: =DATOS!$C$8*J10 -> 778.9824 | L10: =DATOS!$C$23*J10 -> 0 | M10: =K10+L10 -> 778.9824 | N10: =DATOS!$C$22*J10 -> 806.4 | O10: =C10&" FX "&TEXT(M10,"0.00")&" FZ "&TEXT(M10,"0.00") -> 76 FX 778.98 FZ 778.98 | P10: La CM y la CV van en largueros (hoja TECHO) | Q10: Área tributaria (mitades) · masa sísmica del techo (caso 4)
B11: T-3A | C11: 9 | D11: 3 | E11: A | F11: 0 | G11: =DATOS!$C$30 -> 5.04 | H11: =(DATOS!$C$32+DATOS!$C$33)/2 -> 13 | I11: =DATOS!$C$33 -> 16 | J11: =(G11-F11)*(I11-H11) -> 15.12 | K11: =DATOS!$C$8*J11 -> 292.1184 | L11: =DATOS!$C$23*J11 -> 0 | M11: =K11+L11 -> 292.1184 | N11: =DATOS!$C$22*J11 -> 302.4 | O11: =C11&" FX "&TEXT(M11,"0.00")&" FZ "&TEXT(M11,"0.00") -> 9 FX 292.12 FZ 292.12 | P11: La CM y la CV van en largueros (hoja TECHO) | Q11: Área tributaria (mitades) · masa sísmica del techo (caso 4)
B12: T-3B | C12: 10 | D12: 3 | E12: B | F12: =DATOS!$C$30 -> 5.04 | G12: =DATOS!$C$29 -> 10.08 | H12: =(DATOS!$C$32+DATOS!$C$33)/2 -> 13 | I12: =DATOS!$C$33 -> 16 | J12: =(G12-F12)*(I12-H12) -> 15.12 | K12: =DATOS!$C$8*J12 -> 292.1184 | L12: =DATOS!$C$23*J12 -> 0 | M12: =K12+L12 -> 292.1184 | N12: =DATOS!$C$22*J12 -> 302.4 | O12: =C12&" FX "&TEXT(M12,"0.00")&" FZ "&TEXT(M12,"0.00") -> 10 FX 292.12 FZ 292.12 | P12: La CM y la CV van en largueros (hoja TECHO) | Q12: Área tributaria (mitades) · masa sísmica del techo (caso 4)
B13: Total | C13: Suma de áreas de techo (debe dar claro × largo = 10.08 × 16.00) | J13: =SUM(J7:J12) -> 161.28 | K13: =SUM(K7:K12) -> 3115.9296 | L13: =SUM(L7:L12) -> 0 | M13: =SUM(M7:M12) -> 3115.9296 | N13: =SUM(N7:N12) -> 3225.6 | Q13: =IF(AND(ABS(J13-TECHO!$J$19)<0.01,ABS(N13-RESUMEN!$C$16)<0.5),"CUADRA","NO CUADRA") -> CUADRA

Sheet NODOS_MUROS
B1: NODOS DE COLUMNA — MUROS: ÁREA TRIBUTARIA POR NODO (SÓLO REFERENCIA)
B2: En R1.3_3 la masa de los muros va concentrada en las cabezas de columna (hoja STAAD, caso 4). Esta tabla da la parte de lámina por nodo de columna, como referencia.
B4: A. PANELES DE MURO → NODOS DE COLUMNA DE SUS EXTREMOS
B5: ID | C5: Muro | D5: Nivel | E5: Nodo A | F5: Nodo B | G5: L (m) | H5: h en A (m) | I5: h en B (m) | J5: A (m²) | K5: Masa (kg) | L5: Referencia
E6: del .STD | F6: del .STD | G6: del modelo | H6: franja en el nodo A | I6: franja en el nodo B | J6: L × (h A + h B) ÷ 2 | K6: CM muros × A
B7: LA-1.1 | C7: Eje A (X = 0) | D7: 1 | E7: 11 | F7: 12 | G7: 10 | H7: 0.9 | I7: 0.9 | J7: =G7*(H7+I7)/2 -> 9 | K7: =DATOS!$C$10*J7 -> 52.65 | L7: Franja de LA-1.1 (hoja MUROS) · .STD R1.3_3
B8: LA-1.2 | C8: Eje A (X = 0) | D8: 1 | E8: 12 | F8: 13 | G8: 6 | H8: 0.9 | I8: 0.9 | J8: =G8*(H8+I8)/2 -> 5.4 | K8: =DATOS!$C$10*J8 -> 31.59 | L8: Franja de LA-1.2 (hoja MUROS) · .STD R1.3_3
B9: LA-2.1 | C9: Eje A (X = 0) | D9: 2 | E9: 17 | F9: 18 | G9: 10 | H9: 1.2 | I9: 1.2 | J9: =G9*(H9+I9)/2 -> 12 | K9: =DATOS!$C$10*J9 -> 70.2 | L9: Franja de LA-2.1 (hoja MUROS) · .STD R1.3_3
B10: LA-2.2 | C10: Eje A (X = 0) | D10: 2 | E10: 18 | F10: 19 | G10: 6 | H10: 1.2 | I10: 1.2 | J10: =G10*(H10+I10)/2 -> 7.2 | K10: =DATOS!$C$10*J10 -> 42.12 | L10: Franja de LA-2.2 (hoja MUROS) · .STD R1.3_3
B11: LA-3.1 | C11: Eje A (X = 0) | D11: 3 | E11: 23 | F11: 24 | G11: 10 | H11: 1.2 | I11: 1.2 | J11: =G11*(H11+I11)/2 -> 12 | K11: =DATOS!$C$10*J11 -> 70.2 | L11: Franja de LA-3.1 (hoja MUROS) · .STD R1.3_3
B12: LA-3.2 | C12: Eje A (X = 0) | D12: 3 | E12: 24 | F12: 25 | G12: 6 | H12: 1.2 | I12: 1.2 | J12: =G12*(H12+I12)/2 -> 7.2 | K12: =DATOS!$C$10*J12 -> 42.12 | L12: Franja de LA-3.2 (hoja MUROS) · .STD R1.3_3
B13: LA-4.1 | C13: Eje A (X = 0) | D13: 4 | E13: 29 | F13: 30 | G13: 10 | H13: 1.2 | I13: 1.2 | J13: =G13*(H13+I13)/2 -> 12 | K13: =DATOS!$C$10*J13 -> 70.2 | L13: Franja de LA-4.1 (hoja MUROS) · .STD R1.3_3
B14: LA-4.2 | C14: Eje A (X = 0) | D14: 4 | E14: 30 | F14: 31 | G14: 6 | H14: 1.2 | I14: 1.2 | J14: =G14*(H14+I14)/2 -> 7.2 | K14: =DATOS!$C$10*J14 -> 42.12 | L14: Franja de LA-4.2 (hoja MUROS) · .STD R1.3_3
B15: LA-5.1 | C15: Eje A (X = 0) | D15: 5 | E15: 35 | F15: 36 | G15: 10 | H15: 1.2 | I15: 1.2 | J15: =G15*(H15+I15)/2 -> 12 | K15: =DATOS!$C$10*J15 -> 70.2 | L15: Franja de LA-5.1 (hoja MUROS) · .STD R1.3_3
B16: LA-5.2 | C16: Eje A (X = 0) | D16: 5 | E16: 36 | F16: 37 | G16: 6 | H16: 1.2 | I16: 1.2 | J16: =G16*(H16+I16)/2 -> 7.2 | K16: =DATOS!$C$10*J16 -> 42.12 | L16: Franja de LA-5.2 (hoja MUROS) · .STD R1.3_3
B17: LA-6.1 | C17: Eje A (X = 0) | D17: 6 | E17: 41 | F17: 42 | G17: 10 | H17: 1.2 | I17: 1.2 | J17: =G17*(H17+I17)/2 -> 12 | K17: =DATOS!$C$10*J17 -> 70.2 | L17: Franja de LA-6.1 (hoja MUROS) · .STD R1.3_3
B18: LA-6.2 | C18: Eje A (X = 0) | D18: 6 | E18: 42 | F18: 43 | G18: 6 | H18: 1.2 | I18: 1.2 | J18: =G18*(H18+I18)/2 -> 7.2 | K18: =DATOS!$C$10*J18 -> 42.12 | L18: Franja de LA-6.2 (hoja MUROS) · .STD R1.3_3
... B44: LB-T.2 | C44: Eje B (X = 10.08 m) | D44: 10 | E44: 76 | F44: 10 | G44: 6 | H44: 0.45563 | I44: 0.30001 | J44: =G44*(H44+I44)/2 -> 2.26692 | K44: =DATOS!$C$10*J44 -> 13.261482 | L44: Franja superior (mitad entre último larguero y alero) → cabeza de columna · .STD R1.3_3
B45: Total | C45: Muros laterales (debe dar tabla A + tabla B de MUROS) | J45: =SUM(J7:J44) -> 310.88028 | K45: =SUM(K7:K44) -> 1818.6496 | L45: =IF(ABS(J45-MUROS!$O$41-MUROS!$O$69)<0.01,"CUADRA","NO CUADRA") -> CUADRA

Sheet STAAD
B1: LÍNEAS DE CARGA PARA STAAD (kg/cm y kg) — LAS QUE VAN EN EL .STD R1.3_3
B2: Armadas desde TECHO, MUROS, NODOS_TECHO y DATOS con las áreas tributarias del DXF R1.3_3. En R1.3_3 la masa sísmica de cubierta y muros va concentrada en las cabezas de columna (caso 4). El viento está en 002_SISMO_VIENTO_SALVADOR_R1.3_3.xlsx.
B4: CASO 1 — CARGA MUERTA (debajo de SELFWEIGHT Y -1): TECHO EN LARGUEROS Y VIGAS + MUROS EN LARGUEROS + CORTINA
B5: ID | C5: Origen | D5: Línea para STAAD | E5: Nota | F5: Revisión
B6: — | C6: — | D6: MEMBER LOAD | E6: Encabezado | F6: =IF(LEN($D6)>79,"MÁS DE 79","")
B7: LT-2 a LT-6, VM-2, LT-7 a LT-9 | C7: TECHO | D7: ="74 121 TO 124 285 TO 287 310 TO 326 352 TO 371 UNI GY "&TEXT(-TECHO!K9/100,"0.0000") -> 74 121 TO 124 285 TO 287 310 TO 326 352 TO 371 UNI GY -0.2898 | E7: =IF(AND(TECHO!$H$9=TECHO!$H$10,TECHO!$H$9=TECHO!$H$11,TECHO!$H$9=TECHO!$H$12,TECHO!$H$9=TECHO!$H$13,TECHO!$H$9=TECHO!$H$14,TECHO!$H$9=TECHO!$H$15,TECHO!$H$9=TECHO!$H$16,TECHO!$H$9=TECHO!$H$17),"","OJO: las b de este grupo ya no son iguales: separa el renglón") | F7: =IF(LEN($D7)>79,"MÁS DE 79","")
B8: LT-1 | C8: TECHO | D8: ="327 372 TO 375 UNI GY "&TEXT(-TECHO!K8/100,"0.0000") -> 327 372 TO 375 UNI GY -0.2415 | E8: ="CM de techo × b (TECHO K8) · b = "&TEXT(TECHO!H8,"0.00")&" m" -> CM de techo × b (TECHO K8) · b = 1.25 m | F8: =IF(LEN($D8)>79,"MÁS DE 79","")
B9: VM-1 | C9: TECHO | D9: ="11 48 TO 51 UNI GY "&TEXT(-TECHO!K7/100,"0.0000") -> 11 48 TO 51 UNI GY -0.0966 | E9: ="CM de techo × b (TECHO K7) · b = "&TEXT(TECHO!H7,"0.00")&" m" -> CM de techo × b (TECHO K7) · b = 0.50 m | F9: =IF(LEN($D9)>79,"MÁS DE 79","")
B10: VM-3 | C10: TECHO | D10: ="12 52 TO 55 UNI GY "&TEXT(-TECHO!K18/100,"0.0000") -> 12 52 TO 55 UNI GY -0.1449 | E10: ="CM de techo × b (TECHO K18) · b = "&TEXT(TECHO!H18,"0.00")&" m" -> CM de techo × b (TECHO K18) · b = 0.75 m | F10: =IF(LEN($D10)>79,"MÁS DE 79","")
B11: LA y LB, niveles 2 a 7, claro 1-2 | C11: MUROS | D11: ="20 21 24 25 28 29 32 33 36 37 40 41 507 TO 542 UNI GY "&TEXT(MUROS!Q9,"0.0000") -> 20 21 24 25 28 29 32 33 36 37 40 41 507 TO 542 UNI GY -0.0702 | E11: CM de muros × h (MUROS Q9) · Largueros típicos (h = 1.20 m) de los muros 3 y 4, claro 1-2 | F11: =IF(LEN($D11)>79,"MÁS DE 79","")
B12: LA y LB, niveles 2 a 7, claro 2-3 | C12: MUROS | D12: ="201 202 205 TO 214 553 TO 576 UNI GY "&TEXT(MUROS!Q10,"0.0000") -> 201 202 205 TO 214 553 TO 576 UNI GY -0.0702 | E12: CM de muros × h (MUROS Q10) · Largueros típicos (h = 1.20 m) de los muros 3 y 4, claro 2-3 | F12: =IF(LEN($D12)>79,"MÁS DE 79","")
B13: L1 con h = 1.20 m | C13: MUROS | D13: ="23 27 31 68 153 155 161 203 233 793 794 824 UNI GY "&TEXT(MUROS!P78,"0.0000") -> 23 27 31 68 153 155 161 203 233 793 794 824 UNI GY -0.0702 | E13: CM de muros × h (MUROS P78) · Largueros y línea de 6.60 m fuera del vano (h = 1.20 m) del muro 1 | F13: =IF(LEN($D13)>79,"MÁS DE 79","")
B14: Nivel 1 (0.60 m) y L1-3.2 | C14: MUROS | D14: ="16 17 46 149 159 199 200 501 TO 506 549 TO 552 823 UNI GY "&TEXT(MUROS!Q7,"0.0000") -> 16 17 46 149 159 199 200 501 TO 506 549 TO 552 823 UNI GY -0.0527 | E14: CM de muros × h (MUROS Q7) · Primer larguero (h = 0.30 + 0.60 = 0.90 m) y larguero sobre la puerta (L1-3.2) | F14: =IF(LEN($D14)>79,"MÁS DE 79","")
B15: LA-8.1, LB-8.1 | C15: MUROS | D15: ="44 45 543 TO 548 UNI GY "&TEXT(MUROS!Q21,"0.0000") -> 44 45 543 TO 548 UNI GY -0.0483 | E15: CM de muros × h (MUROS Q21) · Larguero a 9.00 m de los muros 3 y 4, claro 1-2 | F15: =IF(LEN($D15)>79,"MÁS DE 79","")
B16: LA-8.2, LB-8.2 | C16: MUROS | D16: ="215 216 577 TO 580 UNI GY "&TEXT(MUROS!Q22,"0.0000") -> 215 216 577 TO 580 UNI GY -0.0572 | E16: CM de muros × h (MUROS Q22) · Último larguero (9.00 m) de los muros 3 y 4, claro 2-3 | F16: =IF(LEN($D16)>79,"MÁS DE 79","")
B17: LA-9.1, LB-9.1 | C17: MUROS | D17: ="843 844 867 TO 872 UNI GY "&TEXT(MUROS!Q23,"0.0000") -> 843 844 867 TO 872 UNI GY -0.0342 | E17: CM de muros × h (MUROS Q23) · Último larguero (9.45 m) de los muros 3 y 4, claro 1-2 | F17: =IF(LEN($D17)>79,"MÁS DE 79","")
B18: L1-P (dintel puerta) | C18: MUROS | D18: ="204 UNI GY "&TEXT(MUROS!P81,"0.0000") -> 204 UNI GY -0.0176 | E18: CM de muros × h (MUROS P81) · Dintel de la puerta a 2.40 m: de 2.40 a 2.70 m | F18: =IF(LEN($D18)>79,"MÁS DE 79","")
B19: L1-5.1, L1-5.2 | C19: MUROS | D19: ="35 157 UNI GY "&TEXT(MUROS!P88,"0.0000") -> 35 157 UNI GY -0.0702 | E19: CM de muros × h (MUROS P88) · Largueros a 5.40 m junto a la cortina | F19: =IF(LEN($D19)>79,"MÁS DE 79","")
B20: L1-6.2 (dintel) | C20: MUROS | D20: ="234 807 808 UNI GY "&TEXT(MUROS!P91,"0.0000") -> 234 807 808 UNI GY -0.0351 | E20: CM de muros × h (MUROS P91) · Dintel de la cortina a 6.60 m (sobre el vano) | F20: =IF(LEN($D20)>79,"MÁS DE 79","")
B21: L1-7.1 | C21: MUROS | D21: ="39 581 TO 584 UNI GY "&TEXT(MUROS!P93,"0.0000") -> 39 581 TO 584 UNI GY -0.0702 | E21: CM de muros × h (MUROS P93) · Larguero a 7.80 m del muro 1 | F21: =IF(LEN($D21)>79,"MÁS DE 79","")
B22: L1-8.1 | C22: MUROS | D22: ="43 585 TO 588 UNI GY "&TEXT(MUROS!P94,"0.0000") -> 43 585 TO 588 UNI GY -0.0483 | E22: CM de muros × h (MUROS P94) · Larguero a 9.00 m del muro 1 | F22: =IF(LEN($D22)>79,"MÁS DE 79","")
B23: L1-9.1 | C23: MUROS | D23: ="840 863 TO 866 UNI GY "&TEXT(MUROS!P95,"0.0000") -> 840 863 TO 866 UNI GY -0.0418 | E23: CM de muros × h (MUROS P95) · Último larguero (9.45 m) del muro 1 | F23: =IF(LEN($D23)>79,"MÁS DE 79","")
B24: VM-1 (franja del muro eje 1) | C24: MUROS | D24: ="11 48 TO 51 UNI GY "&TEXT(MUROS!P96,"0.0000") -> 11 48 TO 51 UNI GY -0.0287 | E24: CM de muros × h (MUROS P96) · Franja alta del muro 1 (arriba de 9.45 m) a la viga del eje 1 | F24: =IF(LEN($D24)>79,"MÁS DE 79","")
B25: VA-1 y VB-1 (franja) | C25: MUROS | D25: ="241 242 269 TO 280 UNI GY "&TEXT(MUROS!Q103,"0.0000") -> 241 242 269 TO 280 UNI GY -0.0211 | E25: CM de muros × h (MUROS Q103) · Vigas de alero del claro 1-2 (arriba de 9.45 m) | F25: =IF(LEN($D25)>79,"MÁS DE 79","")
B26: VA-2 y VB-2 (franja) | C26: MUROS | D26: ="243 TO 250 UNI GY "&TEXT(MUROS!Q104,"0.0000") -> 243 TO 250 UNI GY -0.0221 | E26: CM de muros × h (MUROS Q104) · Vigas de alero del claro 2-3 (arriba de 9.00 m) | F26: =IF(LEN($D26)>79,"MÁS DE 79","")
B27: — | C27: — | D27: JOINT LOAD | E27: Encabezado (cortina en las jambas) | F27: =IF(LEN($D27)>79,"MÁS DE 79","")
B28: Cortina | C28: DATOS | D28: =DATOS!$C$54&" FY "&TEXT(-DATOS!$C$53,"0.0") -> 69 70 FY -198.9 | E28: Mitad del peso de la cortina arriba de cada jamba (DATOS C53) | F28: =IF(LEN($D28)>79,"MÁS DE 79","")
B29: CASO 2 — CARGA VIVA (w_m de DATOS): TECHO EN LARGUEROS Y VIGAS
B30: ID | C30: Origen | D30: Línea para STAAD | E30: Nota | F30: Revisión
B31: — | C31: — | D31: MEMBER LOAD | E31: Encabezado | F31: =IF(LEN($D31)>79,"MÁS DE 79","")
B32: LT-2 a LT-6, VM-2, LT-7 a LT-9 | C32: TECHO | D32: ="74 121 TO 124 285 TO 287 310 TO 326 352 TO 371 UNI GY "&TEXT(-TECHO!L9/100,"0.0000") -> 74 121 TO 124 285 TO 287 310 TO 326 352 TO 371 UNI GY -0.3000 | E32: ="w_m × b (TECHO L9) · b = "&TEXT(TECHO!H9,"0.00")&" m" -> w_m × b (TECHO L9) · b = 1.50 m | F32: =IF(LEN($D32)>79,"MÁS DE 79","")
B33: LT-1 | C33: TECHO | D33: ="327 372 TO 375 UNI GY "&TEXT(-TECHO!L8/100,"0.0000") -> 327 372 TO 375 UNI GY -0.2500 | E33: ="w_m × b (TECHO L8) · b = "&TEXT(TECHO!H8,"0.00")&" m" -> w_m × b (TECHO L8) · b = 1.25 m | F33: =IF(LEN($D33)>79,"MÁS DE 79","")
B34: VM-1 | C34: TECHO | D34: ="11 48 TO 51 UNI GY "&TEXT(-TECHO!L7/100,"0.0000") -> 11 48 TO 51 UNI GY -0.1000 | E34: ="w_m × b (TECHO L7) · b = "&TEXT(TECHO!H7,"0.00")&" m" -> w_m × b (TECHO L7) · b = 0.50 m | F34: =IF(LEN($D34)>79,"MÁS DE 79","")
B35: VM-3 | C35: TECHO | D35: ="12 52 TO 55 UNI GY "&TEXT(-TECHO!L18/100,"0.0000") -> 12 52 TO 55 UNI GY -0.1500 | E35: ="w_m × b (TECHO L18) · b = "&TEXT(TECHO!H18,"0.00")&" m" -> w_m × b (TECHO L18) · b = 0.75 m | F35: =IF(LEN($D35)>79,"MÁS DE 79","")
B37: CASO 3 — CARGA VIVA INSTANTÁNEA
B38: ID | C38: Origen | D38: Línea para STAAD | E38: Nota | F38: Revisión
B39: — | C39: DATOS | D39: =IF(DATOS!$C$23=0,"* w_i = 0: el caso queda sin carga","Aplicar w_i × b como en el caso 2 (w_i = "&DATOS!$C$23&" kg/m²)") -> * w_i = 0: el caso queda sin carga | E39: w_i de DATOS C23 | F39: =IF(LEN($D39)>79,"MÁS DE 79","")
B41: CASO 4 — MASA SÍSMICA R1.3_3: CUBIERTA Y MUROS CONCENTRADOS EN LAS CABEZAS DE COLUMNA
B42: ID | C42: Origen | D42: Línea para STAAD | E42: Nota
B43: — | C43: .STD R1.3_3 | D43: JOINT LOAD | F43: =IF(LEN($D43)>79,"MÁS DE 79","")
...

Sheet RESUMEN
B1: RESUMEN — ÁREAS, CARGAS TOTALES Y PESO SÍSMICO W
B2: Totales para revisar contra STAAD (suma de cargas del caso 1) y el W que va a la hoja de espectros (DATOS C60 y C61).
B4: 1. ÁREAS TRIBUTARIAS
B5: Concepto | C5: Valor | D5: Unidad | E5: Cómo se calcula / de dónde sale | F5: Referencia
B6: Techo (largueros + vigas de marco) | C6: =TECHO!$J$19 -> 161.28 | D6: m² | E6: Suma de la tabla A de TECHO = 10.08 × 16.00. | F6: Hoja TECHO
B7: Muros laterales en largueros (ejes A y B) | C7: =MUROS!$O$41 -> 299.14014 | D7: m² | E7: Suma de la tabla A de MUROS. | F7: Hoja MUROS
B8: Muros laterales, franja a vigas de alero | C8: =MUROS!$O$69 -> 11.74014 | D8: m² | E8: Suma de la tabla B de MUROS. | F8: Hoja MUROS
B9: Muro frontal (eje 1) en miembros | C9: =MUROS!$N$97 -> 67.4184 | D9: m² | E9: Suma de la tabla C de MUROS (sin vanos ni franja de base). | F9: Hoja MUROS
B10: Muros en total (van a largueros y vigas en STAAD) | C10: =C7+C8+C9 -> 378.29868 | D10: m² | E10: CALCULADA. | F10: —
B12: 2. CARGAS TOTALES APLICADAS EN STAAD
B13: Concepto | C13: Valor | D13: Unidad | E13: Cómo se calcula / de dónde sale | F13: Referencia
B14: CM de techo (caso 1) | C14: =DATOS!$C$8*C6 -> 3115.9296 | D14: kg | E14: CM de techo × área de techo. En STAAD: UNI GY en cada larguero y viga con su franja b (hoja TECHO). | F14: DATOS C8 · tabla de CM
B15: CM de muros (caso 1) | C15: =DATOS!$C$10*C10 -> 2213.0473 | D15: kg | E15: CM de muros × área de muros en miembros. En STAAD: UNI GY en largueros, franja alta de VA/VB/VM-1 y dinteles. | F15: DATOS C10 · tabla de CM
B16: CV máxima de techo (caso 2) | C16: =DATOS!$C$22*C6 -> 3225.6 | D16: kg | E16: w_m × área de techo. En STAAD: UNI GY en cada larguero y viga con su franja b (hoja TECHO). | F16: RESESCO · Tabla, pág. 12
B17: CV instantánea de techo (caso 3) | C17: =DATOS!$C$23*C6 -> 0 | D17: kg | E17: w_i × área de techo. | F17: RESESCO · Tabla, pág. 12
B18: CM de cortina (casos 1 y 4) | C18: =DATOS!$C$52 -> 397.8 | D18: kg | E18: Peso de la cortina de oruga: la mitad arriba de cada jamba (nodos 69 y 70). | F18: DATOS · ficha técnica Protec Ingeniería
B20: 3. PESO PROPIO DEL ACERO (LO QUE CALCULA SELFWEIGHT)
B21: Longitudes y pesos del modelo 002_NOSE_DOCK_H5_H6_R1.3_3.STD. Densidad del acero en STAAD: 0.00783341 kg/cm³.
B22: Perfil | C22: L total (m) | D22: A (cm²) | E22: Peso (kg) = L × A × densidad | F22: Uso
B23: W16X36 | C23: 19.8225 | D23: 68.387 | E23: 1061.899 | F23: Columnas eje 2
B24: W10X22 | C24: 20.86 | D24: 41.8709 | E24: 684.191 | F24: Columnas eje 1
B25: W10X12 | C25: 19.2 | D25: 22.8387 | E25: 343.498 | F25: Columnas eje 3
B26: MCE4-14 | C26: 10.08 | D26: 7.8846 | E26: 62.257 | F26: Viga de marco eje 1
B27: MCE10-14 | C27: 10.08 | D27: 16.5577 | E27: 130.741 | F27: Viga de marco eje 2
B28: MCE6-14 | C28: 10.08 | D28: 10.7756 | E28: 85.085 | F28: Viga de marco eje 3
B29: MCE12-14 | C29: 32.043 | D29: 18.4851 | E29: 463.987 | F29: Vigas de alero
B30: MC12-14 | C30: 90.72 | D30: 9.2425 | E30: 656.818 | F30: Largueros de techo
B31: MC10-12 | C31: 150.08 | D31: 11.5552 | E31: 1358.473 | F31: Largueros muros A/B claro 1-2 (0.60 a 7.80 m) y larguero 7.80 m del muro 1
B32: MC10-14 | C32: 124.16 | D32: 8.2789 | E32: 805.198 | F32: Largueros muros A/B claro 2-3, 9.00 m claro 1-2 y 9.00/9.45 m del muro 1
B33: MCC10-14 | C33: 42.08 | D33: 16.5577 | E33: 545.791 | F33: Largueros en cajón (9.45 m claro 1-2, 9.00 m claro 2-3) y dintel de 6.60 m
B34: MC4-14 | C34: 23.68 | D34: 3.9423 | E34: 73.128 | F34: Largueros cortos del muro 1 y dintel de puerta
... B40: Redondo Ø5/8" | C40: 21.5662 | D40: 1.9793 | E40: 33.438 | F40: Tensores del muro 1
B41: Acero total | C41: =SUM(C23:C40) -> 909.1687 | E41: =SUM(E23:E40) -> 6880.449 | F41: Peso de elementos de acero del modelo
B43: 4. PESO SÍSMICO W (NTDS: CM + w_i)
B44: Concepto | C44: Valor | D44: Unidad | E44: Cómo se calcula / de dónde sale | F44: Referencia
B45: Acero (peso propio) | C45: =E41/1000 -> 6.880449 | D45: t | E45: De la sección 3. | F45: —
B46: CM de techo | C46: =C14/1000 -> 3.1159296 | D46: t | E46: De la sección 2 (masa en las 6 cabezas de columna, JOINT LOAD del caso 4). | F46: Hoja NODOS_TECHO
B47: CM de muros | C47: =C15/1000 -> 2.2130473 | D47: t | E47: De la sección 2. En la masa del caso 4 va concentrada en las cabezas de columna (JOINT LOAD). | F47: Hoja MUROS
B48: CM de cortina | C48: =C18/1000 -> 0.3978 | D48: t | E48: De la sección 2: carga puntual arriba de cada jamba en el caso 1 (nodos 69 y 70); en el caso 4 va con los muros. | F48: DATOS C52 y C53
B49: CV instantánea w_i | C49: =C17/1000 -> 0 | D49: t | E49: Con pendiente mayor de 5% vale cero. | F49: RESESCO 1996 · Tabla, pág. 12
...
