Workbook

Sheet DATOS
B1: ÁREAS TRIBUTARIAS Y CARGAS PARA STAAD — HANGAR NOSE-DOCK H5-H6 — DATOS
B2: Largueros y vigas de techo y largueros de muro del modelo 001_NOSE_DOCK_H5_H6_R1.5.STD (en el modelo: cm y kg). Aquí se capturan cargas y geometría; TECHO, MUROS, STAAD y RESUMEN salen solas. Celdas amarillas = captura.
B4: 1. CARGAS MUERTAS (TABLA DE CM DEL PROYECTO)
B5: Concepto | C5: Valor | D5: Unidad | E5: Cómo se calcula / de dónde sale | F5: Referencia
B6: Panel sándwich GLAMET (Metecno) PUR/PIR 1.5" — techo | C6: 9.32 | D6: kg/m² | E6: CAPTURA. Renglón 1 de la tabla de CM, columna Techos. | F6: Tabla de CM del proyecto (foto) · renglón 1
B7: Instalaciones generales (iluminación, datos) — techo | C7: 10 | D7: kg/m² | E7: CAPTURA. Renglón 2 de la tabla de CM, columna Techos. | F7: Tabla de CM del proyecto (foto) · renglón 2
B8: CM de techo | C8: =C6+C7 -> 19.32 | D8: kg/m² | E8: CALCULADA = panel + instalaciones. No incluye el acero: ése lo mete STAAD con SELFWEIGHT. | F8: Tabla de CM del proyecto · total Techos (19.32)
B9: Lámina SSR KR-18 acanalada cal. 24 — muros | C9: 5.85 | D9: kg/m² | E9: CAPTURA. Renglón 3 de la tabla de CM, columna Muros. | F9: Tabla de CM del proyecto (foto) · renglón 3
B10: CM de muros | C10: =C9 -> 5.85 | D10: kg/m² | E10: CALCULADA. Se aplica como carga vertical en los largueros de muro. | F10: Tabla de CM del proyecto · total Muros (5.85)
B12: 2. CARGA VIVA DE TECHO — RESESCO 1996
B13: La tabla del Reglamento cambia con la pendiente: hasta 5% (inciso h) w_m = 100, w_i = 50; más de 5% (inciso i) w_m = 20, w_i = 0 kg/m².
B14: Concepto | C14: Valor | D14: Unidad | E14: Cómo se calcula / de dónde sale | F14: Referencia
B15: Y del techo en el eje 1 (Z = 0) | C15: 10.62 | D15: m | E15: CAPTURA del modelo: nodos 20 y 21, Y = 1062 cm. | F15: 001_NOSE_DOCK_H5_H6_R1.5.STD · JOINT COORDINATES
B16: Y del techo en el eje 4 (Z = 16 m) | C16: 9.82002 | D16: m | E16: CAPTURA del modelo: nodos 16 y 13, Y = 982.002 cm. | F16: 001_NOSE_DOCK_H5_H6_R1.5.STD · JOINT COORDINATES
B17: L — largo en el sentido de la pendiente (eje 1 a eje 4) | C17: 16 | D17: m | E17: CAPTURA del modelo: Z de 0 a 1600 cm. | F17: 001_NOSE_DOCK_H5_H6_R1.5.STD · JOINT COORDINATES
B18: Pendiente del modelo = (Y₁ − Y₄) / L | C18: =(C15-C16)/C17 -> 0.04999875 | D18: % | E18: CALCULADA con la geometría de STAAD (0.80 m de caída en 16 m). | F18: Geometría del modelo
B19: θ — ángulo del techo | C19: =DEGREES(ATAN(C18)) -> 2.8623338 | D19: ° | E19: CALCULADA = arctan(pendiente). | F19: —
B20: Pendiente que rige (arquitectónico) | C20: 0.054 | D20: % | E20: CAPTURA. La que indicaste (5.4%). Cámbiala si el arquitectónico dice otra: w_m y w_i se ajustan solos. | F20: Arquitectónico (dato del proyecto)
B21: Inciso de la tabla que aplica | C21: =IF(C20>0.05,"i) pendiente mayor de 5%","h) pendiente no mayor de 5%") -> i) pendiente mayor de 5% | D21: — | E21: CALCULADA con la pendiente que rige. | F21: RESESCO 1996 · Tabla de Cargas Vivas Unitarias Mínimas, incisos h) e i), pág. 12
B22: w_m — carga viva máxima (caso 2 CV) | C22: =IF(C20>0.05,20,100) -> 20 | D22: kg/m² | E22: CALCULADA. Para diseño por gravedad (combinación 1.4CM + 1.7CV). | F22: RESESCO · Art. 25 num. 1, pág. 9 · Tabla, pág. 12
B23: w_i — carga viva instantánea (caso 3 CVR y masa sísmica) | C23: =IF(C20>0.05,0,50) -> 0 | D23: kg/m² | E23: CALCULADA. Para sismo y viento; con 0 el caso 3 queda vacío y no suma masa. | F23: RESESCO · Art. 25 num. 2, pág. 10 · Tabla, pág. 12
B24: w — carga viva media | C24: =IF(C20>0.05,5,15) -> 5 | D24: kg/m² | E24: CALCULADA. Sólo para deflexiones diferidas. | F24: RESESCO · Art. 25 num. 3, pág. 10 · Tabla, pág. 12
B25: Carga concentrada en elementos de cubierta | C25: 100 | D25: kg | E25: Revisión aparte de largueros y vigas de techo: 100 kg en la posición más crítica (no es un caso general de STAAD). | F25: RESESCO · Observación 5 a la tabla, pág. 13
B27: 3. GEOMETRÍA DEL MODELO
B28: Concepto | C28: Valor | D28: Unidad | E28: Cómo se calcula / de dónde sale | F28: Referencia
B29: Claro de largueros de techo (eje A a eje B) | C29: 10.08 | D29: m | E29: CAPTURA del modelo: X de 0 a 1008 cm. | F29: 001_NOSE_DOCK_H5_H6_R1.5.STD · nodos 16 y 13
B30: Mitad del claro (lo que cada larguero entrega a cada viga de alero) | C30: =C29/2 -> 5.04 | D30: m | E30: CALCULADA. Ancho en X del área de las vigas VA y VB. | F30: Criterio de área tributaria
B31: Z del eje 1 | C31: 0 | D31: m | E31: CAPTURA del modelo. | F31: 001_NOSE_DOCK_H5_H6_R1.5.STD · nodos 1 y 2
B32: Z del eje 2 | C32: 6.75001 | D32: m | E32: CAPTURA del modelo. | F32: 001_NOSE_DOCK_H5_H6_R1.5.STD · nodos 3 y 6
B33: Z del eje 3 | C33: 13.5 | D33: m | E33: CAPTURA del modelo. | F33: 001_NOSE_DOCK_H5_H6_R1.5.STD · nodos 4 y 7
B34: Z del eje 4 | C34: 16 | D34: m | E34: CAPTURA del modelo. | F34: 001_NOSE_DOCK_H5_H6_R1.5.STD · nodos 5 y 8
B35: Factor por pendiente 1 / cos θ | C35: =1/COS(RADIANS(C19)) -> 1.0012492 | D35: — | E35: CALCULADA. Las áreas van en proyección horizontal: este factor se desprecia. | F35: —
B37: 4. CRITERIOS
B38: 1. Los PIPX7 del techo no se consideran portantes: cada larguero MC4-14 trabaja de alero a alero (claro 10.08 m) y entrega la mitad a cada viga MCE6-12 de alero (ejes A y B).
B39: 2. En los ejes 1 a 4 no hay larguero en el modelo: la franja de ese eje la toma directo la viga MCE6-12 del marco (VM-1 a VM-4).
B40: 3. Techo: franja de cada línea = mitad de la separación a cada lado. Muros: igual en vertical; la franja de abajo (0.00–0.60 m) baja directo a la base y la de arriba va a la viga de alero (ejes A y B) o a la VM-1 (eje 1). Los vanos no llevan lámina: la cortina carga su peso al dintel (miembro 25) y su viento a las jambas; la puerta de 1.30 × 2.40 carga su viento a sus postes HSS3x3 (hoja de viento).
B41: 4. El eje 4 (Z = 16 m) no tiene largueros de muro en el modelo: se tomó sin muro.
B42: 5. En STAAD (R1.5): CM y CV de techo como JOINT LOAD FY (−) en los 8 nodos de cabeza de columna (hoja NODOS_TECHO); CM de muros como UNI GY (−) en los largueros y en la franja alta de las vigas de alero y VM-1 (hoja MUROS), w (kg/cm) = w (kg/m) ÷ 100; masa sísmica del caso 4 como JOINT LOAD FX y FZ en los nodos de columna (hojas NODOS_TECHO y NODOS_MUROS), más SELFWEIGHT X 1 y Z 1.
B44: 5. CORTINA DE ORUGA EN EL VANO DEL NOSE DOCK (MASA EN EL DINTEL, MIEMBRO 25)
B45: Concepto | C45: Valor | D45: Unidad | E45: Cómo se calcula / de dónde sale | F45: Referencia
...

Sheet TECHO
B1: TECHO — ÁREAS TRIBUTARIAS DE LARGUEROS MC4-14 Y VIGAS MCE6-12
B2: Planta en proyección horizontal. Las líneas en X (largueros LT y vigas de marco VM) reciben su franja; las vigas de alero VA y VB reciben la mitad del claro de cada larguero. Mismas áreas que el DXF. En STAAD R1.5 el techo ya NO se aplica en largueros ni vigas: va puntual a las 8 cabezas de columna (hoja NODOS_TECHO). Estas cargas por metro quedan para diseñar largueros y vigas.
B4: A. LÍNEAS EN X — LARGUEROS LT Y VIGAS DE MARCO VM
B5: ID | C5: Elemento | D5: Perfil | E5: Z (m) | F5: Franja desde (m) | G5: Franja hasta (m) | H5: b (m) | I5: Claro (m) | J5: A (m²) | K5: w CM (kg/m) | L5: w CV (kg/m) | M5: w CVi (kg/m) | N5: R extremo CM (kg) | O5: R extremo CV (kg) | P5: Miembros STAAD | Q5: Referencia
E6: del modelo | F6: (Z ant. + Z)/2 | G6: (Z + Z sig.)/2 | H6: hasta − desde | I6: DATOS C30 | J6: b × claro | K6: CM techo × b | L6: w_m × b | M6: w_i × b | N6: w CM × claro/2 | O6: w CV × claro/2 | P6: del .STD
B7: VM-1 | C7: Viga de marco eje 1 | D7: MCE6-12 | E7: 0 | F7: =E7 -> 0 | G7: =(E7+E8)/2 -> 0.675 | H7: =G7-F7 -> 0.675 | I7: =DATOS!$C$29 -> 10.08 | J7: =H7*I7 -> 6.804 | K7: =DATOS!$C$8*H7 -> 13.041 | L7: =DATOS!$C$22*H7 -> 13.5 | M7: =DATOS!$C$23*H7 -> 0 | N7: =K7*I7/2 -> 65.72664 | O7: =L7*I7/2 -> 68.04 | P7: 22 85 TO 88 | Q7: .STD R1.5 · nodos 20 a 21 (Z = 0 cm)
B8: LT-1 | C8: Larguero de techo | D8: MC4-14 | E8: 1.35 | F8: =(E7+E8)/2 -> 0.675 | G8: =(E8+E9)/2 -> 2.025 | H8: =G8-F8 -> 1.35 | I8: =DATOS!$C$29 -> 10.08 | J8: =H8*I8 -> 13.608 | K8: =DATOS!$C$8*H8 -> 26.082 | L8: =DATOS!$C$22*H8 -> 27 | M8: =DATOS!$C$23*H8 -> 0 | N8: =K8*I8/2 -> 131.45328 | O8: =L8*I8/2 -> 136.08 | P8: 80 129 TO 132 | Q8: .STD R1.5 · nodos 43 a 47 (Z = 135 cm)
B9: LT-2 | C9: Larguero de techo | D9: MC4-14 | E9: 2.7 | F9: =(E8+E9)/2 -> 2.025 | G9: =(E9+E10)/2 -> 3.375 | H9: =G9-F9 -> 1.35 | I9: =DATOS!$C$29 -> 10.08 | J9: =H9*I9 -> 13.608 | K9: =DATOS!$C$8*H9 -> 26.082 | L9: =DATOS!$C$22*H9 -> 27 | M9: =DATOS!$C$23*H9 -> 0 | N9: =K9*I9/2 -> 131.45328 | O9: =L9*I9/2 -> 136.08 | P9: 79 125 TO 128 | Q9: .STD R1.5 · nodos 42 a 46 (Z = 270 cm)
B10: LT-3 | C10: Larguero de techo | D10: MC4-14 | E10: 4.05 | F10: =(E9+E10)/2 -> 3.375 | G10: =(E10+E11)/2 -> 4.725 | H10: =G10-F10 -> 1.35 | I10: =DATOS!$C$29 -> 10.08 | J10: =H10*I10 -> 13.608 | K10: =DATOS!$C$8*H10 -> 26.082 | L10: =DATOS!$C$22*H10 -> 27 | M10: =DATOS!$C$23*H10 -> 0 | N10: =K10*I10/2 -> 131.45328 | O10: =L10*I10/2 -> 136.08 | P10: 78 121 TO 124 | Q10: .STD R1.5 · nodos 41 a 45 (Z = 405 cm)
B11: LT-4 | C11: Larguero de techo | D11: MC4-14 | E11: 5.4 | F11: =(E10+E11)/2 -> 4.725 | G11: =(E11+E12)/2 -> 6.075 | H11: =G11-F11 -> 1.35 | I11: =DATOS!$C$29 -> 10.08 | J11: =H11*I11 -> 13.608 | K11: =DATOS!$C$8*H11 -> 26.082 | L11: =DATOS!$C$22*H11 -> 27 | M11: =DATOS!$C$23*H11 -> 0 | N11: =K11*I11/2 -> 131.45328 | O11: =L11*I11/2 -> 136.08 | P11: 77 117 TO 120 | Q11: .STD R1.5 · nodos 40 a 44 (Z = 540 cm)
B12: VM-2 | C12: Viga de marco eje 2 | D12: MCE6-12 | E12: 6.75 | F12: =(E11+E12)/2 -> 6.075 | G12: =(E12+E13)/2 -> 7.425 | H12: =G12-F12 -> 1.35 | I12: =DATOS!$C$29 -> 10.08 | J12: =H12*I12 -> 13.608 | K12: =DATOS!$C$8*H12 -> 26.082 | L12: =DATOS!$C$22*H12 -> 27 | M12: =DATOS!$C$23*H12 -> 0 | N12: =K12*I12/2 -> 131.45328 | O12: =L12*I12/2 -> 136.08 | P12: 9 93 TO 96 | Q12: .STD R1.5 · nodos 18 a 19 (Z = 675 cm)
B13: LT-5 | C13: Larguero de techo | D13: MC4-14 | E13: 8.1 | F13: =(E12+E13)/2 -> 7.425 | G13: =(E13+E14)/2 -> 8.775 | H13: =G13-F13 -> 1.35 | I13: =DATOS!$C$29 -> 10.08 | J13: =H13*I13 -> 13.608 | K13: =DATOS!$C$8*H13 -> 26.082 | L13: =DATOS!$C$22*H13 -> 27 | M13: =DATOS!$C$23*H13 -> 0 | N13: =K13*I13/2 -> 131.45328 | O13: =L13*I13/2 -> 136.08 | P13: 76 113 TO 116 | Q13: .STD R1.5 · nodos 51 a 55 (Z = 810 cm)
B14: LT-6 | C14: Larguero de techo | D14: MC4-14 | E14: 9.45 | F14: =(E13+E14)/2 -> 8.775 | G14: =(E14+E15)/2 -> 10.125 | H14: =G14-F14 -> 1.35 | I14: =DATOS!$C$29 -> 10.08 | J14: =H14*I14 -> 13.608 | K14: =DATOS!$C$8*H14 -> 26.082 | L14: =DATOS!$C$22*H14 -> 27 | M14: =DATOS!$C$23*H14 -> 0 | N14: =K14*I14/2 -> 131.45328 | O14: =L14*I14/2 -> 136.08 | P14: 75 109 TO 112 | Q14: .STD R1.5 · nodos 50 a 54 (Z = 945 cm)
B15: LT-7 | C15: Larguero de techo | D15: MC4-14 | E15: 10.8 | F15: =(E14+E15)/2 -> 10.125 | G15: =(E15+E16)/2 -> 11.475 | H15: =G15-F15 -> 1.35 | I15: =DATOS!$C$29 -> 10.08 | J15: =H15*I15 -> 13.608 | K15: =DATOS!$C$8*H15 -> 26.082 | L15: =DATOS!$C$22*H15 -> 27 | M15: =DATOS!$C$23*H15 -> 0 | N15: =K15*I15/2 -> 131.45328 | O15: =L15*I15/2 -> 136.08 | P15: 74 105 TO 108 | Q15: .STD R1.5 · nodos 49 a 53 (Z = 1080 cm)
B16: LT-8 | C16: Larguero de techo | D16: MC4-14 | E16: 12.15 | F16: =(E15+E16)/2 -> 11.475 | G16: =(E16+E17)/2 -> 12.825 | H16: =G16-F16 -> 1.35 | I16: =DATOS!$C$29 -> 10.08 | J16: =H16*I16 -> 13.608 | K16: =DATOS!$C$8*H16 -> 26.082 | L16: =DATOS!$C$22*H16 -> 27 | M16: =DATOS!$C$23*H16 -> 0 | N16: =K16*I16/2 -> 131.45328 | O16: =L16*I16/2 -> 136.08 | P16: 73 101 TO 104 | Q16: .STD R1.5 · nodos 48 a 52 (Z = 1215 cm)
B17: VM-3 | C17: Viga de marco eje 3 | D17: MCE6-12 | E17: 13.5 | F17: =(E16+E17)/2 -> 12.825 | G17: =(E17+E18)/2 -> 14.125 | H17: =G17-F17 -> 1.3 | I17: =DATOS!$C$29 -> 10.08 | J17: =H17*I17 -> 13.104 | K17: =DATOS!$C$8*H17 -> 25.116 | L17: =DATOS!$C$22*H17 -> 26 | M17: =DATOS!$C$23*H17 -> 0 | N17: =K17*I17/2 -> 126.58464 | O17: =L17*I17/2 -> 131.04 | P17: 8 89 TO 92 | Q17: .STD R1.5 · nodos 14 a 15 (Z = 1350 cm)
B18: LT-9 | C18: Larguero de techo | D18: MC4-14 | E18: 14.75 | F18: =(E17+E18)/2 -> 14.125 | G18: =(E18+E19)/2 -> 15.375 | H18: =G18-F18 -> 1.25 | I18: =DATOS!$C$29 -> 10.08 | J18: =H18*I18 -> 12.6 | K18: =DATOS!$C$8*H18 -> 24.15 | L18: =DATOS!$C$22*H18 -> 25 | M18: =DATOS!$C$23*H18 -> 0 | N18: =K18*I18/2 -> 121.716 | O18: =L18*I18/2 -> 126 | P18: 56 97 TO 100 | Q18: .STD R1.5 · nodos 38 a 39 (Z = 1475 cm)
B19: VM-4 | C19: Viga de marco eje 4 | D19: MCE6-12 | E19: 16 | F19: =(E18+E19)/2 -> 15.375 | G19: =E19 -> 16 | H19: =G19-F19 -> 0.625 | I19: =DATOS!$C$29 -> 10.08 | J19: =H19*I19 -> 6.3 | K19: =DATOS!$C$8*H19 -> 12.075 | L19: =DATOS!$C$22*H19 -> 12.5 | M19: =DATOS!$C$23*H19 -> 0 | N19: =K19*I19/2 -> 60.858 | O19: =L19*I19/2 -> 63 | P19: 7 81 TO 84 | Q19: .STD R1.5 · nodos 16 a 13 (Z = 1600 cm)
B20: Total | C20: Suma de áreas de techo (debe dar claro × largo = 10.08 × 16.00) | J20: =SUM(J7:J19) -> 161.28 | K20: =IF(ABS(J20-DATOS!$C$29*(DATOS!$C$34-DATOS!$C$31))<0.01,"CUADRA","NO CUADRA") -> CUADRA
B22: B. VIGAS DE ALERO MCE6-12 (EJES A Y B) — RECIBEN LA MITAD DE CADA LARGUERO
B23: Área = franja en Z de los largueros que se le apoyan × mitad del claro de los largueros. Sirve para diseñar las vigas de alero; en STAAD R1.5 el techo entra en las cabezas de columna (hoja NODOS_TECHO).
B24: ID | C24: Eje y tramo | D24: Perfil | E24: Largueros que recibe | F24: Franja desde (m) | G24: Franja hasta (m) | H24: Ancho en Z (m) | I24: Ancho en X (m) | J24: A (m²) | K24: CM total (kg) | L24: CV total (kg) | M24: Nº de largueros | N24: R CM por larguero (kg) | O24: R CV por larguero (kg) | P24: Miembros STAAD | Q24: Referencia
F25: del 1er larguero | G25: del último larguero | H25: hasta − desde | I25: DATOS C31 | J25: Z × X | K25: CM techo × A | L25: w_m × A | N25: CM total ÷ Nº | O25: CV total ÷ Nº | P25: del .STD
B26: VA-1 | C26: Eje A, tramo 1-2 | D26: MCE6-12 | E26: LT-1 a LT-4 | F26: =F8 -> 0.675 | G26: =G11 -> 6.075 | H26: =G26-F26 -> 5.4 | I26: =DATOS!$C$30 -> 5.04 | J26: =H26*I26 -> 27.216 | K26: =DATOS!$C$8*J26 -> 525.81312 | L26: =DATOS!$C$22*J26 -> 544.32 | M26: 4 | N26: =K26/M26 -> 131.45328 | O26: =L26/M26 -> 136.08 | P26: 10 57 TO 60 | Q26: .STD R1.5 · X = 0 cm, Z 0 a 675 cm
B27: VA-2 | C27: Eje A, tramo 2-3 | D27: MCE6-12 | E27: LT-5 a LT-8 | F27: =F13 -> 7.425 | G27: =G16 -> 12.825 | H27: =G27-F27 -> 5.4 | I27: =DATOS!$C$30 -> 5.04 | J27: =H27*I27 -> 27.216 | K27: =DATOS!$C$8*J27 -> 525.81312 | L27: =DATOS!$C$22*J27 -> 544.32 | M27: 4 | N27: =K27/M27 -> 131.45328 | O27: =L27/M27 -> 136.08 | P27: 43 65 TO 68 | Q27: .STD R1.5 · X = 0 cm, Z 675 a 1350 cm
B28: VA-3 | C28: Eje A, tramo 3-4 | D28: MCE6-12 | E28: LT-9 | F28: =F18 -> 14.125 | G28: =G18 -> 15.375 | H28: =G28-F28 -> 1.25 | I28: =DATOS!$C$30 -> 5.04 | J28: =H28*I28 -> 6.3 | K28: =DATOS!$C$8*J28 -> 121.716 | L28: =DATOS!$C$22*J28 -> 126 | M28: 1 | N28: =K28/M28 -> 121.716 | O28: =L28/M28 -> 126 | P28: 47 54 | Q28: .STD R1.5 · X = 0 cm, Z 1350 a 1600 cm
B29: VB-1 | C29: Eje B, tramo 1-2 | D29: MCE6-12 | E29: LT-1 a LT-4 | F29: =F8 -> 0.675 | G29: =G11 -> 6.075 | H29: =G29-F29 -> 5.4 | I29: =DATOS!$C$30 -> 5.04 | J29: =H29*I29 -> 27.216 | K29: =DATOS!$C$8*J29 -> 525.81312 | L29: =DATOS!$C$22*J29 -> 544.32 | M29: 4 | N29: =K29/M29 -> 131.45328 | O29: =L29/M29 -> 136.08 | P29: 12 61 TO 64 | Q29: .STD R1.5 · X = 1008 cm, Z 0 a 675 cm
B30: VB-2 | C30: Eje B, tramo 2-3 | D30: MCE6-12 | E30: LT-5 a LT-8 | F30: =F13 -> 7.425 | G30: =G16 -> 12.825 | H30: =G30-F30 -> 5.4 | I30: =DATOS!$C$30 -> 5.04 | J30: =H30*I30 -> 27.216 | K30: =DATOS!$C$8*J30 -> 525.81312 | L30: =DATOS!$C$22*J30 -> 544.32 | M30: 4 | N30: =K30/M30 -> 131.45328 | O30: =L30/M30 -> 136.08 | P30: 50 69 TO 72 | Q30: .STD R1.5 · X = 1008 cm, Z 675 a 1350 cm
B31: VB-3 | C31: Eje B, tramo 3-4 | D31: MCE6-12 | E31: LT-9 | F31: =F18 -> 14.125 | G31: =G18 -> 15.375 | H31: =G31-F31 -> 1.25 | I31: =DATOS!$C$30 -> 5.04 | J31: =H31*I31 -> 6.3 | K31: =DATOS!$C$8*J31 -> 121.716 | L31: =DATOS!$C$22*J31 -> 126 | M31: 1 | N31: =K31/M31 -> 121.716 | O31: =L31/M31 -> 126 | P31: 53 55 | Q31: .STD R1.5 · X = 1008 cm, Z 1350 a 1600 cm
B32: Total | C32: Vigas de alero + franjas directas de VM (debe dar el total del techo) | J32: =SUM(J26:J31)+J7+J12+J17+J19 -> 161.28 | K32: =IF(ABS(J32-J20)<0.01,"CUADRA","NO CUADRA") -> CUADRA

Sheet MUROS
B1: MUROS — ÁREAS TRIBUTARIAS DE LARGUEROS DE MURO
B2: Elevaciones de los muros de los ejes A, B (laterales) y 1 (frontal). Franja de cada larguero = mitad de la distancia al miembro de abajo y al de arriba. Carga vertical de la lámina (CM de muros). El eje 4 no tiene largueros en el modelo.
B4: A. MUROS LATERALES — EJE A (X = 0) Y EJE B (X = 10.08 m)
B5: ID | C5: Muro | D5: Nivel | E5: Y larguero (m) | F5: Tramo (ejes) | G5: L (m) | H5: Y abajo (m) | I5: Y arriba inicio (m) | J5: Y arriba fin (m) | K5: Franja desde (m) | L5: Franja hasta inicio (m) | M5: Franja hasta fin (m) | N5: h (m) | O5: A (m²) | P5: w CM (kg/m) | Q5: STAAD CM (kg/cm) | R5: Miembro STAAD | S5: Referencia
E6: del modelo | G6: del modelo | H6: miembro de abajo (0 = base) | I6: miembro de arriba | J6: miembro de arriba | K6: (Y ab. + Y)/2 | L6: (Y + Y arr.)/2 | M6: (Y + Y arr.)/2 | N6: promedio | O6: L × h | P6: CM muros × h | Q6: −w ÷ 100 | R6: del .STD
B7: LA-1.1 | C7: Eje A | D7: 1 | E7: 1.2 | F7: 1-2 | G7: 6.75001 | H7: 0 | I7: 2.4 | J7: 2.4 | K7: =(H7+E7)/2 -> 0.6 | L7: =(E7+I7)/2 -> 1.8 | M7: =(E7+J7)/2 -> 1.8 | N7: =(L7+M7)/2-K7 -> 1.2 | O7: =G7*N7 -> 8.100012 | P7: =DATOS!$C$10*N7 -> 7.02 | Q7: =-P7/100 -> -0.0702 | R7: 261 | S7: .STD R1.5 · nodos 110–108
B8: LA-1.2 | C8: Eje A | D8: 1 | E8: 1.2 | F8: 2-3 | G8: 6.74999 | H8: 0 | I8: 2.4 | J8: 2.4 | K8: =(H8+E8)/2 -> 0.6 | L8: =(E8+I8)/2 -> 1.8 | M8: =(E8+J8)/2 -> 1.8 | N8: =(L8+M8)/2-K8 -> 1.2 | O8: =G8*N8 -> 8.099988 | P8: =DATOS!$C$10*N8 -> 7.02 | Q8: =-P8/100 -> -0.0702 | R8: 260 | S8: .STD R1.5 · nodos 111–110
B9: LA-1.3 | C9: Eje A | D9: 1 | E9: 1.2 | F9: 3-4 | G9: 2.5 | H9: 0 | I9: 2.4 | J9: 2.4 | K9: =(H9+E9)/2 -> 0.6 | L9: =(E9+I9)/2 -> 1.8 | M9: =(E9+J9)/2 -> 1.8 | N9: =(L9+M9)/2-K9 -> 1.2 | O9: =G9*N9 -> 3 | P9: =DATOS!$C$10*N9 -> 7.02 | Q9: =-P9/100 -> -0.0702 | R9: 259 | S9: .STD R1.5 · nodos 112–111
B10: LA-2.1 | C10: Eje A | D10: 2 | E10: 2.4 | F10: 1-2 | G10: 6.75001 | H10: 1.2 | I10: 3.6 | J10: 3.6 | K10: =(H10+E10)/2 -> 1.8 | L10: =(E10+I10)/2 -> 3 | M10: =(E10+J10)/2 -> 3 | N10: =(L10+M10)/2-K10 -> 1.2 | O10: =G10*N10 -> 8.100012 | P10: =DATOS!$C$10*N10 -> 7.02 | Q10: =-P10/100 -> -0.0702 | R10: 270 | S10: .STD R1.5 · nodos 122–120
B11: LA-2.2 | C11: Eje A | D11: 2 | E11: 2.4 | F11: 2-3 | G11: 6.74999 | H11: 1.2 | I11: 3.6 | J11: 3.6 | K11: =(H11+E11)/2 -> 1.8 | L11: =(E11+I11)/2 -> 3 | M11: =(E11+J11)/2 -> 3 | N11: =(L11+M11)/2-K11 -> 1.2 | O11: =G11*N11 -> 8.099988 | P11: =DATOS!$C$10*N11 -> 7.02 | Q11: =-P11/100 -> -0.0702 | R11: 269 | S11: .STD R1.5 · nodos 123–122
B12: LA-2.3 | C12: Eje A | D12: 2 | E12: 2.4 | F12: 3-4 | G12: 2.5 | H12: 1.2 | I12: 3.6 | J12: 3.6 | K12: =(H12+E12)/2 -> 1.8 | L12: =(E12+I12)/2 -> 3 | M12: =(E12+J12)/2 -> 3 | N12: =(L12+M12)/2-K12 -> 1.2 | O12: =G12*N12 -> 3 | P12: =DATOS!$C$10*N12 -> 7.02 | Q12: =-P12/100 -> -0.0702 | R12: 268 | S12: .STD R1.5 · nodos 124–123
B13: LA-3.1 | C13: Eje A | D13: 3 | E13: 3.6 | F13: 1-2 | G13: 6.75001 | H13: 2.4 | I13: 4.8 | J13: 4.8 | K13: =(H13+E13)/2 -> 3 | L13: =(E13+I13)/2 -> 4.2 | M13: =(E13+J13)/2 -> 4.2 | N13: =(L13+M13)/2-K13 -> 1.2 | O13: =G13*N13 -> 8.100012 | P13: =DATOS!$C$10*N13 -> 7.02 | Q13: =-P13/100 -> -0.0702 | R13: 279 | S13: .STD R1.5 · nodos 134–132
B14: LA-3.2 | C14: Eje A | D14: 3 | E14: 3.6 | F14: 2-3 | G14: 6.74999 | H14: 2.4 | I14: 4.8 | J14: 4.8 | K14: =(H14+E14)/2 -> 3 | L14: =(E14+I14)/2 -> 4.2 | M14: =(E14+J14)/2 -> 4.2 | N14: =(L14+M14)/2-K14 -> 1.2 | O14: =G14*N14 -> 8.099988 | P14: =DATOS!$C$10*N14 -> 7.02 | Q14: =-P14/100 -> -0.0702 | R14: 278 | S14: .STD R1.5 · nodos 135–134
B15: LA-3.3 | C15: Eje A | D15: 3 | E15: 3.6 | F15: 3-4 | G15: 2.5 | H15: 2.4 | I15: 4.8 | J15: 4.8 | K15: =(H15+E15)/2 -> 3 | L15: =(E15+I15)/2 -> 4.2 | M15: =(E15+J15)/2 -> 4.2 | N15: =(L15+M15)/2-K15 -> 1.2 | O15: =G15*N15 -> 3 | P15: =DATOS!$C$10*N15 -> 7.02 | Q15: =-P15/100 -> -0.0702 | R15: 277 | S15: .STD R1.5 · nodos 136–135
B16: LA-4.1 | C16: Eje A | D16: 4 | E16: 4.8 | F16: 1-2 | G16: 6.75001 | H16: 3.6 | I16: 6 | J16: 6 | K16: =(H16+E16)/2 -> 4.2 | L16: =(E16+I16)/2 -> 5.4 | M16: =(E16+J16)/2 -> 5.4 | N16: =(L16+M16)/2-K16 -> 1.2 | O16: =G16*N16 -> 8.100012 | P16: =DATOS!$C$10*N16 -> 7.02 | Q16: =-P16/100 -> -0.0702 | R16: 289 | S16: .STD R1.5 · nodos 146–144
B17: LA-4.2 | C17: Eje A | D17: 4 | E17: 4.8 | F17: 2-3 | G17: 6.74999 | H17: 3.6 | I17: 6 | J17: 6 | K17: =(H17+E17)/2 -> 4.2 | L17: =(E17+I17)/2 -> 5.4 | M17: =(E17+J17)/2 -> 5.4 | N17: =(L17+M17)/2-K17 -> 1.2 | O17: =G17*N17 -> 8.099988 | P17: =DATOS!$C$10*N17 -> 7.02 | Q17: =-P17/100 -> -0.0702 | R17: 288 | S17: .STD R1.5 · nodos 147–146
B18: LA-4.3 | C18: Eje A | D18: 4 | E18: 4.8 | F18: 3-4 | G18: 2.5 | H18: 3.6 | I18: 6 | J18: 6 | K18: =(H18+E18)/2 -> 4.2 | L18: =(E18+I18)/2 -> 5.4 | M18: =(E18+J18)/2 -> 5.4 | N18: =(L18+M18)/2-K18 -> 1.2 | O18: =G18*N18 -> 3 | P18: =DATOS!$C$10*N18 -> 7.02 | Q18: =-P18/100 -> -0.0702 | R18: 287 | S18: .STD R1.5 · nodos 148–147
... B54: LB-8.3 | C54: Eje B | D54: 8 | E54: 9.6 | F54: 3-4 | G54: 2.5 | H54: 8.4 | I54: 9.94002 | J54: 9.82002 | K54: =(H54+E54)/2 -> 9 | L54: =(E54+I54)/2 -> 9.77001 | M54: =(E54+J54)/2 -> 9.71001 | N54: =(L54+M54)/2-K54 -> 0.74001 | O54: =G54*N54 -> 1.850025 | P54: =DATOS!$C$10*N54 -> 4.3290585 | Q54: =-P54/100 -> -0.043290585 | R54: 319 | S54: .STD R1.5 · nodos 199–198 · arriba: alero inclinado
B55: Total | C55: Área de muros laterales en largueros (ejes A y B) | O55: =SUM(O7:O54) -> 297.88012
B57: B. FRANJA SUPERIOR DE MUROS LATERALES → VIGAS DE ALERO VA Y VB (POR MIEMBRO DE STAAD)
B58: Arriba del último larguero (Y = 9.60 m) la mitad de la lámina cuelga de la viga de alero. Como el alero baja 5%, la franja cambia a lo largo: se toma el promedio de cada miembro.
B59: Viga | C59: Muro | E59: Miembro STAAD | F59: Z inicio (m) | G59: Z fin (m) | H59: L (m) | I59: Y alero inicio (m) | J59: Y alero fin (m) | K59: Y último larguero (m) | L59: h inicio (m) | M59: h fin (m) | N59: h (m) | O59: A (m²) | P59: w CM (kg/m) | Q59: STAAD CM (kg/cm) | S59: Referencia
E60: del .STD | F60: del modelo | G60: del modelo | H60: fin − inicio | I60: del modelo | J60: del modelo | K60: del modelo | L60: (Y al. − Y)/2 | M60: (Y al. − Y)/2 | N60: promedio | O60: L × h | P60: CM muros × h | Q60: −w ÷ 100
B61: VA-1 | C61: Eje A | E61: 60 | F61: 0 | G61: 1.35 | H61: =G61-F61 -> 1.35 | I61: 10.62 | J61: 10.552 | K61: 9.6 | L61: =(I61-K61)/2 -> 0.51 | M61: =(J61-K61)/2 -> 0.476 | N61: =(L61+M61)/2 -> 0.493 | O61: =H61*N61 -> 0.66555 | P61: =DATOS!$C$10*N61 -> 2.88405 | Q61: =-P61/100 -> -0.0288405 | S61: .STD R1.5 · nodos 43–20
B62: VA-1 | C62: Eje A | E62: 59 | F62: 1.35 | G62: 2.7 | H62: =G62-F62 -> 1.35 | I62: 10.552 | J62: 10.484 | K62: 9.6 | L62: =(I62-K62)/2 -> 0.476 | M62: =(J62-K62)/2 -> 0.442 | N62: =(L62+M62)/2 -> 0.459 | O62: =H62*N62 -> 0.61965 | P62: =DATOS!$C$10*N62 -> 2.68515 | Q62: =-P62/100 -> -0.0268515 | S62: .STD R1.5 · nodos 42–43
B63: VA-1 | C63: Eje A | E63: 58 | F63: 2.7 | G63: 4.05001 | H63: =G63-F63 -> 1.35001 | I63: 10.484 | J63: 10.416 | K63: 9.6 | L63: =(I63-K63)/2 -> 0.442 | M63: =(J63-K63)/2 -> 0.408 | N63: =(L63+M63)/2 -> 0.425 | O63: =H63*N63 -> 0.57375425 | P63: =DATOS!$C$10*N63 -> 2.48625 | Q63: =-P63/100 -> -0.0248625 | S63: .STD R1.5 · nodos 41–42
B64: VA-1 | C64: Eje A | E64: 57 | F64: 4.05001 | G64: 5.40001 | H64: =G64-F64 -> 1.35 | I64: 10.416 | J64: 10.348 | K64: 9.6 | L64: =(I64-K64)/2 -> 0.408 | M64: =(J64-K64)/2 -> 0.374 | N64: =(L64+M64)/2 -> 0.391 | O64: =H64*N64 -> 0.52785 | P64: =DATOS!$C$10*N64 -> 2.28735 | Q64: =-P64/100 -> -0.0228735 | S64: .STD R1.5 · nodos 40–41
B65: VA-1 | C65: Eje A | E65: 10 | F65: 5.40001 | G65: 6.75001 | H65: =G65-F65 -> 1.35 | I65: 10.348 | J65: 10.28 | K65: 9.6 | L65: =(I65-K65)/2 -> 0.374 | M65: =(J65-K65)/2 -> 0.34 | N65: =(L65+M65)/2 -> 0.357 | O65: =H65*N65 -> 0.48195 | P65: =DATOS!$C$10*N65 -> 2.08845 | Q65: =-P65/100 -> -0.0208845 | S65: .STD R1.5 · nodos 18–40
B66: VA-2 | C66: Eje A | E66: 68 | F66: 6.75001 | G66: 8.10001 | H66: =G66-F66 -> 1.35 | I66: 10.28 | J66: 10.212 | K66: 9.6 | L66: =(I66-K66)/2 -> 0.34 | M66: =(J66-K66)/2 -> 0.306 | N66: =(L66+M66)/2 -> 0.323 | O66: =H66*N66 -> 0.43605 | P66: =DATOS!$C$10*N66 -> 1.88955 | Q66: =-P66/100 -> -0.0188955 | S66: .STD R1.5 · nodos 51–18
B67: VA-2 | C67: Eje A | E67: 67 | F67: 8.10001 | G67: 9.45001 | H67: =G67-F67 -> 1.35 | I67: 10.212 | J67: 10.144 | K67: 9.6 | L67: =(I67-K67)/2 -> 0.306 | M67: =(J67-K67)/2 -> 0.272 | N67: =(L67+M67)/2 -> 0.289 | O67: =H67*N67 -> 0.39015 | P67: =DATOS!$C$10*N67 -> 1.69065 | Q67: =-P67/100 -> -0.0169065 | S67: .STD R1.5 · nodos 50–51
B68: VA-2 | C68: Eje A | E68: 66 | F68: 9.45001 | G68: 10.8 | H68: =G68-F68 -> 1.34999 | I68: 10.144 | J68: 10.076 | K68: 9.6 | L68: =(I68-K68)/2 -> 0.272 | M68: =(J68-K68)/2 -> 0.238 | N68: =(L68+M68)/2 -> 0.255 | O68: =H68*N68 -> 0.34424745 | P68: =DATOS!$C$10*N68 -> 1.49175 | Q68: =-P68/100 -> -0.0149175 | S68: .STD R1.5 · nodos 49–50
B69: VA-2 | C69: Eje A | E69: 65 | F69: 10.8 | G69: 12.15 | H69: =G69-F69 -> 1.35 | I69: 10.076 | J69: 10.008 | K69: 9.6 | L69: =(I69-K69)/2 -> 0.238 | M69: =(J69-K69)/2 -> 0.204 | N69: =(L69+M69)/2 -> 0.221 | O69: =H69*N69 -> 0.29835 | P69: =DATOS!$C$10*N69 -> 1.29285 | Q69: =-P69/100 -> -0.0129285 | S69: .STD R1.5 · nodos 48–49
B70: VA-2 | C70: Eje A | E70: 43 | F70: 12.15 | G70: 13.5 | H70: =G70-F70 -> 1.35 | I70: 10.008 | J70: 9.94002 | K70: 9.6 | L70: =(I70-K70)/2 -> 0.204 | M70: =(J70-K70)/2 -> 0.17001 | N70: =(L70+M70)/2 -> 0.187005 | O70: =H70*N70 -> 0.25245675 | P70: =DATOS!$C$10*N70 -> 1.0939793 | Q70: =-P70/100 -> -0.010939793 | S70: .STD R1.5 · nodos 14–48
B71: VA-3 | C71: Eje A | E71: 47 | F71: 13.5 | G71: 14.75 | H71: =G71-F71 -> 1.25 | I71: 9.94002 | J71: 9.88002 | K71: 9.6 | L71: =(I71-K71)/2 -> 0.17001 | M71: =(J71-K71)/2 -> 0.14001 | N71: =(L71+M71)/2 -> 0.15501 | O71: =H71*N71 -> 0.1937625 | P71: =DATOS!$C$10*N71 -> 0.9068085 | Q71: =-P71/100 -> -0.009068085 | S71: .STD R1.5 · nodos 14–38
B72: VA-3 | C72: Eje A | E72: 54 | F72: 14.75 | G72: 16 | H72: =G72-F72 -> 1.25 | I72: 9.88002 | J72: 9.82002 | K72: 9.6 | L72: =(I72-K72)/2 -> 0.14001 | M72: =(J72-K72)/2 -> 0.11001 | N72: =(L72+M72)/2 -> 0.12501 | O72: =H72*N72 -> 0.1562625 | P72: =DATOS!$C$10*N72 -> 0.7313085 | Q72: =-P72/100 -> -0.007313085 | S72: .STD R1.5 · nodos 38–16
... B84: VB-3 | C84: Eje B | E84: 55 | F84: 14.75 | G84: 16 | H84: =G84-F84 -> 1.25 | I84: 9.88002 | J84: 9.82002 | K84: 9.6 | L84: =(I84-K84)/2 -> 0.14001 | M84: =(J84-K84)/2 -> 0.11001 | N84: =(L84+M84)/2 -> 0.12501 | O84: =H84*N84 -> 0.1562625 | P84: =DATOS!$C$10*N84 -> 0.7313085 | Q84: =-P84/100 -> -0.007313085 | S84: .STD R1.5 · nodos 39–13
B85: Total | C85: Franja superior de muros laterales que va a las vigas de alero | O85: =SUM(O61:O84) -> 9.8800669
B87: C. MURO FRONTAL — EJE 1 (Z = 0)
B88: Vanos: puerta de 1.30 × 2.40 m (X 0.64 a 1.94) y vano del nose dock de 5.10 × 6.33 m (X 2.49 a 7.59), sin carga. El larguero de 2.40 sobre la puerta y el dintel MCE6-12 de 6.33 sobre el vano sólo toman la franja de arriba.
B89: ID | C89: Nivel | D89: Perfil | E89: Y (m) | F89: X desde (m) | G89: X hasta (m) | H89: L (m) | I89: Y abajo (m) | J89: Y arriba (m) | K89: Franja desde (m) | L89: Franja hasta (m) | M89: h (m) | N89: A (m²) | O89: w CM (kg/m) | P89: STAAD CM (kg/cm) | Q89: Miembro STAAD | S89: Referencia
...

Sheet NODOS_TECHO
B1: NODOS DE COLUMNA — TECHO: ÁREA TRIBUTARIA, CM, CV Y MASA SÍSMICA PUNTUAL (CASOS 1, 2 Y 4)
B2: El techo se reparte a los 8 nodos de cabeza de columna: mitad del claro en X y mitad de la separación entre marcos en Z, en proyección horizontal. En STAAD R1.5 la CM (caso 1) y la CV (caso 2) van como JOINT LOAD FY negativa en estos nodos; la masa (caso 4) como JOINT LOAD FX y FZ junto con la de muros (NODOS_MUROS). Largueros y vigas ya no llevan carga de techo.
B4: A. TECHO → NODOS DE CABEZA DE COLUMNA
B5: ID | C5: Nodo STAAD | D5: Eje | E5: Lado | F5: X desde (m) | G5: X hasta (m) | H5: Z desde (m) | I5: Z hasta (m) | J5: A (m²) | K5: CM techo (kg) | L5: w_i techo (kg) | M5: Masa techo (kg) | N5: CV techo (kg) | O5: Línea STAAD caso 1 (CM) | P5: Línea STAAD caso 2 (CV) | Q5: Referencia
C6: del .STD | F6: mitad del claro | G6: mitad / claro | H6: (Z ant. + Z)/2 | I6: (Z + Z sig.)/2 | J6: ΔX × ΔZ | K6: CM techo × A | L6: w_i × A | M6: K + L | N6: w_m × A | O6: nodo FY −K | P6: nodo FY −N
B7: T-1A | C7: 20 | D7: 1 | E7: A | F7: 0 | G7: =DATOS!$C$30 -> 5.04 | H7: =DATOS!$C$31 -> 0 | I7: =(DATOS!$C$31+DATOS!$C$32)/2 -> 3.375005 | J7: =(G7-F7)*(I7-H7) -> 17.010025 | K7: =DATOS!$C$8*J7 -> 328.63369 | L7: =DATOS!$C$23*J7 -> 0 | M7: =K7+L7 -> 328.63369 | N7: =DATOS!$C$22*J7 -> 340.2005 | O7: =C7&" FY "&TEXT(-K7,"0.0") -> 20 FY -328.6 | P7: =C7&" FY "&TEXT(-N7,"0.0") -> 20 FY -340.2 | Q7: Área tributaria (mitades) · CM y CV (casos 1 y 2) y masa de techo (caso 4) en cabeza de columna · nodo 20 del .STD R1.5
B8: T-1B | C8: 21 | D8: 1 | E8: B | F8: =DATOS!$C$30 -> 5.04 | G8: =DATOS!$C$29 -> 10.08 | H8: =DATOS!$C$31 -> 0 | I8: =(DATOS!$C$31+DATOS!$C$32)/2 -> 3.375005 | J8: =(G8-F8)*(I8-H8) -> 17.010025 | K8: =DATOS!$C$8*J8 -> 328.63369 | L8: =DATOS!$C$23*J8 -> 0 | M8: =K8+L8 -> 328.63369 | N8: =DATOS!$C$22*J8 -> 340.2005 | O8: =C8&" FY "&TEXT(-K8,"0.0") -> 21 FY -328.6 | P8: =C8&" FY "&TEXT(-N8,"0.0") -> 21 FY -340.2 | Q8: Área tributaria (mitades) · CM y CV (casos 1 y 2) y masa de techo (caso 4) en cabeza de columna · nodo 21 del .STD R1.5
B9: T-2A | C9: 18 | D9: 2 | E9: A | F9: 0 | G9: =DATOS!$C$30 -> 5.04 | H9: =(DATOS!$C$31+DATOS!$C$32)/2 -> 3.375005 | I9: =(DATOS!$C$32+DATOS!$C$33)/2 -> 10.125005 | J9: =(G9-F9)*(I9-H9) -> 34.02 | K9: =DATOS!$C$8*J9 -> 657.2664 | L9: =DATOS!$C$23*J9 -> 0 | M9: =K9+L9 -> 657.2664 | N9: =DATOS!$C$22*J9 -> 680.4 | O9: =C9&" FY "&TEXT(-K9,"0.0") -> 18 FY -657.3 | P9: =C9&" FY "&TEXT(-N9,"0.0") -> 18 FY -680.4 | Q9: Área tributaria (mitades) · CM y CV (casos 1 y 2) y masa de techo (caso 4) en cabeza de columna · nodo 18 del .STD R1.5
B10: T-2B | C10: 19 | D10: 2 | E10: B | F10: =DATOS!$C$30 -> 5.04 | G10: =DATOS!$C$29 -> 10.08 | H10: =(DATOS!$C$31+DATOS!$C$32)/2 -> 3.375005 | I10: =(DATOS!$C$32+DATOS!$C$33)/2 -> 10.125005 | J10: =(G10-F10)*(I10-H10) -> 34.02 | K10: =DATOS!$C$8*J10 -> 657.2664 | L10: =DATOS!$C$23*J10 -> 0 | M10: =K10+L10 -> 657.2664 | N10: =DATOS!$C$22*J10 -> 680.4 | O10: =C10&" FY "&TEXT(-K10,"0.0") -> 19 FY -657.3 | P10: =C10&" FY "&TEXT(-N10,"0.0") -> 19 FY -680.4 | Q10: Área tributaria (mitades) · CM y CV (casos 1 y 2) y masa de techo (caso 4) en cabeza de columna · nodo 19 del .STD R1.5
B11: T-3A | C11: 14 | D11: 3 | E11: A | F11: 0 | G11: =DATOS!$C$30 -> 5.04 | H11: =(DATOS!$C$32+DATOS!$C$33)/2 -> 10.125005 | I11: =(DATOS!$C$33+DATOS!$C$34)/2 -> 14.75 | J11: =(G11-F11)*(I11-H11) -> 23.309975 | K11: =DATOS!$C$8*J11 -> 450.34871 | L11: =DATOS!$C$23*J11 -> 0 | M11: =K11+L11 -> 450.34871 | N11: =DATOS!$C$22*J11 -> 466.1995 | O11: =C11&" FY "&TEXT(-K11,"0.0") -> 14 FY -450.3 | P11: =C11&" FY "&TEXT(-N11,"0.0") -> 14 FY -466.2 | Q11: Área tributaria (mitades) · CM y CV (casos 1 y 2) y masa de techo (caso 4) en cabeza de columna · nodo 14 del .STD R1.5
B12: T-3B | C12: 15 | D12: 3 | E12: B | F12: =DATOS!$C$30 -> 5.04 | G12: =DATOS!$C$29 -> 10.08 | H12: =(DATOS!$C$32+DATOS!$C$33)/2 -> 10.125005 | I12: =(DATOS!$C$33+DATOS!$C$34)/2 -> 14.75 | J12: =(G12-F12)*(I12-H12) -> 23.309975 | K12: =DATOS!$C$8*J12 -> 450.34871 | L12: =DATOS!$C$23*J12 -> 0 | M12: =K12+L12 -> 450.34871 | N12: =DATOS!$C$22*J12 -> 466.1995 | O12: =C12&" FY "&TEXT(-K12,"0.0") -> 15 FY -450.3 | P12: =C12&" FY "&TEXT(-N12,"0.0") -> 15 FY -466.2 | Q12: Área tributaria (mitades) · CM y CV (casos 1 y 2) y masa de techo (caso 4) en cabeza de columna · nodo 15 del .STD R1.5
B13: T-4A | C13: 16 | D13: 4 | E13: A | F13: 0 | G13: =DATOS!$C$30 -> 5.04 | H13: =(DATOS!$C$33+DATOS!$C$34)/2 -> 14.75 | I13: =DATOS!$C$34 -> 16 | J13: =(G13-F13)*(I13-H13) -> 6.3 | K13: =DATOS!$C$8*J13 -> 121.716 | L13: =DATOS!$C$23*J13 -> 0 | M13: =K13+L13 -> 121.716 | N13: =DATOS!$C$22*J13 -> 126 | O13: =C13&" FY "&TEXT(-K13,"0.0") -> 16 FY -121.7 | P13: =C13&" FY "&TEXT(-N13,"0.0") -> 16 FY -126.0 | Q13: Área tributaria (mitades) · CM y CV (casos 1 y 2) y masa de techo (caso 4) en cabeza de columna · nodo 16 del .STD R1.5
B14: T-4B | C14: 13 | D14: 4 | E14: B | F14: =DATOS!$C$30 -> 5.04 | G14: =DATOS!$C$29 -> 10.08 | H14: =(DATOS!$C$33+DATOS!$C$34)/2 -> 14.75 | I14: =DATOS!$C$34 -> 16 | J14: =(G14-F14)*(I14-H14) -> 6.3 | K14: =DATOS!$C$8*J14 -> 121.716 | L14: =DATOS!$C$23*J14 -> 0 | M14: =K14+L14 -> 121.716 | N14: =DATOS!$C$22*J14 -> 126 | O14: =C14&" FY "&TEXT(-K14,"0.0") -> 13 FY -121.7 | P14: =C14&" FY "&TEXT(-N14,"0.0") -> 13 FY -126.0 | Q14: Área tributaria (mitades) · CM y CV (casos 1 y 2) y masa de techo (caso 4) en cabeza de columna · nodo 13 del .STD R1.5
B15: Total | C15: Suma de áreas de techo (debe dar claro × largo = 10.08 × 16.00) | J15: =SUM(J7:J14) -> 161.28 | K15: =SUM(K7:K14) -> 3115.9296 | L15: =SUM(L7:L14) -> 0 | M15: =SUM(M7:M14) -> 3115.9296 | N15: =SUM(N7:N14) -> 3225.6 | Q15: =IF(AND(ABS(J15-TECHO!$J$20)<0.01,ABS(N15-RESUMEN!$C$16)<0.5),"CUADRA","NO CUADRA") -> CUADRA

Sheet NODOS_MUROS
B1: NODOS DE COLUMNA — MUROS: ÁREA TRIBUTARIA Y MASA SÍSMICA PUNTUAL (CASO 4)
B2: Cada franja de larguero (mitad de la separación a cada lado, igual que la hoja MUROS) se parte a la mitad entre los dos nodos de columna de sus extremos. La franja de arriba del último larguero baja a los nodos de cabeza de columna. Los vanos no cargan. La franja de la base (0 a 0.60 m) se va a la cimentación.
B4: A. PANELES DE MURO → NODOS DE COLUMNA DE SUS EXTREMOS
B5: ID | C5: Muro | D5: Nivel | E5: Nodo A | F5: Nodo B | G5: L (m) | H5: h en A (m) | I5: h en B (m) | J5: A (m²) | K5: Masa (kg) | L5: Referencia
E6: del .STD | F6: del .STD | G6: del croquis DXF | H6: franja en el nodo A | I6: franja en el nodo B | J6: L × (h A + h B) ÷ 2 | K6: CM muros × A
B7: LA-1.1 | C7: Eje A (X = 0) | D7: 1 | E7: 108 | F7: 110 | G7: 6.75 | H7: 1.2 | I7: 1.2 | J7: =G7*(H7+I7)/2 -> 8.1 | K7: =DATOS!$C$10*J7 -> 47.385 | L7: Franja de LA-1.1 (hoja MUROS) · croquis DXF R1.5
B8: LA-1.2 | C8: Eje A (X = 0) | D8: 1 | E8: 110 | F8: 111 | G8: 6.75 | H8: 1.2 | I8: 1.2 | J8: =G8*(H8+I8)/2 -> 8.1 | K8: =DATOS!$C$10*J8 -> 47.385 | L8: Franja de LA-1.2 (hoja MUROS) · croquis DXF R1.5
B9: LA-1.3 | C9: Eje A (X = 0) | D9: 1 | E9: 111 | F9: 112 | G9: 2.5 | H9: 1.2 | I9: 1.2 | J9: =G9*(H9+I9)/2 -> 3 | K9: =DATOS!$C$10*J9 -> 17.55 | L9: Franja de LA-1.3 (hoja MUROS) · croquis DXF R1.5
B10: LA-2.1 | C10: Eje A (X = 0) | D10: 2 | E10: 120 | F10: 122 | G10: 6.75 | H10: 1.2 | I10: 1.2 | J10: =G10*(H10+I10)/2 -> 8.1 | K10: =DATOS!$C$10*J10 -> 47.385 | L10: Franja de LA-2.1 (hoja MUROS) · croquis DXF R1.5
B11: LA-2.2 | C11: Eje A (X = 0) | D11: 2 | E11: 122 | F11: 123 | G11: 6.75 | H11: 1.2 | I11: 1.2 | J11: =G11*(H11+I11)/2 -> 8.1 | K11: =DATOS!$C$10*J11 -> 47.385 | L11: Franja de LA-2.2 (hoja MUROS) · croquis DXF R1.5
B12: LA-2.3 | C12: Eje A (X = 0) | D12: 2 | E12: 123 | F12: 124 | G12: 2.5 | H12: 1.2 | I12: 1.2 | J12: =G12*(H12+I12)/2 -> 3 | K12: =DATOS!$C$10*J12 -> 17.55 | L12: Franja de LA-2.3 (hoja MUROS) · croquis DXF R1.5
B13: LA-3.1 | C13: Eje A (X = 0) | D13: 3 | E13: 132 | F13: 134 | G13: 6.75 | H13: 1.2 | I13: 1.2 | J13: =G13*(H13+I13)/2 -> 8.1 | K13: =DATOS!$C$10*J13 -> 47.385 | L13: Franja de LA-3.1 (hoja MUROS) · croquis DXF R1.5
B14: LA-3.2 | C14: Eje A (X = 0) | D14: 3 | E14: 134 | F14: 135 | G14: 6.75 | H14: 1.2 | I14: 1.2 | J14: =G14*(H14+I14)/2 -> 8.1 | K14: =DATOS!$C$10*J14 -> 47.385 | L14: Franja de LA-3.2 (hoja MUROS) · croquis DXF R1.5
B15: LA-3.3 | C15: Eje A (X = 0) | D15: 3 | E15: 135 | F15: 136 | G15: 2.5 | H15: 1.2 | I15: 1.2 | J15: =G15*(H15+I15)/2 -> 3 | K15: =DATOS!$C$10*J15 -> 17.55 | L15: Franja de LA-3.3 (hoja MUROS) · croquis DXF R1.5
B16: LA-4.1 | C16: Eje A (X = 0) | D16: 4 | E16: 144 | F16: 146 | G16: 6.75 | H16: 1.2 | I16: 1.2 | J16: =G16*(H16+I16)/2 -> 8.1 | K16: =DATOS!$C$10*J16 -> 47.385 | L16: Franja de LA-4.1 (hoja MUROS) · croquis DXF R1.5
B17: LA-4.2 | C17: Eje A (X = 0) | D17: 4 | E17: 146 | F17: 147 | G17: 6.75 | H17: 1.2 | I17: 1.2 | J17: =G17*(H17+I17)/2 -> 8.1 | K17: =DATOS!$C$10*J17 -> 47.385 | L17: Franja de LA-4.2 (hoja MUROS) · croquis DXF R1.5
B18: LA-4.3 | C18: Eje A (X = 0) | D18: 4 | E18: 147 | F18: 148 | G18: 2.5 | H18: 1.2 | I18: 1.2 | J18: =G18*(H18+I18)/2 -> 3 | K18: =DATOS!$C$10*J18 -> 17.55 | L18: Franja de LA-4.3 (hoja MUROS) · croquis DXF R1.5
... B80: L1-T | C80: Frontal eje 1 (Z = 0) | D80: 10 | E80: 20 | F80: 21 | G80: 10.08 | H80: 0.51 | I80: 0.51 | J80: =G80*(H80+I80)/2 -> 5.1408 | K80: =DATOS!$C$10*J80 -> 30.07368 | L80: Franja superior (mitad entre último larguero y alero) → cabeza de columna · croquis DXF R1.5
B81: Total | C81: Área de muros en paneles (debe dar la suma de MUROS: laterales + franja alta + frontal) | J81: =SUM(J7:J80) -> 377.18691 | K81: =SUM(K7:K80) -> 2206.5434 | L81: =IF(ABS(J81-(MUROS!$O$55+MUROS!$O$85+MUROS!$N$111))<0.02,"CUADRA","NO CUADRA") -> CUADRA
B83: B. MASA POR NODO DE COLUMNA (TECHO + MUROS) → JOINT LOAD DEL CASO 4
B84: Nodo | C84: X (m) | D84: Y (m) | E84: Z (m) | F84: Ubicación | G84: A muro (m²) | H84: Masa muro (kg) | I84: Masa techo (kg) | J84: Masa total (kg) | K84: Línea para STAAD (FX = FZ) | L84: Referencia
C85: del .STD | D85: del .STD | E85: del .STD | G85: ½ (SUMIF de A y B) | H85: CM muros × A | I85: SUMIF de NODOS_TECHO | J85: H + I | K85: nodo FX FZ
B86: 13 | C86: 10.08 | D86: 9.82 | E86: 16 | F86: Eje B · marco 4 | G86: =0.5*(SUMIF($E$7:$E$80,B86,$J$7:$J$80)+SUMIF($F$7:$F$80,B86,$J$7:$J$80)) -> 0.175 | H86: =DATOS!$C$10*G86 -> 1.02375 | I86: =SUMIF(NODOS_TECHO!$C$7:$C$14,B86,NODOS_TECHO!$M$7:$M$14) -> 121.716 | J86: =H86+I86 -> 122.73975 | K86: =B86&" FX "&TEXT(J86,"0.0")&" FZ "&TEXT(J86,"0.0") -> 13 FX 122.7 FZ 122.7 | L86: Área tributaria por nodo · Walmart: JOINT LOAD FX FZ en el caso 4
B87: 14 | C87: 0 | D87: 9.94 | E87: 13.5 | F87: Eje A · marco 3 | G87: =0.5*(SUMIF($E$7:$E$80,B87,$J$7:$J$80)+SUMIF($F$7:$F$80,B87,$J$7:$J$80)) -> 1.035625 | H87: =DATOS!$C$10*G87 -> 6.0584062 | I87: =SUMIF(NODOS_TECHO!$C$7:$C$14,B87,NODOS_TECHO!$M$7:$M$14) -> 450.34871 | J87: =H87+I87 -> 456.40712 | K87: =B87&" FX "&TEXT(J87,"0.0")&" FZ "&TEXT(J87,"0.0") -> 14 FX 456.4 FZ 456.4 | L87: Área tributaria por nodo · Walmart: JOINT LOAD FX FZ en el caso 4
B88: 15 | C88: 10.08 | D88: 9.94 | E88: 13.5 | F88: Eje B · marco 3 | G88: =0.5*(SUMIF($E$7:$E$80,B88,$J$7:$J$80)+SUMIF($F$7:$F$80,B88,$J$7:$J$80)) -> 1.035625 | H88: =DATOS!$C$10*G88 -> 6.0584062 | I88: =SUMIF(NODOS_TECHO!$C$7:$C$14,B88,NODOS_TECHO!$M$7:$M$14) -> 450.34871 | J88: =H88+I88 -> 456.40712 | K88: =B88&" FX "&TEXT(J88,"0.0")&" FZ "&TEXT(J88,"0.0") -> 15 FX 456.4 FZ 456.4 | L88: Área tributaria por nodo · Walmart: JOINT LOAD FX FZ en el caso 4
B89: 16 | C89: 0 | D89: 9.82 | E89: 16 | F89: Eje A · marco 4 | G89: =0.5*(SUMIF($E$7:$E$80,B89,$J$7:$J$80)+SUMIF($F$7:$F$80,B89,$J$7:$J$80)) -> 0.175 | H89: =DATOS!$C$10*G89 -> 1.02375 | I89: =SUMIF(NODOS_TECHO!$C$7:$C$14,B89,NODOS_TECHO!$M$7:$M$14) -> 121.716 | J89: =H89+I89 -> 122.73975 | K89: =B89&" FX "&TEXT(J89,"0.0")&" FZ "&TEXT(J89,"0.0") -> 16 FX 122.7 FZ 122.7 | L89: Área tributaria por nodo · Walmart: JOINT LOAD FX FZ en el caso 4
B90: 18 | C90: 0 | D90: 10.28 | E90: 6.75 | F90: Eje A · marco 2 | G90: =0.5*(SUMIF($E$7:$E$80,B90,$J$7:$J$80)+SUMIF($F$7:$F$80,B90,$J$7:$J$80)) -> 2.295 | H90: =DATOS!$C$10*G90 -> 13.42575 | I90: =SUMIF(NODOS_TECHO!$C$7:$C$14,B90,NODOS_TECHO!$M$7:$M$14) -> 657.2664 | J90: =H90+I90 -> 670.69215 | K90: =B90&" FX "&TEXT(J90,"0.0")&" FZ "&TEXT(J90,"0.0") -> 18 FX 670.7 FZ 670.7 | L90: Área tributaria por nodo · Walmart: JOINT LOAD FX FZ en el caso 4
B91: 19 | C91: 10.08 | D91: 10.28 | E91: 6.75 | F91: Eje B · marco 2 | G91: =0.5*(SUMIF($E$7:$E$80,B91,$J$7:$J$80)+SUMIF($F$7:$F$80,B91,$J$7:$J$80)) -> 2.295 | H91: =DATOS!$C$10*G91 -> 13.42575 | I91: =SUMIF(NODOS_TECHO!$C$7:$C$14,B91,NODOS_TECHO!$M$7:$M$14) -> 657.2664 | J91: =H91+I91 -> 670.69215 | K91: =B91&" FX "&TEXT(J91,"0.0")&" FZ "&TEXT(J91,"0.0") -> 19 FX 670.7 FZ 670.7 | L91: Área tributaria por nodo · Walmart: JOINT LOAD FX FZ en el caso 4
B92: 20 | C92: 0 | D92: 10.62 | E92: 0 | F92: Esquina Z=0 · eje A | G92: =0.5*(SUMIF($E$7:$E$80,B92,$J$7:$J$80)+SUMIF($F$7:$F$80,B92,$J$7:$J$80)) -> 4.004775 | H92: =DATOS!$C$10*G92 -> 23.427934 | I92: =SUMIF(NODOS_TECHO!$C$7:$C$14,B92,NODOS_TECHO!$M$7:$M$14) -> 328.63369 | J92: =H92+I92 -> 352.06162 | K92: =B92&" FX "&TEXT(J92,"0.0")&" FZ "&TEXT(J92,"0.0") -> 20 FX 352.1 FZ 352.1 | L92: Área tributaria por nodo · Walmart: JOINT LOAD FX FZ en el caso 4
B93: 21 | C93: 10.08 | D93: 10.62 | E93: 0 | F93: Esquina Z=0 · eje B | G93: =0.5*(SUMIF($E$7:$E$80,B93,$J$7:$J$80)+SUMIF($F$7:$F$80,B93,$J$7:$J$80)) -> 4.004775 | H93: =DATOS!$C$10*G93 -> 23.427934 | I93: =SUMIF(NODOS_TECHO!$C$7:$C$14,B93,NODOS_TECHO!$M$7:$M$14) -> 328.63369 | J93: =H93+I93 -> 352.06162 | K93: =B93&" FX "&TEXT(J93,"0.0")&" FZ "&TEXT(J93,"0.0") -> 21 FX 352.1 FZ 352.1 | L93: Área tributaria por nodo · Walmart: JOINT LOAD FX FZ en el caso 4
B94: 26 | C94: 2.487 | D94: 6.33 | E94: 0 | F94: Frente Z=0 · X=2.49 m | G94: =0.5*(SUMIF($E$7:$E$80,B94,$J$7:$J$80)+SUMIF($F$7:$F$80,B94,$J$7:$J$80)) -> 1.855668 | H94: =DATOS!$C$10*G94 -> 10.855658 | I94: =SUMIF(NODOS_TECHO!$C$7:$C$14,B94,NODOS_TECHO!$M$7:$M$14) -> 0 | J94: =H94+I94 -> 10.855658 | K94: =B94&" FX "&TEXT(J94,"0.0")&" FZ "&TEXT(J94,"0.0") -> 26 FX 10.9 FZ 10.9 | L94: Área tributaria por nodo · Walmart: JOINT LOAD FX FZ en el caso 4
B95: 27 | C95: 7.589 | D95: 6.33 | E95: 0 | F95: Frente Z=0 · X=7.59 m | G95: =0.5*(SUMIF($E$7:$E$80,B95,$J$7:$J$80)+SUMIF($F$7:$F$80,B95,$J$7:$J$80)) -> 1.857048 | H95: =DATOS!$C$10*G95 -> 10.863731 | I95: =SUMIF(NODOS_TECHO!$C$7:$C$14,B95,NODOS_TECHO!$M$7:$M$14) -> 0 | J95: =H95+I95 -> 10.863731 | K95: =B95&" FX "&TEXT(J95,"0.0")&" FZ "&TEXT(J95,"0.0") -> 27 FX 10.9 FZ 10.9 | L95: Área tributaria por nodo · Walmart: JOINT LOAD FX FZ en el caso 4
B96: 108 | C96: 0 | D96: 1.2 | E96: 0 | F96: Esquina Z=0 · eje A | G96: =0.5*(SUMIF($E$7:$E$80,B96,$J$7:$J$80)+SUMIF($F$7:$F$80,B96,$J$7:$J$80)) -> 4.4355 | H96: =DATOS!$C$10*G96 -> 25.947675 | I96: =SUMIF(NODOS_TECHO!$C$7:$C$14,B96,NODOS_TECHO!$M$7:$M$14) -> 0 | J96: =H96+I96 -> 25.947675 | K96: =B96&" FX "&TEXT(J96,"0.0")&" FZ "&TEXT(J96,"0.0") -> 108 FX 25.9 FZ 25.9 | L96: Área tributaria por nodo · Walmart: JOINT LOAD FX FZ en el caso 4
B97: 109 | C97: 10.08 | D97: 1.2 | E97: 0 | F97: Esquina Z=0 · eje B | G97: =0.5*(SUMIF($E$7:$E$80,B97,$J$7:$J$80)+SUMIF($F$7:$F$80,B97,$J$7:$J$80)) -> 5.5449 | H97: =DATOS!$C$10*G97 -> 32.437665 | I97: =SUMIF(NODOS_TECHO!$C$7:$C$14,B97,NODOS_TECHO!$M$7:$M$14) -> 0 | J97: =H97+I97 -> 32.437665 | K97: =B97&" FX "&TEXT(J97,"0.0")&" FZ "&TEXT(J97,"0.0") -> 109 FX 32.4 FZ 32.4 | L97: Área tributaria por nodo · Walmart: JOINT LOAD FX FZ en el caso 4
... B175: 201 | C175: 10.08 | D175: 6.33 | E175: 0 | F175: Esquina Z=0 · eje B | G175: =0.5*(SUMIF($E$7:$E$80,B175,$J$7:$J$80)+SUMIF($F$7:$F$80,B175,$J$7:$J$80)) -> 0.74745 | H175: =DATOS!$C$10*G175 -> 4.3725825 | I175: =SUMIF(NODOS_TECHO!$C$7:$C$14,B175,NODOS_TECHO!$M$7:$M$14) -> 0 | J175: =H175+I175 -> 4.3725825 | K175: =B175&" FX "&TEXT(J175,"0.0")&" FZ "&TEXT(J175,"0.0") -> 201 FX 4.4 FZ 4.4 | L175: Área tributaria por nodo · Walmart: JOINT LOAD FX FZ en el caso 4
B176: Total | C176: Masa nodal total (techo + muros) | G176: =SUM(G86:G175) -> 377.18691 | H176: =SUM(H86:H175) -> 2206.5434 | I176: =SUM(I86:I175) -> 3115.9296 | J176: =SUM(J86:J175) -> 5322.473 | K176: =IF(AND(ABS(H176-RESUMEN!$C$15)<0.5,ABS(I176-RESUMEN!$C$14)<0.5),"CUADRA","NO CUADRA") -> CUADRA | L176: Debe dar CM muros y CM techo de RESUMEN (sección 2)

Sheet STAAD
B1: LÍNEAS DE CARGA PARA STAAD (kg/cm y kg) — LAS QUE VAN EN EL .STD R1.5
B2: Armadas con fórmulas desde NODOS_TECHO, MUROS y DATOS. En el .STD R1.5 los JOINT LOAD y los MEMBER LOAD están agrupados por valor (mismo resultado). Si cambias una carga en DATOS, copia de aquí y pega en Edit Input Command File dentro del caso.
B4: CASO 1 — CARGA MUERTA (debajo de SELFWEIGHT Y -1): TECHO EN NODOS + MUROS EN LARGUEROS + CORTINA
B5: ID | C5: Origen | D5: Línea para STAAD | E5: Nota
B6: — | C6: — | D6: JOINT LOAD | E6: Encabezado (techo en cabezas de columna)
B7: ="N"&NODOS_TECHO!C7 -> N20 | C7: NODOS_TECHO | D7: =NODOS_TECHO!O7 -> 20 FY -328.6 | E7: CM de techo × A del nodo
B8: ="N"&NODOS_TECHO!C8 -> N21 | C8: NODOS_TECHO | D8: =NODOS_TECHO!O8 -> 21 FY -328.6 | E8: CM de techo × A del nodo
B9: ="N"&NODOS_TECHO!C9 -> N18 | C9: NODOS_TECHO | D9: =NODOS_TECHO!O9 -> 18 FY -657.3 | E9: CM de techo × A del nodo
B10: ="N"&NODOS_TECHO!C10 -> N19 | C10: NODOS_TECHO | D10: =NODOS_TECHO!O10 -> 19 FY -657.3 | E10: CM de techo × A del nodo
B11: ="N"&NODOS_TECHO!C11 -> N14 | C11: NODOS_TECHO | D11: =NODOS_TECHO!O11 -> 14 FY -450.3 | E11: CM de techo × A del nodo
B12: ="N"&NODOS_TECHO!C12 -> N15 | C12: NODOS_TECHO | D12: =NODOS_TECHO!O12 -> 15 FY -450.3 | E12: CM de techo × A del nodo
B13: ="N"&NODOS_TECHO!C13 -> N16 | C13: NODOS_TECHO | D13: =NODOS_TECHO!O13 -> 16 FY -121.7 | E13: CM de techo × A del nodo
B14: ="N"&NODOS_TECHO!C14 -> N13 | C14: NODOS_TECHO | D14: =NODOS_TECHO!O14 -> 13 FY -121.7 | E14: CM de techo × A del nodo
B15: — | C15: — | D15: MEMBER LOAD | E15: Encabezado (muros en largueros)
B19: LA-1.1 | C19: MUROS | D19: ="261 UNI GY "&TEXT(-MUROS!P7/100,"0.0000") -> 261 UNI GY -0.0702 | E19: CM de muros × h
B20: LA-1.2 | C20: MUROS | D20: ="260 UNI GY "&TEXT(-MUROS!P8/100,"0.0000") -> 260 UNI GY -0.0702 | E20: CM de muros × h
B21: LA-1.3 | C21: MUROS | D21: ="259 UNI GY "&TEXT(-MUROS!P9/100,"0.0000") -> 259 UNI GY -0.0702 | E21: CM de muros × h
B22: LA-2.1 | C22: MUROS | D22: ="270 UNI GY "&TEXT(-MUROS!P10/100,"0.0000") -> 270 UNI GY -0.0702 | E22: CM de muros × h
B23: LA-2.2 | C23: MUROS | D23: ="269 UNI GY "&TEXT(-MUROS!P11/100,"0.0000") -> 269 UNI GY -0.0702 | E23: CM de muros × h
B24: LA-2.3 | C24: MUROS | D24: ="268 UNI GY "&TEXT(-MUROS!P12/100,"0.0000") -> 268 UNI GY -0.0702 | E24: CM de muros × h
B25: LA-3.1 | C25: MUROS | D25: ="279 UNI GY "&TEXT(-MUROS!P13/100,"0.0000") -> 279 UNI GY -0.0702 | E25: CM de muros × h
B26: LA-3.2 | C26: MUROS | D26: ="278 UNI GY "&TEXT(-MUROS!P14/100,"0.0000") -> 278 UNI GY -0.0702 | E26: CM de muros × h
B27: LA-3.3 | C27: MUROS | D27: ="277 UNI GY "&TEXT(-MUROS!P15/100,"0.0000") -> 277 UNI GY -0.0702 | E27: CM de muros × h
B28: LA-4.1 | C28: MUROS | D28: ="289 UNI GY "&TEXT(-MUROS!P16/100,"0.0000") -> 289 UNI GY -0.0702 | E28: CM de muros × h
B29: LA-4.2 | C29: MUROS | D29: ="288 UNI GY "&TEXT(-MUROS!P17/100,"0.0000") -> 288 UNI GY -0.0702 | E29: CM de muros × h
B30: LA-4.3 | C30: MUROS | D30: ="287 UNI GY "&TEXT(-MUROS!P18/100,"0.0000") -> 287 UNI GY -0.0702 | E30: CM de muros × h
B31: LA-5.1 | C31: MUROS | D31: ="297 UNI GY "&TEXT(-MUROS!P19/100,"0.0000") -> 297 UNI GY -0.0702 | E31: CM de muros × h
B32: LA-5.2 | C32: MUROS | D32: ="296 UNI GY "&TEXT(-MUROS!P20/100,"0.0000") -> 296 UNI GY -0.0702 | E32: CM de muros × h
B33: LA-5.3 | C33: MUROS | D33: ="295 UNI GY "&TEXT(-MUROS!P21/100,"0.0000") -> 295 UNI GY -0.0702 | E33: CM de muros × h
B34: LA-6.1 | C34: MUROS | D34: ="305 UNI GY "&TEXT(-MUROS!P22/100,"0.0000") -> 305 UNI GY -0.0702 | E34: CM de muros × h
B35: LA-6.2 | C35: MUROS | D35: ="304 UNI GY "&TEXT(-MUROS!P23/100,"0.0000") -> 304 UNI GY -0.0702 | E35: CM de muros × h
B36: LA-6.3 | C36: MUROS | D36: ="303 UNI GY "&TEXT(-MUROS!P24/100,"0.0000") -> 303 UNI GY -0.0702 | E36: CM de muros × h
B37: LA-7.1 | C37: MUROS | D37: ="314 UNI GY "&TEXT(-MUROS!P25/100,"0.0000") -> 314 UNI GY -0.0702 | E37: CM de muros × h
B38: LA-7.2 | C38: MUROS | D38: ="313 UNI GY "&TEXT(-MUROS!P26/100,"0.0000") -> 313 UNI GY -0.0702 | E38: CM de muros × h
B39: LA-7.3 | C39: MUROS | D39: ="312 UNI GY "&TEXT(-MUROS!P27/100,"0.0000") -> 312 UNI GY -0.0702 | E39: CM de muros × h
B40: LA-8.1 | C40: MUROS | D40: ="317 UNI GY "&TEXT(-MUROS!P28/100,"0.0000") -> 317 UNI GY -0.0600 | E40: CM de muros × h
B41: LA-8.2 | C41: MUROS | D41: ="316 UNI GY "&TEXT(-MUROS!P29/100,"0.0000") -> 316 UNI GY -0.0500 | E41: CM de muros × h
B42: LA-8.3 | C42: MUROS | D42: ="315 UNI GY "&TEXT(-MUROS!P30/100,"0.0000") -> 315 UNI GY -0.0433 | E42: CM de muros × h
B43: LB-1.1 | C43: MUROS | D43: ="265 UNI GY "&TEXT(-MUROS!P31/100,"0.0000") -> 265 UNI GY -0.0702 | E43: CM de muros × h
B44: LB-1.2 | C44: MUROS | D44: ="266 UNI GY "&TEXT(-MUROS!P32/100,"0.0000") -> 266 UNI GY -0.0702 | E44: CM de muros × h
...

Sheet RESUMEN
B1: RESUMEN — ÁREAS, CARGAS TOTALES Y PESO SÍSMICO W
B2: Totales para revisar contra STAAD (suma de cargas del caso 1) y el W que va a la hoja de espectros (DATOS C60 y C61).
B4: 1. ÁREAS TRIBUTARIAS
B5: Concepto | C5: Valor | D5: Unidad | E5: Cómo se calcula / de dónde sale | F5: Referencia
B6: Techo (largueros + vigas de marco) | C6: =TECHO!$J$20 -> 161.28 | D6: m² | E6: Suma de la tabla A de TECHO = 10.08 × 16.00. | F6: Hoja TECHO
B7: Muros laterales en largueros (ejes A y B) | C7: =MUROS!$O$55 -> 297.88012 | D7: m² | E7: Suma de la tabla A de MUROS. | F7: Hoja MUROS
B8: Muros laterales, franja a vigas de alero | C8: =MUROS!$O$85 -> 9.8800669 | D8: m² | E8: Suma de la tabla B de MUROS. | F8: Hoja MUROS
B9: Muro frontal (eje 1) en miembros | C9: =MUROS!$N$111 -> 69.426653 | D9: m² | E9: Suma de la tabla C de MUROS (sin vanos ni franja de base). | F9: Hoja MUROS
B10: Muros en total (van a largueros y vigas en STAAD) | C10: =C7+C8+C9 -> 377.18684 | D10: m² | E10: CALCULADA. | F10: —
B12: 2. CARGAS TOTALES APLICADAS EN STAAD
B13: Concepto | C13: Valor | D13: Unidad | E13: Cómo se calcula / de dónde sale | F13: Referencia
B14: CM de techo (caso 1) | C14: =DATOS!$C$8*C6 -> 3115.9296 | D14: kg | E14: CM de techo × área de techo. En STAAD: JOINT LOAD FY en las 8 cabezas de columna. | F14: DATOS C8 · tabla de CM
B15: CM de muros (caso 1) | C15: =DATOS!$C$10*C10 -> 2206.543 | D15: kg | E15: CM de muros × área de muros en miembros. En STAAD: UNI GY en largueros, franja alta de VA/VB/VM-1 y dintel. | F15: DATOS C10 · tabla de CM
B16: CV máxima de techo (caso 2) | C16: =DATOS!$C$22*C6 -> 3225.6 | D16: kg | E16: w_m × área de techo. En STAAD: JOINT LOAD FY en las 8 cabezas de columna. | F16: RESESCO · Tabla, pág. 12
B17: CV instantánea de techo (caso 3) | C17: =DATOS!$C$23*C6 -> 0 | D17: kg | E17: w_i × área de techo. | F17: RESESCO · Tabla, pág. 12
B18: CM de cortina (casos 1 y 4) | C18: =DATOS!$C$49 -> 387.51754 | D18: kg | E18: Peso de la cortina de oruga sobre el dintel (miembro 25). | F18: DATOS · ficha técnica Protec Ingeniería
B20: 3. PESO PROPIO DEL ACERO (LO QUE CALCULA SELFWEIGHT)
B21: Longitudes medidas en el modelo R1.5 (mismas que R1.4); áreas de la tabla de usuario del .STD o de AISC (t de diseño = 0.93 t nominal). Densidad del acero del .STD: 0.00783341 kg/cm³. Secciones R1.5: columnas HSS16x8x5/16, vigas de marco MCE12-12, jambas HSS5x5x1/4.
B22: Perfil | C22: L total (m) | D22: A (cm²) | E22: Peso (kg) = L × A × densidad | F22: Referencia del área
B23: HSST16X8X0.3125 | C23: 81.32 | D23: 84.6848 | E23: =C23*100*D23*0.00783341 -> 5394.531 | F23: HSS 16x8x5/16 · A calculada con t de diseño = 0.93 t y radio 2t (criterio AISC)
B24: HSST5X5X0.25 | C24: 12.66 | D24: 27.7952 | E24: =C24*100*D24*0.00783341 -> 275.6477 | F24: HSS 5x5x1/4 · A calculada con t de diseño = 0.93 t y radio 2t (criterio AISC)
B25: HSST3X3X0.125 | C25: 4.8 | D25: 8.4354 | E25: =C25*100*D25*0.00783341 -> 31.717414 | F25: AISC 15ª ed. Tabla 1-12 (A = 1.31 in²)
B26: MCE12-12 | C26: 72.36 | D26: 25.81 | E26: =C26*100*D26*0.00783341 -> 1462.9767 | F26: .STD · tabla de usuario 3 (vigas de marco VM, VA y VB)
B27: MCE6-12 | C27: 10.08 | D27: 15.0119 | E27: =C27*100*D27*0.00783341 -> 118.53512 | F27: .STD · tabla de usuario 3 (dintel del vano, miembros 25, 326 y 327)
B28: MC4-14 | C28: 400.55 | D28: 3.9423 | E28: =C28*100*D28*0.00783341 -> 1236.9646 | F28: .STD · tabla de usuario 2
B29: PIPX7 | C29: 64.08 | D29: 2.7935 | E29: =C29*100*D29*0.00783341 -> 140.2239 | F29: Supuesto tubo 3/4" XS, AISC Tabla 1-14 (A = 0.433 in²): confírmalo en STAAD
B30: Acero total | E30: =SUM(E23:E29) -> 8660.5965
B32: 4. PESO SÍSMICO W (NTDS: CM + w_i)
B33: Concepto | C33: Valor | D33: Unidad | E33: Cómo se calcula / de dónde sale | F33: Referencia
B34: Acero (peso propio) | C34: =E30/1000 -> 8.6605965 | D34: t | E34: De la sección 3. | F34: SELFWEIGHT de STAAD
B35: CM de techo | C35: =C14/1000 -> 3.1159296 | D35: t | E35: De la sección 2 (JOINT LOAD en las 8 cabezas de columna). | F35: Tabla de CM
B36: CM de muros | C36: =C15/1000 -> 2.206543 | D36: t | E36: De la sección 2 (JOINT LOAD en cada nodo de columna; sin la franja de la base). | F36: Tabla de CM
B37: CM de cortina | C37: =C18/1000 -> 0.38751754 | D37: t | E37: De la sección 2 (UNI GX y GZ en el miembro 25). | F37: DATOS · ficha técnica
B38: CV instantánea w_i | C38: =C17/1000 -> 0 | D38: t | E38: Con pendiente mayor de 5% vale cero. | F38: RESESCO · Art. 25 num. 2, pág. 10 · Tabla, pág. 12
B39: W — peso sísmico | C39: =SUM(C34:C38) -> 14.370587 | D39: t | E39: CALCULADA. Va a EspectrosSismo_Naves_ElSalvador_NTDS_ASCE.xlsx, DATOS C60 (NTDS) y C61 (ASCE). | F39: NTDS-1994 · §4.1.3, pág. 7
B40: Revisión en STAAD | C40: ="La suma de cargas del caso 1 debe dar ≈ "&TEXT(C34+C35+C36+C37,"0.00")&" t" -> La suma de cargas del caso 1 debe dar ≈ 14.37 t | E40: Output de STAAD: SUMMATION OF APPLIED LOADS del caso 1. La masa dinámica (DYNAMIC WEIGHT) debe dar ≈ W. | F40: Salida de STAAD
B42: 5. CORTANTE MÍNIMO NTDS §5.4.1(3) → FACTOR DEL SPECTRUM EN STAAD
B43: Concepto | C43: Valor | D43: Unidad | E43: Cómo se calcula / de dónde sale | F43: Referencia
B44: A — zona sísmica (zona 1) | C44: 0.4 | D44: — | E44: CAPTURA. Ya usada en el espectro del .STD. | F44: NTDS-1994 · Tabla 1, pág. 19
B45: I — factor de importancia (categoría II) | C45: 1.2 | D45: — | E45: CAPTURA. | F45: NTDS-1994 · Tabla 4, pág. 21
...
