Workbook

Sheet DATOS
B1: PRESIONES DE VIENTO EN NAVES — EL SALVADOR (NORMA TÉCNICA PARA DISEÑO POR VIENTO 1997) — DATOS | AA1: auxiliar del croquis (no se toca)
B2: P = C_p·C_z·K·P_o (ec. 4.1). Nave rectangular de una crujía con techo a dos aguas, a un agua (hacia el muro que elijas), plano o curvo. La hoja resuelve de una vez los cuatro vientos (±X, ±Z) con puertas cerradas y con puertas abiertas (PA) y arma las cargas para STAAD. | AA2: s_k | AB2: h_k | AC2: eje dibujo | AE2: M1 u | AF2: M1 v | AG2: M1 x' | AH2: M1 y' | AI2: M2 u | AJ2: M2 v | AK2: M2 x' | AL2: M2 y' | AM2: M3 u | AN2: M3 v | AO2: M3 x' | AP2: M3 y' | AQ2: M4 u | AR2: M4 v | AS2: M4 x' | AT2: M4 y' | AU2: techo x' | AV2: techo y' | AW2: ejes x' | AX2: ejes y' | BA2: A1 x' | BB2: A1 y' | BC2: A2 x' | BD2: A2 y' | BE2: A3 x' | BF2: A3 y' | BG2: A4 x' | BH2: A4 y' | BI2: A5 x' | BJ2: A5 y' | BK2: A6 x' | BL2: A6 y' | BM2: A7 x' | BN2: A7 y' | BO2: A8 x' | BP2: A8 y' | BQ2: A9 x' | BR2: A9 y' | BS2: A10 x' | BT2: A10 y' | BU2: A11 x' | BV2: A11 y' | BW2: A12 x' | BX2: A12 y' | BY2: A13 x' | BZ2: A13 y' | CA2: A14 x' | CB2: A14 y' | CC2: A15 x' | CD2: A15 y' | CE2: A16 x' | CF2: A16 y' | CG2: A17 x' | CH2: A17 y' | CI2: A18 x' | CJ2: A18 y' | CK2: A19 x' | CL2: A19 y' | CM2: A20 x' | CN2: A20 y'
B3: CÓMO SE LLENA: sólo celdas amarillas con letra azul (aquí, en ABERTURAS y en LINEAS). Muro 1 = atrás (Z = 0: puerta y cortina), Muro 2 = frente (Z = L: abierto, sin muro en STAAD), Muro 3 = izquierdo (X = 0), Muro 4 = derecho (X = B), como se ven en el croquis. Los marcos quedan en el plano X-Y. Lo marcado EJEMPLO es del NOSE DOCK H5-H6 (modelo R3): cámbialo para otra nave. | AA3: =$C$23*0/8 -> 0 | AB3: =IF($C$14="PLANO",$C$17,IF($C$14="DOS AGUAS",$C$17+($C$18-$C$17)*(1-ABS(2*($AA$3)/$C$23-1)),IF($C$14="UN AGUA",IF(N($C$25)=0,$C$18-($C$18-$C$17)*($AA$3)/$C$23,$C$17+($C$18-$C$17)*($AA$3)/$C$23),$C$17+4*($C$18-$C$17)*($AA$3)/$C$23*(1-($AA$3)/$C$23)))) -> 10.62 | AC3: =IF($C$22="Z","Z","X") -> Z | AE3: =0 -> 0 | AF3: =0 -> 0 | AG3: =($AE3+0.42*0+$AZ$8)/$AZ$7 -> 0.30543746 | AH3: =($AF3+0.26*0+$AZ$9)/$AZ$7 -> 0.041677003 | AI3: =0 -> 0 | AJ3: =0 -> 0 | AK3: =($AI3+0.42*$C$13+$AZ$8)/$AZ$7 -> 0.72220749 | AL3: =($AJ3+0.26*$C$13+$AZ$9)/$AZ$7 -> 0.2996775 | AM3: =0 -> 0 | AN3: =0 -> 0 | AO3: =(0+0.42*$AM3+$AZ$8)/$AZ$7 -> 0.30543746 | AP3: =($AN3+0.26*$AM3+$AZ$9)/$AZ$7 -> 0.041677003 | AQ3: =0 -> 0 | AR3: =0 -> 0 | AS3: =($C$12+0.42*$AQ3+$AZ$8)/$AZ$7 -> 0.93059251 | AT3: =($AR3+0.26*$AQ3+$AZ$9)/$AZ$7 -> 0.041677003 | AU3: =(IF($AC$3="X",$AA$3+0.42*0,0+0.42*$AA$3)+$AZ$8)/$AZ$7 -> 0.30543746 | AV3: =($AB$3+0.26*IF($AC$3="X",0,$AA$3)+$AZ$9)/$AZ$7 -> 0.7003225 | AW3: =(1.3*$C$12+$AZ$8)/$AZ$7 -> 1.118139 | AX3: =(0+$AZ$9)/$AZ$7 -> 0.041677003 | AY3: ext x' | AZ3: =MAX(1.3*$C$12,$C$12+0.42*$C$13,0.42*1.25*$C$13) -> 16.8 | BA3: =(IF(ABERTURAS!$K$7="OK",CHOOSE(ABERTURAS!$N$7,ABERTURAS!$O$7,ABERTURAS!$O$7+0.42*$C$13,0.42*ABERTURAS!$O$7,$C$12+0.42*ABERTURAS!$O$7),0)+$AZ$8)/$AZ$7 -> 0.34528489 | BB3: =(IF(ABERTURAS!$K$7="OK",ABERTURAS!$Q$7+0.26*CHOOSE(ABERTURAS!$N$7,0,$C$13,ABERTURAS!$O$7,ABERTURAS!$O$7),0)+$AZ$9)/$AZ$7 -> 0.041677003 | BC3: =(IF(ABERTURAS!$K$8="OK",CHOOSE(ABERTURAS!$N$8,ABERTURAS!$O$8,ABERTURAS!$O$8+0.42*$C$13,0.42*ABERTURAS!$O$8,$C$12+0.42*ABERTURAS!$O$8),0)+$AZ$8)/$AZ$7 -> 0.45967338 | BD3: =(IF(ABERTURAS!$K$8="OK",ABERTURAS!$Q$8+0.26*CHOOSE(ABERTURAS!$N$8,0,$C$13,ABERTURAS!$O$8,ABERTURAS!$O$8),0)+$AZ$9)/$AZ$7 -> 0.041677003 | BE3: =(IF(ABERTURAS!$K$9="OK",CHOOSE(ABERTURAS!$N$9,ABERTURAS!$O$9,ABERTURAS!$O$9+0.42*$C$13,0.42*ABERTURAS!$O$9,$C$12+0.42*ABERTURAS!$O$9),0)+$AZ$8)/$AZ$7 -> 0.72220749 | BF3: =(IF(ABERTURAS!$K$9="OK",ABERTURAS!$Q$9+0.26*CHOOSE(ABERTURAS!$N$9,0,$C$13,ABERTURAS!$O$9,ABERTURAS!$O$9),0)+$AZ$9)/$AZ$7 -> 0.2996775 | BG3: =(IF(ABERTURAS!$K$10="OK",CHOOSE(ABERTURAS!$N$10,ABERTURAS!$O$10,ABERTURAS!$O$10+0.42*$C$13,0.42*ABERTURAS!$O$10,$C$12+0.42*ABERTURAS!$O$10),0)+$AZ$8)/$AZ$7 -> 0.30543746 | BH3: =(IF(ABERTURAS!$K$10="OK",ABERTURAS!$Q$10+0.26*CHOOSE(ABERTURAS!$N$10,0,$C$13,ABERTURAS!$O$10,ABERTURAS!$O$10),0)+$AZ$9)/$AZ$7 -> 0.041677003 | BI3: =(IF(ABERTURAS!$K$11="OK",CHOOSE(ABERTURAS!$N$11,ABERTURAS!$O$11,ABERTURAS!$O$11+0.42*$C$13,0.42*ABERTURAS!$O$11,$C$12+0.42*ABERTURAS!$O$11),0)+$AZ$8)/$AZ$7 -> 0.30543746 | BJ3: =(IF(ABERTURAS!$K$11="OK",ABERTURAS!$Q$11+0.26*CHOOSE(ABERTURAS!$N$11,0,$C$13,ABERTURAS!$O$11,ABERTURAS!$O$11),0)+$AZ$9)/$AZ$7 -> 0.041677003 | BK3: =(IF(ABERTURAS!$K$12="OK",CHOOSE(ABERTURAS!$N$12,ABERTURAS!$O$12,ABERTURAS!$O$12+0.42*$C$13,0.42*ABERTURAS!$O$12,$C$12+0.42*ABERTURAS!$O$12),0)+$AZ$8)/$AZ$7 -> 0.30543746 | BL3: =(IF(ABERTURAS!$K$12="OK",ABERTURAS!$Q$12+0.26*CHOOSE(ABERTURAS!$N$12,0,$C$13,ABERTURAS!$O$12,ABERTURAS!$O$12),0)+$AZ$9)/$AZ$7 -> 0.041677003 | BM3: =(IF(ABERTURAS!$K$13="OK",CHOOSE(ABERTURAS!$N$13,ABERTURAS!$O$13,ABERTURAS!$O$13+0.42*$C$13,0.42*ABERTURAS!$O$13,$C$12+0.42*ABERTURAS!$O$13),0)+$AZ$8)/$AZ$7 -> 0.30543746 | BN3: =(IF(ABERTURAS!$K$13="OK",ABERTURAS!$Q$13+0.26*CHOOSE(ABERTURAS!$N$13,0,$C$13,ABERTURAS!$O$13,ABERTURAS!$O$13),0)+$AZ$9)/$AZ$7 -> 0.041677003 | BO3: =(IF(ABERTURAS!$K$14="OK",CHOOSE(ABERTURAS!$N$14,ABERTURAS!$O$14,ABERTURAS!$O$14+0.42*$C$13,0.42*ABERTURAS!$O$14,$C$12+0.42*ABERTURAS!$O$14),0)+$AZ$8)/$AZ$7 -> 0.30543746 | BP3: =(IF(ABERTURAS!$K$14="OK",ABERTURAS!$Q$14+0.26*CHOOSE(ABERTURAS!$N$14,0,$C$13,ABERTURAS!$O$14,ABERTURAS!$O$14),0)+$AZ$9)/$AZ$7 -> 0.041677003 | BQ3: =(IF(ABERTURAS!$K$15="OK",CHOOSE(ABERTURAS!$N$15,ABERTURAS!$O$15,ABERTURAS!$O$15+0.42*$C$13,0.42*ABERTURAS!$O$15,$C$12+0.42*ABERTURAS!$O$15),0)+$AZ$8)/$AZ$7 -> 0.30543746 | BR3: =(IF(ABERTURAS!$K$15="OK",ABERTURAS!$Q$15+0.26*CHOOSE(ABERTURAS!$N$15,0,$C$13,ABERTURAS!$O$15,ABERTURAS!$O$15),0)+$AZ$9)/$AZ$7 -> 0.041677003 | BS3: =(IF(ABERTURAS!$K$16="OK",CHOOSE(ABERTURAS!$N$16,ABERTURAS!$O$16,ABERTURAS!$O$16+0.42*$C$13,0.42*ABERTURAS!$O$16,$C$12+0.42*ABERTURAS!$O$16),0)+$AZ$8)/$AZ$7 -> 0.30543746 | BT3: =(IF(ABERTURAS!$K$16="OK",ABERTURAS!$Q$16+0.26*CHOOSE(ABERTURAS!$N$16,0,$C$13,ABERTURAS!$O$16,ABERTURAS!$O$16),0)+$AZ$9)/$AZ$7 -> 0.041677003 | BU3: =(IF(ABERTURAS!$K$17="OK",CHOOSE(ABERTURAS!$N$17,ABERTURAS!$O$17,ABERTURAS!$O$17+0.42*$C$13,0.42*ABERTURAS!$O$17,$C$12+0.42*ABERTURAS!$O$17),0)+$AZ$8)/$AZ$7 -> 0.30543746 | BV3: =(IF(ABERTURAS!$K$17="OK",ABERTURAS!$Q$17+0.26*CHOOSE(ABERTURAS!$N$17,0,$C$13,ABERTURAS!$O$17,ABERTURAS!$O$17),0)+$AZ$9)/$AZ$7 -> 0.041677003 | BW3: =(IF(ABERTURAS!$K$18="OK",CHOOSE(ABERTURAS!$N$18,ABERTURAS!$O$18,ABERTURAS!$O$18+0.42*$C$13,0.42*ABERTURAS!$O$18,$C$12+0.42*ABERTURAS!$O$18),0)+$AZ$8)/$AZ$7 -> 0.30543746 | BX3: =(IF(ABERTURAS!$K$18="OK",ABERTURAS!$Q$18+0.26*CHOOSE(ABERTURAS!$N$18,0,$C$13,ABERTURAS!$O$18,ABERTURAS!$O$18),0)+$AZ$9)/$AZ$7 -> 0.041677003 | BY3: =(IF(ABERTURAS!$K$19="OK",CHOOSE(ABERTURAS!$N$19,ABERTURAS!$O$19,ABERTURAS!$O$19+0.42*$C$13,0.42*ABERTURAS!$O$19,$C$12+0.42*ABERTURAS!$O$19),0)+$AZ$8)/$AZ$7 -> 0.30543746 | BZ3: =(IF(ABERTURAS!$K$19="OK",ABERTURAS!$Q$19+0.26*CHOOSE(ABERTURAS!$N$19,0,$C$13,ABERTURAS!$O$19,ABERTURAS!$O$19),0)+$AZ$9)/$AZ$7 -> 0.041677003 | CA3: =(IF(ABERTURAS!$K$20="OK",CHOOSE(ABERTURAS!$N$20,ABERTURAS!$O$20,ABERTURAS!$O$20+0.42*$C$13,0.42*ABERTURAS!$O$20,$C$12+0.42*ABERTURAS!$O$20),0)+$AZ$8)/$AZ$7 -> 0.30543746 | CB3: =(IF(ABERTURAS!$K$20="OK",ABERTURAS!$Q$20+0.26*CHOOSE(ABERTURAS!$N$20,0,$C$13,ABERTURAS!$O$20,ABERTURAS!$O$20),0)+$AZ$9)/$AZ$7 -> 0.041677003 | CC3: =(IF(ABERTURAS!$K$21="OK",CHOOSE(ABERTURAS!$N$21,ABERTURAS!$O$21,ABERTURAS!$O$21+0.42*$C$13,0.42*ABERTURAS!$O$21,$C$12+0.42*ABERTURAS!$O$21),0)+$AZ$8)/$AZ$7 -> 0.30543746 | CD3: =(IF(ABERTURAS!$K$21="OK",ABERTURAS!$Q$21+0.26*CHOOSE(ABERTURAS!$N$21,0,$C$13,ABERTURAS!$O$21,ABERTURAS!$O$21),0)+$AZ$9)/$AZ$7 -> 0.041677003 | CE3: =(IF(ABERTURAS!$K$22="OK",CHOOSE(ABERTURAS!$N$22,ABERTURAS!$O$22,ABERTURAS!$O$22+0.42*$C$13,0.42*ABERTURAS!$O$22,$C$12+0.42*ABERTURAS!$O$22),0)+$AZ$8)/$AZ$7 -> 0.30543746 | CF3: =(IF(ABERTURAS!$K$22="OK",ABERTURAS!$Q$22+0.26*CHOOSE(ABERTURAS!$N$22,0,$C$13,ABERTURAS!$O$22,ABERTURAS!$O$22),0)+$AZ$9)/$AZ$7 -> 0.041677003 | CG3: =(IF(ABERTURAS!$K$23="OK",CHOOSE(ABERTURAS!$N$23,ABERTURAS!$O$23,ABERTURAS!$O$23+0.42*$C$13,0.42*ABERTURAS!$O$23,$C$12+0.42*ABERTURAS!$O$23),0)+$AZ$8)/$AZ$7 -> 0.30543746 | CH3: =(IF(ABERTURAS!$K$23="OK",ABERTURAS!$Q$23+0.26*CHOOSE(ABERTURAS!$N$23,0,$C$13,ABERTURAS!$O$23,ABERTURAS!$O$23),0)+$AZ$9)/$AZ$7 -> 0.041677003 | CI3: =(IF(ABERTURAS!$K$24="OK",CHOOSE(ABERTURAS!$N$24,ABERTURAS!$O$24,ABERTURAS!$O$24+0.42*$C$13,0.42*ABERTURAS!$O$24,$C$12+0.42*ABERTURAS!$O$24),0)+$AZ$8)/$AZ$7 -> 0.30543746 | CJ3: =(IF(ABERTURAS!$K$24="OK",ABERTURAS!$Q$24+0.26*CHOOSE(ABERTURAS!$N$24,0,$C$13,ABERTURAS!$O$24,ABERTURAS!$O$24),0)+$AZ$9)/$AZ$7 -> 0.041677003 | CK3: =(IF(ABERTURAS!$K$25="OK",CHOOSE(ABERTURAS!$N$25,ABERTURAS!$O$25,ABERTURAS!$O$25+0.42*$C$13,0.42*ABERTURAS!$O$25,$C$12+0.42*ABERTURAS!$O$25),0)+$AZ$8)/$AZ$7 -> 0.30543746 | CL3: =(IF(ABERTURAS!$K$25="OK",ABERTURAS!$Q$25+0.26*CHOOSE(ABERTURAS!$N$25,0,$C$13,ABERTURAS!$O$25,ABERTURAS!$O$25),0)+$AZ$9)/$AZ$7 -> 0.041677003 | CM3: =(IF(ABERTURAS!$K$26="OK",CHOOSE(ABERTURAS!$N$26,ABERTURAS!$O$26,ABERTURAS!$O$26+0.42*$C$13,0.42*ABERTURAS!$O$26,$C$12+0.42*ABERTURAS!$O$26),0)+$AZ$8)/$AZ$7 -> 0.30543746 | CN3: =(IF(ABERTURAS!$K$26="OK",ABERTURAS!$Q$26+0.26*CHOOSE(ABERTURAS!$N$26,0,$C$13,ABERTURAS!$O$26,ABERTURAS!$O$26),0)+$AZ$9)/$AZ$7 -> 0.041677003
AA4: =$C$23*1/8 -> 2 | AB4: =IF($C$14="PLANO",$C$17,IF($C$14="DOS AGUAS",$C$17+($C$18-$C$17)*(1-ABS(2*($AA$4)/$C$23-1)),IF($C$14="UN AGUA",IF(N($C$25)=0,$C$18-($C$18-$C$17)*($AA$4)/$C$23,$C$17+($C$18-$C$17)*($AA$4)/$C$23),$C$17+4*($C$18-$C$17)*($AA$4)/$C$23*(1-($AA$4)/$C$23)))) -> 10.52 | AE4: =ABERTURAS!$D$51 -> 10.08 | AF4: =0 -> 0 | AG4: =($AE4+0.42*0+$AZ$8)/$AZ$7 -> 0.93059251 | AH4: =($AF4+0.26*0+$AZ$9)/$AZ$7 -> 0.041677003 | AI4: =ABERTURAS!$D$52 -> 10.08 | AJ4: =0 -> 0 | AK4: =($AI4+0.42*$C$13+$AZ$8)/$AZ$7 -> 1.3473625 | AL4: =($AJ4+0.26*$C$13+$AZ$9)/$AZ$7 -> 0.2996775 | AM4: =ABERTURAS!$D$53 -> 16 | AN4: =0 -> 0 | AO4: =(0+0.42*$AM4+$AZ$8)/$AZ$7 -> 0.72220749 | AP4: =($AN4+0.26*$AM4+$AZ$9)/$AZ$7 -> 0.2996775 | AQ4: =ABERTURAS!$D$54 -> 16 | AR4: =0 -> 0 | AS4: =($C$12+0.42*$AQ4+$AZ$8)/$AZ$7 -> 1.3473625 | AT4: =($AR4+0.26*$AQ4+$AZ$9)/$AZ$7 -> 0.2996775 | AU4: =(IF($AC$3="X",$AA$3+0.42*IF($AC$3="X",$C$13,$C$12),IF($AC$3="X",$C$13,$C$12)+0.42*$AA$3)+$AZ$8)/$AZ$7 -> 0.93059251 | AV4: =($AB$3+0.26*IF($AC$3="X",IF($AC$3="X",$C$13,$C$12),$AA$3)+$AZ$9)/$AZ$7 -> 0.7003225 | AW4: =(0+$AZ$8)/$AZ$7 -> 0.30543746 | AX4: =(0+$AZ$9)/$AZ$7 -> 0.041677003 | AY4: ext y' | AZ4: =MAX(1.25*$C$21,$C$21+0.26*$C$13,0.26*1.25*$C$13) -> 14.78 | BA4: =(IF(ABERTURAS!$K$7="OK",CHOOSE(ABERTURAS!$N$7,ABERTURAS!$P$7,ABERTURAS!$P$7+0.42*$C$13,0.42*ABERTURAS!$P$7,$C$12+0.42*ABERTURAS!$P$7),0)+$AZ$8)/$AZ$7 -> 0.42599687 | BB4: =(IF(ABERTURAS!$K$7="OK",ABERTURAS!$Q$7+0.26*CHOOSE(ABERTURAS!$N$7,0,$C$13,ABERTURAS!$P$7,ABERTURAS!$P$7),0)+$AZ$9)/$AZ$7 -> 0.041677003 | BC4: =(IF(ABERTURAS!$K$8="OK",CHOOSE(ABERTURAS!$N$8,ABERTURAS!$P$8,ABERTURAS!$P$8+0.42*$C$13,0.42*ABERTURAS!$P$8,$C$12+0.42*ABERTURAS!$P$8),0)+$AZ$8)/$AZ$7 -> 0.7760713 | BD4: =(IF(ABERTURAS!$K$8="OK",ABERTURAS!$Q$8+0.26*CHOOSE(ABERTURAS!$N$8,0,$C$13,ABERTURAS!$P$8,ABERTURAS!$P$8),0)+$AZ$9)/$AZ$7 -> 0.041677003 | BE4: =(IF(ABERTURAS!$K$9="OK",CHOOSE(ABERTURAS!$N$9,ABERTURAS!$P$9,ABERTURAS!$P$9+0.42*$C$13,0.42*ABERTURAS!$P$9,$C$12+0.42*ABERTURAS!$P$9),0)+$AZ$8)/$AZ$7 -> 1.3473625 | BF4: =(IF(ABERTURAS!$K$9="OK",ABERTURAS!$Q$9+0.26*CHOOSE(ABERTURAS!$N$9,0,$C$13,ABERTURAS!$P$9,ABERTURAS!$P$9),0)+$AZ$9)/$AZ$7 -> 0.2996775 | BG4: =(IF(ABERTURAS!$K$10="OK",CHOOSE(ABERTURAS!$N$10,ABERTURAS!$P$10,ABERTURAS!$P$10+0.42*$C$13,0.42*ABERTURAS!$P$10,$C$12+0.42*ABERTURAS!$P$10),0)+$AZ$8)/$AZ$7 -> 0.30543746 | BH4: =(IF(ABERTURAS!$K$10="OK",ABERTURAS!$Q$10+0.26*CHOOSE(ABERTURAS!$N$10,0,$C$13,ABERTURAS!$P$10,ABERTURAS!$P$10),0)+$AZ$9)/$AZ$7 -> 0.041677003 | BI4: =(IF(ABERTURAS!$K$11="OK",CHOOSE(ABERTURAS!$N$11,ABERTURAS!$P$11,ABERTURAS!$P$11+0.42*$C$13,0.42*ABERTURAS!$P$11,$C$12+0.42*ABERTURAS!$P$11),0)+$AZ$8)/$AZ$7 -> 0.30543746 | BJ4: =(IF(ABERTURAS!$K$11="OK",ABERTURAS!$Q$11+0.26*CHOOSE(ABERTURAS!$N$11,0,$C$13,ABERTURAS!$P$11,ABERTURAS!$P$11),0)+$AZ$9)/$AZ$7 -> 0.041677003 | BK4: =(IF(ABERTURAS!$K$12="OK",CHOOSE(ABERTURAS!$N$12,ABERTURAS!$P$12,ABERTURAS!$P$12+0.42*$C$13,0.42*ABERTURAS!$P$12,$C$12+0.42*ABERTURAS!$P$12),0)+$AZ$8)/$AZ$7 -> 0.30543746 | BL4: =(IF(ABERTURAS!$K$12="OK",ABERTURAS!$Q$12+0.26*CHOOSE(ABERTURAS!$N$12,0,$C$13,ABERTURAS!$P$12,ABERTURAS!$P$12),0)+$AZ$9)/$AZ$7 -> 0.041677003 | BM4: =(IF(ABERTURAS!$K$13="OK",CHOOSE(ABERTURAS!$N$13,ABERTURAS!$P$13,ABERTURAS!$P$13+0.42*$C$13,0.42*ABERTURAS!$P$13,$C$12+0.42*ABERTURAS!$P$13),0)+$AZ$8)/$AZ$7 -> 0.30543746 | BN4: =(IF(ABERTURAS!$K$13="OK",ABERTURAS!$Q$13+0.26*CHOOSE(ABERTURAS!$N$13,0,$C$13,ABERTURAS!$P$13,ABERTURAS!$P$13),0)+$AZ$9)/$AZ$7 -> 0.041677003 | BO4: =(IF(ABERTURAS!$K$14="OK",CHOOSE(ABERTURAS!$N$14,ABERTURAS!$P$14,ABERTURAS!$P$14+0.42*$C$13,0.42*ABERTURAS!$P$14,$C$12+0.42*ABERTURAS!$P$14),0)+$AZ$8)/$AZ$7 -> 0.30543746 | BP4: =(IF(ABERTURAS!$K$14="OK",ABERTURAS!$Q$14+0.26*CHOOSE(ABERTURAS!$N$14,0,$C$13,ABERTURAS!$P$14,ABERTURAS!$P$14),0)+$AZ$9)/$AZ$7 -> 0.041677003 | BQ4: =(IF(ABERTURAS!$K$15="OK",CHOOSE(ABERTURAS!$N$15,ABERTURAS!$P$15,ABERTURAS!$P$15+0.42*$C$13,0.42*ABERTURAS!$P$15,$C$12+0.42*ABERTURAS!$P$15),0)+$AZ$8)/$AZ$7 -> 0.30543746 | BR4: =(IF(ABERTURAS!$K$15="OK",ABERTURAS!$Q$15+0.26*CHOOSE(ABERTURAS!$N$15,0,$C$13,ABERTURAS!$P$15,ABERTURAS!$P$15),0)+$AZ$9)/$AZ$7 -> 0.041677003 | BS4: =(IF(ABERTURAS!$K$16="OK",CHOOSE(ABERTURAS!$N$16,ABERTURAS!$P$16,ABERTURAS!$P$16+0.42*$C$13,0.42*ABERTURAS!$P$16,$C$12+0.42*ABERTURAS!$P$16),0)+$AZ$8)/$AZ$7 -> 0.30543746 | BT4: =(IF(ABERTURAS!$K$16="OK",ABERTURAS!$Q$16+0.26*CHOOSE(ABERTURAS!$N$16,0,$C$13,ABERTURAS!$P$16,ABERTURAS!$P$16),0)+$AZ$9)/$AZ$7 -> 0.041677003 | BU4: =(IF(ABERTURAS!$K$17="OK",CHOOSE(ABERTURAS!$N$17,ABERTURAS!$P$17,ABERTURAS!$P$17+0.42*$C$13,0.42*ABERTURAS!$P$17,$C$12+0.42*ABERTURAS!$P$17),0)+$AZ$8)/$AZ$7 -> 0.30543746 | BV4: =(IF(ABERTURAS!$K$17="OK",ABERTURAS!$Q$17+0.26*CHOOSE(ABERTURAS!$N$17,0,$C$13,ABERTURAS!$P$17,ABERTURAS!$P$17),0)+$AZ$9)/$AZ$7 -> 0.041677003 | BW4: =(IF(ABERTURAS!$K$18="OK",CHOOSE(ABERTURAS!$N$18,ABERTURAS!$P$18,ABERTURAS!$P$18+0.42*$C$13,0.42*ABERTURAS!$P$18,$C$12+0.42*ABERTURAS!$P$18),0)+$AZ$8)/$AZ$7 -> 0.30543746 | BX4: =(IF(ABERTURAS!$K$18="OK",ABERTURAS!$Q$18+0.26*CHOOSE(ABERTURAS!$N$18,0,$C$13,ABERTURAS!$P$18,ABERTURAS!$P$18),0)+$AZ$9)/$AZ$7 -> 0.041677003 | BY4: =(IF(ABERTURAS!$K$19="OK",CHOOSE(ABERTURAS!$N$19,ABERTURAS!$P$19,ABERTURAS!$P$19+0.42*$C$13,0.42*ABERTURAS!$P$19,$C$12+0.42*ABERTURAS!$P$19),0)+$AZ$8)/$AZ$7 -> 0.30543746 | BZ4: =(IF(ABERTURAS!$K$19="OK",ABERTURAS!$Q$19+0.26*CHOOSE(ABERTURAS!$N$19,0,$C$13,ABERTURAS!$P$19,ABERTURAS!$P$19),0)+$AZ$9)/$AZ$7 -> 0.041677003 | CA4: =(IF(ABERTURAS!$K$20="OK",CHOOSE(ABERTURAS!$N$20,ABERTURAS!$P$20,ABERTURAS!$P$20+0.42*$C$13,0.42*ABERTURAS!$P$20,$C$12+0.42*ABERTURAS!$P$20),0)+$AZ$8)/$AZ$7 -> 0.30543746 | CB4: =(IF(ABERTURAS!$K$20="OK",ABERTURAS!$Q$20+0.26*CHOOSE(ABERTURAS!$N$20,0,$C$13,ABERTURAS!$P$20,ABERTURAS!$P$20),0)+$AZ$9)/$AZ$7 -> 0.041677003 | CC4: =(IF(ABERTURAS!$K$21="OK",CHOOSE(ABERTURAS!$N$21,ABERTURAS!$P$21,ABERTURAS!$P$21+0.42*$C$13,0.42*ABERTURAS!$P$21,$C$12+0.42*ABERTURAS!$P$21),0)+$AZ$8)/$AZ$7 -> 0.30543746 | CD4: =(IF(ABERTURAS!$K$21="OK",ABERTURAS!$Q$21+0.26*CHOOSE(ABERTURAS!$N$21,0,$C$13,ABERTURAS!$P$21,ABERTURAS!$P$21),0)+$AZ$9)/$AZ$7 -> 0.041677003 | CE4: =(IF(ABERTURAS!$K$22="OK",CHOOSE(ABERTURAS!$N$22,ABERTURAS!$P$22,ABERTURAS!$P$22+0.42*$C$13,0.42*ABERTURAS!$P$22,$C$12+0.42*ABERTURAS!$P$22),0)+$AZ$8)/$AZ$7 -> 0.30543746 | CF4: =(IF(ABERTURAS!$K$22="OK",ABERTURAS!$Q$22+0.26*CHOOSE(ABERTURAS!$N$22,0,$C$13,ABERTURAS!$P$22,ABERTURAS!$P$22),0)+$AZ$9)/$AZ$7 -> 0.041677003 | CG4: =(IF(ABERTURAS!$K$23="OK",CHOOSE(ABERTURAS!$N$23,ABERTURAS!$P$23,ABERTURAS!$P$23+0.42*$C$13,0.42*ABERTURAS!$P$23,$C$12+0.42*ABERTURAS!$P$23),0)+$AZ$8)/$AZ$7 -> 0.30543746 | CH4: =(IF(ABERTURAS!$K$23="OK",ABERTURAS!$Q$23+0.26*CHOOSE(ABERTURAS!$N$23,0,$C$13,ABERTURAS!$P$23,ABERTURAS!$P$23),0)+$AZ$9)/$AZ$7 -> 0.041677003 | CI4: =(IF(ABERTURAS!$K$24="OK",CHOOSE(ABERTURAS!$N$24,ABERTURAS!$P$24,ABERTURAS!$P$24+0.42*$C$13,0.42*ABERTURAS!$P$24,$C$12+0.42*ABERTURAS!$P$24),0)+$AZ$8)/$AZ$7 -> 0.30543746 | CJ4: =(IF(ABERTURAS!$K$24="OK",ABERTURAS!$Q$24+0.26*CHOOSE(ABERTURAS!$N$24,0,$C$13,ABERTURAS!$P$24,ABERTURAS!$P$24),0)+$AZ$9)/$AZ$7 -> 0.041677003 | CK4: =(IF(ABERTURAS!$K$25="OK",CHOOSE(ABERTURAS!$N$25,ABERTURAS!$P$25,ABERTURAS!$P$25+0.42*$C$13,0.42*ABERTURAS!$P$25,$C$12+0.42*ABERTURAS!$P$25),0)+$AZ$8)/$AZ$7 -> 0.30543746 | CL4: =(IF(ABERTURAS!$K$25="OK",ABERTURAS!$Q$25+0.26*CHOOSE(ABERTURAS!$N$25,0,$C$13,ABERTURAS!$P$25,ABERTURAS!$P$25),0)+$AZ$9)/$AZ$7 -> 0.041677003 | CM4: =(IF(ABERTURAS!$K$26="OK",CHOOSE(ABERTURAS!$N$26,ABERTURAS!$P$26,ABERTURAS!$P$26+0.42*$C$13,0.42*ABERTURAS!$P$26,$C$12+0.42*ABERTURAS!$P$26),0)+$AZ$8)/$AZ$7 -> 0.30543746 | CN4: =(IF(ABERTURAS!$K$26="OK",ABERTURAS!$Q$26+0.26*CHOOSE(ABERTURAS!$N$26,0,$C$13,ABERTURAS!$P$26,ABERTURAS!$P$26),0)+$AZ$9)/$AZ$7 -> 0.041677003
B5: 1. PROYECTO | AA5: =$C$23*2/8 -> 4 | AB5: =IF($C$14="PLANO",$C$17,IF($C$14="DOS AGUAS",$C$17+($C$18-$C$17)*(1-ABS(2*($AA$5)/$C$23-1)),IF($C$14="UN AGUA",IF(N($C$25)=0,$C$18-($C$18-$C$17)*($AA$5)/$C$23,$C$17+($C$18-$C$17)*($AA$5)/$C$23),$C$17+4*($C$18-$C$17)*($AA$5)/$C$23*(1-($AA$5)/$C$23)))) -> 10.42 | AE5: =ABERTURAS!$D$51*8/8 -> 10.08 | AF5: =IF(ABERTURAS!$E$51="SÍ",$AB$11,ABERTURAS!$F$51) -> 10.62 | AG5: =($AE5+0.42*0+$AZ$8)/$AZ$7 -> 0.93059251 | AH5: =($AF5+0.26*0+$AZ$9)/$AZ$7 -> 0.7003225 | AI5: =ABERTURAS!$D$52*8/8 -> 10.08 | AJ5: =IF(ABERTURAS!$E$52="SÍ",$AB$11,ABERTURAS!$F$52) -> 9.82 | AK5: =($AI5+0.42*$C$13+$AZ$8)/$AZ$7 -> 1.3473625 | AL5: =($AJ5+0.26*$C$13+$AZ$9)/$AZ$7 -> 0.90870752 | AM5: =ABERTURAS!$D$53*8/8 -> 16 | AN5: =IF(ABERTURAS!$E$53="SÍ",$AB$11,ABERTURAS!$F$53) -> 9.82 | AO5: =(0+0.42*$AM5+$AZ$8)/$AZ$7 -> 0.72220749 | AP5: =($AN5+0.26*$AM5+$AZ$9)/$AZ$7 -> 0.90870752 | AQ5: =ABERTURAS!$D$54*8/8 -> 16 | AR5: =IF(ABERTURAS!$E$54="SÍ",$AB$11,ABERTURAS!$F$54) -> 9.82 | AS5: =($C$12+0.42*$AQ5+$AZ$8)/$AZ$7 -> 1.3473625 | AT5: =($AR5+0.26*$AQ5+$AZ$9)/$AZ$7 -> 0.90870752 | AU5: =(IF($AC$3="X",$AA$5+0.42*IF($AC$3="X",$C$13,$C$12),IF($AC$3="X",$C$13,$C$12)+0.42*$AA$5)+$AZ$8)/$AZ$7 -> 1.034785 | AV5: =($AB$5+0.26*IF($AC$3="X",IF($AC$3="X",$C$13,$C$12),$AA$5)+$AZ$9)/$AZ$7 -> 0.75241875 | AW5: =(0+$AZ$8)/$AZ$7 -> 0.30543746 | AX5: =(1.25*$C$21+$AZ$9)/$AZ$7 -> 0.86498387 | AY5: margen | AZ5: =0.04*MAX($AZ$3,$AZ$4) -> 0.672 | BA5: =(IF(ABERTURAS!$K$7="OK",CHOOSE(ABERTURAS!$N$7,ABERTURAS!$P$7,ABERTURAS!$P$7+0.42*$C$13,0.42*ABERTURAS!$P$7,$C$12+0.42*ABERTURAS!$P$7),0)+$AZ$8)/$AZ$7 -> 0.42599687 | BB5: =(IF(ABERTURAS!$K$7="OK",ABERTURAS!$R$7+0.26*CHOOSE(ABERTURAS!$N$7,0,$C$13,ABERTURAS!$P$7,ABERTURAS!$P$7),0)+$AZ$9)/$AZ$7 -> 0.19052344 | BC5: =(IF(ABERTURAS!$K$8="OK",CHOOSE(ABERTURAS!$N$8,ABERTURAS!$P$8,ABERTURAS!$P$8+0.42*$C$13,0.42*ABERTURAS!$P$8,$C$12+0.42*ABERTURAS!$P$8),0)+$AZ$8)/$AZ$7 -> 0.7760713 | BD5: =(IF(ABERTURAS!$K$8="OK",ABERTURAS!$R$8+0.26*CHOOSE(ABERTURAS!$N$8,0,$C$13,ABERTURAS!$P$8,ABERTURAS!$P$8),0)+$AZ$9)/$AZ$7 -> 0.43425949 | BE5: =(IF(ABERTURAS!$K$9="OK",CHOOSE(ABERTURAS!$N$9,ABERTURAS!$P$9,ABERTURAS!$P$9+0.42*$C$13,0.42*ABERTURAS!$P$9,$C$12+0.42*ABERTURAS!$P$9),0)+$AZ$8)/$AZ$7 -> 1.3473625 | BF5: =(IF(ABERTURAS!$K$9="OK",ABERTURAS!$R$9+0.26*CHOOSE(ABERTURAS!$N$9,0,$C$13,ABERTURAS!$P$9,ABERTURAS!$P$9),0)+$AZ$9)/$AZ$7 -> 0.90870752 | BG5: =(IF(ABERTURAS!$K$10="OK",CHOOSE(ABERTURAS!$N$10,ABERTURAS!$P$10,ABERTURAS!$P$10+0.42*$C$13,0.42*ABERTURAS!$P$10,$C$12+0.42*ABERTURAS!$P$10),0)+$AZ$8)/$AZ$7 -> 0.30543746 | BH5: =(IF(ABERTURAS!$K$10="OK",ABERTURAS!$R$10+0.26*CHOOSE(ABERTURAS!$N$10,0,$C$13,ABERTURAS!$P$10,ABERTURAS!$P$10),0)+$AZ$9)/$AZ$7 -> 0.041677003 | BI5: =(IF(ABERTURAS!$K$11="OK",CHOOSE(ABERTURAS!$N$11,ABERTURAS!$P$11,ABERTURAS!$P$11+0.42*$C$13,0.42*ABERTURAS!$P$11,$C$12+0.42*ABERTURAS!$P$11),0)+$AZ$8)/$AZ$7 -> 0.30543746 | BJ5: =(IF(ABERTURAS!$K$11="OK",ABERTURAS!$R$11+0.26*CHOOSE(ABERTURAS!$N$11,0,$C$13,ABERTURAS!$P$11,ABERTURAS!$P$11),0)+$AZ$9)/$AZ$7 -> 0.041677003 | BK5: =(IF(ABERTURAS!$K$12="OK",CHOOSE(ABERTURAS!$N$12,ABERTURAS!$P$12,ABERTURAS!$P$12+0.42*$C$13,0.42*ABERTURAS!$P$12,$C$12+0.42*ABERTURAS!$P$12),0)+$AZ$8)/$AZ$7 -> 0.30543746 | BL5: =(IF(ABERTURAS!$K$12="OK",ABERTURAS!$R$12+0.26*CHOOSE(ABERTURAS!$N$12,0,$C$13,ABERTURAS!$P$12,ABERTURAS!$P$12),0)+$AZ$9)/$AZ$7 -> 0.041677003 | BM5: =(IF(ABERTURAS!$K$13="OK",CHOOSE(ABERTURAS!$N$13,ABERTURAS!$P$13,ABERTURAS!$P$13+0.42*$C$13,0.42*ABERTURAS!$P$13,$C$12+0.42*ABERTURAS!$P$13),0)+$AZ$8)/$AZ$7 -> 0.30543746 | BN5: =(IF(ABERTURAS!$K$13="OK",ABERTURAS!$R$13+0.26*CHOOSE(ABERTURAS!$N$13,0,$C$13,ABERTURAS!$P$13,ABERTURAS!$P$13),0)+$AZ$9)/$AZ$7 -> 0.041677003 | BO5: =(IF(ABERTURAS!$K$14="OK",CHOOSE(ABERTURAS!$N$14,ABERTURAS!$P$14,ABERTURAS!$P$14+0.42*$C$13,0.42*ABERTURAS!$P$14,$C$12+0.42*ABERTURAS!$P$14),0)+$AZ$8)/$AZ$7 -> 0.30543746 | BP5: =(IF(ABERTURAS!$K$14="OK",ABERTURAS!$R$14+0.26*CHOOSE(ABERTURAS!$N$14,0,$C$13,ABERTURAS!$P$14,ABERTURAS!$P$14),0)+$AZ$9)/$AZ$7 -> 0.041677003 | BQ5: =(IF(ABERTURAS!$K$15="OK",CHOOSE(ABERTURAS!$N$15,ABERTURAS!$P$15,ABERTURAS!$P$15+0.42*$C$13,0.42*ABERTURAS!$P$15,$C$12+0.42*ABERTURAS!$P$15),0)+$AZ$8)/$AZ$7 -> 0.30543746 | BR5: =(IF(ABERTURAS!$K$15="OK",ABERTURAS!$R$15+0.26*CHOOSE(ABERTURAS!$N$15,0,$C$13,ABERTURAS!$P$15,ABERTURAS!$P$15),0)+$AZ$9)/$AZ$7 -> 0.041677003 | BS5: =(IF(ABERTURAS!$K$16="OK",CHOOSE(ABERTURAS!$N$16,ABERTURAS!$P$16,ABERTURAS!$P$16+0.42*$C$13,0.42*ABERTURAS!$P$16,$C$12+0.42*ABERTURAS!$P$16),0)+$AZ$8)/$AZ$7 -> 0.30543746 | BT5: =(IF(ABERTURAS!$K$16="OK",ABERTURAS!$R$16+0.26*CHOOSE(ABERTURAS!$N$16,0,$C$13,ABERTURAS!$P$16,ABERTURAS!$P$16),0)+$AZ$9)/$AZ$7 -> 0.041677003 | BU5: =(IF(ABERTURAS!$K$17="OK",CHOOSE(ABERTURAS!$N$17,ABERTURAS!$P$17,ABERTURAS!$P$17+0.42*$C$13,0.42*ABERTURAS!$P$17,$C$12+0.42*ABERTURAS!$P$17),0)+$AZ$8)/$AZ$7 -> 0.30543746 | BV5: =(IF(ABERTURAS!$K$17="OK",ABERTURAS!$R$17+0.26*CHOOSE(ABERTURAS!$N$17,0,$C$13,ABERTURAS!$P$17,ABERTURAS!$P$17),0)+$AZ$9)/$AZ$7 -> 0.041677003 | BW5: =(IF(ABERTURAS!$K$18="OK",CHOOSE(ABERTURAS!$N$18,ABERTURAS!$P$18,ABERTURAS!$P$18+0.42*$C$13,0.42*ABERTURAS!$P$18,$C$12+0.42*ABERTURAS!$P$18),0)+$AZ$8)/$AZ$7 -> 0.30543746 | BX5: =(IF(ABERTURAS!$K$18="OK",ABERTURAS!$R$18+0.26*CHOOSE(ABERTURAS!$N$18,0,$C$13,ABERTURAS!$P$18,ABERTURAS!$P$18),0)+$AZ$9)/$AZ$7 -> 0.041677003 | BY5: =(IF(ABERTURAS!$K$19="OK",CHOOSE(ABERTURAS!$N$19,ABERTURAS!$P$19,ABERTURAS!$P$19+0.42*$C$13,0.42*ABERTURAS!$P$19,$C$12+0.42*ABERTURAS!$P$19),0)+$AZ$8)/$AZ$7 -> 0.30543746 | BZ5: =(IF(ABERTURAS!$K$19="OK",ABERTURAS!$R$19+0.26*CHOOSE(ABERTURAS!$N$19,0,$C$13,ABERTURAS!$P$19,ABERTURAS!$P$19),0)+$AZ$9)/$AZ$7 -> 0.041677003 | CA5: =(IF(ABERTURAS!$K$20="OK",CHOOSE(ABERTURAS!$N$20,ABERTURAS!$P$20,ABERTURAS!$P$20+0.42*$C$13,0.42*ABERTURAS!$P$20,$C$12+0.42*ABERTURAS!$P$20),0)+$AZ$8)/$AZ$7 -> 0.30543746 | CB5: =(IF(ABERTURAS!$K$20="OK",ABERTURAS!$R$20+0.26*CHOOSE(ABERTURAS!$N$20,0,$C$13,ABERTURAS!$P$20,ABERTURAS!$P$20),0)+$AZ$9)/$AZ$7 -> 0.041677003 | CC5: =(IF(ABERTURAS!$K$21="OK",CHOOSE(ABERTURAS!$N$21,ABERTURAS!$P$21,ABERTURAS!$P$21+0.42*$C$13,0.42*ABERTURAS!$P$21,$C$12+0.42*ABERTURAS!$P$21),0)+$AZ$8)/$AZ$7 -> 0.30543746 | CD5: =(IF(ABERTURAS!$K$21="OK",ABERTURAS!$R$21+0.26*CHOOSE(ABERTURAS!$N$21,0,$C$13,ABERTURAS!$P$21,ABERTURAS!$P$21),0)+$AZ$9)/$AZ$7 -> 0.041677003 | CE5: =(IF(ABERTURAS!$K$22="OK",CHOOSE(ABERTURAS!$N$22,ABERTURAS!$P$22,ABERTURAS!$P$22+0.42*$C$13,0.42*ABERTURAS!$P$22,$C$12+0.42*ABERTURAS!$P$22),0)+$AZ$8)/$AZ$7 -> 0.30543746 | CF5: =(IF(ABERTURAS!$K$22="OK",ABERTURAS!$R$22+0.26*CHOOSE(ABERTURAS!$N$22,0,$C$13,ABERTURAS!$P$22,ABERTURAS!$P$22),0)+$AZ$9)/$AZ$7 -> 0.041677003 | CG5: =(IF(ABERTURAS!$K$23="OK",CHOOSE(ABERTURAS!$N$23,ABERTURAS!$P$23,ABERTURAS!$P$23+0.42*$C$13,0.42*ABERTURAS!$P$23,$C$12+0.42*ABERTURAS!$P$23),0)+$AZ$8)/$AZ$7 -> 0.30543746 | CH5: =(IF(ABERTURAS!$K$23="OK",ABERTURAS!$R$23+0.26*CHOOSE(ABERTURAS!$N$23,0,$C$13,ABERTURAS!$P$23,ABERTURAS!$P$23),0)+$AZ$9)/$AZ$7 -> 0.041677003 | CI5: =(IF(ABERTURAS!$K$24="OK",CHOOSE(ABERTURAS!$N$24,ABERTURAS!$P$24,ABERTURAS!$P$24+0.42*$C$13,0.42*ABERTURAS!$P$24,$C$12+0.42*ABERTURAS!$P$24),0)+$AZ$8)/$AZ$7 -> 0.30543746 | CJ5: =(IF(ABERTURAS!$K$24="OK",ABERTURAS!$R$24+0.26*CHOOSE(ABERTURAS!$N$24,0,$C$13,ABERTURAS!$P$24,ABERTURAS!$P$24),0)+$AZ$9)/$AZ$7 -> 0.041677003 | CK5: =(IF(ABERTURAS!$K$25="OK",CHOOSE(ABERTURAS!$N$25,ABERTURAS!$P$25,ABERTURAS!$P$25+0.42*$C$13,0.42*ABERTURAS!$P$25,$C$12+0.42*ABERTURAS!$P$25),0)+$AZ$8)/$AZ$7 -> 0.30543746 | CL5: =(IF(ABERTURAS!$K$25="OK",ABERTURAS!$R$25+0.26*CHOOSE(ABERTURAS!$N$25,0,$C$13,ABERTURAS!$P$25,ABERTURAS!$P$25),0)+$AZ$9)/$AZ$7 -> 0.041677003 | CM5: =(IF(ABERTURAS!$K$26="OK",CHOOSE(ABERTURAS!$N$26,ABERTURAS!$P$26,ABERTURAS!$P$26+0.42*$C$13,0.42*ABERTURAS!$P$26,$C$12+0.42*ABERTURAS!$P$26),0)+$AZ$8)/$AZ$7 -> 0.30543746 | CN5: =(IF(ABERTURAS!$K$26="OK",ABERTURAS!$R$26+0.26*CHOOSE(ABERTURAS!$N$26,0,$C$13,ABERTURAS!$P$26,ABERTURAS!$P$26),0)+$AZ$9)/$AZ$7 -> 0.041677003
B6: Concepto | C6: Valor | D6: Unidad | E6: Cómo se calcula / de dónde sale | F6: Referencia | AA6: =$C$23*3/8 -> 6 | AB6: =IF($C$14="PLANO",$C$17,IF($C$14="DOS AGUAS",$C$17+($C$18-$C$17)*(1-ABS(2*($AA$6)/$C$23-1)),IF($C$14="UN AGUA",IF(N($C$25)=0,$C$18-($C$18-$C$17)*($AA$6)/$C$23,$C$17+($C$18-$C$17)*($AA$6)/$C$23),$C$17+4*($C$18-$C$17)*($AA$6)/$C$23*(1-($AA$6)/$C$23)))) -> 10.32 | AE6: =ABERTURAS!$D$51*7/8 -> 8.82 | AF6: =IF(ABERTURAS!$E$51="SÍ",$AB$10,ABERTURAS!$F$51) -> 10.62 | AG6: =($AE6+0.42*0+$AZ$8)/$AZ$7 -> 0.85244813 | AH6: =($AF6+0.26*0+$AZ$9)/$AZ$7 -> 0.7003225 | AI6: =ABERTURAS!$D$52*7/8 -> 8.82 | AJ6: =IF(ABERTURAS!$E$52="SÍ",$AB$10,ABERTURAS!$F$52) -> 9.82 | AK6: =($AI6+0.42*$C$13+$AZ$8)/$AZ$7 -> 1.2692182 | AL6: =($AJ6+0.26*$C$13+$AZ$9)/$AZ$7 -> 0.90870752 | AM6: =ABERTURAS!$D$53*7/8 -> 14 | AN6: =IF(ABERTURAS!$E$53="SÍ",$AB$10,ABERTURAS!$F$53) -> 9.92 | AO6: =(0+0.42*$AM6+$AZ$8)/$AZ$7 -> 0.67011124 | AP6: =($AN6+0.26*$AM6+$AZ$9)/$AZ$7 -> 0.88265939 | AQ6: =ABERTURAS!$D$54*7/8 -> 14 | AR6: =IF(ABERTURAS!$E$54="SÍ",$AB$10,ABERTURAS!$F$54) -> 9.92 | AS6: =($C$12+0.42*$AQ6+$AZ$8)/$AZ$7 -> 1.2952663 | AT6: =($AR6+0.26*$AQ6+$AZ$9)/$AZ$7 -> 0.88265939 | AU6: =(IF($AC$3="X",$AA$5+0.42*0,0+0.42*$AA$5)+$AZ$8)/$AZ$7 -> 0.40962997 | AV6: =($AB$5+0.26*IF($AC$3="X",0,$AA$5)+$AZ$9)/$AZ$7 -> 0.75241875 | AW6: =(0+$AZ$8)/$AZ$7 -> 0.30543746 | AX6: =(0+$AZ$9)/$AZ$7 -> 0.041677003 | AY6: aspecto | AZ6: =1.6528 -> 1.6528 | BA6: =(IF(ABERTURAS!$K$7="OK",CHOOSE(ABERTURAS!$N$7,ABERTURAS!$O$7,ABERTURAS!$O$7+0.42*$C$13,0.42*ABERTURAS!$O$7,$C$12+0.42*ABERTURAS!$O$7),0)+$AZ$8)/$AZ$7 -> 0.34528489 | BB6: =(IF(ABERTURAS!$K$7="OK",ABERTURAS!$R$7+0.26*CHOOSE(ABERTURAS!$N$7,0,$C$13,ABERTURAS!$O$7,ABERTURAS!$O$7),0)+$AZ$9)/$AZ$7 -> 0.19052344 | BC6: =(IF(ABERTURAS!$K$8="OK",CHOOSE(ABERTURAS!$N$8,ABERTURAS!$O$8,ABERTURAS!$O$8+0.42*$C$13,0.42*ABERTURAS!$O$8,$C$12+0.42*ABERTURAS!$O$8),0)+$AZ$8)/$AZ$7 -> 0.45967338 | BD6: =(IF(ABERTURAS!$K$8="OK",ABERTURAS!$R$8+0.26*CHOOSE(ABERTURAS!$N$8,0,$C$13,ABERTURAS!$O$8,ABERTURAS!$O$8),0)+$AZ$9)/$AZ$7 -> 0.43425949 | BE6: =(IF(ABERTURAS!$K$9="OK",CHOOSE(ABERTURAS!$N$9,ABERTURAS!$O$9,ABERTURAS!$O$9+0.42*$C$13,0.42*ABERTURAS!$O$9,$C$12+0.42*ABERTURAS!$O$9),0)+$AZ$8)/$AZ$7 -> 0.72220749 | BF6: =(IF(ABERTURAS!$K$9="OK",ABERTURAS!$R$9+0.26*CHOOSE(ABERTURAS!$N$9,0,$C$13,ABERTURAS!$O$9,ABERTURAS!$O$9),0)+$AZ$9)/$AZ$7 -> 0.90870752 | BG6: =(IF(ABERTURAS!$K$10="OK",CHOOSE(ABERTURAS!$N$10,ABERTURAS!$O$10,ABERTURAS!$O$10+0.42*$C$13,0.42*ABERTURAS!$O$10,$C$12+0.42*ABERTURAS!$O$10),0)+$AZ$8)/$AZ$7 -> 0.30543746 | BH6: =(IF(ABERTURAS!$K$10="OK",ABERTURAS!$R$10+0.26*CHOOSE(ABERTURAS!$N$10,0,$C$13,ABERTURAS!$O$10,ABERTURAS!$O$10),0)+$AZ$9)/$AZ$7 -> 0.041677003 | BI6: =(IF(ABERTURAS!$K$11="OK",CHOOSE(ABERTURAS!$N$11,ABERTURAS!$O$11,ABERTURAS!$O$11+0.42*$C$13,0.42*ABERTURAS!$O$11,$C$12+0.42*ABERTURAS!$O$11),0)+$AZ$8)/$AZ$7 -> 0.30543746 | BJ6: =(IF(ABERTURAS!$K$11="OK",ABERTURAS!$R$11+0.26*CHOOSE(ABERTURAS!$N$11,0,$C$13,ABERTURAS!$O$11,ABERTURAS!$O$11),0)+$AZ$9)/$AZ$7 -> 0.041677003 | BK6: =(IF(ABERTURAS!$K$12="OK",CHOOSE(ABERTURAS!$N$12,ABERTURAS!$O$12,ABERTURAS!$O$12+0.42*$C$13,0.42*ABERTURAS!$O$12,$C$12+0.42*ABERTURAS!$O$12),0)+$AZ$8)/$AZ$7 -> 0.30543746 | BL6: =(IF(ABERTURAS!$K$12="OK",ABERTURAS!$R$12+0.26*CHOOSE(ABERTURAS!$N$12,0,$C$13,ABERTURAS!$O$12,ABERTURAS!$O$12),0)+$AZ$9)/$AZ$7 -> 0.041677003 | BM6: =(IF(ABERTURAS!$K$13="OK",CHOOSE(ABERTURAS!$N$13,ABERTURAS!$O$13,ABERTURAS!$O$13+0.42*$C$13,0.42*ABERTURAS!$O$13,$C$12+0.42*ABERTURAS!$O$13),0)+$AZ$8)/$AZ$7 -> 0.30543746 | BN6: =(IF(ABERTURAS!$K$13="OK",ABERTURAS!$R$13+0.26*CHOOSE(ABERTURAS!$N$13,0,$C$13,ABERTURAS!$O$13,ABERTURAS!$O$13),0)+$AZ$9)/$AZ$7 -> 0.041677003 | BO6: =(IF(ABERTURAS!$K$14="OK",CHOOSE(ABERTURAS!$N$14,ABERTURAS!$O$14,ABERTURAS!$O$14+0.42*$C$13,0.42*ABERTURAS!$O$14,$C$12+0.42*ABERTURAS!$O$14),0)+$AZ$8)/$AZ$7 -> 0.30543746 | BP6: =(IF(ABERTURAS!$K$14="OK",ABERTURAS!$R$14+0.26*CHOOSE(ABERTURAS!$N$14,0,$C$13,ABERTURAS!$O$14,ABERTURAS!$O$14),0)+$AZ$9)/$AZ$7 -> 0.041677003 | BQ6: =(IF(ABERTURAS!$K$15="OK",CHOOSE(ABERTURAS!$N$15,ABERTURAS!$O$15,ABERTURAS!$O$15+0.42*$C$13,0.42*ABERTURAS!$O$15,$C$12+0.42*ABERTURAS!$O$15),0)+$AZ$8)/$AZ$7 -> 0.30543746 | BR6: =(IF(ABERTURAS!$K$15="OK",ABERTURAS!$R$15+0.26*CHOOSE(ABERTURAS!$N$15,0,$C$13,ABERTURAS!$O$15,ABERTURAS!$O$15),0)+$AZ$9)/$AZ$7 -> 0.041677003 | BS6: =(IF(ABERTURAS!$K$16="OK",CHOOSE(ABERTURAS!$N$16,ABERTURAS!$O$16,ABERTURAS!$O$16+0.42*$C$13,0.42*ABERTURAS!$O$16,$C$12+0.42*ABERTURAS!$O$16),0)+$AZ$8)/$AZ$7 -> 0.30543746 | BT6: =(IF(ABERTURAS!$K$16="OK",ABERTURAS!$R$16+0.26*CHOOSE(ABERTURAS!$N$16,0,$C$13,ABERTURAS!$O$16,ABERTURAS!$O$16),0)+$AZ$9)/$AZ$7 -> 0.041677003 | BU6: =(IF(ABERTURAS!$K$17="OK",CHOOSE(ABERTURAS!$N$17,ABERTURAS!$O$17,ABERTURAS!$O$17+0.42*$C$13,0.42*ABERTURAS!$O$17,$C$12+0.42*ABERTURAS!$O$17),0)+$AZ$8)/$AZ$7 -> 0.30543746 | BV6: =(IF(ABERTURAS!$K$17="OK",ABERTURAS!$R$17+0.26*CHOOSE(ABERTURAS!$N$17,0,$C$13,ABERTURAS!$O$17,ABERTURAS!$O$17),0)+$AZ$9)/$AZ$7 -> 0.041677003 | BW6: =(IF(ABERTURAS!$K$18="OK",CHOOSE(ABERTURAS!$N$18,ABERTURAS!$O$18,ABERTURAS!$O$18+0.42*$C$13,0.42*ABERTURAS!$O$18,$C$12+0.42*ABERTURAS!$O$18),0)+$AZ$8)/$AZ$7 -> 0.30543746 | BX6: =(IF(ABERTURAS!$K$18="OK",ABERTURAS!$R$18+0.26*CHOOSE(ABERTURAS!$N$18,0,$C$13,ABERTURAS!$O$18,ABERTURAS!$O$18),0)+$AZ$9)/$AZ$7 -> 0.041677003 | BY6: =(IF(ABERTURAS!$K$19="OK",CHOOSE(ABERTURAS!$N$19,ABERTURAS!$O$19,ABERTURAS!$O$19+0.42*$C$13,0.42*ABERTURAS!$O$19,$C$12+0.42*ABERTURAS!$O$19),0)+$AZ$8)/$AZ$7 -> 0.30543746 | BZ6: =(IF(ABERTURAS!$K$19="OK",ABERTURAS!$R$19+0.26*CHOOSE(ABERTURAS!$N$19,0,$C$13,ABERTURAS!$O$19,ABERTURAS!$O$19),0)+$AZ$9)/$AZ$7 -> 0.041677003 | CA6: =(IF(ABERTURAS!$K$20="OK",CHOOSE(ABERTURAS!$N$20,ABERTURAS!$O$20,ABERTURAS!$O$20+0.42*$C$13,0.42*ABERTURAS!$O$20,$C$12+0.42*ABERTURAS!$O$20),0)+$AZ$8)/$AZ$7 -> 0.30543746 | CB6: =(IF(ABERTURAS!$K$20="OK",ABERTURAS!$R$20+0.26*CHOOSE(ABERTURAS!$N$20,0,$C$13,ABERTURAS!$O$20,ABERTURAS!$O$20),0)+$AZ$9)/$AZ$7 -> 0.041677003 | CC6: =(IF(ABERTURAS!$K$21="OK",CHOOSE(ABERTURAS!$N$21,ABERTURAS!$O$21,ABERTURAS!$O$21+0.42*$C$13,0.42*ABERTURAS!$O$21,$C$12+0.42*ABERTURAS!$O$21),0)+$AZ$8)/$AZ$7 -> 0.30543746 | CD6: =(IF(ABERTURAS!$K$21="OK",ABERTURAS!$R$21+0.26*CHOOSE(ABERTURAS!$N$21,0,$C$13,ABERTURAS!$O$21,ABERTURAS!$O$21),0)+$AZ$9)/$AZ$7 -> 0.041677003 | CE6: =(IF(ABERTURAS!$K$22="OK",CHOOSE(ABERTURAS!$N$22,ABERTURAS!$O$22,ABERTURAS!$O$22+0.42*$C$13,0.42*ABERTURAS!$O$22,$C$12+0.42*ABERTURAS!$O$22),0)+$AZ$8)/$AZ$7 -> 0.30543746 | CF6: =(IF(ABERTURAS!$K$22="OK",ABERTURAS!$R$22+0.26*CHOOSE(ABERTURAS!$N$22,0,$C$13,ABERTURAS!$O$22,ABERTURAS!$O$22),0)+$AZ$9)/$AZ$7 -> 0.041677003 | CG6: =(IF(ABERTURAS!$K$23="OK",CHOOSE(ABERTURAS!$N$23,ABERTURAS!$O$23,ABERTURAS!$O$23+0.42*$C$13,0.42*ABERTURAS!$O$23,$C$12+0.42*ABERTURAS!$O$23),0)+$AZ$8)/$AZ$7 -> 0.30543746 | CH6: =(IF(ABERTURAS!$K$23="OK",ABERTURAS!$R$23+0.26*CHOOSE(ABERTURAS!$N$23,0,$C$13,ABERTURAS!$O$23,ABERTURAS!$O$23),0)+$AZ$9)/$AZ$7 -> 0.041677003 | CI6: =(IF(ABERTURAS!$K$24="OK",CHOOSE(ABERTURAS!$N$24,ABERTURAS!$O$24,ABERTURAS!$O$24+0.42*$C$13,0.42*ABERTURAS!$O$24,$C$12+0.42*ABERTURAS!$O$24),0)+$AZ$8)/$AZ$7 -> 0.30543746 | CJ6: =(IF(ABERTURAS!$K$24="OK",ABERTURAS!$R$24+0.26*CHOOSE(ABERTURAS!$N$24,0,$C$13,ABERTURAS!$O$24,ABERTURAS!$O$24),0)+$AZ$9)/$AZ$7 -> 0.041677003 | CK6: =(IF(ABERTURAS!$K$25="OK",CHOOSE(ABERTURAS!$N$25,ABERTURAS!$O$25,ABERTURAS!$O$25+0.42*$C$13,0.42*ABERTURAS!$O$25,$C$12+0.42*ABERTURAS!$O$25),0)+$AZ$8)/$AZ$7 -> 0.30543746 | CL6: =(IF(ABERTURAS!$K$25="OK",ABERTURAS!$R$25+0.26*CHOOSE(ABERTURAS!$N$25,0,$C$13,ABERTURAS!$O$25,ABERTURAS!$O$25),0)+$AZ$9)/$AZ$7 -> 0.041677003 | CM6: =(IF(ABERTURAS!$K$26="OK",CHOOSE(ABERTURAS!$N$26,ABERTURAS!$O$26,ABERTURAS!$O$26+0.42*$C$13,0.42*ABERTURAS!$O$26,$C$12+0.42*ABERTURAS!$O$26),0)+$AZ$8)/$AZ$7 -> 0.30543746 | CN6: =(IF(ABERTURAS!$K$26="OK",ABERTURAS!$R$26+0.26*CHOOSE(ABERTURAS!$N$26,0,$C$13,ABERTURAS!$O$26,ABERTURAS!$O$26),0)+$AZ$9)/$AZ$7 -> 0.041677003
B7: Proyecto | C7: HANGAR NOSE-DOCK H5-H6 | E7: CAPTURA. Sólo para identificar la corrida. | F7: — | AA7: =$C$23*4/8 -> 8 | AB7: =IF($C$14="PLANO",$C$17,IF($C$14="DOS AGUAS",$C$17+($C$18-$C$17)*(1-ABS(2*($AA$7)/$C$23-1)),IF($C$14="UN AGUA",IF(N($C$25)=0,$C$18-($C$18-$C$17)*($AA$7)/$C$23,$C$17+($C$18-$C$17)*($AA$7)/$C$23),$C$17+4*($C$18-$C$17)*($AA$7)/$C$23*(1-($AA$7)/$C$23)))) -> 10.22 | AE7: =ABERTURAS!$D$51*6/8 -> 7.56 | AF7: =IF(ABERTURAS!$E$51="SÍ",$AB$9,ABERTURAS!$F$51) -> 10.62 | AG7: =($AE7+0.42*0+$AZ$8)/$AZ$7 -> 0.77430375 | AH7: =($AF7+0.26*0+$AZ$9)/$AZ$7 -> 0.7003225 | AI7: =ABERTURAS!$D$52*6/8 -> 7.56 | AJ7: =IF(ABERTURAS!$E$52="SÍ",$AB$9,ABERTURAS!$F$52) -> 9.82 | AK7: =($AI7+0.42*$C$13+$AZ$8)/$AZ$7 -> 1.1910738 | AL7: =($AJ7+0.26*$C$13+$AZ$9)/$AZ$7 -> 0.90870752 | AM7: =ABERTURAS!$D$53*6/8 -> 12 | AN7: =IF(ABERTURAS!$E$53="SÍ",$AB$9,ABERTURAS!$F$53) -> 10.02 | AO7: =(0+0.42*$AM7+$AZ$8)/$AZ$7 -> 0.61801498 | AP7: =($AN7+0.26*$AM7+$AZ$9)/$AZ$7 -> 0.85661126 | AQ7: =ABERTURAS!$D$54*6/8 -> 12 | AR7: =IF(ABERTURAS!$E$54="SÍ",$AB$9,ABERTURAS!$F$54) -> 10.02 | AS7: =($C$12+0.42*$AQ7+$AZ$8)/$AZ$7 -> 1.24317 | AT7: =($AR7+0.26*$AQ7+$AZ$9)/$AZ$7 -> 0.85661126 | AU7: =(IF($AC$3="X",$AA$7+0.42*0,0+0.42*$AA$7)+$AZ$8)/$AZ$7 -> 0.51382248 | AV7: =($AB$7+0.26*IF($AC$3="X",0,$AA$7)+$AZ$9)/$AZ$7 -> 0.80451501 | AW7: =(0.42*1.25*$C$13+$AZ$8)/$AZ$7 -> 0.8264 | AX7: =(0.26*1.25*$C$13+$AZ$9)/$AZ$7 -> 0.36417762 | AY7: s | AZ7: =MAX(($AZ$3+2*$AZ$5)/$AZ$6,$AZ$4+2*$AZ$5) -> 16.124 | BA7: =(IF(ABERTURAS!$K$7="OK",CHOOSE(ABERTURAS!$N$7,ABERTURAS!$O$7,ABERTURAS!$O$7+0.42*$C$13,0.42*ABERTURAS!$O$7,$C$12+0.42*ABERTURAS!$O$7),0)+$AZ$8)/$AZ$7 -> 0.34528489 | BB7: =(IF(ABERTURAS!$K$7="OK",ABERTURAS!$Q$7+0.26*CHOOSE(ABERTURAS!$N$7,0,$C$13,ABERTURAS!$O$7,ABERTURAS!$O$7),0)+$AZ$9)/$AZ$7 -> 0.041677003 | BC7: =(IF(ABERTURAS!$K$8="OK",CHOOSE(ABERTURAS!$N$8,ABERTURAS!$O$8,ABERTURAS!$O$8+0.42*$C$13,0.42*ABERTURAS!$O$8,$C$12+0.42*ABERTURAS!$O$8),0)+$AZ$8)/$AZ$7 -> 0.45967338 | BD7: =(IF(ABERTURAS!$K$8="OK",ABERTURAS!$Q$8+0.26*CHOOSE(ABERTURAS!$N$8,0,$C$13,ABERTURAS!$O$8,ABERTURAS!$O$8),0)+$AZ$9)/$AZ$7 -> 0.041677003 | BE7: =(IF(ABERTURAS!$K$9="OK",CHOOSE(ABERTURAS!$N$9,ABERTURAS!$O$9,ABERTURAS!$O$9+0.42*$C$13,0.42*ABERTURAS!$O$9,$C$12+0.42*ABERTURAS!$O$9),0)+$AZ$8)/$AZ$7 -> 0.72220749 | BF7: =(IF(ABERTURAS!$K$9="OK",ABERTURAS!$Q$9+0.26*CHOOSE(ABERTURAS!$N$9,0,$C$13,ABERTURAS!$O$9,ABERTURAS!$O$9),0)+$AZ$9)/$AZ$7 -> 0.2996775 | BG7: =(IF(ABERTURAS!$K$10="OK",CHOOSE(ABERTURAS!$N$10,ABERTURAS!$O$10,ABERTURAS!$O$10+0.42*$C$13,0.42*ABERTURAS!$O$10,$C$12+0.42*ABERTURAS!$O$10),0)+$AZ$8)/$AZ$7 -> 0.30543746 | BH7: =(IF(ABERTURAS!$K$10="OK",ABERTURAS!$Q$10+0.26*CHOOSE(ABERTURAS!$N$10,0,$C$13,ABERTURAS!$O$10,ABERTURAS!$O$10),0)+$AZ$9)/$AZ$7 -> 0.041677003 | BI7: =(IF(ABERTURAS!$K$11="OK",CHOOSE(ABERTURAS!$N$11,ABERTURAS!$O$11,ABERTURAS!$O$11+0.42*$C$13,0.42*ABERTURAS!$O$11,$C$12+0.42*ABERTURAS!$O$11),0)+$AZ$8)/$AZ$7 -> 0.30543746 | BJ7: =(IF(ABERTURAS!$K$11="OK",ABERTURAS!$Q$11+0.26*CHOOSE(ABERTURAS!$N$11,0,$C$13,ABERTURAS!$O$11,ABERTURAS!$O$11),0)+$AZ$9)/$AZ$7 -> 0.041677003 | BK7: =(IF(ABERTURAS!$K$12="OK",CHOOSE(ABERTURAS!$N$12,ABERTURAS!$O$12,ABERTURAS!$O$12+0.42*$C$13,0.42*ABERTURAS!$O$12,$C$12+0.42*ABERTURAS!$O$12),0)+$AZ$8)/$AZ$7 -> 0.30543746 | BL7: =(IF(ABERTURAS!$K$12="OK",ABERTURAS!$Q$12+0.26*CHOOSE(ABERTURAS!$N$12,0,$C$13,ABERTURAS!$O$12,ABERTURAS!$O$12),0)+$AZ$9)/$AZ$7 -> 0.041677003 | BM7: =(IF(ABERTURAS!$K$13="OK",CHOOSE(ABERTURAS!$N$13,ABERTURAS!$O$13,ABERTURAS!$O$13+0.42*$C$13,0.42*ABERTURAS!$O$13,$C$12+0.42*ABERTURAS!$O$13),0)+$AZ$8)/$AZ$7 -> 0.30543746 | BN7: =(IF(ABERTURAS!$K$13="OK",ABERTURAS!$Q$13+0.26*CHOOSE(ABERTURAS!$N$13,0,$C$13,ABERTURAS!$O$13,ABERTURAS!$O$13),0)+$AZ$9)/$AZ$7 -> 0.041677003 | BO7: =(IF(ABERTURAS!$K$14="OK",CHOOSE(ABERTURAS!$N$14,ABERTURAS!$O$14,ABERTURAS!$O$14+0.42*$C$13,0.42*ABERTURAS!$O$14,$C$12+0.42*ABERTURAS!$O$14),0)+$AZ$8)/$AZ$7 -> 0.30543746 | BP7: =(IF(ABERTURAS!$K$14="OK",ABERTURAS!$Q$14+0.26*CHOOSE(ABERTURAS!$N$14,0,$C$13,ABERTURAS!$O$14,ABERTURAS!$O$14),0)+$AZ$9)/$AZ$7 -> 0.041677003 | BQ7: =(IF(ABERTURAS!$K$15="OK",CHOOSE(ABERTURAS!$N$15,ABERTURAS!$O$15,ABERTURAS!$O$15+0.42*$C$13,0.42*ABERTURAS!$O$15,$C$12+0.42*ABERTURAS!$O$15),0)+$AZ$8)/$AZ$7 -> 0.30543746 | BR7: =(IF(ABERTURAS!$K$15="OK",ABERTURAS!$Q$15+0.26*CHOOSE(ABERTURAS!$N$15,0,$C$13,ABERTURAS!$O$15,ABERTURAS!$O$15),0)+$AZ$9)/$AZ$7 -> 0.041677003 | BS7: =(IF(ABERTURAS!$K$16="OK",CHOOSE(ABERTURAS!$N$16,ABERTURAS!$O$16,ABERTURAS!$O$16+0.42*$C$13,0.42*ABERTURAS!$O$16,$C$12+0.42*ABERTURAS!$O$16),0)+$AZ$8)/$AZ$7 -> 0.30543746 | BT7: =(IF(ABERTURAS!$K$16="OK",ABERTURAS!$Q$16+0.26*CHOOSE(ABERTURAS!$N$16,0,$C$13,ABERTURAS!$O$16,ABERTURAS!$O$16),0)+$AZ$9)/$AZ$7 -> 0.041677003 | BU7: =(IF(ABERTURAS!$K$17="OK",CHOOSE(ABERTURAS!$N$17,ABERTURAS!$O$17,ABERTURAS!$O$17+0.42*$C$13,0.42*ABERTURAS!$O$17,$C$12+0.42*ABERTURAS!$O$17),0)+$AZ$8)/$AZ$7 -> 0.30543746 | BV7: =(IF(ABERTURAS!$K$17="OK",ABERTURAS!$Q$17+0.26*CHOOSE(ABERTURAS!$N$17,0,$C$13,ABERTURAS!$O$17,ABERTURAS!$O$17),0)+$AZ$9)/$AZ$7 -> 0.041677003 | BW7: =(IF(ABERTURAS!$K$18="OK",CHOOSE(ABERTURAS!$N$18,ABERTURAS!$O$18,ABERTURAS!$O$18+0.42*$C$13,0.42*ABERTURAS!$O$18,$C$12+0.42*ABERTURAS!$O$18),0)+$AZ$8)/$AZ$7 -> 0.30543746 | BX7: =(IF(ABERTURAS!$K$18="OK",ABERTURAS!$Q$18+0.26*CHOOSE(ABERTURAS!$N$18,0,$C$13,ABERTURAS!$O$18,ABERTURAS!$O$18),0)+$AZ$9)/$AZ$7 -> 0.041677003 | BY7: =(IF(ABERTURAS!$K$19="OK",CHOOSE(ABERTURAS!$N$19,ABERTURAS!$O$19,ABERTURAS!$O$19+0.42*$C$13,0.42*ABERTURAS!$O$19,$C$12+0.42*ABERTURAS!$O$19),0)+$AZ$8)/$AZ$7 -> 0.30543746 | BZ7: =(IF(ABERTURAS!$K$19="OK",ABERTURAS!$Q$19+0.26*CHOOSE(ABERTURAS!$N$19,0,$C$13,ABERTURAS!$O$19,ABERTURAS!$O$19),0)+$AZ$9)/$AZ$7 -> 0.041677003 | CA7: =(IF(ABERTURAS!$K$20="OK",CHOOSE(ABERTURAS!$N$20,ABERTURAS!$O$20,ABERTURAS!$O$20+0.42*$C$13,0.42*ABERTURAS!$O$20,$C$12+0.42*ABERTURAS!$O$20),0)+$AZ$8)/$AZ$7 -> 0.30543746 | CB7: =(IF(ABERTURAS!$K$20="OK",ABERTURAS!$Q$20+0.26*CHOOSE(ABERTURAS!$N$20,0,$C$13,ABERTURAS!$O$20,ABERTURAS!$O$20),0)+$AZ$9)/$AZ$7 -> 0.041677003 | CC7: =(IF(ABERTURAS!$K$21="OK",CHOOSE(ABERTURAS!$N$21,ABERTURAS!$O$21,ABERTURAS!$O$21+0.42*$C$13,0.42*ABERTURAS!$O$21,$C$12+0.42*ABERTURAS!$O$21),0)+$AZ$8)/$AZ$7 -> 0.30543746 | CD7: =(IF(ABERTURAS!$K$21="OK",ABERTURAS!$Q$21+0.26*CHOOSE(ABERTURAS!$N$21,0,$C$13,ABERTURAS!$O$21,ABERTURAS!$O$21),0)+$AZ$9)/$AZ$7 -> 0.041677003 | CE7: =(IF(ABERTURAS!$K$22="OK",CHOOSE(ABERTURAS!$N$22,ABERTURAS!$O$22,ABERTURAS!$O$22+0.42*$C$13,0.42*ABERTURAS!$O$22,$C$12+0.42*ABERTURAS!$O$22),0)+$AZ$8)/$AZ$7 -> 0.30543746 | CF7: =(IF(ABERTURAS!$K$22="OK",ABERTURAS!$Q$22+0.26*CHOOSE(ABERTURAS!$N$22,0,$C$13,ABERTURAS!$O$22,ABERTURAS!$O$22),0)+$AZ$9)/$AZ$7 -> 0.041677003 | CG7: =(IF(ABERTURAS!$K$23="OK",CHOOSE(ABERTURAS!$N$23,ABERTURAS!$O$23,ABERTURAS!$O$23+0.42*$C$13,0.42*ABERTURAS!$O$23,$C$12+0.42*ABERTURAS!$O$23),0)+$AZ$8)/$AZ$7 -> 0.30543746 | CH7: =(IF(ABERTURAS!$K$23="OK",ABERTURAS!$Q$23+0.26*CHOOSE(ABERTURAS!$N$23,0,$C$13,ABERTURAS!$O$23,ABERTURAS!$O$23),0)+$AZ$9)/$AZ$7 -> 0.041677003 | CI7: =(IF(ABERTURAS!$K$24="OK",CHOOSE(ABERTURAS!$N$24,ABERTURAS!$O$24,ABERTURAS!$O$24+0.42*$C$13,0.42*ABERTURAS!$O$24,$C$12+0.42*ABERTURAS!$O$24),0)+$AZ$8)/$AZ$7 -> 0.30543746 | CJ7: =(IF(ABERTURAS!$K$24="OK",ABERTURAS!$Q$24+0.26*CHOOSE(ABERTURAS!$N$24,0,$C$13,ABERTURAS!$O$24,ABERTURAS!$O$24),0)+$AZ$9)/$AZ$7 -> 0.041677003 | CK7: =(IF(ABERTURAS!$K$25="OK",CHOOSE(ABERTURAS!$N$25,ABERTURAS!$O$25,ABERTURAS!$O$25+0.42*$C$13,0.42*ABERTURAS!$O$25,$C$12+0.42*ABERTURAS!$O$25),0)+$AZ$8)/$AZ$7 -> 0.30543746 | CL7: =(IF(ABERTURAS!$K$25="OK",ABERTURAS!$Q$25+0.26*CHOOSE(ABERTURAS!$N$25,0,$C$13,ABERTURAS!$O$25,ABERTURAS!$O$25),0)+$AZ$9)/$AZ$7 -> 0.041677003 | CM7: =(IF(ABERTURAS!$K$26="OK",CHOOSE(ABERTURAS!$N$26,ABERTURAS!$O$26,ABERTURAS!$O$26+0.42*$C$13,0.42*ABERTURAS!$O$26,$C$12+0.42*ABERTURAS!$O$26),0)+$AZ$8)/$AZ$7 -> 0.30543746 | CN7: =(IF(ABERTURAS!$K$26="OK",ABERTURAS!$Q$26+0.26*CHOOSE(ABERTURAS!$N$26,0,$C$13,ABERTURAS!$O$26,ABERTURAS!$O$26),0)+$AZ$9)/$AZ$7 -> 0.041677003
B8: Ubicación | C8: Departamento de LA PAZ, EL SALVADOR | E8: CAPTURA. | F8: — | AA8: =$C$23*5/8 -> 10 | AB8: =IF($C$14="PLANO",$C$17,IF($C$14="DOS AGUAS",$C$17+($C$18-$C$17)*(1-ABS(2*($AA$8)/$C$23-1)),IF($C$14="UN AGUA",IF(N($C$25)=0,$C$18-($C$18-$C$17)*($AA$8)/$C$23,$C$17+($C$18-$C$17)*($AA$8)/$C$23),$C$17+4*($C$18-$C$17)*($AA$8)/$C$23*(1-($AA$8)/$C$23)))) -> 10.12 | AE8: =ABERTURAS!$D$51*5/8 -> 6.3 | AF8: =IF(ABERTURAS!$E$51="SÍ",$AB$8,ABERTURAS!$F$51) -> 10.62 | AG8: =($AE8+0.42*0+$AZ$8)/$AZ$7 -> 0.69615936 | AH8: =($AF8+0.26*0+$AZ$9)/$AZ$7 -> 0.7003225 | AI8: =ABERTURAS!$D$52*5/8 -> 6.3 | AJ8: =IF(ABERTURAS!$E$52="SÍ",$AB$8,ABERTURAS!$F$52) -> 9.82 | AK8: =($AI8+0.42*$C$13+$AZ$8)/$AZ$7 -> 1.1129294 | AL8: =($AJ8+0.26*$C$13+$AZ$9)/$AZ$7 -> 0.90870752 | AM8: =ABERTURAS!$D$53*5/8 -> 10 | AN8: =IF(ABERTURAS!$E$53="SÍ",$AB$8,ABERTURAS!$F$53) -> 10.12 | AO8: =(0+0.42*$AM8+$AZ$8)/$AZ$7 -> 0.56591873 | AP8: =($AN8+0.26*$AM8+$AZ$9)/$AZ$7 -> 0.83056314 | AQ8: =ABERTURAS!$D$54*5/8 -> 10 | AR8: =IF(ABERTURAS!$E$54="SÍ",$AB$8,ABERTURAS!$F$54) -> 10.12 | AS8: =($C$12+0.42*$AQ8+$AZ$8)/$AZ$7 -> 1.1910738 | AT8: =($AR8+0.26*$AQ8+$AZ$9)/$AZ$7 -> 0.83056314 | AU8: =(IF($AC$3="X",$AA$7+0.42*IF($AC$3="X",$C$13,$C$12),IF($AC$3="X",$C$13,$C$12)+0.42*$AA$7)+$AZ$8)/$AZ$7 -> 1.1389775 | AV8: =($AB$7+0.26*IF($AC$3="X",IF($AC$3="X",$C$13,$C$12),$AA$7)+$AZ$9)/$AZ$7 -> 0.80451501 | AY8: offX | AZ8: =($AZ$6*$AZ$7-($AZ$3+2*$AZ$5))/2+$AZ$5 -> 4.9248736
AA9: =$C$23*6/8 -> 12 | AB9: =IF($C$14="PLANO",$C$17,IF($C$14="DOS AGUAS",$C$17+($C$18-$C$17)*(1-ABS(2*($AA$9)/$C$23-1)),IF($C$14="UN AGUA",IF(N($C$25)=0,$C$18-($C$18-$C$17)*($AA$9)/$C$23,$C$17+($C$18-$C$17)*($AA$9)/$C$23),$C$17+4*($C$18-$C$17)*($AA$9)/$C$23*(1-($AA$9)/$C$23)))) -> 10.02 | AE9: =ABERTURAS!$D$51*4/8 -> 5.04 | AF9: =IF(ABERTURAS!$E$51="SÍ",$AB$7,ABERTURAS!$F$51) -> 10.62 | AG9: =($AE9+0.42*0+$AZ$8)/$AZ$7 -> 0.61801498 | AH9: =($AF9+0.26*0+$AZ$9)/$AZ$7 -> 0.7003225 | AI9: =ABERTURAS!$D$52*4/8 -> 5.04 | AJ9: =IF(ABERTURAS!$E$52="SÍ",$AB$7,ABERTURAS!$F$52) -> 9.82 | AK9: =($AI9+0.42*$C$13+$AZ$8)/$AZ$7 -> 1.034785 | AL9: =($AJ9+0.26*$C$13+$AZ$9)/$AZ$7 -> 0.90870752 | AM9: =ABERTURAS!$D$53*4/8 -> 8 | AN9: =IF(ABERTURAS!$E$53="SÍ",$AB$7,ABERTURAS!$F$53) -> 10.22 | AO9: =(0+0.42*$AM9+$AZ$8)/$AZ$7 -> 0.51382248 | AP9: =($AN9+0.26*$AM9+$AZ$9)/$AZ$7 -> 0.80451501 | AQ9: =ABERTURAS!$D$54*4/8 -> 8 | AR9: =IF(ABERTURAS!$E$54="SÍ",$AB$7,ABERTURAS!$F$54) -> 10.22 | AS9: =($C$12+0.42*$AQ9+$AZ$8)/$AZ$7 -> 1.1389775 | AT9: =($AR9+0.26*$AQ9+$AZ$9)/$AZ$7 -> 0.80451501 | AU9: =(IF($AC$3="X",$AA$9+0.42*IF($AC$3="X",$C$13,$C$12),IF($AC$3="X",$C$13,$C$12)+0.42*$AA$9)+$AZ$8)/$AZ$7 -> 1.24317 | AV9: =($AB$9+0.26*IF($AC$3="X",IF($AC$3="X",$C$13,$C$12),$AA$9)+$AZ$9)/$AZ$7 -> 0.85661126 | AY9: offY | AZ9: =($AZ$7-($AZ$4+2*$AZ$5))/2+$AZ$5 -> 0.672
B10: 2. GEOMETRÍA DE LA NAVE | AA10: =$C$23*7/8 -> 14 | AB10: =IF($C$14="PLANO",$C$17,IF($C$14="DOS AGUAS",$C$17+($C$18-$C$17)*(1-ABS(2*($AA$10)/$C$23-1)),IF($C$14="UN AGUA",IF(N($C$25)=0,$C$18-($C$18-$C$17)*($AA$10)/$C$23,$C$17+($C$18-$C$17)*($AA$10)/$C$23),$C$17+4*($C$18-$C$17)*($AA$10)/$C$23*(1-($AA$10)/$C$23)))) -> 9.92 | AE10: =ABERTURAS!$D$51*3/8 -> 3.78 | AF10: =IF(ABERTURAS!$E$51="SÍ",$AB$6,ABERTURAS!$F$51) -> 10.62 | AG10: =($AE10+0.42*0+$AZ$8)/$AZ$7 -> 0.5398706 | AH10: =($AF10+0.26*0+$AZ$9)/$AZ$7 -> 0.7003225 | AI10: =ABERTURAS!$D$52*3/8 -> 3.78 | AJ10: =IF(ABERTURAS!$E$52="SÍ",$AB$6,ABERTURAS!$F$52) -> 9.82 | AK10: =($AI10+0.42*$C$13+$AZ$8)/$AZ$7 -> 0.95664064 | AL10: =($AJ10+0.26*$C$13+$AZ$9)/$AZ$7 -> 0.90870752 | AM10: =ABERTURAS!$D$53*3/8 -> 6 | AN10: =IF(ABERTURAS!$E$53="SÍ",$AB$6,ABERTURAS!$F$53) -> 10.32 | AO10: =(0+0.42*$AM10+$AZ$8)/$AZ$7 -> 0.46172622 | AP10: =($AN10+0.26*$AM10+$AZ$9)/$AZ$7 -> 0.77846688 | AQ10: =ABERTURAS!$D$54*3/8 -> 6 | AR10: =IF(ABERTURAS!$E$54="SÍ",$AB$6,ABERTURAS!$F$54) -> 10.32 | AS10: =($C$12+0.42*$AQ10+$AZ$8)/$AZ$7 -> 1.0868813 | AT10: =($AR10+0.26*$AQ10+$AZ$9)/$AZ$7 -> 0.77846688 | AU10: =(IF($AC$3="X",$AA$9+0.42*0,0+0.42*$AA$9)+$AZ$8)/$AZ$7 -> 0.61801498 | AV10: =($AB$9+0.26*IF($AC$3="X",0,$AA$9)+$AZ$9)/$AZ$7 -> 0.85661126
B11: Concepto | C11: Valor | D11: Unidad | E11: Cómo se calcula / de dónde sale | F11: Referencia | AA11: =$C$23*8/8 -> 16 | AB11: =IF($C$14="PLANO",$C$17,IF($C$14="DOS AGUAS",$C$17+($C$18-$C$17)*(1-ABS(2*($AA$11)/$C$23-1)),IF($C$14="UN AGUA",IF(N($C$25)=0,$C$18-($C$18-$C$17)*($AA$11)/$C$23,$C$17+($C$18-$C$17)*($AA$11)/$C$23),$C$17+4*($C$18-$C$17)*($AA$11)/$C$23*(1-($AA$11)/$C$23)))) -> 9.82 | AE11: =ABERTURAS!$D$51*2/8 -> 2.52 | AF11: =IF(ABERTURAS!$E$51="SÍ",$AB$5,ABERTURAS!$F$51) -> 10.62 | AG11: =($AE11+0.42*0+$AZ$8)/$AZ$7 -> 0.46172622 | AH11: =($AF11+0.26*0+$AZ$9)/$AZ$7 -> 0.7003225 | AI11: =ABERTURAS!$D$52*2/8 -> 2.52 | AJ11: =IF(ABERTURAS!$E$52="SÍ",$AB$5,ABERTURAS!$F$52) -> 9.82 | AK11: =($AI11+0.42*$C$13+$AZ$8)/$AZ$7 -> 0.87849625 | AL11: =($AJ11+0.26*$C$13+$AZ$9)/$AZ$7 -> 0.90870752 | AM11: =ABERTURAS!$D$53*2/8 -> 4 | AN11: =IF(ABERTURAS!$E$53="SÍ",$AB$5,ABERTURAS!$F$53) -> 10.42 | AO11: =(0+0.42*$AM11+$AZ$8)/$AZ$7 -> 0.40962997 | AP11: =($AN11+0.26*$AM11+$AZ$9)/$AZ$7 -> 0.75241875 | AQ11: =ABERTURAS!$D$54*2/8 -> 4 | AR11: =IF(ABERTURAS!$E$54="SÍ",$AB$5,ABERTURAS!$F$54) -> 10.42 | AS11: =($C$12+0.42*$AQ11+$AZ$8)/$AZ$7 -> 1.034785 | AT11: =($AR11+0.26*$AQ11+$AZ$9)/$AZ$7 -> 0.75241875 | AU11: =(IF($AC$3="X",$AA$11+0.42*0,0+0.42*$AA$11)+$AZ$8)/$AZ$7 -> 0.72220749 | AV11: =($AB$11+0.26*IF($AC$3="X",0,$AA$11)+$AZ$9)/$AZ$7 -> 0.90870752
B12: B — ancho en X (de Muro 3 a Muro 4) | C12: 10.08 | D12: m | E12: CAPTURA. EJEMPLO: NOSE DOCK, X de 0 a 10.08 m (claro de los marcos). | F12: Modelo STAAD / arquitectónico | AE12: =ABERTURAS!$D$51*1/8 -> 1.26 | AF12: =IF(ABERTURAS!$E$51="SÍ",$AB$4,ABERTURAS!$F$51) -> 10.62 | AG12: =($AE12+0.42*0+$AZ$8)/$AZ$7 -> 0.38358184 | AH12: =($AF12+0.26*0+$AZ$9)/$AZ$7 -> 0.7003225 | AI12: =ABERTURAS!$D$52*1/8 -> 1.26 | AJ12: =IF(ABERTURAS!$E$52="SÍ",$AB$4,ABERTURAS!$F$52) -> 9.82 | AK12: =($AI12+0.42*$C$13+$AZ$8)/$AZ$7 -> 0.80035187 | AL12: =($AJ12+0.26*$C$13+$AZ$9)/$AZ$7 -> 0.90870752 | AM12: =ABERTURAS!$D$53*1/8 -> 2 | AN12: =IF(ABERTURAS!$E$53="SÍ",$AB$4,ABERTURAS!$F$53) -> 10.52 | AO12: =(0+0.42*$AM12+$AZ$8)/$AZ$7 -> 0.35753371 | AP12: =($AN12+0.26*$AM12+$AZ$9)/$AZ$7 -> 0.72637063 | AQ12: =ABERTURAS!$D$54*1/8 -> 2 | AR12: =IF(ABERTURAS!$E$54="SÍ",$AB$4,ABERTURAS!$F$54) -> 10.52 | AS12: =($C$12+0.42*$AQ12+$AZ$8)/$AZ$7 -> 0.98268876 | AT12: =($AR12+0.26*$AQ12+$AZ$9)/$AZ$7 -> 0.72637063 | AU12: =(IF($AC$3="X",$AA$11+0.42*IF($AC$3="X",$C$13,$C$12),IF($AC$3="X",$C$13,$C$12)+0.42*$AA$11)+$AZ$8)/$AZ$7 -> 1.3473625 | AV12: =($AB$11+0.26*IF($AC$3="X",IF($AC$3="X",$C$13,$C$12),$AA$11)+$AZ$9)/$AZ$7 -> 0.90870752
B13: L — largo en Z (de Muro 1 a Muro 2) | C13: 16 | D13: m | E13: CAPTURA. EJEMPLO: NOSE DOCK, Z de 0 a 16.00 m. | F13: Modelo STAAD / arquitectónico | AE13: =ABERTURAS!$D$51*0/8 -> 0 | AF13: =IF(ABERTURAS!$E$51="SÍ",$AB$3,ABERTURAS!$F$51) -> 10.62 | AG13: =($AE13+0.42*0+$AZ$8)/$AZ$7 -> 0.30543746 | AH13: =($AF13+0.26*0+$AZ$9)/$AZ$7 -> 0.7003225 | AI13: =ABERTURAS!$D$52*0/8 -> 0 | AJ13: =IF(ABERTURAS!$E$52="SÍ",$AB$3,ABERTURAS!$F$52) -> 9.82 | AK13: =($AI13+0.42*$C$13+$AZ$8)/$AZ$7 -> 0.72220749 | AL13: =($AJ13+0.26*$C$13+$AZ$9)/$AZ$7 -> 0.90870752 | AM13: =ABERTURAS!$D$53*0/8 -> 0 | AN13: =IF(ABERTURAS!$E$53="SÍ",$AB$3,ABERTURAS!$F$53) -> 10.62 | AO13: =(0+0.42*$AM13+$AZ$8)/$AZ$7 -> 0.30543746 | AP13: =($AN13+0.26*$AM13+$AZ$9)/$AZ$7 -> 0.7003225 | AQ13: =ABERTURAS!$D$54*0/8 -> 0 | AR13: =IF(ABERTURAS!$E$54="SÍ",$AB$3,ABERTURAS!$F$54) -> 10.62 | AS13: =($C$12+0.42*$AQ13+$AZ$8)/$AZ$7 -> 0.93059251 | AT13: =($AR13+0.26*$AQ13+$AZ$9)/$AZ$7 -> 0.7003225
B14: Tipo de techo | C14: UN AGUA | D14: — | E14: SELECTOR: DOS AGUAS, UN AGUA, PLANO o CURVO. | F14: NTV 1997 · 4.3.1, pág. 5 · Tabla 4.2, pág. 6 | AE14: =0 -> 0 | AF14: =0 -> 0 | AG14: =($AE14+0.42*0+$AZ$8)/$AZ$7 -> 0.30543746 | AH14: =($AF14+0.26*0+$AZ$9)/$AZ$7 -> 0.041677003 | AI14: =0 -> 0 | AJ14: =0 -> 0 | AK14: =($AI14+0.42*$C$13+$AZ$8)/$AZ$7 -> 0.72220749 | AL14: =($AJ14+0.26*$C$13+$AZ$9)/$AZ$7 -> 0.2996775 | AM14: =0 -> 0 | AN14: =0 -> 0 | AO14: =(0+0.42*$AM14+$AZ$8)/$AZ$7 -> 0.30543746 | AP14: =($AN14+0.26*$AM14+$AZ$9)/$AZ$7 -> 0.041677003 | AQ14: =0 -> 0 | AR14: =0 -> 0 | AS14: =($C$12+0.42*$AQ14+$AZ$8)/$AZ$7 -> 0.93059251 | AT14: =($AR14+0.26*$AQ14+$AZ$9)/$AZ$7 -> 0.041677003
B15: El agua escurre hacia (sólo UN AGUA) | C15: MURO 2 (Z = L) | D15: — | E15: SELECTOR. El muro por donde baja el agua; el lado alto queda en el muro opuesto. Muro 3 = izquierda, Muro 4 = derecha, Muro 1 = atrás, Muro 2 = frente (como en la vista de STAAD). EJEMPLO: NOSE DOCK, alto en el eje 1 y bajo en el eje 4. | F15: Croquis / arquitectónico
B16: Cumbrera (o eje del arco) paralela a (DOS AGUAS y CURVO) | C16: L (EJE Z) | D16: — | E16: SELECTOR. L (EJE Z): cumbrera a lo largo, hastiales en Muros 1 y 2. B (EJE X): cumbrera de lado a lado, hastiales en Muros 3 y 4. | F16: Croquis / arquitectónico
B17: h_a — altura baja (alero, o lado bajo en UN AGUA) | C17: 9.82 | D17: m | E17: CAPTURA. Del piso al alero. EJEMPLO: NOSE DOCK, 9.82 m en el eje 4 (nodos 13 y 16). | F17: Modelo STAAD / arquitectónico
B18: h_c — altura alta (cumbrera, clave o lado alto) | C18: 10.62 | D18: m | E18: CAPTURA. Con techo PLANO no se usa. EJEMPLO: NOSE DOCK, 10.62 m en el eje 1 (nodos 20 y 21). | F18: Modelo STAAD / arquitectónico
B19: ¿El arco arranca desde el suelo? (sólo CURVO) | C19: NO | D19: — | E19: SELECTOR. Con SÍ la zona A1 de la Tabla 4.2 pasa a empuje 1.4r ≤ 0.9. | F19: NTV 1997 · Tabla 4.2, pág. 6
B20: Separación típica entre marcos | C20: 6.75 | D20: m | E20: CAPTURA. Sólo para la carga de un marco intermedio en 2D (PRESIONES §F). EJEMPLO: ejes 1-2 y 2-3 del NOSE DOCK. | F20: Modelo STAAD / arquitectónico
B21: H — altura máxima de la nave | C21: =IF($C$14="PLANO",$C$17,MAX($C$17,$C$18)) -> 10.62 | D21: m | E21: CALCULADA. | F21: —
B22: Eje de la pendiente del techo | C22: =IF($C$14="PLANO","—",IF($C$14="UN AGUA",IF(OR(LEFT($C$15,6)="MURO 1",LEFT($C$15,6)="MURO 2"),"Z","X"),IF(LEFT($C$16,1)="L","X","Z"))) -> Z | D22: — | E22: CALCULADA. Dirección en la que cambia la altura del techo (s va de 0 a S en ese eje). | F22: Croquis
B23: S — claro en el sentido de la pendiente | C23: =IF($C$22="Z",$C$13,$C$12) -> 16 | D23: m | E23: CALCULADA. | F23: —
B24: Lado alto del techo (UN AGUA) | C24: =IF($C$14<>"UN AGUA","—",CHOOSE(VALUE(MID($C$15,6,1)),"MURO 2","MURO 1","MURO 4","MURO 3")) -> MURO 1 | D24: — | E24: CALCULADA: el muro opuesto al que escurre el agua. | F24: Croquis
B25: s del lado alto (UN AGUA) | C25: =IF($C$14<>"UN AGUA","—",IF(OR($C$24="MURO 1",$C$24="MURO 3"),0,$C$23)) -> 0 | D25: m | E25: CALCULADA. 0 si el lado alto está en X = 0 o Z = 0; S si está en el otro extremo. | F25: —
B26: θ — inclinación del techo | C26: =IF($C$14="DOS AGUAS",DEGREES(ATAN(($C$18-$C$17)/($C$23/2))),IF($C$14="UN AGUA",DEGREES(ATAN(($C$18-$C$17)/$C$23)),0)) -> 2.8624052 | D26: ° | E26: CALCULADA. Decide el C_p del faldón de barlovento. | F26: NTV 1997 · 4.3.1, pág. 5
B27: Pendiente del techo | C27: =TAN(RADIANS($C$26)) -> 0.05 | D27: % | E27: CALCULADA. | F27: —
B28: Revisión de la geometría | C28: =IF(OR(N($C$12)<=0,N($C$13)<=0),"FALTA B o L",IF(AND(N($C$17)<=0,NOT(AND($C$14="CURVO",$C$19="SÍ"))),"FALTA h_a",IF(AND($C$14<>"PLANO",N($C$18)<=N($C$17)),"h_c debe ser mayor que h_a (salvo techo PLANO)",IF(AND($C$14="CURVO",PRESIONES!$C$17>0.6),"Techo curvo con r > 0.6: fuera de la Tabla 4.2","OK")))) -> OK | D28: — | E28: CALCULADA. Debe decir OK. | F28: —
B29: Croquis con tus datos (se actualiza solo): muros numerados como en ABERTURAS, PRESIONES y LINEAS; en rojo las aberturas. Proyección oblicua: X a la derecha, Y arriba y Z hacia el fondo del dibujo (el Muro 1, Z = 0, con puerta y cortina, se dibuja adelante; en la vista de STAAD queda atrás).
B52: 3. EXPOSICIÓN Y TIPO DE ESTRUCTURA
B53: Concepto | C53: Valor | D53: Unidad | E53: Cómo se calcula / de dónde sale | F53: Referencia
B54: Zona de exposición | C54: C | D54: — | E54: SELECTOR. A: muchos edificios altos alrededor; B: construcciones medianas o bajas, o árboles; C: terreno abierto (aeropuertos, campo, costa). EJEMPLO: C por estar en aeropuerto. | F54: NTV 1997 · Tabla 4.1, pág. 5
B55: K — factor de exposición | C55: =INDEX(TABLAS!$D$7:$D$9,MATCH($C$54,TABLAS!$B$7:$B$9,0)) -> 1.6 | D55: — | E55: CALCULADA de la Tabla 4.1. | F55: NTV 1997 · Tabla 4.1, pág. 5
B56: a — exponente de variación con la altura | C56: =INDEX(TABLAS!$E$7:$E$9,MATCH($C$54,TABLAS!$B$7:$B$9,0)) -> 7 | D56: — | E56: CALCULADA. C_z = 1 hasta 10 m y (z/10)^(2/a) arriba. | F56: NTV 1997 · 4.2 y Tabla 4.1, pág. 5
B57: P_o — presión básica de diseño | C57: 30 | D57: kg/m² | E57: FIJA por la norma (80 km/h a 10 m). | F57: NTV 1997 · 2.1, pág. 2 · 4.1, pág. 5
B58: T — periodo natural de la nave | C58: 0.579 | D58: s | E58: CAPTURA. Periodo del modo dominante de STAAD (R1.5: réplica del modelo con HSS16x8x5/16, T = 0.579 s en Z y 0.489 s en X); cámbialo por el de tu output. | F58: NTV 1997 · 3.1, pág. 3
B59: Esbeltez = H / dimensión menor en planta | C59: =$C$21/MIN($C$12,$C$13) -> 1.0535714 | D59: — | E59: CALCULADA. | F59: NTV 1997 · 2.1, pág. 2 · 3.1, pág. 3
B60: Tipo de estructura | C60: =IF(AND($C$59<=5,$C$58<=2),"TIPO 1","TIPO 2") -> TIPO 1 | D60: — | E60: CALCULADA. Tipo 1: esbeltez ≤ 5 y T ≤ 2 s. Tipo 2: presiones × 1.3 por ráfaga. El Tipo 3 (vórtices) no lo cubre esta hoja. | F60: NTV 1997 · 3.1, pág. 3 · 4.6.1, pág. 7
B61: FR — factor por ráfaga | C61: =IF($C$60="TIPO 2",1.3,1) -> 1 | D61: — | E61: CALCULADA. | F61: NTV 1997 · 4.6.1, pág. 7
B63: 4. CASOS DE VIENTO PARA STAAD
...

Sheet ABERTURAS
B1: ABERTURAS POR MURO (POSICIÓN Y TAMAÑO) Y PRESIÓN INTERIOR
B2: Captura cada abertura donde está: portones, cortinas, puertas, ventanas, louvers o un muro que no se forra. Con eso la hoja dibuja los muros, saca el área abierta de cada escenario, decide la presión interior (NTV 4.4, pág. 7) y descuenta las aberturas de las cargas de LINEAS.
B3: CÓMO SE LLENA: un renglón por abertura. x = distancia horizontal desde la esquina con el Muro 3 (en Muros 1 y 2, igual a la X de STAAD) o desde la esquina con el Muro 1 (en Muros 3 y 4, igual a la Z de STAAD); y = altura del piso a la parte baja. FIJA = siempre abierta (vano sin cerrar, louver, muro sin forro). OPERABLE = puerta o cortina: cerrada en los casos normales y abierta en los casos PA. Deja en blanco lo que no uses.
B5: A. LISTA DE ABERTURAS | N5: auxiliares (no se tocan) | Y5: auxiliares de la elevación (no se tocan)
B6: # | C6: Descripción | D6: Muro | E6: Tipo | F6: x desde (m) | G6: y desde (m) | H6: Ancho (m) | I6: Alto (m) | J6: Área (m²) | K6: ¿Cabe en el muro? | L6: Nota / de dónde sale | N6: nº muro | O6: u₁ | P6: u₂ | Q6: v₁ | R6: v₂ | S6: tope en u₁ | T6: tope en u₂ | U6: abierta CERR | V6: abierta PA | W6: largo muro | Y6: hueco | Z6: =MAX(1.5,0.1*MAX(DATOS!$C$12,DATOS!$C$13)) -> 1.6 | AA6: desfase | AB6: =0 -> 0 | AC6: =$D$51+$Z$6 -> 11.68 | AD6: =$D$51+$D$52+2*$Z$6 -> 23.36 | AE6: =$D$51+$D$52+$D$53+3*$Z$6 -> 40.96
